Workbook

Sheet 2024 Store Reset Summary
C1: Average % | F1: =AVERAGE(F11:F80,F82:F87) -> 0.037817117 | G1: =AVERAGE(G11:G80,F82:F87) -> 0.074467745 | H1: =AVERAGE(H11:H87) -> -0.0061948052
C2: # of Stores Beating Kohler Avg | F2: {=SUMPRODUCT(--(F11:F87>H11:H87))} -> 52 | G2: {=SUMPRODUCT(--(G11:G87>H11:H87))} -> 58 | P2: & Change | T2: Case Change
C3: # of Stores Where Constellation > All Kohler Brands | G3: {=SUMPRODUCT(--(G11:G87>F11:F87))} -> 48 | P3: Acct Class | Q3: All Brands | R3: Constellation | T3: Acct Class | U3: All Brands | V3: Constellation
P4: A | Q4: =AVERAGEIF(B11:B86,"A",F11:F86) -> 0.059717179 | R4: =AVERAGEIF($B$11:$B$86,P4,$G$11:$G$86) -> 0.086316976 | T4: A | U4: =AVERAGEIF($B$11:$B$86,T4, $J$11:$J$86) -> 828.7 | V4: =AVERAGEIF($B$11:$B$86,T4, $K$11:$K$86) -> 660.8
P5: B | Q5: =AVERAGEIF(B11:B86,"B",F11:F86) -> 0.060482101 | R5: =AVERAGEIF($B$11:$B$86,P5,$G$11:$G$86) -> 0.14657076 | T5: B | U5: =AVERAGEIF($B$11:$B$86,T5, $J$11:$J$86) -> 198.19048 | V5: =AVERAGEIF($B$11:$B$86,T5, $K$11:$K$86) -> 279.85714
P6: C | Q6: =AVERAGEIF(B11:B86,"C",F11:F86) -> 0.013725815 | R6: =AVERAGEIF($B$11:$B$86,P6,$G$11:$G$86) -> -0.0068097032 | T6: C | U6: =AVERAGEIF($B$11:$B$86,T6, $J$11:$J$86) -> 50.466667 | V6: =AVERAGEIF($B$11:$B$86,T6, $K$11:$K$86) -> 60.133333
F8: Reset Date - 12/31/2024
F9: ACCOUNT SPECIFIC: Case Sold % Change (2023 vs 2024) | H9: ALL ACCOUNTS: Kohler Sales % Difference (2023 vs 2024)
B10: Segmentation | C10: Customer Name | D10: Address | E10: Reset Date | F10: All Kohler Brands | G10: Constellation Brands | I10: when matching selling days | J10: All Kohler Brands | K10: Constellation Brands
B11: =_xlfn.XLOOKUP(C11,'2024 Store Reset Data'!B:B,'2024 Store Reset Data'!H:H,"") -> A | C11: ='2024 Store Reset Data'!B30 -> BOMBOLOM LIQUORS | D11: =_xlfn.XLOOKUP(C11,'2024 Store Reset Data'!B:B,'2024 Store Reset Data'!E:E,"") -> 192 E 16TH ST, PATERSON | E11: =_xlfn.XLOOKUP(C11,'2024 Store Reset Data'!B:B, '2024 Store Reset Data'!I:I, "") -> 45400 | F11: =_xlfn.XLOOKUP(C11,'2024 Store Reset Data'!B:B,'2024 Store Reset Data'!M:M,"") -> 0.35009017 | G11: =_xlfn.XLOOKUP(C11,'2024 Store Reset Data'!B:B,'2024 Store Reset Data'!R:R,"") -> 0.338 | H11: -0.012 | J11: =_xlfn.XLOOKUP(C11,'2024 Store Reset Data'!$B$3:$B$80,'2024 Store Reset Data'!$L$3:$L$80,"") -> 3106 | K11: =_xlfn.XLOOKUP(C11,'2024 Store Reset Data'!$B$3:$B$80,'2024 Store Reset Data'!$Q$3:$Q$80,"") -> 2028
B12: =_xlfn.XLOOKUP(C12,'2024 Store Reset Data'!B:B,'2024 Store Reset Data'!H:H,"") -> A | C12: ='2024 Store Reset Data'!B29 -> FARMBOY SUPER FRESH LIQUOR | D12: =_xlfn.XLOOKUP(C12,'2024 Store Reset Data'!B:B,'2024 Store Reset Data'!E:E,"") -> 465 GETTY AVE, PATERSON | E12: =_xlfn.XLOOKUP(C12,'2024 Store Reset Data'!B:B, '2024 Store Reset Data'!I:I, "") -> 45399 | F12: =_xlfn.XLOOKUP(C12,'2024 Store Reset Data'!B:B,'2024 Store Reset Data'!M:M,"") -> 0.34612839 | G12: =_xlfn.XLOOKUP(C12,'2024 Store Reset Data'!B:B,'2024 Store Reset Data'!R:R,"") -> 0.35066185 | H12: -0.014 | J12: =_xlfn.XLOOKUP(C12,'2024 Store Reset Data'!$B$3:$B$80,'2024 Store Reset Data'!$L$3:$L$80,"") -> 4184 | K12: =_xlfn.XLOOKUP(C12,'2024 Store Reset Data'!$B$3:$B$80,'2024 Store Reset Data'!$Q$3:$Q$80,"") -> 2914
B13: =_xlfn.XLOOKUP(C13,'2024 Store Reset Data'!B:B,'2024 Store Reset Data'!H:H,"") -> A | C13: ='2024 Store Reset Data'!B48 -> C TOWN LIQUOR | D13: =_xlfn.XLOOKUP(C13,'2024 Store Reset Data'!B:B,'2024 Store Reset Data'!E:E,"") -> 444 20TH AVE, PATERSON | E13: =_xlfn.XLOOKUP(C13,'2024 Store Reset Data'!B:B, '2024 Store Reset Data'!I:I, "") -> 45425 | F13: =_xlfn.XLOOKUP(C13,'2024 Store Reset Data'!B:B,'2024 Store Reset Data'!M:M,"") -> 0.30773067 | G13: =_xlfn.XLOOKUP(C13,'2024 Store Reset Data'!B:B,'2024 Store Reset Data'!R:R,"") -> 0.38671255 | H13: 0.002 | J13: =_xlfn.XLOOKUP(C13,'2024 Store Reset Data'!$B$3:$B$80,'2024 Store Reset Data'!$L$3:$L$80,"") -> 1851 | K13: =_xlfn.XLOOKUP(C13,'2024 Store Reset Data'!$B$3:$B$80,'2024 Store Reset Data'!$Q$3:$Q$80,"") -> 1461
B14: =_xlfn.XLOOKUP(C14,'2024 Store Reset Data'!B:B,'2024 Store Reset Data'!H:H,"") -> B | C14: ='2024 Store Reset Data'!B77 -> GARYS | D14: =_xlfn.XLOOKUP(C14,'2024 Store Reset Data'!B:B,'2024 Store Reset Data'!E:E,"") -> 67 VER VALEN ST, CLOSTER | E14: =_xlfn.XLOOKUP(C14,'2024 Store Reset Data'!B:B, '2024 Store Reset Data'!I:I, "") -> 45603 | F14: =_xlfn.XLOOKUP(C14,'2024 Store Reset Data'!B:B,'2024 Store Reset Data'!M:M,"") -> 0.2876304 | G14: =_xlfn.XLOOKUP(C14,'2024 Store Reset Data'!B:B,'2024 Store Reset Data'!R:R,"") -> 0.3878327 | H14: -0.021 | J14: =_xlfn.XLOOKUP(C14,'2024 Store Reset Data'!$B$3:$B$80,'2024 Store Reset Data'!$L$3:$L$80,"") -> 386 | K14: =_xlfn.XLOOKUP(C14,'2024 Store Reset Data'!$B$3:$B$80,'2024 Store Reset Data'!$Q$3:$Q$80,"") -> 102
B15: =_xlfn.XLOOKUP(C15,'2024 Store Reset Data'!B:B,'2024 Store Reset Data'!H:H,"") -> A | C15: ='2024 Store Reset Data'!B15 -> GARDEN LIQUORS & WINES | D15: =_xlfn.XLOOKUP(C15,'2024 Store Reset Data'!B:B,'2024 Store Reset Data'!E:E,"") -> 300 HARRISON AVE, LODI | E15: =_xlfn.XLOOKUP(C15,'2024 Store Reset Data'!B:B, '2024 Store Reset Data'!I:I, "") -> 45384 | F15: =_xlfn.XLOOKUP(C15,'2024 Store Reset Data'!B:B,'2024 Store Reset Data'!M:M,"") -> 0.24650276 | G15: =_xlfn.XLOOKUP(C15,'2024 Store Reset Data'!B:B,'2024 Store Reset Data'!R:R,"") -> 0.35511864 | H15: -0.007 | J15: =_xlfn.XLOOKUP(C15,'2024 Store Reset Data'!$B$3:$B$80,'2024 Store Reset Data'!$L$3:$L$80,"") -> 3489 | K15: =_xlfn.XLOOKUP(C15,'2024 Store Reset Data'!$B$3:$B$80,'2024 Store Reset Data'!$Q$3:$Q$80,"") -> 2619
B16: =_xlfn.XLOOKUP(C16,'2024 Store Reset Data'!B:B,'2024 Store Reset Data'!H:H,"") -> A | C16: ='2024 Store Reset Data'!B72 -> BUY RITE LIQUOR LODI | D16: =_xlfn.XLOOKUP(C16,'2024 Store Reset Data'!B:B,'2024 Store Reset Data'!E:E,"") -> 449 MAIN ST, LODI | E16: =_xlfn.XLOOKUP(C16,'2024 Store Reset Data'!B:B, '2024 Store Reset Data'!I:I, "") -> 45580 | F16: =_xlfn.XLOOKUP(C16,'2024 Store Reset Data'!B:B,'2024 Store Reset Data'!M:M,"") -> 0.23645546 | G16: =_xlfn.XLOOKUP(C16,'2024 Store Reset Data'!B:B,'2024 Store Reset Data'!R:R,"") -> 0.33980583 | H16: 0.029 | J16: =_xlfn.XLOOKUP(C16,'2024 Store Reset Data'!$B$3:$B$80,'2024 Store Reset Data'!$L$3:$L$80,"") -> 515 | K16: =_xlfn.XLOOKUP(C16,'2024 Store Reset Data'!$B$3:$B$80,'2024 Store Reset Data'!$Q$3:$Q$80,"") -> 280
B17: =_xlfn.XLOOKUP(C17,'2024 Store Reset Data'!B:B,'2024 Store Reset Data'!H:H,"") -> B | C17: ='2024 Store Reset Data'!B53 -> CAPRI LIQUOR & DELI | D17: =_xlfn.XLOOKUP(C17,'2024 Store Reset Data'!B:B,'2024 Store Reset Data'!E:E,"") -> 226 PATERSON AVE, EAST RUTHERFORD | E17: =_xlfn.XLOOKUP(C17,'2024 Store Reset Data'!B:B, '2024 Store Reset Data'!I:I, "") -> 45432 | F17: =_xlfn.XLOOKUP(C17,'2024 Store Reset Data'!B:B,'2024 Store Reset Data'!M:M,"") -> 0.23110494 | G17: =_xlfn.XLOOKUP(C17,'2024 Store Reset Data'!B:B,'2024 Store Reset Data'!R:R,"") -> 0.2095165 | H17: 0.01 | J17: =_xlfn.XLOOKUP(C17,'2024 Store Reset Data'!$B$3:$B$80,'2024 Store Reset Data'!$L$3:$L$80,"") -> 1165 | K17: =_xlfn.XLOOKUP(C17,'2024 Store Reset Data'!$B$3:$B$80,'2024 Store Reset Data'!$Q$3:$Q$80,"") -> 546
B18: =_xlfn.XLOOKUP(C18,'2024 Store Reset Data'!B:B,'2024 Store Reset Data'!H:H,"") -> A | C18: ='2024 Store Reset Data'!B75 -> HIGH SPIRITS (Exquisite W & L (A)) | D18: =_xlfn.XLOOKUP(C18,'2024 Store Reset Data'!B:B,'2024 Store Reset Data'!E:E,"") -> 215 MAIN ST, RIDGEFIELD PARK | E18: =_xlfn.XLOOKUP(C18,'2024 Store Reset Data'!B:B, '2024 Store Reset Data'!I:I, "") -> 45593 | F18: =_xlfn.XLOOKUP(C18,'2024 Store Reset Data'!B:B,'2024 Store Reset Data'!M:M,"") -> 0.22828428 | G18: =_xlfn.XLOOKUP(C18,'2024 Store Reset Data'!B:B,'2024 Store Reset Data'!R:R,"") -> 0.20533333 | H18: 0.03 | J18: =_xlfn.XLOOKUP(C18,'2024 Store Reset Data'!$B$3:$B$80,'2024 Store Reset Data'!$L$3:$L$80,"") -> 636 | K18: =_xlfn.XLOOKUP(C18,'2024 Store Reset Data'!$B$3:$B$80,'2024 Store Reset Data'!$Q$3:$Q$80,"") -> 231
B19: =_xlfn.XLOOKUP(C19,'2024 Store Reset Data'!B:B,'2024 Store Reset Data'!H:H,"") -> A | C19: ='2024 Store Reset Data'!B37 -> THE LIQUOR SHOP | D19: =_xlfn.XLOOKUP(C19,'2024 Store Reset Data'!B:B,'2024 Store Reset Data'!E:E,"") -> 498 E 30TH ST, PATERSON | E19: =_xlfn.XLOOKUP(C19,'2024 Store Reset Data'!B:B, '2024 Store Reset Data'!I:I, "") -> 45411 | F19: =_xlfn.XLOOKUP(C19,'2024 Store Reset Data'!B:B,'2024 Store Reset Data'!M:M,"") -> 0.21611755 | G19: =_xlfn.XLOOKUP(C19,'2024 Store Reset Data'!B:B,'2024 Store Reset Data'!R:R,"") -> 0.21893268 | H19: 0.001 | J19: =_xlfn.XLOOKUP(C19,'2024 Store Reset Data'!$B$3:$B$80,'2024 Store Reset Data'!$L$3:$L$80,"") -> 4795 | K19: =_xlfn.XLOOKUP(C19,'2024 Store Reset Data'!$B$3:$B$80,'2024 Store Reset Data'!$Q$3:$Q$80,"") -> 3483
B20: =_xlfn.XLOOKUP(C20,'2024 Store Reset Data'!B:B,'2024 Store Reset Data'!H:H,"") -> B | C20: ='2024 Store Reset Data'!B78 -> FINE WINE & SPIRITS | D20: =_xlfn.XLOOKUP(C20,'2024 Store Reset Data'!B:B,'2024 Store Reset Data'!E:E,"") -> 14 RIVEREDGE RD, TENAFLY | E20: =_xlfn.XLOOKUP(C20,'2024 Store Reset Data'!B:B, '2024 Store Reset Data'!I:I, "") -> 45614 | F20: =_xlfn.XLOOKUP(C20,'2024 Store Reset Data'!B:B,'2024 Store Reset Data'!M:M,"") -> 0.21076747 | G20: =_xlfn.XLOOKUP(C20,'2024 Store Reset Data'!B:B,'2024 Store Reset Data'!R:R,"") -> 0.67628205 | H20: -0.006 | J20: =_xlfn.XLOOKUP(C20,'2024 Store Reset Data'!$B$3:$B$80,'2024 Store Reset Data'!$L$3:$L$80,"") -> 184 | K20: =_xlfn.XLOOKUP(C20,'2024 Store Reset Data'!$B$3:$B$80,'2024 Store Reset Data'!$Q$3:$Q$80,"") -> 211
B21: =_xlfn.XLOOKUP(C21,'2024 Store Reset Data'!B:B,'2024 Store Reset Data'!H:H,"") -> C | C21: ='2024 Store Reset Data'!B71 -> PETES LIQUORS | D21: =_xlfn.XLOOKUP(C21,'2024 Store Reset Data'!B:B,'2024 Store Reset Data'!E:E,"") -> 383 VALLEY RD, CLIFTON | E21: =_xlfn.XLOOKUP(C21,'2024 Store Reset Data'!B:B, '2024 Store Reset Data'!I:I, "") -> 45574 | F21: =_xlfn.XLOOKUP(C21,'2024 Store Reset Data'!B:B,'2024 Store Reset Data'!M:M,"") -> 0.19595645 | G21: =_xlfn.XLOOKUP(C21,'2024 Store Reset Data'!B:B,'2024 Store Reset Data'!R:R,"") -> 0.24183007 | H21: -0.01 | J21: =_xlfn.XLOOKUP(C21,'2024 Store Reset Data'!$B$3:$B$80,'2024 Store Reset Data'!$L$3:$L$80,"") -> 252 | K21: =_xlfn.XLOOKUP(C21,'2024 Store Reset Data'!$B$3:$B$80,'2024 Store Reset Data'!$Q$3:$Q$80,"") -> 111
B22: =_xlfn.XLOOKUP(C22,'2024 Store Reset Data'!B:B,'2024 Store Reset Data'!H:H,"") -> A | C22: ='2024 Store Reset Data'!B60 -> SUPER FRESH LIQUORS (Food Universe Marketplace) | D22: =_xlfn.XLOOKUP(C22,'2024 Store Reset Data'!B:B,'2024 Store Reset Data'!E:E,"") -> 937 LINCOLN AVE, GLEN ROCK | E22: =_xlfn.XLOOKUP(C22,'2024 Store Reset Data'!B:B, '2024 Store Reset Data'!I:I, "") -> 45456 | F22: =_xlfn.XLOOKUP(C22,'2024 Store Reset Data'!B:B,'2024 Store Reset Data'!M:M,"") -> 0.18659509 | G22: =_xlfn.XLOOKUP(C22,'2024 Store Reset Data'!B:B,'2024 Store Reset Data'!R:R,"") -> 0.30936948 | H22: -0.007 | J22: =_xlfn.XLOOKUP(C22,'2024 Store Reset Data'!$B$3:$B$80,'2024 Store Reset Data'!$L$3:$L$80,"") -> 1147 | K22: =_xlfn.XLOOKUP(C22,'2024 Store Reset Data'!$B$3:$B$80,'2024 Store Reset Data'!$Q$3:$Q$80,"") -> 525
B23: =_xlfn.XLOOKUP(C23,'2024 Store Reset Data'!B:B,'2024 Store Reset Data'!H:H,"") -> A | C23: ='2024 Store Reset Data'!B43 -> C & S LUCKY LIQUORS | D23: =_xlfn.XLOOKUP(C23,'2024 Store Reset Data'!B:B,'2024 Store Reset Data'!E:E,"") -> 299 GRAND ST, PATERSON | E23: =_xlfn.XLOOKUP(C23,'2024 Store Reset Data'!B:B, '2024 Store Reset Data'!I:I, "") -> 45418 | F23: =_xlfn.XLOOKUP(C23,'2024 Store Reset Data'!B:B,'2024 Store Reset Data'!M:M,"") -> 0.17440067 | G23: =_xlfn.XLOOKUP(C23,'2024 Store Reset Data'!B:B,'2024 Store Reset Data'!R:R,"") -> 0.23053502 | H23: -0.001 | J23: =_xlfn.XLOOKUP(C23,'2024 Store Reset Data'!$B$3:$B$80,'2024 Store Reset Data'!$L$3:$L$80,"") -> 1244 | K23: =_xlfn.XLOOKUP(C23,'2024 Store Reset Data'!$B$3:$B$80,'2024 Store Reset Data'!$Q$3:$Q$80,"") -> 1060
B24: =_xlfn.XLOOKUP(C24,'2024 Store Reset Data'!B:B,'2024 Store Reset Data'!H:H,"") -> B | C24: ='2024 Store Reset Data'!B5 -> TEANECK LIQUORS | D24: =_xlfn.XLOOKUP(C24,'2024 Store Reset Data'!B:B,'2024 Store Reset Data'!E:E,"") -> 1531 TEANECK RD, TEANECK | E24: =_xlfn.XLOOKUP(C24,'2024 Store Reset Data'!B:B, '2024 Store Reset Data'!I:I, "") -> 45327 | F24: =_xlfn.XLOOKUP(C24,'2024 Store Reset Data'!B:B,'2024 Store Reset Data'!M:M,"") -> 0.16508224 | G24: =_xlfn.XLOOKUP(C24,'2024 Store Reset Data'!B:B,'2024 Store Reset Data'!R:R,"") -> 0.22796846 | H24: 0.001 | J24: =_xlfn.XLOOKUP(C24,'2024 Store Reset Data'!$B$3:$B$80,'2024 Store Reset Data'!$L$3:$L$80,"") -> 1094 | K24: =_xlfn.XLOOKUP(C24,'2024 Store Reset Data'!$B$3:$B$80,'2024 Store Reset Data'!$Q$3:$Q$80,"") -> 983
B25: =_xlfn.XLOOKUP(C25,'2024 Store Reset Data'!B:B,'2024 Store Reset Data'!H:H,"") -> A | C25: ='2024 Store Reset Data'!B57 -> SHOPRITE LIQUORS (Englewood) | D25: =_xlfn.XLOOKUP(C25,'2024 Store Reset Data'!B:B,'2024 Store Reset Data'!E:E,"") -> 53 NATHANIEL PL, ENGLEWOOD | E25: =_xlfn.XLOOKUP(C25,'2024 Store Reset Data'!B:B, '2024 Store Reset Data'!I:I, "") -> 45447 | F25: =_xlfn.XLOOKUP(C25,'2024 Store Reset Data'!B:B,'2024 Store Reset Data'!M:M,"") -> 0.15986026 | G25: =_xlfn.XLOOKUP(C25,'2024 Store Reset Data'!B:B,'2024 Store Reset Data'!R:R,"") -> 0.21834096 | H25: 0.002 | J25: =_xlfn.XLOOKUP(C25,'2024 Store Reset Data'!$B$3:$B$80,'2024 Store Reset Data'!$L$3:$L$80,"") -> 3981 | K25: =_xlfn.XLOOKUP(C25,'2024 Store Reset Data'!$B$3:$B$80,'2024 Store Reset Data'!$Q$3:$Q$80,"") -> 2719
B26: =_xlfn.XLOOKUP(C26,'2024 Store Reset Data'!B:B,'2024 Store Reset Data'!H:H,"") -> C | C26: ='2024 Store Reset Data'!B79 -> PAY LESS LIQUOR & DELI | D26: =_xlfn.XLOOKUP(C26,'2024 Store Reset Data'!B:B,'2024 Store Reset Data'!E:E,"") -> 251 ELM ST, ELMWOOD PARK | E26: =_xlfn.XLOOKUP(C26,'2024 Store Reset Data'!B:B, '2024 Store Reset Data'!I:I, "") -> 45616 | F26: =_xlfn.XLOOKUP(C26,'2024 Store Reset Data'!B:B,'2024 Store Reset Data'!M:M,"") -> 0.15896488 | G26: =_xlfn.XLOOKUP(C26,'2024 Store Reset Data'!B:B,'2024 Store Reset Data'!R:R,"") -> 0.089361702 | H26: -0.006 | J26: =_xlfn.XLOOKUP(C26,'2024 Store Reset Data'!$B$3:$B$80,'2024 Store Reset Data'!$L$3:$L$80,"") -> 86 | K26: =_xlfn.XLOOKUP(C26,'2024 Store Reset Data'!$B$3:$B$80,'2024 Store Reset Data'!$Q$3:$Q$80,"") -> 21
B27: =_xlfn.XLOOKUP(C27,'2024 Store Reset Data'!B:B,'2024 Store Reset Data'!H:H,"") -> B | C27: ='2024 Store Reset Data'!B31 -> METRO LIQUORS | D27: =_xlfn.XLOOKUP(C27,'2024 Store Reset Data'!B:B,'2024 Store Reset Data'!E:E,"") -> 100 BROADWAY, ELMWOOD PARK | E27: =_xlfn.XLOOKUP(C27,'2024 Store Reset Data'!B:B, '2024 Store Reset Data'!I:I, "") -> 45400 | F27: =_xlfn.XLOOKUP(C27,'2024 Store Reset Data'!B:B,'2024 Store Reset Data'!M:M,"") -> 0.14152441 | G27: =_xlfn.XLOOKUP(C27,'2024 Store Reset Data'!B:B,'2024 Store Reset Data'!R:R,"") -> 0.19727602 | H27: -0.012 | J27: =_xlfn.XLOOKUP(C27,'2024 Store Reset Data'!$B$3:$B$80,'2024 Store Reset Data'!$L$3:$L$80,"") -> 1426 | K27: =_xlfn.XLOOKUP(C27,'2024 Store Reset Data'!$B$3:$B$80,'2024 Store Reset Data'!$Q$3:$Q$80,"") -> 927
B28: =_xlfn.XLOOKUP(C28,'2024 Store Reset Data'!B:B,'2024 Store Reset Data'!H:H,"") -> B | C28: ='2024 Store Reset Data'!B34 -> METRO LIQUORS | D28: =_xlfn.XLOOKUP(C28,'2024 Store Reset Data'!B:B,'2024 Store Reset Data'!E:E,"") -> 100 BROADWAY, ELMWOOD PARK | E28: =_xlfn.XLOOKUP(C28,'2024 Store Reset Data'!B:B, '2024 Store Reset Data'!I:I, "") -> 45400 | F28: =_xlfn.XLOOKUP(C28,'2024 Store Reset Data'!B:B,'2024 Store Reset Data'!M:M,"") -> 0.14152441 | G28: =_xlfn.XLOOKUP(C28,'2024 Store Reset Data'!B:B,'2024 Store Reset Data'!R:R,"") -> 0.19727602 | H28: -0.012 | J28: =_xlfn.XLOOKUP(C28,'2024 Store Reset Data'!$B$3:$B$80,'2024 Store Reset Data'!$L$3:$L$80,"") -> 1426 | K28: =_xlfn.XLOOKUP(C28,'2024 Store Reset Data'!$B$3:$B$80,'2024 Store Reset Data'!$Q$3:$Q$80,"") -> 927
B29: =_xlfn.XLOOKUP(C29,'2024 Store Reset Data'!B:B,'2024 Store Reset Data'!H:H,"") -> B | C29: ='2024 Store Reset Data'!B67 -> SANDYS WINE & SPIRITS | D29: =_xlfn.XLOOKUP(C29,'2024 Store Reset Data'!B:B,'2024 Store Reset Data'!E:E,"") -> 98 US HWY 46, BUDD LAKE | E29: =_xlfn.XLOOKUP(C29,'2024 Store Reset Data'!B:B, '2024 Store Reset Data'!I:I, "") -> 45561 | F29: =_xlfn.XLOOKUP(C29,'2024 Store Reset Data'!B:B,'2024 Store Reset Data'!M:M,"") -> 0.13711512 | G29: =_xlfn.XLOOKUP(C29,'2024 Store Reset Data'!B:B,'2024 Store Reset Data'!R:R,"") -> 0.45134731 | H29: -0.007 | J29: =_xlfn.XLOOKUP(C29,'2024 Store Reset Data'!$B$3:$B$80,'2024 Store Reset Data'!$L$3:$L$80,"") -> 904 | K29: =_xlfn.XLOOKUP(C29,'2024 Store Reset Data'!$B$3:$B$80,'2024 Store Reset Data'!$Q$3:$Q$80,"") -> 603
B30: =_xlfn.XLOOKUP(C30,'2024 Store Reset Data'!B:B,'2024 Store Reset Data'!H:H,"") -> B | C30: ='2024 Store Reset Data'!B14 -> FOREST DAIRY LIQUOR STORE | D30: =_xlfn.XLOOKUP(C30,'2024 Store Reset Data'!B:B,'2024 Store Reset Data'!E:E,"") -> 10 SPRING DELL, RUTHERFORD | E30: =_xlfn.XLOOKUP(C30,'2024 Store Reset Data'!B:B, '2024 Store Reset Data'!I:I, "") -> 45383 | F30: =_xlfn.XLOOKUP(C30,'2024 Store Reset Data'!B:B,'2024 Store Reset Data'!M:M,"") -> 0.12191104 | G30: =_xlfn.XLOOKUP(C30,'2024 Store Reset Data'!B:B,'2024 Store Reset Data'!R:R,"") -> 0.083892617 | H30: -0.007 | J30: =_xlfn.XLOOKUP(C30,'2024 Store Reset Data'!$B$3:$B$80,'2024 Store Reset Data'!$L$3:$L$80,"") -> 222 | K30: =_xlfn.XLOOKUP(C30,'2024 Store Reset Data'!$B$3:$B$80,'2024 Store Reset Data'!$Q$3:$Q$80,"") -> 50
B31: =_xlfn.XLOOKUP(C31,'2024 Store Reset Data'!B:B,'2024 Store Reset Data'!H:H,"") -> A | C31: ='2024 Store Reset Data'!B16 -> CLIFTON DISCOUNT LIQUORS | D31: =_xlfn.XLOOKUP(C31,'2024 Store Reset Data'!B:B,'2024 Store Reset Data'!E:E,"") -> 73 ACKERMAN AVE, CLIFTON | E31: =_xlfn.XLOOKUP(C31,'2024 Store Reset Data'!B:B, '2024 Store Reset Data'!I:I, "") -> 45385 | F31: =_xlfn.XLOOKUP(C31,'2024 Store Reset Data'!B:B,'2024 Store Reset Data'!M:M,"") -> 0.11257161 | G31: =_xlfn.XLOOKUP(C31,'2024 Store Reset Data'!B:B,'2024 Store Reset Data'!R:R,"") -> 0.13479884 | H31: -0.007 | J31: =_xlfn.XLOOKUP(C31,'2024 Store Reset Data'!$B$3:$B$80,'2024 Store Reset Data'!$L$3:$L$80,"") -> 4539 | K31: =_xlfn.XLOOKUP(C31,'2024 Store Reset Data'!$B$3:$B$80,'2024 Store Reset Data'!$Q$3:$Q$80,"") -> 3575
B32: =_xlfn.XLOOKUP(C32,'2024 Store Reset Data'!B:B,'2024 Store Reset Data'!H:H,"") -> A | C32: ='2024 Store Reset Data'!B27 -> HOME WINES & LIQUORS | D32: =_xlfn.XLOOKUP(C32,'2024 Store Reset Data'!B:B,'2024 Store Reset Data'!E:E,"") -> 593 MAIN AVE, PASSAIC | E32: =_xlfn.XLOOKUP(C32,'2024 Store Reset Data'!B:B, '2024 Store Reset Data'!I:I, "") -> 45397 | F32: =_xlfn.XLOOKUP(C32,'2024 Store Reset Data'!B:B,'2024 Store Reset Data'!M:M,"") -> 0.10922227 | G32: =_xlfn.XLOOKUP(C32,'2024 Store Reset Data'!B:B,'2024 Store Reset Data'!R:R,"") -> 0.15393481 | H32: -0.008 | J32: =_xlfn.XLOOKUP(C32,'2024 Store Reset Data'!$B$3:$B$80,'2024 Store Reset Data'!$L$3:$L$80,"") -> 3855 | K32: =_xlfn.XLOOKUP(C32,'2024 Store Reset Data'!$B$3:$B$80,'2024 Store Reset Data'!$Q$3:$Q$80,"") -> 3339
B33: =_xlfn.XLOOKUP(C33,'2024 Store Reset Data'!B:B,'2024 Store Reset Data'!H:H,"") -> A | C33: ='2024 Store Reset Data'!B58 -> SHOPPERS VINEYARD | D33: =_xlfn.XLOOKUP(C33,'2024 Store Reset Data'!B:B,'2024 Store Reset Data'!E:E,"") -> 875 BLOOMFIELD AVE, CLIFTON | E33: =_xlfn.XLOOKUP(C33,'2024 Store Reset Data'!B:B, '2024 Store Reset Data'!I:I, "") -> 45448 | F33: =_xlfn.XLOOKUP(C33,'2024 Store Reset Data'!B:B,'2024 Store Reset Data'!M:M,"") -> 0.10768722 | G33: =_xlfn.XLOOKUP(C33,'2024 Store Reset Data'!B:B,'2024 Store Reset Data'!R:R,"") -> 0.10883776 | H33: -0.006 | J33: =_xlfn.XLOOKUP(C33,'2024 Store Reset Data'!$B$3:$B$80,'2024 Store Reset Data'!$L$3:$L$80,"") -> 3257 | K33: =_xlfn.XLOOKUP(C33,'2024 Store Reset Data'!$B$3:$B$80,'2024 Store Reset Data'!$Q$3:$Q$80,"") -> 1665
B34: =_xlfn.XLOOKUP(C34,'2024 Store Reset Data'!B:B,'2024 Store Reset Data'!H:H,"") -> A | C34: ='2024 Store Reset Data'!B65 -> REGALADO LIQUORS | D34: =_xlfn.XLOOKUP(C34,'2024 Store Reset Data'!B:B,'2024 Store Reset Data'!E:E,"") -> 168 MARKET ST, PASSAIC | E34: =_xlfn.XLOOKUP(C34,'2024 Store Reset Data'!B:B, '2024 Store Reset Data'!I:I, "") -> 45552 | F34: =_xlfn.XLOOKUP(C34,'2024 Store Reset Data'!B:B,'2024 Store Reset Data'!M:M,"") -> 0.094362497 | G34: =_xlfn.XLOOKUP(C34,'2024 Store Reset Data'!B:B,'2024 Store Reset Data'!R:R,"") -> 0.066152477 | H34: 0.023 | J34: =_xlfn.XLOOKUP(C34,'2024 Store Reset Data'!$B$3:$B$80,'2024 Store Reset Data'!$L$3:$L$80,"") -> 467 | K34: =_xlfn.XLOOKUP(C34,'2024 Store Reset Data'!$B$3:$B$80,'2024 Store Reset Data'!$Q$3:$Q$80,"") -> 223
B35: =_xlfn.XLOOKUP(C35,'2024 Store Reset Data'!B:B,'2024 Store Reset Data'!H:H,"") -> A | C35: ='2024 Store Reset Data'!B19 -> LIQUOR STOP | D35: =_xlfn.XLOOKUP(C35,'2024 Store Reset Data'!B:B,'2024 Store Reset Data'!E:E,"") -> 321 BROADWAY, PASSAIC | E35: =_xlfn.XLOOKUP(C35,'2024 Store Reset Data'!B:B, '2024 Store Reset Data'!I:I, "") -> 45387 | F35: =_xlfn.XLOOKUP(C35,'2024 Store Reset Data'!B:B,'2024 Store Reset Data'!M:M,"") -> 0.087017814 | G35: =_xlfn.XLOOKUP(C35,'2024 Store Reset Data'!B:B,'2024 Store Reset Data'!R:R,"") -> 0.04536121 | H35: -0.007 | J35: =_xlfn.XLOOKUP(C35,'2024 Store Reset Data'!$B$3:$B$80,'2024 Store Reset Data'!$L$3:$L$80,"") -> 679 | K35: =_xlfn.XLOOKUP(C35,'2024 Store Reset Data'!$B$3:$B$80,'2024 Store Reset Data'!$Q$3:$Q$80,"") -> 243
B36: =_xlfn.XLOOKUP(C36,'2024 Store Reset Data'!B:B,'2024 Store Reset Data'!H:H,"") -> B | C36: ='2024 Store Reset Data'!B63 -> RIDGEFIELD LIQUOR | D36: =_xlfn.XLOOKUP(C36,'2024 Store Reset Data'!B:B,'2024 Store Reset Data'!E:E,"") -> 520 SHALER BLVD, RIDGEFIELD | E36: =_xlfn.XLOOKUP(C36,'2024 Store Reset Data'!B:B, '2024 Store Reset Data'!I:I, "") -> 45531 | F36: =_xlfn.XLOOKUP(C36,'2024 Store Reset Data'!B:B,'2024 Store Reset Data'!M:M,"") -> 0.081925243 | G36: =_xlfn.XLOOKUP(C36,'2024 Store Reset Data'!B:B,'2024 Store Reset Data'!R:R,"") -> 0.15256588 | H36: -0.004 | J36: =_xlfn.XLOOKUP(C36,'2024 Store Reset Data'!$B$3:$B$80,'2024 Store Reset Data'!$L$3:$L$80,"") -> 160 | K36: =_xlfn.XLOOKUP(C36,'2024 Store Reset Data'!$B$3:$B$80,'2024 Store Reset Data'!$Q$3:$Q$80,"") -> 110
B37: =_xlfn.XLOOKUP(C37,'2024 Store Reset Data'!B:B,'2024 Store Reset Data'!H:H,"") -> C | C37: ='2024 Store Reset Data'!B33 -> CARISMA LIQUORS | D37: =_xlfn.XLOOKUP(C37,'2024 Store Reset Data'!B:B,'2024 Store Reset Data'!E:E,"") -> 234 VREELAND AVE, PATERSON | E37: =_xlfn.XLOOKUP(C37,'2024 Store Reset Data'!B:B, '2024 Store Reset Data'!I:I, "") -> 45405 | F37: =_xlfn.XLOOKUP(C37,'2024 Store Reset Data'!B:B,'2024 Store Reset Data'!M:M,"") -> 0.079859895 | G37: =_xlfn.XLOOKUP(C37,'2024 Store Reset Data'!B:B,'2024 Store Reset Data'!R:R,"") -> 0.11138614 | H37: -0.004 | J37: =_xlfn.XLOOKUP(C37,'2024 Store Reset Data'!$B$3:$B$80,'2024 Store Reset Data'!$L$3:$L$80,"") -> 456 | K37: =_xlfn.XLOOKUP(C37,'2024 Store Reset Data'!$B$3:$B$80,'2024 Store Reset Data'!$Q$3:$Q$80,"") -> 360
B38: =_xlfn.XLOOKUP(C38,'2024 Store Reset Data'!B:B,'2024 Store Reset Data'!H:H,"") -> A | C38: ='2024 Store Reset Data'!B20 -> SUNNYS LIQUORS | D38: =_xlfn.XLOOKUP(C38,'2024 Store Reset Data'!B:B,'2024 Store Reset Data'!E:E,"") -> 413 MONROE ST, PASSAIC | E38: =_xlfn.XLOOKUP(C38,'2024 Store Reset Data'!B:B, '2024 Store Reset Data'!I:I, "") -> 45390 | F38: =_xlfn.XLOOKUP(C38,'2024 Store Reset Data'!B:B,'2024 Store Reset Data'!M:M,"") -> 0.077918845 | G38: =_xlfn.XLOOKUP(C38,'2024 Store Reset Data'!B:B,'2024 Store Reset Data'!R:R,"") -> 0.050653744 | H38: -0.005 | J38: =_xlfn.XLOOKUP(C38,'2024 Store Reset Data'!$B$3:$B$80,'2024 Store Reset Data'!$L$3:$L$80,"") -> 1252 | K38: =_xlfn.XLOOKUP(C38,'2024 Store Reset Data'!$B$3:$B$80,'2024 Store Reset Data'!$Q$3:$Q$80,"") -> 554
B39: =_xlfn.XLOOKUP(C39,'2024 Store Reset Data'!B:B,'2024 Store Reset Data'!H:H,"") -> A | C39: ='2024 Store Reset Data'!B38 -> SUPER WINE WAREHOUSE | D39: =_xlfn.XLOOKUP(C39,'2024 Store Reset Data'!B:B,'2024 Store Reset Data'!E:E,"") -> 42 E 30TH ST, PATERSON | E39: =_xlfn.XLOOKUP(C39,'2024 Store Reset Data'!B:B, '2024 Store Reset Data'!I:I, "") -> 45412 | F39: =_xlfn.XLOOKUP(C39,'2024 Store Reset Data'!B:B,'2024 Store Reset Data'!M:M,"") -> 0.076166391 | G39: =_xlfn.XLOOKUP(C39,'2024 Store Reset Data'!B:B,'2024 Store Reset Data'!R:R,"") -> 0.032811868 | H39: -0.005 | J39: =_xlfn.XLOOKUP(C39,'2024 Store Reset Data'!$B$3:$B$80,'2024 Store Reset Data'!$L$3:$L$80,"") -> 4367 | K39: =_xlfn.XLOOKUP(C39,'2024 Store Reset Data'!$B$3:$B$80,'2024 Store Reset Data'!$Q$3:$Q$80,"") -> 1055
B40: =_xlfn.XLOOKUP(C40,'2024 Store Reset Data'!B:B,'2024 Store Reset Data'!H:H,"") -> A | C40: ='2024 Store Reset Data'!B25 -> EDGEWATER WINE & SPIRITS | D40: =_xlfn.XLOOKUP(C40,'2024 Store Reset Data'!B:B,'2024 Store Reset Data'!E:E,"") -> 547 RIVER RD, EDGEWATER | E40: =_xlfn.XLOOKUP(C40,'2024 Store Reset Data'!B:B, '2024 Store Reset Data'!I:I, "") -> 45393 | F40: =_xlfn.XLOOKUP(C40,'2024 Store Reset Data'!B:B,'2024 Store Reset Data'!M:M,"") -> 0.074304834 | G40: =_xlfn.XLOOKUP(C40,'2024 Store Reset Data'!B:B,'2024 Store Reset Data'!R:R,"") -> 0.20394208 | H40: -0.013 | J40: =_xlfn.XLOOKUP(C40,'2024 Store Reset Data'!$B$3:$B$80,'2024 Store Reset Data'!$L$3:$L$80,"") -> 644 | K40: =_xlfn.XLOOKUP(C40,'2024 Store Reset Data'!$B$3:$B$80,'2024 Store Reset Data'!$Q$3:$Q$80,"") -> 507
B41: =_xlfn.XLOOKUP(C41,'2024 Store Reset Data'!B:B,'2024 Store Reset Data'!H:H,"") -> B | C41: ='2024 Store Reset Data'!B42 -> BELMONT LIQUORS | D41: =_xlfn.XLOOKUP(C41,'2024 Store Reset Data'!B:B,'2024 Store Reset Data'!E:E,"") -> 136 BELMONT AVE, PATERSON | E41: =_xlfn.XLOOKUP(C41,'2024 Store Reset Data'!B:B, '2024 Store Reset Data'!I:I, "") -> 45418 | F41: =_xlfn.XLOOKUP(C41,'2024 Store Reset Data'!B:B,'2024 Store Reset Data'!M:M,"") -> 0.069016153 | G41: =_xlfn.XLOOKUP(C41,'2024 Store Reset Data'!B:B,'2024 Store Reset Data'!R:R,"") -> 0.088867188 | H41: -0.001 | J41: =_xlfn.XLOOKUP(C41,'2024 Store Reset Data'!$B$3:$B$80,'2024 Store Reset Data'!$L$3:$L$80,"") -> 235 | K41: =_xlfn.XLOOKUP(C41,'2024 Store Reset Data'!$B$3:$B$80,'2024 Store Reset Data'!$Q$3:$Q$80,"") -> 182
...

Sheet 2024 Store Reset Data
A1: 2024 SFS SUBMISSIONS | O1: Constellation Sales | S1: Constellation Placements
A2: TD Linx # | B2: Account Name | C2: Address | D2: City | E2: Column 1 | F2: State | G2: Zip | H2: Segmentation | I2: RESET DATE | J2: 2023 Sales | K2: 2024 Sales | M2: Percentage Change | N2: 2024 Sales Trend | O2: 2023 Sales | P2: 2024 Sales | Q2: Case Change | R2: Percentage Change | S2: 2023 Placements | T2: 2024 Placements | U2: Placement Count Difference
A3: 767151 | B3: SHOPRITE LIQUORS (Lincoln Park) | C3: 60 BEAVERBROOK RD | D3: LINCOLN PARK | E3: =C3 & ", " & D3 -> 60 BEAVERBROOK RD, LINCOLN PARK | F3: NEW JERSEY | G3: 7035 | H3: B | I3: 45309 | J3: 24792 | K3: 23167 | L3: =K3-J3 -> -1625 | M3: =(K3-J3)/J3 -> -0.065545337 | O3: 3479 | P3: 4326 | Q3: =P3-O3 -> 847 | R3: =(P3-O3)/O3 -> 0.24346076 | S3: 47 | T3: 66 | U3: =T3-S3 -> 19
A4: 7467043 | B4: SHOPRITE LIQUORS (Wallington) | C4: 375 PATERSON AVE STE C | D4: WALLINGTON | E4: =C4 & ", " & D4 -> 375 PATERSON AVE STE C, WALLINGTON | F4: NEW JERSEY | G4: 7057 | H4: A | I4: 45323 | J4: 16318 | K4: 17364 | L4: =K4-J4 -> 1046 | M4: =(K4-J4)/J4 -> 0.064100993 | O4: 3800 | P4: 4120 | Q4: =P4-O4 -> 320 | R4: =(P4-O4)/O4 -> 0.084210526 | S4: 31 | T4: 44 | U4: =T4-S4 -> 13
A5: 883429 | B5: TEANECK LIQUORS | C5: 1531 TEANECK RD | D5: TEANECK | E5: =C5 & ", " & D5 -> 1531 TEANECK RD, TEANECK | F5: NEW JERSEY | G5: 7666 | H5: B | I5: 45327 | J5: 6627 | K5: 7721 | L5: =K5-J5 -> 1094 | M5: =(K5-J5)/J5 -> 0.16508224 | O5: 4312 | P5: 5295 | Q5: =P5-O5 -> 983 | R5: =(P5-O5)/O5 -> 0.22796846 | S5: 37 | T5: 43 | U5: =T5-S5 -> 6
A6: 7523110 | B6: WIDES DELI & LIQUORS | C6: 85 CENTRAL AVE | D6: RIDGEFIELD PARK | E6: =C6 & ", " & D6 -> 85 CENTRAL AVE, RIDGEFIELD PARK | F6: NEW JERSEY | G6: 7660 | H6: C | I6: 45330 | J6: 2445 | K6: 2160 | L6: =K6-J6 -> -285 | M6: =(K6-J6)/J6 -> -0.11656442 | O6: 1278 | P6: 1166 | Q6: =P6-O6 -> -112 | R6: =(P6-O6)/O6 -> -0.087636933 | S6: 26 | T6: 29 | U6: =T6-S6 -> 3
A7: 889755 | B7: LIQUOR GALLERY | C7: 459 MCBRIDE AVE | D7: PATERSON | E7: =C7 & ", " & D7 -> 459 MCBRIDE AVE, PATERSON | F7: NEW JERSEY | G7: 7501 | H7: A | I7: 45349 | J7: 12571 | K7: 11341 | L7: =K7-J7 -> -1230 | M7: =(K7-J7)/J7 -> -0.097844245 | O7: 7343 | P7: 6716 | Q7: =P7-O7 -> -627 | R7: =(P7-O7)/O7 -> -0.085387444 | S7: 57 | T7: 57 | U7: =T7-S7 -> 0
A8: 1456887 | B8: GARDEN STATE DAIRY & LIQUOR | C8: 135 OAKLAND AVE | D8: CLOSTER | E8: =C8 & ", " & D8 -> 135 OAKLAND AVE, CLOSTER | F8: NEW JERSEY | G8: 7624 | H8: C | I8: 45355 | J8: 8731 | K8: 9155 | L8: =K8-J8 -> 424 | M8: =(K8-J8)/J8 -> 0.048562593 | O8: 3780 | P8: 4177 | Q8: =P8-O8 -> 397 | R8: =(P8-O8)/O8 -> 0.10502646 | S8: 35 | T8: 46 | U8: =T8-S8 -> 11
A9: 766558 | B9: PAULISON LIQUORS | C9: 621 PAULISON AVE | D9: CLIFTON | E9: =C9 & ", " & D9 -> 621 PAULISON AVE, CLIFTON | F9: NEW JERSEY | G9: 7011 | H9: B | I9: 45357 | J9: 10194 | K9: 10386 | L9: =K9-J9 -> 192 | M9: =(K9-J9)/J9 -> 0.018834609 | O9: 6752 | P9: 6793 | Q9: =P9-O9 -> 41 | R9: =(P9-O9)/O9 -> 0.0060722749 | S9: 38 | T9: 44 | U9: =T9-S9 -> 6
A10: 766455 | B10: PALS WINE & LIQUOR | C10: 241 UNION AVE | D10: PATERSON | E10: =C10 & ", " & D10 -> 241 UNION AVE, PATERSON | F10: NEW JERSEY | G10: 7502 | H10: A | I10: 45365 | J10: 17092 | K10: 17538 | L10: =K10-J10 -> 446 | M10: =(K10-J10)/J10 -> 0.026094079 | O10: 9021 | P10: 9890 | Q10: =P10-O10 -> 869 | R10: =(P10-O10)/O10 -> 0.096330784 | S10: 46 | T10: 46 | U10: =T10-S10 -> 0
A11: 6954 | B11: SHOPRITE LIQUORS (Clifton) | C11: 895 PAULISON AVE | D11: CLIFTON | E11: =C11 & ", " & D11 -> 895 PAULISON AVE, CLIFTON | F11: NEW JERSEY | G11: 7011 | H11: A | I11: 45371 | J11: 38609 | K11: 34221 | L11: =K11-J11 -> -4388 | M11: =(K11-J11)/J11 -> -0.11365226 | O11: 19572 | P11: 18500 | Q11: =P11-O11 -> -1072 | R11: =(P11-O11)/O11 -> -0.054772123 | S11: 71 | T11: 75 | U11: =T11-S11 -> 4
A12: 2231918 | B12: ECONOMY LIQUORS | C12: 186 5TH AVE | D12: PATERSON | E12: =C12 & ", " & D12 -> 186 5TH AVE, PATERSON | F12: NEW JERSEY | G12: 7524 | H12: A | I12: 45372 | J12: 26410 | K12: 27720 | L12: =K12-J12 -> 1310 | M12: =(K12-J12)/J12 -> 0.049602423 | O12: 17659 | P12: 18478 | Q12: =P12-O12 -> 819 | R12: =(P12-O12)/O12 -> 0.046378617 | S12: 48 | T12: 51 | U12: =T12-S12 -> 3
A13: 764427 | B13: LUNA LIQUORS | C13: 291 PARK AVE | D13: PATERSON | E13: =C13 & ", " & D13 -> 291 PARK AVE, PATERSON | F13: NEW JERSEY | G13: 7513 | H13: A | I13: 45378 | J13: 15173 | K13: 15262 | L13: =K13-J13 -> 89 | M13: =(K13-J13)/J13 -> 0.0058656825 | O13: 10189 | P13: 10236 | Q13: =P13-O13 -> 47 | R13: =(P13-O13)/O13 -> 0.0046128177 | S13: 34 | T13: 31 | U13: =T13-S13 -> -3
A14: 7355829 | B14: FOREST DAIRY LIQUOR STORE | C14: 10 SPRING DELL | D14: RUTHERFORD | E14: =C14 & ", " & D14 -> 10 SPRING DELL, RUTHERFORD | F14: NEW JERSEY | G14: 7070 | H14: B | I14: 45383 | J14: 1821 | K14: 2043 | L14: =K14-J14 -> 222 | M14: =(K14-J14)/J14 -> 0.12191104 | O14: 596 | P14: 646 | Q14: =P14-O14 -> 50 | R14: =(P14-O14)/O14 -> 0.083892617 | S14: 28 | T14: 29 | U14: =T14-S14 -> 1
... A40: 883666 | B40: JOHNNYS LIQUORS | C40: 370 MONROE ST | D40: PASSAIC | E40: =C40 & ", " & D40 -> 370 MONROE ST, PASSAIC | F40: NEW JERSEY | G40: 7055 | H40: A | I40: 45413 | J40: 13228 | K40: 12832 | L40: =K40-J40 -> -396 | M40: =(K40-J40)/J40 -> -0.029936498 | O40: 9658 | P40: 9240 | Q40: =P40-O40 -> -418 | R40: =(P40-O40)/O40 -> -0.043280182 | S40: 50 | T40: 50 | U40: =T40-S40 -> 0
A41: 1692898 | B41: KRAUSERS | C41: 121 VALLEY BROOK AVE | D41: LYNDHURST | E41: =C41 & ", " & D41 -> 121 VALLEY BROOK AVE, LYNDHURST | F41: NEW JERSEY | G41: 7071 | H41: C | I41: 45415 | J41: Only showing data for 2024
A42: 763269 | B42: BELMONT LIQUORS | C42: 136 BELMONT AVE | D42: PATERSON | E42: =C42 & ", " & D42 -> 136 BELMONT AVE, PATERSON | F42: NEW JERSEY | G42: 7522 | H42: B | I42: 45418 | J42: 3405 | K42: 3640 | L42: =K42-J42 -> 235 | M42: =(K42-J42)/J42 -> 0.069016153 | O42: 2048 | P42: 2230 | Q42: =P42-O42 -> 182 | R42: =(P42-O42)/O42 -> 0.088867188 | S42: 23 | T42: 30 | U42: =T42-S42 -> 7
A43: 889760 | B43: C & S LUCKY LIQUORS | C43: 299 GRAND ST | D43: PATERSON | E43: =C43 & ", " & D43 -> 299 GRAND ST, PATERSON | F43: NEW JERSEY | G43: 7501 | H43: A | I43: 45418 | J43: 7133 | K43: 8377 | L43: =K43-J43 -> 1244 | M43: =(K43-J43)/J43 -> 0.17440067 | O43: 4598 | P43: 5658 | Q43: =P43-O43 -> 1060 | R43: =(P43-O43)/O43 -> 0.23053502 | S43: 45 | T43: 51 | U43: =T43-S43 -> 6
A44: 883814 | B44: MORLOT WINES & LIQUORS | C44: 22 10 MORLOT AVE | D44: FAIR LAWN | E44: =C44 & ", " & D44 -> 22 10 MORLOT AVE, FAIR LAWN | F44: NEW JERSEY | G44: 7410 | H44: C | I44: 45419 | J44: 1834 | K44: 1760 | L44: =K44-J44 -> -74 | M44: =(K44-J44)/J44 -> -0.040348964 | O44: 695 | P44: 666 | Q44: =P44-O44 -> -29 | R44: =(P44-O44)/O44 -> -0.041726619 | S44: 19 | T44: 21 | U44: =T44-S44 -> 2
A45: 883383 | B45: PARKER LIQUOR | C45: 203 PARKER AVE | D45: CLIFTON | E45: =C45 & ", " & D45 -> 203 PARKER AVE, CLIFTON | F45: NEW JERSEY | G45: 7011 | H45: A | I45: 45420 | J45: 15517 | K45: 13755 | L45: =K45-J45 -> -1762 | M45: =(K45-J45)/J45 -> -0.11355288 | O45: 9374 | P45: 8850 | Q45: =P45-O45 -> -524 | R45: =(P45-O45)/O45 -> -0.055899296 | S45: 44 | T45: 50 | U45: =T45-S45 -> 6
A46: 883810 | B46: RADBURN LIQUORS | C46: 14-35 PLAZA RD | D46: FAIR LAWN | E46: =C46 & ", " & D46 -> 14-35 PLAZA RD, FAIR LAWN | F46: NEW JERSEY | G46: 7410 | H46: B | I46: 45420 | J46: 3331 | K46: 3068 | L46: =K46-J46 -> -263 | M46: =(K46-J46)/J46 -> -0.078955269 | O46: 927 | P46: 825 | Q46: =P46-O46 -> -102 | R46: =(P46-O46)/O46 -> -0.11003236 | S46: 25 | T46: 25 | U46: =T46-S46 -> 0
A47: 883668 | B47: PRESIDENT WINES & LIQUORS | C47: 158 PRESIDENT ST | D47: PASSAIC | E47: =C47 & ", " & D47 -> 158 PRESIDENT ST, PASSAIC | F47: NEW JERSEY | G47: 7055 | H47: A | I47: 45421 | J47: 12837 | K47: 11943 | L47: =K47-J47 -> -894 | M47: =(K47-J47)/J47 -> -0.06964244 | O47: 8428 | P47: 8411 | Q47: =P47-O47 -> -17 | R47: =(P47-O47)/O47 -> -0.0020170859 | S47: 44 | T47: 51 | U47: =T47-S47 -> 7
A48: 7355731 | B48: C TOWN LIQUOR | C48: 444 20TH AVE | D48: PATERSON | E48: =C48 & ", " & D48 -> 444 20TH AVE, PATERSON | F48: NEW JERSEY | G48: 7513 | H48: A | I48: 45425 | J48: 6015 | K48: 7866 | L48: =K48-J48 -> 1851 | M48: =(K48-J48)/J48 -> 0.30773067 | O48: 3778 | P48: 5239 | Q48: =P48-O48 -> 1461 | R48: =(P48-O48)/O48 -> 0.38671255 | S48: 45 | T48: 54 | U48: =T48-S48 -> 9
A49: 7355866 | B49: C TOWN LIQUORS | C49: 680 MAIN ST | D49: PATERSON | E49: =C49 & ", " & D49 -> 680 MAIN ST, PATERSON | F49: NEW JERSEY | G49: 7503 | H49: B | I49: 45426 | J49: 3003 | K49: 2863 | L49: =K49-J49 -> -140 | M49: =(K49-J49)/J49 -> -0.046620047 | O49: 1765 | P49: 1920 | Q49: =P49-O49 -> 155 | R49: =(P49-O49)/O49 -> 0.087818697 | S49: 43 | T49: 45 | U49: =T49-S49 -> 2
A50: 883652 | B50: BERMUDA LIQUORS | C50: 177 HOPE AVE | D50: PASSAIC | E50: =C50 & ", " & D50 -> 177 HOPE AVE, PASSAIC | F50: NEW JERSEY | G50: 7055 | H50: A | I50: 45427 | J50: 11456 | K50: 11940 | L50: =K50-J50 -> 484 | M50: =(K50-J50)/J50 -> 0.042248603 | O50: 7134 | P50: 7115 | Q50: =P50-O50 -> -19 | R50: =(P50-O50)/O50 -> -0.0026633025 | S50: 44 | T50: 50 | U50: =T50-S50 -> 6
A51: 764602 | B51: FIGLARS LIQUOR STORE | C51: 327 HOPE AVE | D51: CLIFTON | E51: =C51 & ", " & D51 -> 327 HOPE AVE, CLIFTON | F51: NEW JERSEY | G51: 7011 | H51: A | I51: 45427 | J51: 10407 | K51: 9704 | L51: =K51-J51 -> -703 | M51: =(K51-J51)/J51 -> -0.067550687 | O51: 7154 | P51: 5939 | Q51: =P51-O51 -> -1215 | R51: =(P51-O51)/O51 -> -0.16983506 | S51: 51 | T51: 52 | U51: =T51-S51 -> 1
A52: 883625 | B52: SHANIK LIQUORS | C52: 952 MAIN AVE | D52: PASSAIC | E52: =C52 & ", " & D52 -> 952 MAIN AVE, PASSAIC | F52: NEW JERSEY | G52: 7055 | H52: A | I52: 45428 | J52: 13334 | K52: 12004 | L52: =K52-J52 -> -1330 | M52: =(K52-J52)/J52 -> -0.099745013 | O52: 8911 | P52: 7954 | Q52: =P52-O52 -> -957 | R52: =(P52-O52)/O52 -> -0.10739535 | S52: 53 | T52: 50 | U52: =T52-S52 -> -3
A53: 883781 | B53: CAPRI LIQUOR & DELI | C53: 226 PATERSON AVE | D53: EAST RUTHERFORD | E53: =C53 & ", " & D53 -> 226 PATERSON AVE, EAST RUTHERFORD | F53: NEW JERSEY | G53: 7073 | H53: B | I53: 45432 | J53: 5041 | K53: 6206 | L53: =K53-J53 -> 1165 | M53: =(K53-J53)/J53 -> 0.23110494 | O53: 2606 | P53: 3152 | Q53: =P53-O53 -> 546 | R53: =(P53-O53)/O53 -> 0.2095165 | S53: 53 | T53: 52 | U53: =T53-S53 -> -1
... A68: 883599 | B68: ARCHIES LIQUOR | C68: 229 MAIN AVE | D68: PASSAIC | E68: =C68 & ", " & D68 -> 229 MAIN AVE, PASSAIC | F68: NEW JERSEY | G68: 7055 | H68: A | I68: 45567 | J68: 4632 | K68: 3801 | L68: =K68-J68 -> -831 | M68: =(K68-J68)/J68 -> -0.17940415 | O68: 2473 | P68: 2218 | Q68: =P68-O68 -> -255 | R68: =(P68-O68)/O68 -> -0.10311363 | S68: 33 | T68: 44 | U68: =T68-S68 -> 11
A69: 7355818 | B69: QUICK CHEK LIQUOR | C69: 70 MAIN ST | D69: NETCONG | E69: =C69 & ", " & D69 -> 70 MAIN ST, NETCONG | F69: NEW JERSEY | G69: 7857 | H69: C | I69: 45568 | J69: Only showing data for 2024
A70: 7355901 | B70: ORADELL LIQUOR | C70: 219 KINDERKAMACK RD | D70: ORADELL | E70: =C70 & ", " & D70 -> 219 KINDERKAMACK RD, ORADELL | F70: NEW JERSEY | G70: 7649 | H70: C | I70: 45573 | J70: 694 | K70: 741 | L70: =K70-J70 -> 47 | M70: =(K70-J70)/J70 -> 0.067723343 | O70: 224 | P70: 313 | Q70: =P70-O70 -> 89 | R70: =(P70-O70)/O70 -> 0.39732143 | S70: 18 | T70: 23 | U70: =T70-S70 -> 5
A71: 883465 | B71: PETES LIQUORS | C71: 383 VALLEY RD | D71: CLIFTON | E71: =C71 & ", " & D71 -> 383 VALLEY RD, CLIFTON | F71: NEW JERSEY | G71: 7013 | H71: C | I71: 45574 | J71: 1286 | K71: 1538 | L71: =K71-J71 -> 252 | M71: =(K71-J71)/J71 -> 0.19595645 | O71: 459 | P71: 570 | Q71: =P71-O71 -> 111 | R71: =(P71-O71)/O71 -> 0.24183007 | S71: 35 | T71: 37 | U71: =T71-S71 -> 2
A72: 7498928 | B72: BUY RITE LIQUOR LODI | C72: 449 MAIN ST | D72: LODI | E72: =C72 & ", " & D72 -> 449 MAIN ST, LODI | F72: NEW JERSEY | G72: 7644 | H72: A | I72: 45580 | J72: 2178 | K72: 2693 | L72: =K72-J72 -> 515 | M72: =(K72-J72)/J72 -> 0.23645546 | O72: 824 | P72: 1104 | Q72: =P72-O72 -> 280 | R72: =(P72-O72)/O72 -> 0.33980583 | S72: 28 | T72: 43 | U72: =T72-S72 -> 15
A73: 7611933 | B73: LIQUOR MART | C73: 1132 US HIGHWAY 46 | D73: CLIFTON | E73: =C73 & ", " & D73 -> 1132 US HIGHWAY 46, CLIFTON | F73: NEW JERSEY | G73: 7013 | H73: B | I73: 45582 | J73: 925 | K73: -141 | L73: =K73-J73 -> -1066 | M73: =(K73-J73)/J73 -> -1.1524324 | O73: 434 | P73: -78 | Q73: =P73-O73 -> -512 | R73: =(P73-O73)/O73 -> -1.1797235 | U73: =T73-S73 -> 0
A74: 7466056 | B74: M & M WINE & SPIRITS | C74: 429 MARKET ST STE 1 | D74: ELMWOOD PARK | E74: =C74 & ", " & D74 -> 429 MARKET ST STE 1, ELMWOOD PARK | F74: NEW JERSEY | G74: 7407 | H74: B | I74: 45589 | J74: 3420 | K74: 3511 | L74: =K74-J74 -> 91 | M74: =(K74-J74)/J74 -> 0.026608187 | O74: 970 | P74: 1021 | Q74: =P74-O74 -> 51 | R74: =(P74-O74)/O74 -> 0.05257732 | S74: 36 | T74: 47 | U74: =T74-S74 -> 11
A75: 1872531 | B75: HIGH SPIRITS (Exquisite W & L (A)) | C75: 215 MAIN ST | D75: RIDGEFIELD PARK | E75: =C75 & ", " & D75 -> 215 MAIN ST, RIDGEFIELD PARK | F75: NEW JERSEY | G75: 7660 | H75: A | I75: 45593 | J75: 2786 | K75: 3422 | L75: =K75-J75 -> 636 | M75: =(K75-J75)/J75 -> 0.22828428 | O75: 1125 | P75: 1356 | Q75: =P75-O75 -> 231 | R75: =(P75-O75)/O75 -> 0.20533333 | S75: 35 | T75: 40 | U75: =T75-S75 -> 5
A76: 766433 | B76: LIQUOR MASTER | C76: 459 RTE 17 S | D76: HASBROUCK HEIGHTS | E76: =C76 & ", " & D76 -> 459 RTE 17 S, HASBROUCK HEIGHTS | F76: NEW JERSEY | G76: 7604 | H76: C | I76: 45601 | J76: 600 | K76: 634 | L76: =K76-J76 -> 34 | M76: =(K76-J76)/J76 -> 0.056666667 | O76: 212 | P76: 217 | Q76: =P76-O76 -> 5 | R76: =(P76-O76)/O76 -> 0.023584906 | S76: 25 | T76: 22 | U76: =T76-S76 -> -3
A77: 7564593 | B77: GARYS | C77: 67 VER VALEN ST | D77: CLOSTER | E77: =C77 & ", " & D77 -> 67 VER VALEN ST, CLOSTER | F77: NEW JERSEY | G77: 7624 | H77: B | I77: 45603 | J77: 1342 | K77: 1728 | L77: =K77-J77 -> 386 | M77: =(K77-J77)/J77 -> 0.2876304 | O77: 263 | P77: 365 | Q77: =P77-O77 -> 102 | R77: =(P77-O77)/O77 -> 0.3878327 | S77: 14 | T77: 19 | U77: =T77-S77 -> 5
A78: 883428 | B78: FINE WINE & SPIRITS | C78: 14 RIVEREDGE RD | D78: TENAFLY | E78: =C78 & ", " & D78 -> 14 RIVEREDGE RD, TENAFLY | F78: NEW JERSEY | G78: 7670 | H78: B | I78: 45614 | J78: 873 | K78: 1057 | L78: =K78-J78 -> 184 | M78: =(K78-J78)/J78 -> 0.21076747 | O78: 312 | P78: 523 | Q78: =P78-O78 -> 211 | R78: =(P78-O78)/O78 -> 0.67628205 | S78: 20 | T78: 23 | U78: =T78-S78 -> 3
A79: 883818 | B79: PAY LESS LIQUOR & DELI | C79: 251 ELM ST | D79: ELMWOOD PARK | E79: =C79 & ", " & D79 -> 251 ELM ST, ELMWOOD PARK | F79: NEW JERSEY | G79: 7407 | H79: C | I79: 45616 | J79: 541 | K79: 627 | L79: =K79-J79 -> 86 | M79: =(K79-J79)/J79 -> 0.15896488 | O79: 235 | P79: 256 | Q79: =P79-O79 -> 21 | R79: =(P79-O79)/O79 -> 0.089361702 | S79: 18 | T79: 16 | U79: =T79-S79 -> -2
...

Sheet Sheet3
E2: Account Name
E3: ARCHIES LIQUOR | F3: 229 MAIN AVE
E4: B & B LIQUORS | F4: 13 05 RIVER RD
E5: BELMONT LIQUORS | F5: 136 BELMONT AVE
E6: BERMUDA LIQUORS | F6: 177 HOPE AVE
E7: BEVERAGE BARN | F7: 224 LIVINGSTON ST
E8: BIRCHWOOD DELI & LIQUOR | F8: 545 MOLA BLVD
E9: BOMBOLOM LIQUORS | F9: 192 E 16TH ST
E10: BOTTLE LIQUOR STORE | F10: 550 LEXINGTON AVE
E11: BUY RITE LIQUOR LODI | F11: 449 MAIN ST
E12: C & S LUCKY LIQUORS | F12: 299 GRAND ST
E13: C TOWN LIQUOR | F13: 444 20TH AVE
E14: C TOWN LIQUORS | F14: 680 MAIN ST
... E80: WOODRIDGE WINE & LIQUOR | F80: 206 HACKENSACK ST
