Workbook

Sheet Store Reset Overview
F3: 3 Month Results From Reset Date (2024 vs 2025) | I3: Reset Date to July 1 (2024 vs 2025) | K3: Reset Date to July 1
F4: ACCOUNT SPECIFIC: Cases Sold % Change | H4: ALL ACCOUNTS: Kohler Sales % Difference (2024 vs 2025) | I4: Cases Sold % Change (2024 vs 2025) | K4: Overall Kohler Sales % Difference 2024 vs 2025 | L4: ACCOUNT SPECIFIC: Cases Sold Change
A5: Segmentation | B5: Customer | C5: Address | D5: City | E5: Reset Date | F5: All Kohler Brands | G5: Constellation Brands | I5: All Kohler Brands | J5: Constellation Brands | L5: All Kohler Brands | M5: Constellation Brands
A6: =_xlfn.XLOOKUP(B6,Table2[Account Name],Table2[Segmentation]) -> C | B6: ='Store Reset Data'!B15 -> MAIN STREET LIQUOR | C6: =_xlfn.XLOOKUP(B6, 'Store Reset Data'!B:B, 'Store Reset Data'!E:E, "") -> 340 S MAIN ST, WHARTON | D6: =_xlfn.XLOOKUP(B6,'Store Reset Data'!B:B,'Store Reset Data'!D:D,"") -> WHARTON | E6: =_xlfn.XLOOKUP(B6,'Store Reset Data'!B:B,'Store Reset Data'!I:I, "") -> 45715 | F6: =_xlfn.XLOOKUP(B6, 'Store Reset Data'!B:B, 'Store Reset Data'!AD:AD, "") -> 0.2007722 | G6: =_xlfn.XLOOKUP(B6,'Store Reset Data'!B:B,'Store Reset Data'!AL:AL, "") -> 0.21286371 | H6: -0.026 | I6: ='Store Reset Data'!O15 -> 0.13868613 | J6: ='Store Reset Data'!W15 -> 0.10697674 | K6: ='Store Reset Data'!P15 -> -0.076 | L6: =_xlfn.XLOOKUP(B6,'Store Reset Data'!B:B,'Store Reset Data'!AC:AC,"") -> 260 | M6: =_xlfn.XLOOKUP(B6,'Store Reset Data'!B:B,'Store Reset Data'!AK:AK,"") -> 139
A7: =_xlfn.XLOOKUP(B7,Table2[Account Name],Table2[Segmentation]) -> C | B7: ='Store Reset Data'!B21 -> WIDES DELI & LIQUORS | C7: =_xlfn.XLOOKUP(B7, 'Store Reset Data'!B:B, 'Store Reset Data'!E:E, "") -> 85 CENTRAL AVE, RIDGEFIELD PARK | D7: =_xlfn.XLOOKUP(B7,'Store Reset Data'!B:B,'Store Reset Data'!D:D,"") -> RIDGEFIELD PARK | E7: =_xlfn.XLOOKUP(B7,'Store Reset Data'!B:B,'Store Reset Data'!I:I, "") -> 45756 | F7: =_xlfn.XLOOKUP(B7, 'Store Reset Data'!B:B, 'Store Reset Data'!AD:AD, "") -> 0.11947627 | G7: =_xlfn.XLOOKUP(B7,'Store Reset Data'!B:B,'Store Reset Data'!AL:AL, "") -> 0.25 | H7: -0.08 | I7: ='Store Reset Data'!O21 -> 0.11947627 | J7: ='Store Reset Data'!W21 -> 0.25 | K7: ='Store Reset Data'!P21 -> -0.082 | L7: =_xlfn.XLOOKUP(B7,'Store Reset Data'!B:B,'Store Reset Data'!AC:AC,"") -> 73 | M7: =_xlfn.XLOOKUP(B7,'Store Reset Data'!B:B,'Store Reset Data'!AK:AK,"") -> 83
A8: =_xlfn.XLOOKUP(B8,Table2[Account Name],Table2[Segmentation]) -> A | B8: ='Store Reset Data'!B36 -> FARMBOY SUPER FRESH LIQUOR | C8: =_xlfn.XLOOKUP(B8, 'Store Reset Data'!B:B, 'Store Reset Data'!E:E, "") -> 465 GETTY AVE, PATERSON | D8: =_xlfn.XLOOKUP(B8,'Store Reset Data'!B:B,'Store Reset Data'!D:D,"") -> PATERSON | E8: =_xlfn.XLOOKUP(B8,'Store Reset Data'!B:B,'Store Reset Data'!I:I, "") -> 45770 | H8: -0.092 | I8: ='Store Reset Data'!O36 -> 0.10321232 | J8: ='Store Reset Data'!W36 -> 0.1509901 | K8: ='Store Reset Data'!P36 -> -0.085
A9: =_xlfn.XLOOKUP(B9,Table2[Account Name],Table2[Segmentation]) -> A | B9: ='Store Reset Data'!B34 -> THE LIQUOR SHOP | C9: =_xlfn.XLOOKUP(B9, 'Store Reset Data'!B:B, 'Store Reset Data'!E:E, "") -> 498 E 30TH ST, PATERSON | D9: =_xlfn.XLOOKUP(B9,'Store Reset Data'!B:B,'Store Reset Data'!D:D,"") -> PATERSON | E9: =_xlfn.XLOOKUP(B9,'Store Reset Data'!B:B,'Store Reset Data'!I:I, "") -> 45768 | F9: =_xlfn.XLOOKUP(B9, 'Store Reset Data'!B:B, 'Store Reset Data'!AD:AD, "") -> 0.13738165 | G9: =_xlfn.XLOOKUP(B9,'Store Reset Data'!B:B,'Store Reset Data'!AL:AL, "") -> 0.21786632 | H9: -0.07 | I9: ='Store Reset Data'!O34 -> 0.073079463 | J9: ='Store Reset Data'!W34 -> 0.15842978 | K9: ='Store Reset Data'!P34 -> -0.085 | L9: =_xlfn.XLOOKUP(B9,'Store Reset Data'!B:B,'Store Reset Data'!AC:AC,"") -> 1509 | M9: =_xlfn.XLOOKUP(B9,'Store Reset Data'!B:B,'Store Reset Data'!AK:AK,"") -> 1695
A10: =_xlfn.XLOOKUP(B10,Table2[Account Name],Table2[Segmentation]) -> C | B10: ='Store Reset Data'!B24 -> FOOD MART LIQUOR | C10: =_xlfn.XLOOKUP(B10, 'Store Reset Data'!B:B, 'Store Reset Data'!E:E, "") -> 430 MARKET ST, ELMWOOD PARK | D10: =_xlfn.XLOOKUP(B10,'Store Reset Data'!B:B,'Store Reset Data'!D:D,"") -> ELMWOOD PARK | E10: =_xlfn.XLOOKUP(B10,'Store Reset Data'!B:B,'Store Reset Data'!I:I, "") -> 45756 | F10: =_xlfn.XLOOKUP(B10, 'Store Reset Data'!B:B, 'Store Reset Data'!AD:AD, "") -> 0.18455744 | G10: =_xlfn.XLOOKUP(B10,'Store Reset Data'!B:B,'Store Reset Data'!AL:AL, "") -> 0.41525424 | H10: -0.08 | I10: ='Store Reset Data'!O24 -> 0.18455744 | J10: ='Store Reset Data'!W24 -> 0.41525424 | K10: ='Store Reset Data'!P24 -> -0.082 | L10: =_xlfn.XLOOKUP(B10,'Store Reset Data'!B:B,'Store Reset Data'!AC:AC,"") -> 98 | M10: =_xlfn.XLOOKUP(B10,'Store Reset Data'!B:B,'Store Reset Data'!AK:AK,"") -> 98
A11: =_xlfn.XLOOKUP(B11,Table2[Account Name],Table2[Segmentation]) -> A | B11: ='Store Reset Data'!B20 -> LUCKY 7 WINE & LIQUORS | C11: =_xlfn.XLOOKUP(B11, 'Store Reset Data'!B:B, 'Store Reset Data'!E:E, "") -> 77 RIVER RD, NORTH ARLINGTON | D11: =_xlfn.XLOOKUP(B11,'Store Reset Data'!B:B,'Store Reset Data'!D:D,"") -> NORTH ARLINGTON | E11: =_xlfn.XLOOKUP(B11,'Store Reset Data'!B:B,'Store Reset Data'!I:I, "") -> 45756 | F11: =_xlfn.XLOOKUP(B11, 'Store Reset Data'!B:B, 'Store Reset Data'!AD:AD, "") -> 0.078233785 | G11: =_xlfn.XLOOKUP(B11,'Store Reset Data'!B:B,'Store Reset Data'!AL:AL, "") -> 0.1397011 | H11: -0.08 | I11: ='Store Reset Data'!O20 -> 0.078233785 | J11: ='Store Reset Data'!W20 -> 0.1397011 | K11: ='Store Reset Data'!P20 -> -0.082 | L11: =_xlfn.XLOOKUP(B11,'Store Reset Data'!B:B,'Store Reset Data'!AC:AC,"") -> 427 | M11: =_xlfn.XLOOKUP(B11,'Store Reset Data'!B:B,'Store Reset Data'!AK:AK,"") -> 215
A12: =_xlfn.XLOOKUP(B12,Table2[Account Name],Table2[Segmentation]) -> B | B12: ='Store Reset Data'!B8 -> RAINBOW DELI & DISCOUNT LIQUORS | C12: =_xlfn.XLOOKUP(B12, 'Store Reset Data'!B:B, 'Store Reset Data'!E:E, "") -> 292 LAKEVIEW AVE, CLIFTON | D12: =_xlfn.XLOOKUP(B12,'Store Reset Data'!B:B,'Store Reset Data'!D:D,"") -> CLIFTON | E12: =_xlfn.XLOOKUP(B12,'Store Reset Data'!B:B,'Store Reset Data'!I:I, "") -> 45685 | F12: =_xlfn.XLOOKUP(B12, 'Store Reset Data'!B:B, 'Store Reset Data'!AD:AD, "") -> -0.067375887 | G12: =_xlfn.XLOOKUP(B12,'Store Reset Data'!B:B,'Store Reset Data'!AL:AL, "") -> -0.088536336 | H12: -0.054 | I12: ='Store Reset Data'!O8 -> 0.00072516316 | J12: ='Store Reset Data'!W8 -> -0.012735609 | K12: ='Store Reset Data'!P8 -> -0.08 | L12: =_xlfn.XLOOKUP(B12,'Store Reset Data'!B:B,'Store Reset Data'!AC:AC,"") -> -228 | M12: =_xlfn.XLOOKUP(B12,'Store Reset Data'!B:B,'Store Reset Data'!AK:AK,"") -> -173
A13: =_xlfn.XLOOKUP(B13,Table2[Account Name],Table2[Segmentation]) -> B | B13: ='Store Reset Data'!B22 -> RIDGEFIELD LIQUOR | C13: =_xlfn.XLOOKUP(B13, 'Store Reset Data'!B:B, 'Store Reset Data'!E:E, "") -> 520 SHALER BLVD, RIDGEFIELD | D13: =_xlfn.XLOOKUP(B13,'Store Reset Data'!B:B,'Store Reset Data'!D:D,"") -> RIDGEFIELD | E13: =_xlfn.XLOOKUP(B13,'Store Reset Data'!B:B,'Store Reset Data'!I:I, "") -> 45757 | F13: =_xlfn.XLOOKUP(B13, 'Store Reset Data'!B:B, 'Store Reset Data'!AD:AD, "") -> -0.019230769 | G13: =_xlfn.XLOOKUP(B13,'Store Reset Data'!B:B,'Store Reset Data'!AL:AL, "") -> 0.075782537 | H13: -0.08 | I13: ='Store Reset Data'!O22 -> -0.019230769 | J13: ='Store Reset Data'!W22 -> 0.075782537 | K13: ='Store Reset Data'!P22 -> -0.082 | L13: =_xlfn.XLOOKUP(B13,'Store Reset Data'!B:B,'Store Reset Data'!AC:AC,"") -> -29 | M13: =_xlfn.XLOOKUP(B13,'Store Reset Data'!B:B,'Store Reset Data'!AK:AK,"") -> 46
A14: =_xlfn.XLOOKUP(B14,Table2[Account Name],Table2[Segmentation]) -> A | B14: ='Store Reset Data'!B37 -> CLIFTON DISCOUNT LIQUORS | C14: =_xlfn.XLOOKUP(B14, 'Store Reset Data'!B:B, 'Store Reset Data'!E:E, "") -> 73 ACKERMAN AVE, CLIFTON | D14: =_xlfn.XLOOKUP(B14,'Store Reset Data'!B:B,'Store Reset Data'!D:D,"") -> CLIFTON | E14: =_xlfn.XLOOKUP(B14,'Store Reset Data'!B:B,'Store Reset Data'!I:I, "") -> 45775 | H14: -0.084 | I14: ='Store Reset Data'!O37 -> -0.018478429 | J14: ='Store Reset Data'!W37 -> -0.0055536272 | K14: ='Store Reset Data'!P37 -> -0.083
A15: =_xlfn.XLOOKUP(B15,Table2[Account Name],Table2[Segmentation]) -> B | B15: ='Store Reset Data'!B11 -> PARK AVENUE LIQUORS | C15: =_xlfn.XLOOKUP(B15, 'Store Reset Data'!B:B, 'Store Reset Data'!E:E, "") -> 307 PARK AVE, PATERSON | D15: =_xlfn.XLOOKUP(B15,'Store Reset Data'!B:B,'Store Reset Data'!D:D,"") -> PATERSON | E15: =_xlfn.XLOOKUP(B15,'Store Reset Data'!B:B,'Store Reset Data'!I:I, "") -> 45713 | F15: =_xlfn.XLOOKUP(B15, 'Store Reset Data'!B:B, 'Store Reset Data'!AD:AD, "") -> 0.068917988 | G15: =_xlfn.XLOOKUP(B15,'Store Reset Data'!B:B,'Store Reset Data'!AL:AL, "") -> 0.097132285 | H15: -0.039 | I15: ='Store Reset Data'!O11 -> -0.01937658 | J15: ='Store Reset Data'!W11 -> 0.01430143 | K15: ='Store Reset Data'!P11 -> -0.069 | L15: =_xlfn.XLOOKUP(B15,'Store Reset Data'!B:B,'Store Reset Data'!AC:AC,"") -> 100 | M15: =_xlfn.XLOOKUP(B15,'Store Reset Data'!B:B,'Store Reset Data'!AK:AK,"") -> 105
A16: =_xlfn.XLOOKUP(B16,Table2[Account Name],Table2[Segmentation]) -> A | B16: ='Store Reset Data'!B30 -> SHOPPERS VINEYARD | C16: =_xlfn.XLOOKUP(B16, 'Store Reset Data'!B:B, 'Store Reset Data'!E:E, "") -> 875 BLOOMFIELD AVE, CLIFTON | D16: =_xlfn.XLOOKUP(B16,'Store Reset Data'!B:B,'Store Reset Data'!D:D,"") -> CLIFTON | E16: =_xlfn.XLOOKUP(B16,'Store Reset Data'!B:B,'Store Reset Data'!I:I, "") -> 45772 | H16: -0.09 | I16: ='Store Reset Data'!O30 -> -0.024879818 | J16: ='Store Reset Data'!W30 -> 0.046134883 | K16: ='Store Reset Data'!P30 -> -0.08 | M16: =_xlfn.XLOOKUP(B16,'Store Reset Data'!B:B,'Store Reset Data'!AK:AK,"") -> 0
A17: =_xlfn.XLOOKUP(B17,Table2[Account Name],Table2[Segmentation]) -> B | B17: ='Store Reset Data'!B12 -> MANOR BEVERAGES | C17: =_xlfn.XLOOKUP(B17, 'Store Reset Data'!B:B, 'Store Reset Data'!E:E, "") -> 430 BROAD AVE, LEONIA | D17: =_xlfn.XLOOKUP(B17,'Store Reset Data'!B:B,'Store Reset Data'!D:D,"") -> LEONIA | E17: =_xlfn.XLOOKUP(B17,'Store Reset Data'!B:B,'Store Reset Data'!I:I, "") -> 45719 | F17: =_xlfn.XLOOKUP(B17, 'Store Reset Data'!B:B, 'Store Reset Data'!AD:AD, "") -> 0.053855569 | G17: =_xlfn.XLOOKUP(B17,'Store Reset Data'!B:B,'Store Reset Data'!AL:AL, "") -> 0.10655738 | H17: -0.031 | I17: ='Store Reset Data'!O12 -> -0.032539683 | J17: ='Store Reset Data'!W12 -> 0.13456464 | K17: ='Store Reset Data'!P12 -> -0.067 | L17: =_xlfn.XLOOKUP(B17,'Store Reset Data'!B:B,'Store Reset Data'!AC:AC,"") -> 44 | M17: =_xlfn.XLOOKUP(B17,'Store Reset Data'!B:B,'Store Reset Data'!AK:AK,"") -> 26
A18: =_xlfn.XLOOKUP(B18,Table2[Account Name],Table2[Segmentation]) -> C | B18: ='Store Reset Data'!B7 -> LIQUOR MART | C18: =_xlfn.XLOOKUP(B18, 'Store Reset Data'!B:B, 'Store Reset Data'!E:E, "") -> 126 RIDGE RD, NORTH ARLINGTON | D18: =_xlfn.XLOOKUP(B18,'Store Reset Data'!B:B,'Store Reset Data'!D:D,"") -> NORTH ARLINGTON | E18: =_xlfn.XLOOKUP(B18,'Store Reset Data'!B:B,'Store Reset Data'!I:I, "") -> 45680 | F18: =_xlfn.XLOOKUP(B18, 'Store Reset Data'!B:B, 'Store Reset Data'!AD:AD, "") -> -0.1006192 | G18: =_xlfn.XLOOKUP(B18,'Store Reset Data'!B:B,'Store Reset Data'!AL:AL, "") -> -0.061425061 | H18: -0.078 | I18: ='Store Reset Data'!O7 -> -0.033243139 | J18: ='Store Reset Data'!W7 -> -0.011198208 | K18: ='Store Reset Data'!P7 -> -0.074 | L18: =_xlfn.XLOOKUP(B18,'Store Reset Data'!B:B,'Store Reset Data'!AC:AC,"") -> -130 | M18: =_xlfn.XLOOKUP(B18,'Store Reset Data'!B:B,'Store Reset Data'!AK:AK,"") -> -25
A19: =_xlfn.XLOOKUP(B19,Table2[Account Name],Table2[Segmentation]) -> C | B19: ='Store Reset Data'!B6 -> PAY LESS LIQUOR & DELI | C19: =_xlfn.XLOOKUP(B19, 'Store Reset Data'!B:B, 'Store Reset Data'!E:E, "") -> 251 ELM ST, ELMWOOD PARK | D19: =_xlfn.XLOOKUP(B19,'Store Reset Data'!B:B,'Store Reset Data'!D:D,"") -> ELMWOOD PARK | E19: =_xlfn.XLOOKUP(B19,'Store Reset Data'!B:B,'Store Reset Data'!I:I, "") -> 45677 | F19: =_xlfn.XLOOKUP(B19, 'Store Reset Data'!B:B, 'Store Reset Data'!AD:AD, "") -> 0.1011236 | G19: =_xlfn.XLOOKUP(B19,'Store Reset Data'!B:B,'Store Reset Data'!AL:AL, "") -> -0.071038251 | H19: -0.075 | I19: ='Store Reset Data'!O6 -> -0.044174757 | J19: ='Store Reset Data'!W6 -> -0.21578947 | K19: ='Store Reset Data'!P6 -> -0.074 | L19: =_xlfn.XLOOKUP(B19,'Store Reset Data'!B:B,'Store Reset Data'!AC:AC,"") -> 90 | M19: =_xlfn.XLOOKUP(B19,'Store Reset Data'!B:B,'Store Reset Data'!AK:AK,"") -> -26
A20: =_xlfn.XLOOKUP(B20,Table2[Account Name],Table2[Segmentation]) -> A | B20: ='Store Reset Data'!B29 -> BUY RITE | C20: =_xlfn.XLOOKUP(B20, 'Store Reset Data'!B:B, 'Store Reset Data'!E:E, "") -> 410 RIVER ST, HACKENSACK | D20: =_xlfn.XLOOKUP(B20,'Store Reset Data'!B:B,'Store Reset Data'!D:D,"") -> HACKENSACK | E20: =_xlfn.XLOOKUP(B20,'Store Reset Data'!B:B,'Store Reset Data'!I:I, "") -> 45776 | H20: -0.084 | I20: ='Store Reset Data'!O29 -> -0.046599023 | J20: ='Store Reset Data'!W29 -> -0.015727124 | K20: ='Store Reset Data'!P29 -> -0.083
A21: =_xlfn.XLOOKUP(B21,Table2[Account Name],Table2[Segmentation]) -> A | B21: ='Store Reset Data'!B19 -> HIGH SPIRITS (Exquisite W&L?) | C21: =_xlfn.XLOOKUP(B21, 'Store Reset Data'!B:B, 'Store Reset Data'!E:E, "") -> 215 MAIN ST, RIDGEFIELD PARK | D21: =_xlfn.XLOOKUP(B21,'Store Reset Data'!B:B,'Store Reset Data'!D:D,"") -> RIDGEFIELD PARK | E21: =_xlfn.XLOOKUP(B21,'Store Reset Data'!B:B,'Store Reset Data'!I:I, "") -> 45755 | F21: =_xlfn.XLOOKUP(B21, 'Store Reset Data'!B:B, 'Store Reset Data'!AD:AD, "") -> 0.03074952 | G21: =_xlfn.XLOOKUP(B21,'Store Reset Data'!B:B,'Store Reset Data'!AL:AL, "") -> 0.087309645 | H21: -0.08 | I21: ='Store Reset Data'!O19 -> 0.03074952 | J21: ='Store Reset Data'!W19 -> 0.087309645 | K21: ='Store Reset Data'!P19 -> -0.082 | L21: =_xlfn.XLOOKUP(B21,'Store Reset Data'!B:B,'Store Reset Data'!AC:AC,"") -> 144 | M21: =_xlfn.XLOOKUP(B21,'Store Reset Data'!B:B,'Store Reset Data'!AK:AK,"") -> 172
A22: =_xlfn.XLOOKUP(B22,Table2[Account Name],Table2[Segmentation]) -> B | B22: ='Store Reset Data'!B4 -> GARYS | C22: =_xlfn.XLOOKUP(B22, 'Store Reset Data'!B:B, 'Store Reset Data'!E:E, "") -> 67 VER VALEN ST, CLOSTER | D22: =_xlfn.XLOOKUP(B22,'Store Reset Data'!B:B,'Store Reset Data'!D:D,"") -> CLOSTER | E22: =_xlfn.XLOOKUP(B22,'Store Reset Data'!B:B,'Store Reset Data'!I:I, "") -> 45664 | F22: =_xlfn.XLOOKUP(B22, 'Store Reset Data'!B:B, 'Store Reset Data'!AD:AD, "") -> 0.041688379 | G22: =_xlfn.XLOOKUP(B22,'Store Reset Data'!B:B,'Store Reset Data'!AL:AL, "") -> 0.17647059 | H22: -0.074 | I22: ='Store Reset Data'!O4 -> -0.077584483 | J22: ='Store Reset Data'!W4 -> -0.14117647 | K22: ='Store Reset Data'!P4 -> -0.078 | L22: =_xlfn.XLOOKUP(B22,'Store Reset Data'!B:B,'Store Reset Data'!AC:AC,"") -> 80 | M22: =_xlfn.XLOOKUP(B22,'Store Reset Data'!B:B,'Store Reset Data'!AK:AK,"") -> 66
A23: =_xlfn.XLOOKUP(B23,Table2[Account Name],Table2[Segmentation]) -> A | B23: ='Store Reset Data'!B35 -> SUPER WINE WAREHOUSE | C23: =_xlfn.XLOOKUP(B23, 'Store Reset Data'!B:B, 'Store Reset Data'!E:E, "") -> 42 E 30TH ST, PATERSON | D23: =_xlfn.XLOOKUP(B23,'Store Reset Data'!B:B,'Store Reset Data'!D:D,"") -> PATERSON | E23: =_xlfn.XLOOKUP(B23,'Store Reset Data'!B:B,'Store Reset Data'!I:I, "") -> 45768 | F23: =_xlfn.XLOOKUP(B23, 'Store Reset Data'!B:B, 'Store Reset Data'!AD:AD, "") -> -0.055842607 | G23: =_xlfn.XLOOKUP(B23,'Store Reset Data'!B:B,'Store Reset Data'!AL:AL, "") -> -0.0095231475 | H23: -0.07 | I23: ='Store Reset Data'!O35 -> -0.084109281 | J23: ='Store Reset Data'!W35 -> -0.049893941 | K23: ='Store Reset Data'!P35 -> -0.085 | L23: =_xlfn.XLOOKUP(B23,'Store Reset Data'!B:B,'Store Reset Data'!AC:AC,"") -> -1405 | M23: =_xlfn.XLOOKUP(B23,'Store Reset Data'!B:B,'Store Reset Data'!AK:AK,"") -> -137
A24: =_xlfn.XLOOKUP(B24,Table2[Account Name],Table2[Segmentation]) -> B | B24: ='Store Reset Data'!B5 -> FINE WINE & SPIRITS | C24: =_xlfn.XLOOKUP(B24, 'Store Reset Data'!B:B, 'Store Reset Data'!E:E, "") -> 14 RIVEREDGE RD, TENAFLY | D24: =_xlfn.XLOOKUP(B24,'Store Reset Data'!B:B,'Store Reset Data'!D:D,"") -> TENAFLY | E24: =_xlfn.XLOOKUP(B24,'Store Reset Data'!B:B,'Store Reset Data'!I:I, "") -> 45670 | F24: =_xlfn.XLOOKUP(B24, 'Store Reset Data'!B:B, 'Store Reset Data'!AD:AD, "") -> -0.085582998 | G24: =_xlfn.XLOOKUP(B24,'Store Reset Data'!B:B,'Store Reset Data'!AL:AL, "") -> 0.049921997 | H24: -0.082 | I24: ='Store Reset Data'!O5 -> -0.090173685 | J24: ='Store Reset Data'!W5 -> 0.086670652 | K24: ='Store Reset Data'!P5 -> -0.08 | L24: =_xlfn.XLOOKUP(B24,'Store Reset Data'!B:B,'Store Reset Data'!AC:AC,"") -> -149 | M24: =_xlfn.XLOOKUP(B24,'Store Reset Data'!B:B,'Store Reset Data'!AK:AK,"") -> 32
A25: =_xlfn.XLOOKUP(B25,Table2[Account Name],Table2[Segmentation]) -> C | B25: ='Store Reset Data'!B16 -> WINE SHOP | C25: =_xlfn.XLOOKUP(B25, 'Store Reset Data'!B:B, 'Store Reset Data'!E:E, "") -> 434 HACKENSACK ST, CARLSTADT | D25: =_xlfn.XLOOKUP(B25,'Store Reset Data'!B:B,'Store Reset Data'!D:D,"") -> CARLSTADT | E25: =_xlfn.XLOOKUP(B25,'Store Reset Data'!B:B,'Store Reset Data'!I:I, "") -> 45741 | F25: =_xlfn.XLOOKUP(B25, 'Store Reset Data'!B:B, 'Store Reset Data'!AD:AD, "") -> -0.1306391 | G25: =_xlfn.XLOOKUP(B25,'Store Reset Data'!B:B,'Store Reset Data'!AL:AL, "") -> -0.37383178 | H25: -0.069 | I25: ='Store Reset Data'!O16 -> -0.10314685 | J25: ='Store Reset Data'!W16 -> -0.14953271 | K25: ='Store Reset Data'!P16 -> -0.072 | L25: =_xlfn.XLOOKUP(B25,'Store Reset Data'!B:B,'Store Reset Data'!AC:AC,"") -> -139 | M25: =_xlfn.XLOOKUP(B25,'Store Reset Data'!B:B,'Store Reset Data'!AK:AK,"") -> -120
A26: =_xlfn.XLOOKUP(B26,Table2[Account Name],Table2[Segmentation]) -> A | B26: ='Store Reset Data'!B26 -> SHANIK LIQUORS | C26: =_xlfn.XLOOKUP(B26, 'Store Reset Data'!B:B, 'Store Reset Data'!E:E, "") -> 952 MAIN AVE, PASSAIC | D26: =_xlfn.XLOOKUP(B26,'Store Reset Data'!B:B,'Store Reset Data'!D:D,"") -> PASSAIC | E26: =_xlfn.XLOOKUP(B26,'Store Reset Data'!B:B,'Store Reset Data'!I:I, "") -> 45762 | F26: =_xlfn.XLOOKUP(B26, 'Store Reset Data'!B:B, 'Store Reset Data'!AD:AD, "") -> -0.031284916 | G26: =_xlfn.XLOOKUP(B26,'Store Reset Data'!B:B,'Store Reset Data'!AL:AL, "") -> -0.053839847 | H26: -0.084 | I26: ='Store Reset Data'!O26 -> -0.031284916 | J26: ='Store Reset Data'!W26 -> -0.053839847 | K26: ='Store Reset Data'!P26 -> -0.084 | L26: =_xlfn.XLOOKUP(B26,'Store Reset Data'!B:B,'Store Reset Data'!AC:AC,"") -> -168 | M26: =_xlfn.XLOOKUP(B26,'Store Reset Data'!B:B,'Store Reset Data'!AK:AK,"") -> -197
A27: =_xlfn.XLOOKUP(B27,Table2[Account Name],Table2[Segmentation]) -> B | B27: ='Store Reset Data'!B42 -> STEW LEONARDS | C27: =_xlfn.XLOOKUP(B27, 'Store Reset Data'!B:B, 'Store Reset Data'!E:E, "") -> 467 ALLWOOD RD, CLIFTON | D27: =_xlfn.XLOOKUP(B27,'Store Reset Data'!B:B,'Store Reset Data'!D:D,"") -> CLIFTON | E27: =_xlfn.XLOOKUP(B27,'Store Reset Data'!B:B,'Store Reset Data'!I:I, "") -> 45777 | H27: -0.105 | I27: ='Store Reset Data'!O42 -> -0.11969887 | J27: ='Store Reset Data'!W42 -> 0.11658654 | K27: ='Store Reset Data'!P42 -> -0.104
A28: =_xlfn.XLOOKUP(B28,Table2[Account Name],Table2[Segmentation]) -> A | B28: ='Store Reset Data'!B13 -> SHOPRITE LIQUORS (Northvale) | C28: =_xlfn.XLOOKUP(B28, 'Store Reset Data'!B:B, 'Store Reset Data'!E:E, "") -> 254 LIVINGSTON ST STE F, NORTHVALE | D28: =_xlfn.XLOOKUP(B28,'Store Reset Data'!B:B,'Store Reset Data'!D:D,"") -> NORTHVALE | E28: =_xlfn.XLOOKUP(B28,'Store Reset Data'!B:B,'Store Reset Data'!I:I, "") -> 45726 | F28: =_xlfn.XLOOKUP(B28, 'Store Reset Data'!B:B, 'Store Reset Data'!AD:AD, "") -> -0.031492786 | G28: =_xlfn.XLOOKUP(B28,'Store Reset Data'!B:B,'Store Reset Data'!AL:AL, "") -> -0.11849957 | H28: -0.04 | I28: ='Store Reset Data'!O13 -> -0.12880355 | J28: ='Store Reset Data'!W13 -> -0.19379845 | K28: ='Store Reset Data'!P13 -> -0.069 | L28: =_xlfn.XLOOKUP(B28,'Store Reset Data'!B:B,'Store Reset Data'!AC:AC,"") -> -227 | M28: =_xlfn.XLOOKUP(B28,'Store Reset Data'!B:B,'Store Reset Data'!AK:AK,"") -> -139
A29: =_xlfn.XLOOKUP(B29,Table2[Account Name],Table2[Segmentation]) -> A | B29: ='Store Reset Data'!B28 -> SHOPRITE LIQUORS (Clifton) | C29: =_xlfn.XLOOKUP(B29, 'Store Reset Data'!B:B, 'Store Reset Data'!E:E, "") -> 895 PAULISON AVE, CLIFTON | D29: =_xlfn.XLOOKUP(B29,'Store Reset Data'!B:B,'Store Reset Data'!D:D,"") -> CLIFTON | E29: =_xlfn.XLOOKUP(B29,'Store Reset Data'!B:B,'Store Reset Data'!I:I, "") -> 45775 | H29: -0.084 | I29: ='Store Reset Data'!$O$28 -> -0.14317647 | J29: ='Store Reset Data'!W28 -> -0.18611922 | K29: ='Store Reset Data'!P28 -> -0.083
A30: =_xlfn.XLOOKUP(B30,Table2[Account Name],Table2[Segmentation]) -> A | B30: ='Store Reset Data'!B38 -> CLIFTON COMMONS SPIRITS & WINES | C30: =_xlfn.XLOOKUP(B30, 'Store Reset Data'!B:B, 'Store Reset Data'!E:E, "") -> 132 KINGSLAND RD, CLIFTON | D30: =_xlfn.XLOOKUP(B30,'Store Reset Data'!B:B,'Store Reset Data'!D:D,"") -> CLIFTON | E30: =_xlfn.XLOOKUP(B30,'Store Reset Data'!B:B,'Store Reset Data'!I:I, "") -> 45772 | H30: -0.093 | I30: ='Store Reset Data'!$O$38 -> -0.16094532 | J30: ='Store Reset Data'!W38 -> -0.18885246 | K30: ='Store Reset Data'!P38 -> -0.078
A31: =_xlfn.XLOOKUP(B31,Table2[Account Name],Table2[Segmentation]) -> C | B31: ='Store Reset Data'!B17 -> SUSSEX DISCOUNT LIQUORS | C31: =_xlfn.XLOOKUP(B31, 'Store Reset Data'!B:B, 'Store Reset Data'!E:E, "") -> 3235 STATE RT 94, FRANKLIN | D31: =_xlfn.XLOOKUP(B31,'Store Reset Data'!B:B,'Store Reset Data'!D:D,"") -> FRANKLIN | E31: =_xlfn.XLOOKUP(B31,'Store Reset Data'!B:B,'Store Reset Data'!I:I, "") -> 45747 | F31: =_xlfn.XLOOKUP(B31, 'Store Reset Data'!B:B, 'Store Reset Data'!AD:AD, "") -> -0.16809672 | G31: =_xlfn.XLOOKUP(B31,'Store Reset Data'!B:B,'Store Reset Data'!AL:AL, "") -> -0.35714286 | H31: -0.06 | I31: ='Store Reset Data'!O17 -> -0.16809672 | J31: ='Store Reset Data'!W17 -> -0.35714286 | K31: ='Store Reset Data'!P17 -> -0.063 | L31: =_xlfn.XLOOKUP(B31,'Store Reset Data'!B:B,'Store Reset Data'!AC:AC,"") -> -431 | M31: =_xlfn.XLOOKUP(B31,'Store Reset Data'!B:B,'Store Reset Data'!AK:AK,"") -> -90
A32: =_xlfn.XLOOKUP(B32,Table2[Account Name],Table2[Segmentation]) -> A | B32: ='Store Reset Data'!B41 -> SHOPRITE LIQUORS (Englewood) | C32: =_xlfn.XLOOKUP(B32, 'Store Reset Data'!B:B, 'Store Reset Data'!E:E, "") -> 53 NATHANIEL PL, ENGLEWOOD | D32: =_xlfn.XLOOKUP(B32,'Store Reset Data'!B:B,'Store Reset Data'!D:D,"") -> ENGLEWOOD | E32: =_xlfn.XLOOKUP(B32,'Store Reset Data'!B:B,'Store Reset Data'!I:I, "") -> 45769 | F32: =_xlfn.XLOOKUP(B32, 'Store Reset Data'!B:B, 'Store Reset Data'!AD:AD, "") -> -0.11015896 | G32: =_xlfn.XLOOKUP(B32,'Store Reset Data'!B:B,'Store Reset Data'!AL:AL, "") -> -0.094806991 | H32: -0.09 | I32: ='Store Reset Data'!O41 -> -0.16832159 | J32: ='Store Reset Data'!W41 -> -0.12152724 | K32: ='Store Reset Data'!P41 -> -0.085 | L32: =_xlfn.XLOOKUP(B32,'Store Reset Data'!B:B,'Store Reset Data'!AC:AC,"") -> -1684 | M32: =_xlfn.XLOOKUP(B32,'Store Reset Data'!B:B,'Store Reset Data'!AK:AK,"") -> -754
A33: =_xlfn.XLOOKUP(B33,Table2[Account Name],Table2[Segmentation]) -> A | B33: ='Store Reset Data'!B40 -> SHOPRITE LIQUORS (Paramus) | C33: =_xlfn.XLOOKUP(B33, 'Store Reset Data'!B:B, 'Store Reset Data'!E:E, "") -> 224 E STATE RT 4, PARAMUS | D33: =_xlfn.XLOOKUP(B33,'Store Reset Data'!B:B,'Store Reset Data'!D:D,"") -> PARAMUS | E33: =_xlfn.XLOOKUP(B33,'Store Reset Data'!B:B,'Store Reset Data'!I:I, "") -> 45769 | F33: =_xlfn.XLOOKUP(B33, 'Store Reset Data'!B:B, 'Store Reset Data'!AD:AD, "") -> -0.11533607 | G33: =_xlfn.XLOOKUP(B33,'Store Reset Data'!B:B,'Store Reset Data'!AL:AL, "") -> -0.1213778 | H33: -0.07 | I33: ='Store Reset Data'!O40 -> -0.16850394 | J33: ='Store Reset Data'!W40 -> -0.16080402 | K33: ='Store Reset Data'!P40 -> -0.085 | L33: =_xlfn.XLOOKUP(B33,'Store Reset Data'!B:B,'Store Reset Data'!AC:AC,"") -> -731 | M33: =_xlfn.XLOOKUP(B33,'Store Reset Data'!B:B,'Store Reset Data'!AK:AK,"") -> -222
A34: =_xlfn.XLOOKUP(B34,Table2[Account Name],Table2[Segmentation]) -> A | B34: ='Store Reset Data'!B23 -> FIGLARS LIQUOR STORE | C34: =_xlfn.XLOOKUP(B34, 'Store Reset Data'!B:B, 'Store Reset Data'!E:E, "") -> 327 HOPE AVE, CLIFTON | D34: =_xlfn.XLOOKUP(B34,'Store Reset Data'!B:B,'Store Reset Data'!D:D,"") -> CLIFTON | E34: =_xlfn.XLOOKUP(B34,'Store Reset Data'!B:B,'Store Reset Data'!I:I, "") -> 45766 | F34: =_xlfn.XLOOKUP(B34, 'Store Reset Data'!B:B, 'Store Reset Data'!AD:AD, "") -> -0.15574122 | G34: =_xlfn.XLOOKUP(B34,'Store Reset Data'!B:B,'Store Reset Data'!AL:AL, "") -> -0.086881274 | H34: -0.08 | I34: ='Store Reset Data'!O23 -> -0.15574122 | J34: ='Store Reset Data'!W23 -> -0.086881274 | K34: ='Store Reset Data'!P23 -> -0.081 | L34: =_xlfn.XLOOKUP(B34,'Store Reset Data'!B:B,'Store Reset Data'!AC:AC,"") -> -727 | M34: =_xlfn.XLOOKUP(B34,'Store Reset Data'!B:B,'Store Reset Data'!AK:AK,"") -> -251
A35: =_xlfn.XLOOKUP(B35,Table2[Account Name],Table2[Segmentation]) -> A | B35: ='Store Reset Data'!B31 -> BOTTLE KING | C35: =_xlfn.XLOOKUP(B35, 'Store Reset Data'!B:B, 'Store Reset Data'!E:E, "") -> 909 PROSPECT ST, GLEN ROCK | D35: =_xlfn.XLOOKUP(B35,'Store Reset Data'!B:B,'Store Reset Data'!D:D,"") -> GLEN ROCK | E35: =_xlfn.XLOOKUP(B35,'Store Reset Data'!B:B,'Store Reset Data'!I:I, "") -> 45771 | H35: -0.09 | I35: ='Store Reset Data'!O31 -> -0.18419715 | J35: ='Store Reset Data'!W31 -> -0.21793921 | K35: ='Store Reset Data'!P31 -> -0.08
A36: =_xlfn.XLOOKUP(B36,Table2[Account Name],Table2[Segmentation]) -> C | B36: ='Store Reset Data'!B9 -> QUICK STOP WINE & LIQUOR | C36: =_xlfn.XLOOKUP(B36, 'Store Reset Data'!B:B, 'Store Reset Data'!E:E, "") -> 83 GODWIN AVE, RIDGEWOOD | D36: =_xlfn.XLOOKUP(B36,'Store Reset Data'!B:B,'Store Reset Data'!D:D,"") -> RIDGEWOOD | E36: =_xlfn.XLOOKUP(B36,'Store Reset Data'!B:B,'Store Reset Data'!I:I, "") -> 45687 | F36: =_xlfn.XLOOKUP(B36, 'Store Reset Data'!B:B, 'Store Reset Data'!AD:AD, "") -> -0.091898428 | G36: =_xlfn.XLOOKUP(B36,'Store Reset Data'!B:B,'Store Reset Data'!AL:AL, "") -> -0.21005917 | H36: -0.068 | I36: ='Store Reset Data'!O9 -> -0.22385707 | J36: ='Store Reset Data'!W9 -> -0.35741445 | K36: ='Store Reset Data'!P9 -> -0.08 | L36: =_xlfn.XLOOKUP(B36,'Store Reset Data'!B:B,'Store Reset Data'!AC:AC,"") -> -76 | M36: =_xlfn.XLOOKUP(B36,'Store Reset Data'!B:B,'Store Reset Data'!AK:AK,"") -> -71
A37: =_xlfn.XLOOKUP(B37,Table2[Account Name],Table2[Segmentation]) -> A | B37: ='Store Reset Data'!B25 -> ARCHIES LIQUOR | C37: =_xlfn.XLOOKUP(B37, 'Store Reset Data'!B:B, 'Store Reset Data'!E:E, "") -> 229 MAIN AVE, PASSAIC | D37: =_xlfn.XLOOKUP(B37,'Store Reset Data'!B:B,'Store Reset Data'!D:D,"") -> PASSAIC | E37: =_xlfn.XLOOKUP(B37,'Store Reset Data'!B:B,'Store Reset Data'!I:I, "") -> 45761 | F37: =_xlfn.XLOOKUP(B37, 'Store Reset Data'!B:B, 'Store Reset Data'!AD:AD, "") -> -0.18797729 | G37: =_xlfn.XLOOKUP(B37,'Store Reset Data'!B:B,'Store Reset Data'!AL:AL, "") -> -0.11259957 | H37: -0.067 | I37: ='Store Reset Data'!O25 -> -0.18797729 | J37: ='Store Reset Data'!W25 -> -0.11259957 | K37: ='Store Reset Data'!P25 -> -0.084 | L37: =_xlfn.XLOOKUP(B37,'Store Reset Data'!B:B,'Store Reset Data'!AC:AC,"") -> -960 | M37: =_xlfn.XLOOKUP(B37,'Store Reset Data'!B:B,'Store Reset Data'!AK:AK,"") -> -311
A38: =_xlfn.XLOOKUP(B38,Table2[Account Name],Table2[Segmentation]) -> C | B38: ='Store Reset Data'!B43 -> STEW LEONARDS WINES & SPIRITS | C38: =_xlfn.XLOOKUP(B38, 'Store Reset Data'!B:B, 'Store Reset Data'!E:E, "") -> 700 PARAMUS PARK, PARAMUS | D38: =_xlfn.XLOOKUP(B38,'Store Reset Data'!B:B,'Store Reset Data'!D:D,"") -> PARAMUS | E38: =_xlfn.XLOOKUP(B38,'Store Reset Data'!B:B,'Store Reset Data'!I:I, "") -> 45777 | H38: -0.105 | I38: ='Store Reset Data'!O43 -> -0.26754386 | J38: ='Store Reset Data'!W43 -> -0.23483146 | K38: ='Store Reset Data'!P43 -> -0.104
A39: =_xlfn.XLOOKUP(B39,Table2[Account Name],Table2[Segmentation]) -> C | B39: ='Store Reset Data'!B10 -> CIRCLE LIQUORS | C39: =_xlfn.XLOOKUP(B39, 'Store Reset Data'!B:B, 'Store Reset Data'!E:E, "") -> 1 S MAIN ST STE 1, LODI | D39: =_xlfn.XLOOKUP(B39,'Store Reset Data'!B:B,'Store Reset Data'!D:D,"") -> LODI | E39: =_xlfn.XLOOKUP(B39,'Store Reset Data'!B:B,'Store Reset Data'!I:I, "") -> 45720 | F39: =_xlfn.XLOOKUP(B39, 'Store Reset Data'!B:B, 'Store Reset Data'!AD:AD, "") -> -0.31392694 | G39: =_xlfn.XLOOKUP(B39,'Store Reset Data'!B:B,'Store Reset Data'!AL:AL, "") -> -0.15643564 | H39: -0.05 | I39: ='Store Reset Data'!O10 -> -0.34876774 | J39: ='Store Reset Data'!W10 -> -0.22133333 | K39: ='Store Reset Data'!P10 -> -0.081 | L39: =_xlfn.XLOOKUP(B39,'Store Reset Data'!B:B,'Store Reset Data'!AC:AC,"") -> -275 | M39: =_xlfn.XLOOKUP(B39,'Store Reset Data'!B:B,'Store Reset Data'!AK:AK,"") -> -79
A41: % Change
A42: Acct Class | B42: All Brands | C42: Constellation
A43: A | B43: =AVERAGEIF($A$6:$A$39,A43,$F$6:$F$39) -> -0.044146889 | C43: =AVERAGEIF($A$6:$A$39,A43,$G$6:$G$39) -> -0.015265113
...

Sheet Store Reset Data
L1: From reset date to July 1 | AA1: 3 Months From Reset Date
L2: Kohler Overall | T2: Constellation | AA2: Kohler House | AI2: Constellation
A3: TD Linx # | B3: Account Name | C3: Address | D3: City | E3: Column1 | F3: State | G3: Zip | H3: Segmentation | I3: RESET DATE | J3: Before PSA? (in Dropbox) | K3: After PSA? (in Dropbox) | L3: 2024 Cases Sold | M3: 2025 Cases Sold | N3: Cases Sold Diff | O3: % Change | P3: 2025 Sales Trend | Q3: Placement Count 2024 | R3: Placement Count 2025 | S3: Placement Count Diff | T3: 2024 Cases Sold2 | U3: 2025 Cases Sold3 | V3: Cases Sold Diff2 | W3: % Change4 | X3: Placement Count 20245 | Y3: Placement Count 20256 | Z3: Placement Count Diff7 | AA3: 2024 Cases Sold8 | AB3: 2025 Cases Sold9 | AC3: 2026 Cases Sold9 | AD3: % Change10 | AE3: 2025 Sales Trend11 | AF3: Placement Count 202412 | AG3: Placement Count 202513 | AH3: Placement Count Diff14 | AI3: 2024 Cases Sold15 | AJ3: 2025 Cases Sold16 | AK3: 2026 Cases Sold16 | AL3: % Change17 | AM3: Placement Count 202418 | AN3: Placement Count 202519 | AO3: Placement Count Diff20
A4: 7564593 | B4: GARYS | C4: 67 VER VALEN ST | D4: CLOSTER | E4: =C4 & ", " & D4 -> 67 VER VALEN ST, CLOSTER | F4: NEW JERSEY | G4: 7624 | H4: B | I4: 45664 | J4: Yes | K4: Yes | L4: 5001 | M4: 4613 | N4: =Table2[[#This Row],[2025 Cases Sold]]-Table2[[#This Row],[2024 Cases Sold]] -> -388 | O4: =(M4-L4)/L4 -> -0.077584483 | P4: -0.078 | Q4: 303 | R4: 403 | S4: =R4-Q4 -> 100 | T4: 1190 | U4: 1022 | V4: =Table2[[#This Row],[2025 Cases Sold3]]-Table2[[#This Row],[2024 Cases Sold2]] -> -168 | W4: =(U4-T4)/T4 -> -0.14117647 | X4: 25 | Y4: 32 | Z4: =Y4-X4 -> 7 | AA4: 1919 | AB4: 1999 | AC4: =Table2[[#This Row],[2025 Cases Sold9]]-Table2[[#This Row],[2024 Cases Sold8]] -> 80 | AD4: =(AB4-AA4)/AA4 -> 0.041688379 | AF4: 190 | AG4: 254 | AI4: 374 | AJ4: 440 | AK4: =Table2[[#This Row],[2025 Cases Sold16]]-Table2[[#This Row],[2024 Cases Sold15]] -> 66 | AL4: =(AJ4-AI4)/AI4 -> 0.17647059 | AM4: 14 | AN4: 25
A5: 883428 | B5: FINE WINE & SPIRITS | C5: 14 RIVEREDGE RD | D5: TENAFLY | E5: =C5 & ", " & D5 -> 14 RIVEREDGE RD, TENAFLY | F5: NEW JERSEY | G5: 7670 | H5: B | I5: 45670 | J5: Yes | K5: Yes | L5: 4203 | M5: 3824 | N5: =Table2[[#This Row],[2025 Cases Sold]]-Table2[[#This Row],[2024 Cases Sold]] -> -379 | O5: =(M5-L5)/L5 -> -0.090173685 | P5: -0.08 | Q5: 176 | R5: 192 | S5: =R5-Q5 -> 16 | T5: 1673 | U5: 1818 | V5: =Table2[[#This Row],[2025 Cases Sold3]]-Table2[[#This Row],[2024 Cases Sold2]] -> 145 | W5: =(U5-T5)/T5 -> 0.086670652 | X5: 31 | Y5: 39 | Z5: =Y5-X5 -> 8 | AA5: 1741 | AB5: 1592 | AC5: =Table2[[#This Row],[2025 Cases Sold9]]-Table2[[#This Row],[2024 Cases Sold8]] -> -149 | AD5: =(AB5-AA5)/AA5 -> -0.085582998 | AF5: 145 | AG5: 151 | AI5: 641 | AJ5: 673 | AK5: =Table2[[#This Row],[2025 Cases Sold16]]-Table2[[#This Row],[2024 Cases Sold15]] -> 32 | AL5: =(AJ5-AI5)/AI5 -> 0.049921997 | AM5: 27 | AN5: 31
A6: 883818 | B6: PAY LESS LIQUOR & DELI | C6: 251 ELM ST | D6: ELMWOOD PARK | E6: =C6 & ", " & D6 -> 251 ELM ST, ELMWOOD PARK | F6: NEW JERSEY | G6: 7407 | H6: C | I6: 45677 | J6: Yes | K6: Yes | L6: 2060 | M6: 1969 | N6: =Table2[[#This Row],[2025 Cases Sold]]-Table2[[#This Row],[2024 Cases Sold]] -> -91 | O6: =(M6-L6)/L6 -> -0.044174757 | P6: -0.074 | Q6: 109 | R6: 113 | S6: =R6-Q6 -> 4 | T6: 950 | U6: 745 | V6: =Table2[[#This Row],[2025 Cases Sold3]]-Table2[[#This Row],[2024 Cases Sold2]] -> -205 | W6: =(U6-T6)/T6 -> -0.21578947 | X6: 25 | Y6: 28 | Z6: =Y6-X6 -> 3 | AA6: 890 | AB6: 980 | AC6: =Table2[[#This Row],[2025 Cases Sold9]]-Table2[[#This Row],[2024 Cases Sold8]] -> 90 | AD6: =(AB6-AA6)/AA6 -> 0.1011236 | AF6: 87 | AG6: 97 | AI6: 366 | AJ6: 340 | AK6: =Table2[[#This Row],[2025 Cases Sold16]]-Table2[[#This Row],[2024 Cases Sold15]] -> -26 | AL6: =(AJ6-AI6)/AI6 -> -0.071038251 | AM6: 25 | AN6: 25
A7: 1408721 | B7: LIQUOR MART | C7: 126 RIDGE RD | D7: NORTH ARLINGTON | E7: =C7 & ", " & D7 -> 126 RIDGE RD, NORTH ARLINGTON | F7: NEW JERSEY | G7: 7031 | H7: C | I7: 45680 | J7: Yes | K7: Yes | L7: 2587 | M7: 2501 | N7: =Table2[[#This Row],[2025 Cases Sold]]-Table2[[#This Row],[2024 Cases Sold]] -> -86 | O7: =(M7-L7)/L7 -> -0.033243139 | P7: -0.074 | Q7: 280 | R7: 272 | S7: =R7-Q7 -> -8 | T7: 893 | U7: 883 | V7: =Table2[[#This Row],[2025 Cases Sold3]]-Table2[[#This Row],[2024 Cases Sold2]] -> -10 | W7: =(U7-T7)/T7 -> -0.011198208 | X7: 42 | Y7: 38 | Z7: =Y7-X7 -> -4 | AA7: 1292 | AB7: 1162 | AC7: =Table2[[#This Row],[2025 Cases Sold9]]-Table2[[#This Row],[2024 Cases Sold8]] -> -130 | AD7: =(AB7-AA7)/AA7 -> -0.1006192 | AF7: 232 | AG7: 215 | AI7: 407 | AJ7: 382 | AK7: =Table2[[#This Row],[2025 Cases Sold16]]-Table2[[#This Row],[2024 Cases Sold15]] -> -25 | AL7: =(AJ7-AI7)/AI7 -> -0.061425061 | AM7: 36 | AN7: 34
A8: 883360 | B8: RAINBOW DELI & DISCOUNT LIQUORS | C8: 292 LAKEVIEW AVE | D8: CLIFTON | E8: =C8 & ", " & D8 -> 292 LAKEVIEW AVE, CLIFTON | F8: NEW JERSEY | G8: 7011 | H8: B | I8: 45685 | J8: Yes | K8: Yes | L8: 6895 | M8: 6900 | N8: =Table2[[#This Row],[2025 Cases Sold]]-Table2[[#This Row],[2024 Cases Sold]] -> 5 | O8: =(M8-L8)/L8 -> 0.00072516316 | P8: -0.08 | Q8: 306 | R8: 298 | S8: =R8-Q8 -> -8 | T8: 3926 | U8: 3876 | V8: =Table2[[#This Row],[2025 Cases Sold3]]-Table2[[#This Row],[2024 Cases Sold2]] -> -50 | W8: =(U8-T8)/T8 -> -0.012735609 | X8: 50 | Y8: 54 | Z8: =Y8-X8 -> 4 | AA8: 3384 | AB8: 3156 | AC8: =Table2[[#This Row],[2025 Cases Sold9]]-Table2[[#This Row],[2024 Cases Sold8]] -> -228 | AD8: =(AB8-AA8)/AA8 -> -0.067375887 | AF8: 234 | AG8: 233 | AI8: 1954 | AJ8: 1781 | AK8: =Table2[[#This Row],[2025 Cases Sold16]]-Table2[[#This Row],[2024 Cases Sold15]] -> -173 | AL8: =(AJ8-AI8)/AI8 -> -0.088536336 | AM8: 47 | AN8: 43
A9: 925590 | B9: QUICK STOP WINE & LIQUOR | C9: 83 GODWIN AVE | D9: RIDGEWOOD | E9: =C9 & ", " & D9 -> 83 GODWIN AVE, RIDGEWOOD | F9: NEW JERSEY | G9: 7450 | H9: C | I9: 45687 | J9: Yes | K9: Yes | L9: 1903 | M9: 1477 | N9: =Table2[[#This Row],[2025 Cases Sold]]-Table2[[#This Row],[2024 Cases Sold]] -> -426 | O9: =(M9-L9)/L9 -> -0.22385707 | P9: -0.08 | Q9: 247 | R9: 214 | S9: =R9-Q9 -> -33 | T9: 789 | U9: 507 | V9: =Table2[[#This Row],[2025 Cases Sold3]]-Table2[[#This Row],[2024 Cases Sold2]] -> -282 | W9: =(U9-T9)/T9 -> -0.35741445 | X9: 32 | Y9: 27 | Z9: =Y9-X9 -> -5 | AA9: 827 | AB9: 751 | AC9: =Table2[[#This Row],[2025 Cases Sold9]]-Table2[[#This Row],[2024 Cases Sold8]] -> -76 | AD9: =(AB9-AA9)/AA9 -> -0.091898428 | AF9: 185 | AG9: 168 | AI9: 338 | AJ9: 267 | AK9: =Table2[[#This Row],[2025 Cases Sold16]]-Table2[[#This Row],[2024 Cases Sold15]] -> -71 | AL9: =(AJ9-AI9)/AI9 -> -0.21005917 | AM9: 25 | AN9: 24
A10: 2031047 | B10: CIRCLE LIQUORS | C10: 1 S MAIN ST STE 1 | D10: LODI | E10: =C10 & ", " & D10 -> 1 S MAIN ST STE 1, LODI | F10: NEW JERSEY | G10: 7644 | H10: C | I10: 45720 | J10: Yes | K10: Yes | L10: 1339 | M10: 872 | N10: =Table2[[#This Row],[2025 Cases Sold]]-Table2[[#This Row],[2024 Cases Sold]] -> -467 | O10: =(M10-L10)/L10 -> -0.34876774 | P10: -0.081 | Q10: 191 | R10: 123 | S10: =R10-Q10 -> -68 | T10: 750 | U10: 584 | V10: =Table2[[#This Row],[2025 Cases Sold3]]-Table2[[#This Row],[2024 Cases Sold2]] -> -166 | W10: =(U10-T10)/T10 -> -0.22133333 | X10: 42 | Y10: 38 | Z10: =Y10-X10 -> -4 | AA10: 876 | AB10: 601 | AC10: =Table2[[#This Row],[2025 Cases Sold9]]-Table2[[#This Row],[2024 Cases Sold8]] -> -275 | AD10: =(AB10-AA10)/AA10 -> -0.31392694 | AF10: 156 | AG10: 89 | AI10: 505 | AJ10: 426 | AK10: =Table2[[#This Row],[2025 Cases Sold16]]-Table2[[#This Row],[2024 Cases Sold15]] -> -79 | AL10: =(AJ10-AI10)/AI10 -> -0.15643564 | AM10: 38 | AN10: 32
A11: 5101071 | B11: PARK AVENUE LIQUORS | C11: 307 PARK AVE | D11: PATERSON | E11: =C11 & ", " & D11 -> 307 PARK AVE, PATERSON | F11: NEW JERSEY | G11: 7504 | H11: B | I11: 45713 | J11: Yes | K11: Yes | L11: 2374 | M11: 2328 | N11: =Table2[[#This Row],[2025 Cases Sold]]-Table2[[#This Row],[2024 Cases Sold]] -> -46 | O11: =(M11-L11)/L11 -> -0.01937658 | P11: -0.069 | Q11: 87 | R11: 82 | S11: =R11-Q11 -> -5 | T11: 1818 | U11: 1844 | V11: =Table2[[#This Row],[2025 Cases Sold3]]-Table2[[#This Row],[2024 Cases Sold2]] -> 26 | W11: =(U11-T11)/T11 -> 0.01430143 | X11: 28 | Y11: 26 | Z11: =Y11-X11 -> -2 | AA11: 1451 | AB11: 1551 | AC11: =Table2[[#This Row],[2025 Cases Sold9]]-Table2[[#This Row],[2024 Cases Sold8]] -> 100 | AD11: =(AB11-AA11)/AA11 -> 0.068917988 | AF11: 73 | AG11: 60 | AI11: 1081 | AJ11: 1186 | AK11: =Table2[[#This Row],[2025 Cases Sold16]]-Table2[[#This Row],[2024 Cases Sold15]] -> 105 | AL11: =(AJ11-AI11)/AI11 -> 0.097132285 | AM11: 25 | AN11: 23
A12: 765916 | B12: MANOR BEVERAGES | C12: 430 BROAD AVE | D12: LEONIA | E12: =C12 & ", " & D12 -> 430 BROAD AVE, LEONIA | F12: NEW JERSEY | G12: 7605 | H12: B | I12: 45719 | J12: Yes | K12: Yes | L12: 1260 | M12: 1219 | N12: =Table2[[#This Row],[2025 Cases Sold]]-Table2[[#This Row],[2024 Cases Sold]] -> -41 | O12: =(M12-L12)/L12 -> -0.032539683 | P12: -0.067 | Q12: 114 | R12: 136 | S12: =R12-Q12 -> 22 | T12: 379 | U12: 430 | V12: =Table2[[#This Row],[2025 Cases Sold3]]-Table2[[#This Row],[2024 Cases Sold2]] -> 51 | W12: =(U12-T12)/T12 -> 0.13456464 | X12: 22 | Y12: 30 | Z12: =Y12-X12 -> 8 | AA12: 817 | AB12: 861 | AC12: =Table2[[#This Row],[2025 Cases Sold9]]-Table2[[#This Row],[2024 Cases Sold8]] -> 44 | AD12: =(AB12-AA12)/AA12 -> 0.053855569 | AF12: 90 | AG12: 113 | AI12: 244 | AJ12: 270 | AK12: =Table2[[#This Row],[2025 Cases Sold16]]-Table2[[#This Row],[2024 Cases Sold15]] -> 26 | AL12: =(AJ12-AI12)/AI12 -> 0.10655738 | AM12: 19 | AN12: 26
A13: 1873673 | B13: SHOPRITE LIQUORS (Northvale) | C13: 254 LIVINGSTON ST STE F | D13: NORTHVALE | E13: =C13 & ", " & D13 -> 254 LIVINGSTON ST STE F, NORTHVALE | F13: NEW JERSEY | G13: 7647 | H13: A | I13: 45726 | J13: Yes | K13: Yes | L13: 10155 | M13: 8847 | N13: =Table2[[#This Row],[2025 Cases Sold]]-Table2[[#This Row],[2024 Cases Sold]] -> -1308 | O13: =(M13-L13)/L13 -> -0.12880355 | P13: -0.069 | Q13: 466 | R13: 467 | S13: =R13-Q13 -> 1 | T13: 1806 | U13: 1456 | V13: =Table2[[#This Row],[2025 Cases Sold3]]-Table2[[#This Row],[2024 Cases Sold2]] -> -350 | W13: =(U13-T13)/T13 -> -0.19379845 | X13: 33 | Y13: 32 | Z13: =Y13-X13 -> -1 | AA13: 7208 | AB13: 6981 | AC13: =Table2[[#This Row],[2025 Cases Sold9]]-Table2[[#This Row],[2024 Cases Sold8]] -> -227 | AD13: =(AB13-AA13)/AA13 -> -0.031492786 | AF13: 428 | AG13: 435 | AI13: 1173 | AJ13: 1034 | AK13: =Table2[[#This Row],[2025 Cases Sold16]]-Table2[[#This Row],[2024 Cases Sold15]] -> -139 | AL13: =(AJ13-AI13)/AI13 -> -0.11849957 | AM13: 31 | AN13: 32
A14: 7514143 | B14: WALLINGTON LIQUORS | C14: 168 MAIN AVE | D14: WALLINGTON | E14: =C14 & ", " & D14 -> 168 MAIN AVE, WALLINGTON | F14: NEW JERSEY | G14: 7057 | H14: C | I14: 45728 | J14: No | K14: Yes | AC14: =Table2[[#This Row],[2025 Cases Sold9]]-Table2[[#This Row],[2024 Cases Sold8]] -> 0 | AK14: =Table2[[#This Row],[2025 Cases Sold16]]-Table2[[#This Row],[2024 Cases Sold15]] -> 0
A15: 1457427 | B15: MAIN STREET LIQUOR | C15: 340 S MAIN ST | D15: WHARTON | E15: =C15 & ", " & D15 -> 340 S MAIN ST, WHARTON | F15: NEW JERSEY | G15: 7885 | H15: C | I15: 45715 | J15: Yes | K15: Yes | L15: 2055 | M15: 2340 | N15: =Table2[[#This Row],[2025 Cases Sold]]-Table2[[#This Row],[2024 Cases Sold]] -> 285 | O15: =(M15-L15)/L15 -> 0.13868613 | P15: -0.076 | Q15: 171 | R15: 184 | S15: =R15-Q15 -> 13 | T15: 1075 | U15: 1190 | V15: =Table2[[#This Row],[2025 Cases Sold3]]-Table2[[#This Row],[2024 Cases Sold2]] -> 115 | W15: =(U15-T15)/T15 -> 0.10697674 | X15: 38 | Y15: 43 | Z15: =Y15-X15 -> 5 | AA15: 1295 | AB15: 1555 | AC15: =Table2[[#This Row],[2025 Cases Sold9]]-Table2[[#This Row],[2024 Cases Sold8]] -> 260 | AD15: =(AB15-AA15)/AA15 -> 0.2007722 | AF15: 164 | AG15: 167 | AI15: 653 | AJ15: 792 | AK15: =Table2[[#This Row],[2025 Cases Sold16]]-Table2[[#This Row],[2024 Cases Sold15]] -> 139 | AL15: =(AJ15-AI15)/AI15 -> 0.21286371 | AM15: 37 | AN15: 41
A16: 7611598 | B16: WINE SHOP | C16: 434 HACKENSACK ST | D16: CARLSTADT | E16: =C16 & ", " & D16 -> 434 HACKENSACK ST, CARLSTADT | F16: NEW JERSEY | G16: 7072 | H16: C | I16: 45741 | J16: Yes | K16: Yes | L16: 1144 | M16: 1026 | N16: =Table2[[#This Row],[2025 Cases Sold]]-Table2[[#This Row],[2024 Cases Sold]] -> -118 | O16: =(M16-L16)/L16 -> -0.10314685 | P16: -0.072 | Q16: 221 | R16: 215 | S16: =R16-Q16 -> -6 | T16: 321 | U16: 273 | V16: =Table2[[#This Row],[2025 Cases Sold3]]-Table2[[#This Row],[2024 Cases Sold2]] -> -48 | W16: =(U16-T16)/T16 -> -0.14953271 | X16: 31 | Y16: 40 | Z16: =Y16-X16 -> 9 | AA16: 1064 | AB16: 925 | AC16: =Table2[[#This Row],[2025 Cases Sold9]]-Table2[[#This Row],[2024 Cases Sold8]] -> -139 | AD16: =(AB16-AA16)/AA16 -> -0.1306391 | AF16: 205 | AG16: 202 | AI16: 321 | AJ16: 201 | AK16: =Table2[[#This Row],[2025 Cases Sold16]]-Table2[[#This Row],[2024 Cases Sold15]] -> -120 | AL16: =(AJ16-AI16)/AI16 -> -0.37383178 | AM16: 31 | AN16: 37
A17: 7335402 | B17: SUSSEX DISCOUNT LIQUORS | C17: 3235 STATE RT 94 | D17: FRANKLIN | E17: =C17 & ", " & D17 -> 3235 STATE RT 94, FRANKLIN | F17: NEW JERSEY | G17: 7416 | H17: C | I17: 45747 | J17: Yes | K17: Yes | L17: 2564 | M17: 2133 | N17: =Table2[[#This Row],[2025 Cases Sold]]-Table2[[#This Row],[2024 Cases Sold]] -> -431 | O17: =(M17-L17)/L17 -> -0.16809672 | P17: -0.063 | Q17: 257 | R17: 257 | S17: =R17-Q17 -> 0 | T17: 252 | U17: 162 | V17: =Table2[[#This Row],[2025 Cases Sold3]]-Table2[[#This Row],[2024 Cases Sold2]] -> -90 | W17: =(U17-T17)/T17 -> -0.35714286 | X17: 25 | Y17: 20 | Z17: =Y17-X17 -> -5 | AA17: 2564 | AB17: 2133 | AC17: =Table2[[#This Row],[2025 Cases Sold9]]-Table2[[#This Row],[2024 Cases Sold8]] -> -431 | AD17: =(AB17-AA17)/AA17 -> -0.16809672 | AF17: 257 | AG17: 257 | AI17: 252 | AJ17: 162 | AK17: =Table2[[#This Row],[2025 Cases Sold16]]-Table2[[#This Row],[2024 Cases Sold15]] -> -90 | AL17: =(AJ17-AI17)/AI17 -> -0.35714286 | AM17: 25 | AN17: 20
A18: 3759473 | B18: SAM ON THE ROCKS | C18: 101 NEWARK POMPTON TPK | D18: LITTLE FALLS | E18: =C18 & ", " & D18 -> 101 NEWARK POMPTON TPK, LITTLE FALLS | F18: NEW JERSEY | G18: 7424 | H18: C | I18: 45734 | J18: No | K18: Yes | AC18: =Table2[[#This Row],[2025 Cases Sold9]]-Table2[[#This Row],[2024 Cases Sold8]] -> 0 | AK18: =Table2[[#This Row],[2025 Cases Sold16]]-Table2[[#This Row],[2024 Cases Sold15]] -> 0
A19: 1872531 | B19: HIGH SPIRITS (Exquisite W&L?) | C19: 215 MAIN ST | D19: RIDGEFIELD PARK | E19: =C19 & ", " & D19 -> 215 MAIN ST, RIDGEFIELD PARK | F19: NEW JERSEY | G19: 7660 | H19: A | I19: 45755 | J19: Yes | K19: Yes | L19: 4683 | M19: 4827 | N19: =Table2[[#This Row],[2025 Cases Sold]]-Table2[[#This Row],[2024 Cases Sold]] -> 144 | O19: =(M19-L19)/L19 -> 0.03074952 | P19: -0.082 | Q19: 269 | R19: 296 | S19: =R19-Q19 -> 27 | T19: 1970 | U19: 2142 | V19: =Table2[[#This Row],[2025 Cases Sold3]]-Table2[[#This Row],[2024 Cases Sold2]] -> 172 | W19: =(U19-T19)/T19 -> 0.087309645 | X19: 45 | Y19: 45 | Z19: =Y19-X19 -> 0 | AA19: 4683 | AB19: 4827 | AC19: =Table2[[#This Row],[2025 Cases Sold9]]-Table2[[#This Row],[2024 Cases Sold8]] -> 144 | AD19: =(AB19-AA19)/AA19 -> 0.03074952 | AI19: 1970 | AJ19: 2142 | AK19: =Table2[[#This Row],[2025 Cases Sold16]]-Table2[[#This Row],[2024 Cases Sold15]] -> 172 | AL19: =(AJ19-AI19)/AI19 -> 0.087309645
A20: 951582 | B20: LUCKY 7 WINE & LIQUORS | C20: 77 RIVER RD | D20: NORTH ARLINGTON | E20: =C20 & ", " & D20 -> 77 RIVER RD, NORTH ARLINGTON | F20: NEW JERSEY | G20: 7031 | H20: A | I20: 45756 | J20: Yes | K20: Yes | L20: 5458 | M20: 5885 | N20: =Table2[[#This Row],[2025 Cases Sold]]-Table2[[#This Row],[2024 Cases Sold]] -> 427 | O20: =(M20-L20)/L20 -> 0.078233785 | P20: -0.082 | Q20: 272 | R20: 307 | S20: =R20-Q20 -> 35 | T20: 1539 | U20: 1754 | V20: =Table2[[#This Row],[2025 Cases Sold3]]-Table2[[#This Row],[2024 Cases Sold2]] -> 215 | W20: =(U20-T20)/T20 -> 0.1397011 | X20: 39 | Y20: 45 | Z20: =Y20-X20 -> 6 | AA20: 5458 | AB20: 5885 | AC20: =Table2[[#This Row],[2025 Cases Sold9]]-Table2[[#This Row],[2024 Cases Sold8]] -> 427 | AD20: =(AB20-AA20)/AA20 -> 0.078233785 | AI20: 1539 | AJ20: 1754 | AK20: =Table2[[#This Row],[2025 Cases Sold16]]-Table2[[#This Row],[2024 Cases Sold15]] -> 215 | AL20: =(AJ20-AI20)/AI20 -> 0.1397011
A21: 7523110 | B21: WIDES DELI & LIQUORS | C21: 85 CENTRAL AVE | D21: RIDGEFIELD PARK | E21: =C21 & ", " & D21 -> 85 CENTRAL AVE, RIDGEFIELD PARK | F21: NEW JERSEY | G21: 7660 | H21: C | I21: 45756 | J21: Yes | K21: Yes | L21: 611 | M21: 684 | N21: =Table2[[#This Row],[2025 Cases Sold]]-Table2[[#This Row],[2024 Cases Sold]] -> 73 | O21: =(M21-L21)/L21 -> 0.11947627 | P21: -0.082 | Q21: 24 | R21: 25 | S21: =R21-Q21 -> 1 | T21: 332 | U21: 415 | V21: =Table2[[#This Row],[2025 Cases Sold3]]-Table2[[#This Row],[2024 Cases Sold2]] -> 83 | W21: =(U21-T21)/T21 -> 0.25 | X21: 24 | Y21: 25 | Z21: =Y21-X21 -> 1 | AA21: 611 | AB21: 684 | AC21: =Table2[[#This Row],[2025 Cases Sold9]]-Table2[[#This Row],[2024 Cases Sold8]] -> 73 | AD21: =(AB21-AA21)/AA21 -> 0.11947627 | AI21: 332 | AJ21: 415 | AK21: =Table2[[#This Row],[2025 Cases Sold16]]-Table2[[#This Row],[2024 Cases Sold15]] -> 83 | AL21: =(AJ21-AI21)/AI21 -> 0.25
A22: 7335895 | B22: RIDGEFIELD LIQUOR | C22: 520 SHALER BLVD | D22: RIDGEFIELD | E22: =C22 & ", " & D22 -> 520 SHALER BLVD, RIDGEFIELD | F22: NEW JERSEY | G22: 7657 | H22: B | I22: 45757 | J22: Yes | K22: Yes | L22: 1508 | M22: 1479 | N22: =Table2[[#This Row],[2025 Cases Sold]]-Table2[[#This Row],[2024 Cases Sold]] -> -29 | O22: =(M22-L22)/L22 -> -0.019230769 | P22: -0.082 | Q22: 132 | R22: 140 | S22: =R22-Q22 -> 8 | T22: 607 | U22: 653 | V22: =Table2[[#This Row],[2025 Cases Sold3]]-Table2[[#This Row],[2024 Cases Sold2]] -> 46 | W22: =(U22-T22)/T22 -> 0.075782537 | X22: 19 | Y22: 27 | Z22: =Y22-X22 -> 8 | AA22: 1508 | AB22: 1479 | AC22: =Table2[[#This Row],[2025 Cases Sold9]]-Table2[[#This Row],[2024 Cases Sold8]] -> -29 | AD22: =(AB22-AA22)/AA22 -> -0.019230769 | AI22: 607 | AJ22: 653 | AK22: =Table2[[#This Row],[2025 Cases Sold16]]-Table2[[#This Row],[2024 Cases Sold15]] -> 46 | AL22: =(AJ22-AI22)/AI22 -> 0.075782537
A23: 764602 | B23: FIGLARS LIQUOR STORE | C23: 327 HOPE AVE | D23: CLIFTON | E23: =C23 & ", " & D23 -> 327 HOPE AVE, CLIFTON | F23: NEW JERSEY | G23: 7011 | H23: A | I23: 45766 | J23: Yes | K23: Yes | L23: 4668 | M23: 3941 | N23: =Table2[[#This Row],[2025 Cases Sold]]-Table2[[#This Row],[2024 Cases Sold]] -> -727 | O23: =(M23-L23)/L23 -> -0.15574122 | P23: -0.081 | Q23: 45 | R23: 48 | S23: =R23-Q23 -> 3 | T23: 2889 | U23: 2638 | V23: =Table2[[#This Row],[2025 Cases Sold3]]-Table2[[#This Row],[2024 Cases Sold2]] -> -251 | W23: =(U23-T23)/T23 -> -0.086881274 | X23: 45 | Y23: 48 | Z23: =Y23-X23 -> 3 | AA23: 4668 | AB23: 3941 | AC23: =Table2[[#This Row],[2025 Cases Sold9]]-Table2[[#This Row],[2024 Cases Sold8]] -> -727 | AD23: =(AB23-AA23)/AA23 -> -0.15574122 | AI23: 2889 | AJ23: 2638 | AK23: =Table2[[#This Row],[2025 Cases Sold16]]-Table2[[#This Row],[2024 Cases Sold15]] -> -251 | AL23: =(AJ23-AI23)/AI23 -> -0.086881274
A24: 7355880 | B24: FOOD MART LIQUOR | C24: 430 MARKET ST | D24: ELMWOOD PARK | E24: =C24 & ", " & D24 -> 430 MARKET ST, ELMWOOD PARK | F24: NEW JERSEY | G24: 7407 | H24: C | I24: 45756 | J24: Yes | K24: Yes | L24: 531 | M24: 629 | N24: =Table2[[#This Row],[2025 Cases Sold]]-Table2[[#This Row],[2024 Cases Sold]] -> 98 | O24: =(M24-L24)/L24 -> 0.18455744 | P24: -0.082 | Q24: 96 | R24: 67 | S24: =R24-Q24 -> -29 | T24: 236 | U24: 334 | V24: =Table2[[#This Row],[2025 Cases Sold3]]-Table2[[#This Row],[2024 Cases Sold2]] -> 98 | W24: =(U24-T24)/T24 -> 0.41525424 | X24: 25 | Y24: 26 | Z24: =Y24-X24 -> 1 | AA24: 531 | AB24: 629 | AC24: =Table2[[#This Row],[2025 Cases Sold9]]-Table2[[#This Row],[2024 Cases Sold8]] -> 98 | AD24: =(AB24-AA24)/AA24 -> 0.18455744 | AI24: 236 | AJ24: 334 | AK24: =Table2[[#This Row],[2025 Cases Sold16]]-Table2[[#This Row],[2024 Cases Sold15]] -> 98 | AL24: =(AJ24-AI24)/AI24 -> 0.41525424
A25: 883599 | B25: ARCHIES LIQUOR | C25: 229 MAIN AVE | D25: PASSAIC | E25: =C25 & ", " & D25 -> 229 MAIN AVE, PASSAIC | F25: NEW JERSEY | G25: 7055 | H25: A | I25: 45761 | J25: Yes | K25: Yes | L25: 5107 | M25: 4147 | N25: =Table2[[#This Row],[2025 Cases Sold]]-Table2[[#This Row],[2024 Cases Sold]] -> -960 | O25: =(M25-L25)/L25 -> -0.18797729 | P25: -0.084 | Q25: 128 | R25: 106 | S25: =R25-Q25 -> -22 | T25: 2762 | U25: 2451 | V25: =Table2[[#This Row],[2025 Cases Sold3]]-Table2[[#This Row],[2024 Cases Sold2]] -> -311 | W25: =(U25-T25)/T25 -> -0.11259957 | X25: 41 | Y25: 37 | Z25: =Y25-X25 -> -4 | AA25: 5107 | AB25: 4147 | AC25: =Table2[[#This Row],[2025 Cases Sold9]]-Table2[[#This Row],[2024 Cases Sold8]] -> -960 | AD25: =(AB25-AA25)/AA25 -> -0.18797729 | AI25: 2762 | AJ25: 2451 | AK25: =Table2[[#This Row],[2025 Cases Sold16]]-Table2[[#This Row],[2024 Cases Sold15]] -> -311 | AL25: =(AJ25-AI25)/AI25 -> -0.11259957
A26: 883625 | B26: SHANIK LIQUORS | C26: 952 MAIN AVE | D26: PASSAIC | E26: =C26 & ", " & D26 -> 952 MAIN AVE, PASSAIC | F26: NEW JERSEY | G26: 7055 | H26: A | I26: 45762 | J26: Yes | K26: Yes | L26: 5370 | M26: 5202 | N26: =Table2[[#This Row],[2025 Cases Sold]]-Table2[[#This Row],[2024 Cases Sold]] -> -168 | O26: =(M26-L26)/L26 -> -0.031284916 | P26: -0.084 | Q26: 128 | R26: 129 | S26: =R26-Q26 -> 1 | T26: 3659 | U26: 3462 | V26: =Table2[[#This Row],[2025 Cases Sold3]]-Table2[[#This Row],[2024 Cases Sold2]] -> -197 | W26: =(U26-T26)/T26 -> -0.053839847 | X26: 47 | Y26: 50 | Z26: =Y26-X26 -> 3 | AA26: 5370 | AB26: 5202 | AC26: =Table2[[#This Row],[2025 Cases Sold9]]-Table2[[#This Row],[2024 Cases Sold8]] -> -168 | AD26: =(AB26-AA26)/AA26 -> -0.031284916 | AI26: 3659 | AJ26: 3462 | AK26: =Table2[[#This Row],[2025 Cases Sold16]]-Table2[[#This Row],[2024 Cases Sold15]] -> -197 | AL26: =(AJ26-AI26)/AI26 -> -0.053839847
A27: 7588093 | B27: MARINAS WINE & SPIRIT | C27: 497 VAN HOUTEN AVE | D27: PASSAIC | E27: =C27 & ", " & D27 -> 497 VAN HOUTEN AVE, PASSAIC | F27: NEW JERSEY | G27: 7055 | H27: B | I27: 45768 | J27: No | K27: Yes | AC27: =Table2[[#This Row],[2025 Cases Sold9]]-Table2[[#This Row],[2024 Cases Sold8]] -> 0 | AK27: =Table2[[#This Row],[2025 Cases Sold16]]-Table2[[#This Row],[2024 Cases Sold15]] -> 0
A28: 6954 | B28: SHOPRITE LIQUORS (Clifton) | C28: 895 PAULISON AVE | D28: CLIFTON | E28: =C28 & ", " & D28 -> 895 PAULISON AVE, CLIFTON | F28: NEW JERSEY | G28: 7011 | H28: A | I28: 45775 | J28: Yes | K28: Yes | L28: 8500 | M28: 7283 | N28: =Table2[[#This Row],[2025 Cases Sold]]-Table2[[#This Row],[2024 Cases Sold]] -> -1217 | O28: =(M28-L28)/L28 -> -0.14317647 | P28: -0.083 | Q28: 421 | R28: 469 | S28: =R28-Q28 -> 48 | T28: 4798 | U28: 3905 | V28: =Table2[[#This Row],[2025 Cases Sold3]]-Table2[[#This Row],[2024 Cases Sold2]] -> -893 | W28: =(U28-T28)/T28 -> -0.18611922 | X28: 60 | Y28: 62 | Z28: =Y28-X28 -> 2 | AC28: =Table2[[#This Row],[2025 Cases Sold9]]-Table2[[#This Row],[2024 Cases Sold8]] -> 0 | AK28: =Table2[[#This Row],[2025 Cases Sold16]]-Table2[[#This Row],[2024 Cases Sold15]] -> 0
A29: 883901 | B29: BUY RITE | C29: 410 RIVER ST | D29: HACKENSACK | E29: =C29 & ", " & D29 -> 410 RIVER ST, HACKENSACK | F29: NEW JERSEY | G29: 7601 | H29: A | I29: 45776 | J29: Yes | K29: Yes | L29: 7983 | M29: 7611 | N29: =Table2[[#This Row],[2025 Cases Sold]]-Table2[[#This Row],[2024 Cases Sold]] -> -372 | O29: =(M29-L29)/L29 -> -0.046599023 | P29: -0.083 | Q29: 46 | R29: 49 | S29: =R29-Q29 -> 3 | T29: 4896 | U29: 4819 | V29: =Table2[[#This Row],[2025 Cases Sold3]]-Table2[[#This Row],[2024 Cases Sold2]] -> -77 | W29: =(U29-T29)/T29 -> -0.015727124 | X29: 46 | Y29: 49 | Z29: =Y29-X29 -> 3 | AC29: =Table2[[#This Row],[2025 Cases Sold9]]-Table2[[#This Row],[2024 Cases Sold8]] -> 0 | AK29: =Table2[[#This Row],[2025 Cases Sold16]]-Table2[[#This Row],[2024 Cases Sold15]] -> 0
A30: 883459 | B30: SHOPPERS VINEYARD | C30: 875 BLOOMFIELD AVE | D30: CLIFTON | E30: =C30 & ", " & D30 -> 875 BLOOMFIELD AVE, CLIFTON | F30: NEW JERSEY | G30: 7012 | H30: A | I30: 45772 | J30: Yes | K30: Yes | L30: 11857 | M30: 11562 | N30: =Table2[[#This Row],[2025 Cases Sold]]-Table2[[#This Row],[2024 Cases Sold]] -> -295 | O30: =(M30-L30)/L30 -> -0.024879818 | P30: -0.08 | Q30: 334 | R30: 360 | S30: =R30-Q30 -> 26 | T30: 5679 | U30: 5941 | V30: =Table2[[#This Row],[2025 Cases Sold3]]-Table2[[#This Row],[2024 Cases Sold2]] -> 262 | W30: =(U30-T30)/T30 -> 0.046134883 | X30: 47 | Y30: 49 | Z30: =Y30-X30 -> 2 | AC30: =Table2[[#This Row],[2025 Cases Sold9]]-Table2[[#This Row],[2024 Cases Sold8]] -> 0 | AK30: =Table2[[#This Row],[2025 Cases Sold16]]-Table2[[#This Row],[2024 Cases Sold15]] -> 0
A31: 883883 | B31: BOTTLE KING | C31: 909 PROSPECT ST | D31: GLEN ROCK | E31: =C31 & ", " & D31 -> 909 PROSPECT ST, GLEN ROCK | F31: NEW JERSEY | G31: 7452 | H31: A | I31: 45771 | J31: Yes | K31: Yes | L31: 15744 | M31: 12844 | N31: =Table2[[#This Row],[2025 Cases Sold]]-Table2[[#This Row],[2024 Cases Sold]] -> -2900 | O31: =(M31-L31)/L31 -> -0.18419715 | P31: -0.08 | Q31: 677 | R31: 699 | S31: =R31-Q31 -> 22 | T31: 2698 | U31: 2110 | V31: =Table2[[#This Row],[2025 Cases Sold3]]-Table2[[#This Row],[2024 Cases Sold2]] -> -588 | W31: =(U31-T31)/T31 -> -0.21793921 | X31: 42 | Y31: 46 | Z31: =Y31-X31 -> 4 | AC31: =Table2[[#This Row],[2025 Cases Sold9]]-Table2[[#This Row],[2024 Cases Sold8]] -> 0 | AK31: =Table2[[#This Row],[2025 Cases Sold16]]-Table2[[#This Row],[2024 Cases Sold15]] -> 0
A32: 883465 | B32: PETES LIQUORS | C32: 383 VALLEY RD | D32: CLIFTON | E32: =C32 & ", " & D32 -> 383 VALLEY RD, CLIFTON | F32: NEW JERSEY | G32: 7013 | H32: C | I32: 45783 | J32: Yes | K32: Yes | AC32: =Table2[[#This Row],[2025 Cases Sold9]]-Table2[[#This Row],[2024 Cases Sold8]] -> 0 | AK32: =Table2[[#This Row],[2025 Cases Sold16]]-Table2[[#This Row],[2024 Cases Sold15]] -> 0
A33: 889722 | B33: ALTIERO LIQUORS | C33: 498 ELLISON ST | D33: PATERSON | E33: =C33 & ", " & D33 -> 498 ELLISON ST, PATERSON | F33: NEW JERSEY | G33: 7501 | H33: C | I33: 45784 | J33: No | K33: Yes | AC33: =Table2[[#This Row],[2025 Cases Sold9]]-Table2[[#This Row],[2024 Cases Sold8]] -> 0 | AK33: =Table2[[#This Row],[2025 Cases Sold16]]-Table2[[#This Row],[2024 Cases Sold15]] -> 0
A34: 883771 | B34: THE LIQUOR SHOP | C34: 498 E 30TH ST | D34: PATERSON | E34: =C34 & ", " & D34 -> 498 E 30TH ST, PATERSON | F34: NEW JERSEY | G34: 7504 | H34: A | I34: 45768 | J34: Yes | K34: Yes | L34: 9086 | M34: 9750 | N34: =Table2[[#This Row],[2025 Cases Sold]]-Table2[[#This Row],[2024 Cases Sold]] -> 664 | O34: =(M34-L34)/L34 -> 0.073079463 | P34: -0.085 | Q34: 154 | R34: 137 | S34: =R34-Q34 -> -17 | T34: 6394 | U34: 7407 | V34: =Table2[[#This Row],[2025 Cases Sold3]]-Table2[[#This Row],[2024 Cases Sold2]] -> 1013 | W34: =(U34-T34)/T34 -> 0.15842978 | X34: 46 | Y34: 48 | Z34: =Y34-X34 -> 2 | AA34: 10984 | AB34: 12493 | AC34: =Table2[[#This Row],[2025 Cases Sold9]]-Table2[[#This Row],[2024 Cases Sold8]] -> 1509 | AD34: =(AB34-AA34)/AA34 -> 0.13738165 | AF34: 163 | AG34: 151 | AH34: =(AG34-AF34)/AF34 -> -0.073619632 | AI34: 7780 | AJ34: 9475 | AK34: =Table2[[#This Row],[2025 Cases Sold16]]-Table2[[#This Row],[2024 Cases Sold15]] -> 1695 | AL34: =(AJ34-AI34)/AI34 -> 0.21786632 | AM34: 47 | AN34: 50
A35: 889832 | B35: SUPER WINE WAREHOUSE | C35: 42 E 30TH ST | D35: PATERSON | E35: =C35 & ", " & D35 -> 42 E 30TH ST, PATERSON | F35: NEW JERSEY | G35: 7514 | H35: A | I35: 45768 | J35: Yes | K35: Yes | L35: 19546 | M35: 17902 | N35: =Table2[[#This Row],[2025 Cases Sold]]-Table2[[#This Row],[2024 Cases Sold]] -> -1644 | O35: =(M35-L35)/L35 -> -0.084109281 | P35: -0.085 | Q35: 405 | R35: 401 | S35: =R35-Q35 -> -4 | T35: 10843 | U35: 10302 | V35: =Table2[[#This Row],[2025 Cases Sold3]]-Table2[[#This Row],[2024 Cases Sold2]] -> -541 | W35: =(U35-T35)/T35 -> -0.049893941 | X35: 58 | Y35: 65 | Z35: =Y35-X35 -> 7 | AA35: 25160 | AB35: 23755 | AC35: =Table2[[#This Row],[2025 Cases Sold9]]-Table2[[#This Row],[2024 Cases Sold8]] -> -1405 | AD35: =(AB35-AA35)/AA35 -> -0.055842607 | AF35: 424 | AG35: 424 | AI35: 14386 | AJ35: 14249 | AK35: =Table2[[#This Row],[2025 Cases Sold16]]-Table2[[#This Row],[2024 Cases Sold15]] -> -137 | AL35: =(AJ35-AI35)/AI35 -> -0.0095231475
A36: 7355800 | B36: FARMBOY SUPER FRESH LIQUOR | C36: 465 GETTY AVE | D36: PATERSON | E36: =C36 & ", " & D36 -> 465 GETTY AVE, PATERSON | F36: NEW JERSEY | G36: 7503 | H36: A | I36: 45770 | J36: Yes | K36: Yes | L36: 5261 | M36: 5804 | N36: =Table2[[#This Row],[2025 Cases Sold]]-Table2[[#This Row],[2024 Cases Sold]] -> 543 | O36: =(M36-L36)/L36 -> 0.10321232 | P36: -0.085 | Q36: 154 | R36: 153 | S36: =R36-Q36 -> -1 | T36: 3636 | U36: 4185 | V36: =Table2[[#This Row],[2025 Cases Sold3]]-Table2[[#This Row],[2024 Cases Sold2]] -> 549 | W36: =(U36-T36)/T36 -> 0.1509901 | X36: 54 | Y36: 55 | Z36: =Y36-X36 -> 1 | AC36: =Table2[[#This Row],[2025 Cases Sold9]]-Table2[[#This Row],[2024 Cases Sold8]] -> 0 | AK36: =Table2[[#This Row],[2025 Cases Sold16]]-Table2[[#This Row],[2024 Cases Sold15]] -> 0
A37: 1408390 | B37: CLIFTON DISCOUNT LIQUORS | C37: 73 ACKERMAN AVE | D37: CLIFTON | E37: =C37 & ", " & D37 -> 73 ACKERMAN AVE, CLIFTON | F37: NEW JERSEY | G37: 7011 | H37: A | I37: 45775 | J37: Yes | K37: Yes | L37: 12934 | M37: 12695 | N37: =Table2[[#This Row],[2025 Cases Sold]]-Table2[[#This Row],[2024 Cases Sold]] -> -239 | O37: =(M37-L37)/L37 -> -0.018478429 | P37: -0.083 | Q37: 228 | R37: 247 | S37: =R37-Q37 -> 19 | T37: 8643 | U37: 8595 | V37: =Table2[[#This Row],[2025 Cases Sold3]]-Table2[[#This Row],[2024 Cases Sold2]] -> -48 | W37: =(U37-T37)/T37 -> -0.0055536272 | X37: 54 | Y37: 58 | Z37: =Y37-X37 -> 4 | AC37: =Table2[[#This Row],[2025 Cases Sold9]]-Table2[[#This Row],[2024 Cases Sold8]] -> 0 | AK37: =Table2[[#This Row],[2025 Cases Sold16]]-Table2[[#This Row],[2024 Cases Sold15]] -> 0
A38: 2621540 | B38: CLIFTON COMMONS SPIRITS & WINES | C38: 132 KINGSLAND RD | D38: CLIFTON | E38: =C38 & ", " & D38 -> 132 KINGSLAND RD, CLIFTON | F38: NEW JERSEY | G38: 7014 | H38: A | I38: 45772 | J38: Yes | K38: Yes | L38: 5797 | M38: 4864 | N38: =Table2[[#This Row],[2025 Cases Sold]]-Table2[[#This Row],[2024 Cases Sold]] -> -933 | O38: =(M38-L38)/L38 -> -0.16094532 | P38: -0.078 | Q38: 459 | R38: 421 | S38: =R38-Q38 -> -38 | T38: 1525 | U38: 1237 | V38: =Table2[[#This Row],[2025 Cases Sold3]]-Table2[[#This Row],[2024 Cases Sold2]] -> -288 | W38: =(U38-T38)/T38 -> -0.18885246 | X38: 46 | Y38: 51 | Z38: =Y38-X38 -> 5 | AC38: =Table2[[#This Row],[2025 Cases Sold9]]-Table2[[#This Row],[2024 Cases Sold8]] -> 0 | AK38: =Table2[[#This Row],[2025 Cases Sold16]]-Table2[[#This Row],[2024 Cases Sold15]] -> 0
A39: 7595164 | B39: SUPER CELLARS - Westwood Wines & Liquor | C39: 725 BROADWAY | D39: WESTWOOD | E39: =C39 & ", " & D39 -> 725 BROADWAY, WESTWOOD | F39: NEW JERSEY | G39: 7675 | H39: B | I39: 45790 | J39: Yes | K39: Yes | AC39: =Table2[[#This Row],[2025 Cases Sold9]]-Table2[[#This Row],[2024 Cases Sold8]] -> 0 | AK39: =Table2[[#This Row],[2025 Cases Sold16]]-Table2[[#This Row],[2024 Cases Sold15]] -> 0
