Workbook

Sheet Summary by Supplier
A1: Summer Display Auction — Qualifying Displays by Supplier
A2: Kohler iSell Beer Summer Display Program · 07/01/2026 – 08/31/2026 · one row per photo submission, counted once in its case-size tier
A4: Supplier / Brand Group | B4: Gold 70+ cases | C4: Silver 40-69 cases | D4: Bronze 20-39 cases | E4: Other 10-19 cases | F4: Total Qualifying Displays | G4: Total Cases (qualifying) | H4: Total Points | I4: Non-Qualifying (<10 cases) | J4: Total Submissions
A5: Constellation | B5: =COUNTIFS('Display Detail'!$J$2:$J$656,$A5,'Display Detail'!$K$2:$K$656,4) -> 58 | C5: =COUNTIFS('Display Detail'!$J$2:$J$656,$A5,'Display Detail'!$K$2:$K$656,3) -> 51 | D5: =COUNTIFS('Display Detail'!$J$2:$J$656,$A5,'Display Detail'!$K$2:$K$656,2) -> 23 | E5: =COUNTIFS('Display Detail'!$J$2:$J$656,$A5,'Display Detail'!$K$2:$K$656,1) -> 10 | F5: =COUNTIFS('Display Detail'!$J$2:$J$656,$A5,'Display Detail'!$K$2:$K$656,">0") -> 142 | G5: =SUMIFS('Display Detail'!$M$2:$M$656,'Display Detail'!$J$2:$J$656,$A5,'Display Detail'!$K$2:$K$656,">0") -> 9087 | H5: =SUMIFS('Display Detail'!$P$2:$P$656,'Display Detail'!$J$2:$J$656,$A5,'Display Detail'!$K$2:$K$656,">0") -> 92400 | I5: =COUNTIFS('Display Detail'!$J$2:$J$656,$A5,'Display Detail'!$K$2:$K$656,0) -> 45 | J5: =COUNTIF('Display Detail'!$J$2:$J$656,$A5) -> 187
A6: Molson Coors | B6: =COUNTIFS('Display Detail'!$J$2:$J$656,$A6,'Display Detail'!$K$2:$K$656,4) -> 38 | C6: =COUNTIFS('Display Detail'!$J$2:$J$656,$A6,'Display Detail'!$K$2:$K$656,3) -> 28 | D6: =COUNTIFS('Display Detail'!$J$2:$J$656,$A6,'Display Detail'!$K$2:$K$656,2) -> 15 | E6: =COUNTIFS('Display Detail'!$J$2:$J$656,$A6,'Display Detail'!$K$2:$K$656,1) -> 6 | F6: =COUNTIFS('Display Detail'!$J$2:$J$656,$A6,'Display Detail'!$K$2:$K$656,">0") -> 87 | G6: =SUMIFS('Display Detail'!$M$2:$M$656,'Display Detail'!$J$2:$J$656,$A6,'Display Detail'!$K$2:$K$656,">0") -> 5983 | H6: =SUMIFS('Display Detail'!$P$2:$P$656,'Display Detail'!$J$2:$J$656,$A6,'Display Detail'!$K$2:$K$656,">0") -> 57700 | I6: =COUNTIFS('Display Detail'!$J$2:$J$656,$A6,'Display Detail'!$K$2:$K$656,0) -> 22 | J6: =COUNTIF('Display Detail'!$J$2:$J$656,$A6) -> 109
A7: HUSA (Heineken USA) | B7: =COUNTIFS('Display Detail'!$J$2:$J$656,$A7,'Display Detail'!$K$2:$K$656,4) -> 15 | C7: =COUNTIFS('Display Detail'!$J$2:$J$656,$A7,'Display Detail'!$K$2:$K$656,3) -> 19 | D7: =COUNTIFS('Display Detail'!$J$2:$J$656,$A7,'Display Detail'!$K$2:$K$656,2) -> 5 | E7: =COUNTIFS('Display Detail'!$J$2:$J$656,$A7,'Display Detail'!$K$2:$K$656,1) -> 6 | F7: =COUNTIFS('Display Detail'!$J$2:$J$656,$A7,'Display Detail'!$K$2:$K$656,">0") -> 45 | G7: =SUMIFS('Display Detail'!$M$2:$M$656,'Display Detail'!$J$2:$J$656,$A7,'Display Detail'!$K$2:$K$656,">0") -> 2710 | H7: =SUMIFS('Display Detail'!$P$2:$P$656,'Display Detail'!$J$2:$J$656,$A7,'Display Detail'!$K$2:$K$656,">0") -> 27200 | I7: =COUNTIFS('Display Detail'!$J$2:$J$656,$A7,'Display Detail'!$K$2:$K$656,0) -> 3 | J7: =COUNTIF('Display Detail'!$J$2:$J$656,$A7) -> 48
A8: Boston Beer | B8: =COUNTIFS('Display Detail'!$J$2:$J$656,$A8,'Display Detail'!$K$2:$K$656,4) -> 46 | C8: =COUNTIFS('Display Detail'!$J$2:$J$656,$A8,'Display Detail'!$K$2:$K$656,3) -> 41 | D8: =COUNTIFS('Display Detail'!$J$2:$J$656,$A8,'Display Detail'!$K$2:$K$656,2) -> 38 | E8: =COUNTIFS('Display Detail'!$J$2:$J$656,$A8,'Display Detail'!$K$2:$K$656,1) -> 13 | F8: =COUNTIFS('Display Detail'!$J$2:$J$656,$A8,'Display Detail'!$K$2:$K$656,">0") -> 138 | G8: =SUMIFS('Display Detail'!$M$2:$M$656,'Display Detail'!$J$2:$J$656,$A8,'Display Detail'!$K$2:$K$656,">0") -> 8104 | H8: =SUMIFS('Display Detail'!$P$2:$P$656,'Display Detail'!$J$2:$J$656,$A8,'Display Detail'!$K$2:$K$656,">0") -> 80500 | I8: =COUNTIFS('Display Detail'!$J$2:$J$656,$A8,'Display Detail'!$K$2:$K$656,0) -> 71 | J8: =COUNTIF('Display Detail'!$J$2:$J$656,$A8) -> 209
A9: Mark Anthony | B9: =COUNTIFS('Display Detail'!$J$2:$J$656,$A9,'Display Detail'!$K$2:$K$656,4) -> 24 | C9: =COUNTIFS('Display Detail'!$J$2:$J$656,$A9,'Display Detail'!$K$2:$K$656,3) -> 11 | D9: =COUNTIFS('Display Detail'!$J$2:$J$656,$A9,'Display Detail'!$K$2:$K$656,2) -> 2 | E9: =COUNTIFS('Display Detail'!$J$2:$J$656,$A9,'Display Detail'!$K$2:$K$656,1) -> 1 | F9: =COUNTIFS('Display Detail'!$J$2:$J$656,$A9,'Display Detail'!$K$2:$K$656,">0") -> 38 | G9: =SUMIFS('Display Detail'!$M$2:$M$656,'Display Detail'!$J$2:$J$656,$A9,'Display Detail'!$K$2:$K$656,">0") -> 3566 | H9: =SUMIFS('Display Detail'!$P$2:$P$656,'Display Detail'!$J$2:$J$656,$A9,'Display Detail'!$K$2:$K$656,">0") -> 30300 | I9: =COUNTIFS('Display Detail'!$J$2:$J$656,$A9,'Display Detail'!$K$2:$K$656,0) -> 1 | J9: =COUNTIF('Display Detail'!$J$2:$J$656,$A9) -> 39
A10: Yuengling | B10: =COUNTIFS('Display Detail'!$J$2:$J$656,$A10,'Display Detail'!$K$2:$K$656,4) -> 2 | C10: =COUNTIFS('Display Detail'!$J$2:$J$656,$A10,'Display Detail'!$K$2:$K$656,3) -> 0 | D10: =COUNTIFS('Display Detail'!$J$2:$J$656,$A10,'Display Detail'!$K$2:$K$656,2) -> 1 | E10: =COUNTIFS('Display Detail'!$J$2:$J$656,$A10,'Display Detail'!$K$2:$K$656,1) -> 1 | F10: =COUNTIFS('Display Detail'!$J$2:$J$656,$A10,'Display Detail'!$K$2:$K$656,">0") -> 4 | G10: =SUMIFS('Display Detail'!$M$2:$M$656,'Display Detail'!$J$2:$J$656,$A10,'Display Detail'!$K$2:$K$656,">0") -> 197 | H10: =SUMIFS('Display Detail'!$P$2:$P$656,'Display Detail'!$J$2:$J$656,$A10,'Display Detail'!$K$2:$K$656,">0") -> 2100 | I10: =COUNTIFS('Display Detail'!$J$2:$J$656,$A10,'Display Detail'!$K$2:$K$656,0) -> 1 | J10: =COUNTIF('Display Detail'!$J$2:$J$656,$A10) -> 5
A11: Garage | B11: =COUNTIFS('Display Detail'!$J$2:$J$656,$A11,'Display Detail'!$K$2:$K$656,4) -> 0 | C11: =COUNTIFS('Display Detail'!$J$2:$J$656,$A11,'Display Detail'!$K$2:$K$656,3) -> 0 | D11: =COUNTIFS('Display Detail'!$J$2:$J$656,$A11,'Display Detail'!$K$2:$K$656,2) -> 3 | E11: =COUNTIFS('Display Detail'!$J$2:$J$656,$A11,'Display Detail'!$K$2:$K$656,1) -> 5 | F11: =COUNTIFS('Display Detail'!$J$2:$J$656,$A11,'Display Detail'!$K$2:$K$656,">0") -> 8 | G11: =SUMIFS('Display Detail'!$M$2:$M$656,'Display Detail'!$J$2:$J$656,$A11,'Display Detail'!$K$2:$K$656,">0") -> 120 | H11: =SUMIFS('Display Detail'!$P$2:$P$656,'Display Detail'!$J$2:$J$656,$A11,'Display Detail'!$K$2:$K$656,">0") -> 1900 | I11: =COUNTIFS('Display Detail'!$J$2:$J$656,$A11,'Display Detail'!$K$2:$K$656,0) -> 2 | J11: =COUNTIF('Display Detail'!$J$2:$J$656,$A11) -> 10
A12: Sapporo | B12: =COUNTIFS('Display Detail'!$J$2:$J$656,$A12,'Display Detail'!$K$2:$K$656,4) -> 1 | C12: =COUNTIFS('Display Detail'!$J$2:$J$656,$A12,'Display Detail'!$K$2:$K$656,3) -> 1 | D12: =COUNTIFS('Display Detail'!$J$2:$J$656,$A12,'Display Detail'!$K$2:$K$656,2) -> 0 | E12: =COUNTIFS('Display Detail'!$J$2:$J$656,$A12,'Display Detail'!$K$2:$K$656,1) -> 0 | F12: =COUNTIFS('Display Detail'!$J$2:$J$656,$A12,'Display Detail'!$K$2:$K$656,">0") -> 2 | G12: =SUMIFS('Display Detail'!$M$2:$M$656,'Display Detail'!$J$2:$J$656,$A12,'Display Detail'!$K$2:$K$656,">0") -> 150 | H12: =SUMIFS('Display Detail'!$P$2:$P$656,'Display Detail'!$J$2:$J$656,$A12,'Display Detail'!$K$2:$K$656,">0") -> 1500 | I12: =COUNTIFS('Display Detail'!$J$2:$J$656,$A12,'Display Detail'!$K$2:$K$656,0) -> 1 | J12: =COUNTIF('Display Detail'!$J$2:$J$656,$A12) -> 3
A13: Pabst | B13: =COUNTIFS('Display Detail'!$J$2:$J$656,$A13,'Display Detail'!$K$2:$K$656,4) -> 0 | C13: =COUNTIFS('Display Detail'!$J$2:$J$656,$A13,'Display Detail'!$K$2:$K$656,3) -> 0 | D13: =COUNTIFS('Display Detail'!$J$2:$J$656,$A13,'Display Detail'!$K$2:$K$656,2) -> 0 | E13: =COUNTIFS('Display Detail'!$J$2:$J$656,$A13,'Display Detail'!$K$2:$K$656,1) -> 0 | F13: =COUNTIFS('Display Detail'!$J$2:$J$656,$A13,'Display Detail'!$K$2:$K$656,">0") -> 0 | G13: =SUMIFS('Display Detail'!$M$2:$M$656,'Display Detail'!$J$2:$J$656,$A13,'Display Detail'!$K$2:$K$656,">0") -> 0 | H13: =SUMIFS('Display Detail'!$P$2:$P$656,'Display Detail'!$J$2:$J$656,$A13,'Display Detail'!$K$2:$K$656,">0") -> 0 | I13: =COUNTIFS('Display Detail'!$J$2:$J$656,$A13,'Display Detail'!$K$2:$K$656,0) -> 0 | J13: =COUNTIF('Display Detail'!$J$2:$J$656,$A13) -> 0
A14: Montauk | B14: =COUNTIFS('Display Detail'!$J$2:$J$656,$A14,'Display Detail'!$K$2:$K$656,4) -> 0 | C14: =COUNTIFS('Display Detail'!$J$2:$J$656,$A14,'Display Detail'!$K$2:$K$656,3) -> 0 | D14: =COUNTIFS('Display Detail'!$J$2:$J$656,$A14,'Display Detail'!$K$2:$K$656,2) -> 1 | E14: =COUNTIFS('Display Detail'!$J$2:$J$656,$A14,'Display Detail'!$K$2:$K$656,1) -> 0 | F14: =COUNTIFS('Display Detail'!$J$2:$J$656,$A14,'Display Detail'!$K$2:$K$656,">0") -> 1 | G14: =SUMIFS('Display Detail'!$M$2:$M$656,'Display Detail'!$J$2:$J$656,$A14,'Display Detail'!$K$2:$K$656,">0") -> 25 | H14: =SUMIFS('Display Detail'!$P$2:$P$656,'Display Detail'!$J$2:$J$656,$A14,'Display Detail'!$K$2:$K$656,">0") -> 300 | I14: =COUNTIFS('Display Detail'!$J$2:$J$656,$A14,'Display Detail'!$K$2:$K$656,0) -> 0 | J14: =COUNTIF('Display Detail'!$J$2:$J$656,$A14) -> 1
A15: Carbliss | B15: =COUNTIFS('Display Detail'!$J$2:$J$656,$A15,'Display Detail'!$K$2:$K$656,4) -> 0 | C15: =COUNTIFS('Display Detail'!$J$2:$J$656,$A15,'Display Detail'!$K$2:$K$656,3) -> 0 | D15: =COUNTIFS('Display Detail'!$J$2:$J$656,$A15,'Display Detail'!$K$2:$K$656,2) -> 0 | E15: =COUNTIFS('Display Detail'!$J$2:$J$656,$A15,'Display Detail'!$K$2:$K$656,1) -> 2 | F15: =COUNTIFS('Display Detail'!$J$2:$J$656,$A15,'Display Detail'!$K$2:$K$656,">0") -> 2 | G15: =SUMIFS('Display Detail'!$M$2:$M$656,'Display Detail'!$J$2:$J$656,$A15,'Display Detail'!$K$2:$K$656,">0") -> 22 | H15: =SUMIFS('Display Detail'!$P$2:$P$656,'Display Detail'!$J$2:$J$656,$A15,'Display Detail'!$K$2:$K$656,">0") -> 400 | I15: =COUNTIFS('Display Detail'!$J$2:$J$656,$A15,'Display Detail'!$K$2:$K$656,0) -> 4 | J15: =COUNTIF('Display Detail'!$J$2:$J$656,$A15) -> 6
A16: ALL OTHER BRANDS / SUPPLIERS — not named on the program slide
A17: All Other: 1925 SPIRITS LLC | B17: =COUNTIFS('Display Detail'!$J$2:$J$656,$A17,'Display Detail'!$K$2:$K$656,4) -> 0 | C17: =COUNTIFS('Display Detail'!$J$2:$J$656,$A17,'Display Detail'!$K$2:$K$656,3) -> 0 | D17: =COUNTIFS('Display Detail'!$J$2:$J$656,$A17,'Display Detail'!$K$2:$K$656,2) -> 0 | E17: =COUNTIFS('Display Detail'!$J$2:$J$656,$A17,'Display Detail'!$K$2:$K$656,1) -> 0 | F17: =COUNTIFS('Display Detail'!$J$2:$J$656,$A17,'Display Detail'!$K$2:$K$656,">0") -> 0 | G17: =SUMIFS('Display Detail'!$M$2:$M$656,'Display Detail'!$J$2:$J$656,$A17,'Display Detail'!$K$2:$K$656,">0") -> 0 | H17: =SUMIFS('Display Detail'!$P$2:$P$656,'Display Detail'!$J$2:$J$656,$A17,'Display Detail'!$K$2:$K$656,">0") -> 0 | I17: =COUNTIFS('Display Detail'!$J$2:$J$656,$A17,'Display Detail'!$K$2:$K$656,0) -> 1 | J17: =COUNTIF('Display Detail'!$J$2:$J$656,$A17) -> 1
A18: All Other: ARTISANAL BREWING VENTURES (EBI) | B18: =COUNTIFS('Display Detail'!$J$2:$J$656,$A18,'Display Detail'!$K$2:$K$656,4) -> 0 | C18: =COUNTIFS('Display Detail'!$J$2:$J$656,$A18,'Display Detail'!$K$2:$K$656,3) -> 1 | D18: =COUNTIFS('Display Detail'!$J$2:$J$656,$A18,'Display Detail'!$K$2:$K$656,2) -> 1 | E18: =COUNTIFS('Display Detail'!$J$2:$J$656,$A18,'Display Detail'!$K$2:$K$656,1) -> 0 | F18: =COUNTIFS('Display Detail'!$J$2:$J$656,$A18,'Display Detail'!$K$2:$K$656,">0") -> 2 | G18: =SUMIFS('Display Detail'!$M$2:$M$656,'Display Detail'!$J$2:$J$656,$A18,'Display Detail'!$K$2:$K$656,">0") -> 70 | H18: =SUMIFS('Display Detail'!$P$2:$P$656,'Display Detail'!$J$2:$J$656,$A18,'Display Detail'!$K$2:$K$656,">0") -> 500 | I18: =COUNTIFS('Display Detail'!$J$2:$J$656,$A18,'Display Detail'!$K$2:$K$656,0) -> 1 | J18: =COUNTIF('Display Detail'!$J$2:$J$656,$A18) -> 3
A19: All Other: ATHLETIC BREWING COMPANY | B19: =COUNTIFS('Display Detail'!$J$2:$J$656,$A19,'Display Detail'!$K$2:$K$656,4) -> 0 | C19: =COUNTIFS('Display Detail'!$J$2:$J$656,$A19,'Display Detail'!$K$2:$K$656,3) -> 0 | D19: =COUNTIFS('Display Detail'!$J$2:$J$656,$A19,'Display Detail'!$K$2:$K$656,2) -> 1 | E19: =COUNTIFS('Display Detail'!$J$2:$J$656,$A19,'Display Detail'!$K$2:$K$656,1) -> 1 | F19: =COUNTIFS('Display Detail'!$J$2:$J$656,$A19,'Display Detail'!$K$2:$K$656,">0") -> 2 | G19: =SUMIFS('Display Detail'!$M$2:$M$656,'Display Detail'!$J$2:$J$656,$A19,'Display Detail'!$K$2:$K$656,">0") -> 48 | H19: =SUMIFS('Display Detail'!$P$2:$P$656,'Display Detail'!$J$2:$J$656,$A19,'Display Detail'!$K$2:$K$656,">0") -> 300 | I19: =COUNTIFS('Display Detail'!$J$2:$J$656,$A19,'Display Detail'!$K$2:$K$656,0) -> 0 | J19: =COUNTIF('Display Detail'!$J$2:$J$656,$A19) -> 2
A20: All Other: ATOMIC BRANDS | B20: =COUNTIFS('Display Detail'!$J$2:$J$656,$A20,'Display Detail'!$K$2:$K$656,4) -> 0 | C20: =COUNTIFS('Display Detail'!$J$2:$J$656,$A20,'Display Detail'!$K$2:$K$656,3) -> 0 | D20: =COUNTIFS('Display Detail'!$J$2:$J$656,$A20,'Display Detail'!$K$2:$K$656,2) -> 0 | E20: =COUNTIFS('Display Detail'!$J$2:$J$656,$A20,'Display Detail'!$K$2:$K$656,1) -> 0 | F20: =COUNTIFS('Display Detail'!$J$2:$J$656,$A20,'Display Detail'!$K$2:$K$656,">0") -> 0 | G20: =SUMIFS('Display Detail'!$M$2:$M$656,'Display Detail'!$J$2:$J$656,$A20,'Display Detail'!$K$2:$K$656,">0") -> 0 | H20: =SUMIFS('Display Detail'!$P$2:$P$656,'Display Detail'!$J$2:$J$656,$A20,'Display Detail'!$K$2:$K$656,">0") -> 0 | I20: =COUNTIFS('Display Detail'!$J$2:$J$656,$A20,'Display Detail'!$K$2:$K$656,0) -> 1 | J20: =COUNTIF('Display Detail'!$J$2:$J$656,$A20) -> 1
A21: All Other: CENTRAL BEER IMPORT & EXPORT FAMOSA | B21: =COUNTIFS('Display Detail'!$J$2:$J$656,$A21,'Display Detail'!$K$2:$K$656,4) -> 0 | C21: =COUNTIFS('Display Detail'!$J$2:$J$656,$A21,'Display Detail'!$K$2:$K$656,3) -> 0 | D21: =COUNTIFS('Display Detail'!$J$2:$J$656,$A21,'Display Detail'!$K$2:$K$656,2) -> 2 | E21: =COUNTIFS('Display Detail'!$J$2:$J$656,$A21,'Display Detail'!$K$2:$K$656,1) -> 1 | F21: =COUNTIFS('Display Detail'!$J$2:$J$656,$A21,'Display Detail'!$K$2:$K$656,">0") -> 3 | G21: =SUMIFS('Display Detail'!$M$2:$M$656,'Display Detail'!$J$2:$J$656,$A21,'Display Detail'!$K$2:$K$656,">0") -> 61 | H21: =SUMIFS('Display Detail'!$P$2:$P$656,'Display Detail'!$J$2:$J$656,$A21,'Display Detail'!$K$2:$K$656,">0") -> 500 | I21: =COUNTIFS('Display Detail'!$J$2:$J$656,$A21,'Display Detail'!$K$2:$K$656,0) -> 4 | J21: =COUNTIF('Display Detail'!$J$2:$J$656,$A21) -> 7
A22: All Other: DELTA BEVERAGES LLC | B22: =COUNTIFS('Display Detail'!$J$2:$J$656,$A22,'Display Detail'!$K$2:$K$656,4) -> 0 | C22: =COUNTIFS('Display Detail'!$J$2:$J$656,$A22,'Display Detail'!$K$2:$K$656,3) -> 0 | D22: =COUNTIFS('Display Detail'!$J$2:$J$656,$A22,'Display Detail'!$K$2:$K$656,2) -> 0 | E22: =COUNTIFS('Display Detail'!$J$2:$J$656,$A22,'Display Detail'!$K$2:$K$656,1) -> 1 | F22: =COUNTIFS('Display Detail'!$J$2:$J$656,$A22,'Display Detail'!$K$2:$K$656,">0") -> 1 | G22: =SUMIFS('Display Detail'!$M$2:$M$656,'Display Detail'!$J$2:$J$656,$A22,'Display Detail'!$K$2:$K$656,">0") -> 10 | H22: =SUMIFS('Display Detail'!$P$2:$P$656,'Display Detail'!$J$2:$J$656,$A22,'Display Detail'!$K$2:$K$656,">0") -> 100 | I22: =COUNTIFS('Display Detail'!$J$2:$J$656,$A22,'Display Detail'!$K$2:$K$656,0) -> 0 | J22: =COUNTIF('Display Detail'!$J$2:$J$656,$A22) -> 1
A23: All Other: F.X. MATT BREWING COMPANY | B23: =COUNTIFS('Display Detail'!$J$2:$J$656,$A23,'Display Detail'!$K$2:$K$656,4) -> 0 | C23: =COUNTIFS('Display Detail'!$J$2:$J$656,$A23,'Display Detail'!$K$2:$K$656,3) -> 0 | D23: =COUNTIFS('Display Detail'!$J$2:$J$656,$A23,'Display Detail'!$K$2:$K$656,2) -> 1 | E23: =COUNTIFS('Display Detail'!$J$2:$J$656,$A23,'Display Detail'!$K$2:$K$656,1) -> 0 | F23: =COUNTIFS('Display Detail'!$J$2:$J$656,$A23,'Display Detail'!$K$2:$K$656,">0") -> 1 | G23: =SUMIFS('Display Detail'!$M$2:$M$656,'Display Detail'!$J$2:$J$656,$A23,'Display Detail'!$K$2:$K$656,">0") -> 29 | H23: =SUMIFS('Display Detail'!$P$2:$P$656,'Display Detail'!$J$2:$J$656,$A23,'Display Detail'!$K$2:$K$656,">0") -> 200 | I23: =COUNTIFS('Display Detail'!$J$2:$J$656,$A23,'Display Detail'!$K$2:$K$656,0) -> 0 | J23: =COUNTIF('Display Detail'!$J$2:$J$656,$A23) -> 1
A24: All Other: FEVER TREE USA | B24: =COUNTIFS('Display Detail'!$J$2:$J$656,$A24,'Display Detail'!$K$2:$K$656,4) -> 0 | C24: =COUNTIFS('Display Detail'!$J$2:$J$656,$A24,'Display Detail'!$K$2:$K$656,3) -> 0 | D24: =COUNTIFS('Display Detail'!$J$2:$J$656,$A24,'Display Detail'!$K$2:$K$656,2) -> 0 | E24: =COUNTIFS('Display Detail'!$J$2:$J$656,$A24,'Display Detail'!$K$2:$K$656,1) -> 1 | F24: =COUNTIFS('Display Detail'!$J$2:$J$656,$A24,'Display Detail'!$K$2:$K$656,">0") -> 1 | G24: =SUMIFS('Display Detail'!$M$2:$M$656,'Display Detail'!$J$2:$J$656,$A24,'Display Detail'!$K$2:$K$656,">0") -> 14 | H24: =SUMIFS('Display Detail'!$P$2:$P$656,'Display Detail'!$J$2:$J$656,$A24,'Display Detail'!$K$2:$K$656,">0") -> 200 | I24: =COUNTIFS('Display Detail'!$J$2:$J$656,$A24,'Display Detail'!$K$2:$K$656,0) -> 1 | J24: =COUNTIF('Display Detail'!$J$2:$J$656,$A24) -> 2
A25: All Other: KIRIN BREWERY COMPANY | B25: =COUNTIFS('Display Detail'!$J$2:$J$656,$A25,'Display Detail'!$K$2:$K$656,4) -> 1 | C25: =COUNTIFS('Display Detail'!$J$2:$J$656,$A25,'Display Detail'!$K$2:$K$656,3) -> 0 | D25: =COUNTIFS('Display Detail'!$J$2:$J$656,$A25,'Display Detail'!$K$2:$K$656,2) -> 0 | E25: =COUNTIFS('Display Detail'!$J$2:$J$656,$A25,'Display Detail'!$K$2:$K$656,1) -> 0 | F25: =COUNTIFS('Display Detail'!$J$2:$J$656,$A25,'Display Detail'!$K$2:$K$656,">0") -> 1 | G25: =SUMIFS('Display Detail'!$M$2:$M$656,'Display Detail'!$J$2:$J$656,$A25,'Display Detail'!$K$2:$K$656,">0") -> 150 | H25: =SUMIFS('Display Detail'!$P$2:$P$656,'Display Detail'!$J$2:$J$656,$A25,'Display Detail'!$K$2:$K$656,">0") -> 600 | I25: =COUNTIFS('Display Detail'!$J$2:$J$656,$A25,'Display Detail'!$K$2:$K$656,0) -> 1 | J25: =COUNTIF('Display Detail'!$J$2:$J$656,$A25) -> 2
A26: All Other: NEW BELGIUM BRANDS | B26: =COUNTIFS('Display Detail'!$J$2:$J$656,$A26,'Display Detail'!$K$2:$K$656,4) -> 3 | C26: =COUNTIFS('Display Detail'!$J$2:$J$656,$A26,'Display Detail'!$K$2:$K$656,3) -> 0 | D26: =COUNTIFS('Display Detail'!$J$2:$J$656,$A26,'Display Detail'!$K$2:$K$656,2) -> 0 | E26: =COUNTIFS('Display Detail'!$J$2:$J$656,$A26,'Display Detail'!$K$2:$K$656,1) -> 0 | F26: =COUNTIFS('Display Detail'!$J$2:$J$656,$A26,'Display Detail'!$K$2:$K$656,">0") -> 3 | G26: =SUMIFS('Display Detail'!$M$2:$M$656,'Display Detail'!$J$2:$J$656,$A26,'Display Detail'!$K$2:$K$656,">0") -> 300 | H26: =SUMIFS('Display Detail'!$P$2:$P$656,'Display Detail'!$J$2:$J$656,$A26,'Display Detail'!$K$2:$K$656,">0") -> 1800 | I26: =COUNTIFS('Display Detail'!$J$2:$J$656,$A26,'Display Detail'!$K$2:$K$656,0) -> 0 | J26: =COUNTIF('Display Detail'!$J$2:$J$656,$A26) -> 3
A27: All Other: NOCA BEVERAGES | B27: =COUNTIFS('Display Detail'!$J$2:$J$656,$A27,'Display Detail'!$K$2:$K$656,4) -> 1 | C27: =COUNTIFS('Display Detail'!$J$2:$J$656,$A27,'Display Detail'!$K$2:$K$656,3) -> 3 | D27: =COUNTIFS('Display Detail'!$J$2:$J$656,$A27,'Display Detail'!$K$2:$K$656,2) -> 0 | E27: =COUNTIFS('Display Detail'!$J$2:$J$656,$A27,'Display Detail'!$K$2:$K$656,1) -> 0 | F27: =COUNTIFS('Display Detail'!$J$2:$J$656,$A27,'Display Detail'!$K$2:$K$656,">0") -> 4 | G27: =SUMIFS('Display Detail'!$M$2:$M$656,'Display Detail'!$J$2:$J$656,$A27,'Display Detail'!$K$2:$K$656,">0") -> 220 | H27: =SUMIFS('Display Detail'!$P$2:$P$656,'Display Detail'!$J$2:$J$656,$A27,'Display Detail'!$K$2:$K$656,">0") -> 1500 | I27: =COUNTIFS('Display Detail'!$J$2:$J$656,$A27,'Display Detail'!$K$2:$K$656,0) -> 0 | J27: =COUNTIF('Display Detail'!$J$2:$J$656,$A27) -> 4
A28: All Other: PAULANER | B28: =COUNTIFS('Display Detail'!$J$2:$J$656,$A28,'Display Detail'!$K$2:$K$656,4) -> 1 | C28: =COUNTIFS('Display Detail'!$J$2:$J$656,$A28,'Display Detail'!$K$2:$K$656,3) -> 1 | D28: =COUNTIFS('Display Detail'!$J$2:$J$656,$A28,'Display Detail'!$K$2:$K$656,2) -> 1 | E28: =COUNTIFS('Display Detail'!$J$2:$J$656,$A28,'Display Detail'!$K$2:$K$656,1) -> 0 | F28: =COUNTIFS('Display Detail'!$J$2:$J$656,$A28,'Display Detail'!$K$2:$K$656,">0") -> 3 | G28: =SUMIFS('Display Detail'!$M$2:$M$656,'Display Detail'!$J$2:$J$656,$A28,'Display Detail'!$K$2:$K$656,">0") -> 177 | H28: =SUMIFS('Display Detail'!$P$2:$P$656,'Display Detail'!$J$2:$J$656,$A28,'Display Detail'!$K$2:$K$656,">0") -> 1100 | I28: =COUNTIFS('Display Detail'!$J$2:$J$656,$A28,'Display Detail'!$K$2:$K$656,0) -> 0 | J28: =COUNTIF('Display Detail'!$J$2:$J$656,$A28) -> 3
... A34: All Other: VIVA BEVERAGES | B34: =COUNTIFS('Display Detail'!$J$2:$J$656,$A34,'Display Detail'!$K$2:$K$656,4) -> 0 | C34: =COUNTIFS('Display Detail'!$J$2:$J$656,$A34,'Display Detail'!$K$2:$K$656,3) -> 0 | D34: =COUNTIFS('Display Detail'!$J$2:$J$656,$A34,'Display Detail'!$K$2:$K$656,2) -> 0 | E34: =COUNTIFS('Display Detail'!$J$2:$J$656,$A34,'Display Detail'!$K$2:$K$656,1) -> 0 | F34: =COUNTIFS('Display Detail'!$J$2:$J$656,$A34,'Display Detail'!$K$2:$K$656,">0") -> 0 | G34: =SUMIFS('Display Detail'!$M$2:$M$656,'Display Detail'!$J$2:$J$656,$A34,'Display Detail'!$K$2:$K$656,">0") -> 0 | H34: =SUMIFS('Display Detail'!$P$2:$P$656,'Display Detail'!$J$2:$J$656,$A34,'Display Detail'!$K$2:$K$656,">0") -> 0 | I34: =COUNTIFS('Display Detail'!$J$2:$J$656,$A34,'Display Detail'!$K$2:$K$656,0) -> 1 | J34: =COUNTIF('Display Detail'!$J$2:$J$656,$A34) -> 1
A35: TOTAL — ALL DISPLAYS | B35: =COUNTIF('Display Detail'!$K$2:$K$656,4) -> 190 | C35: =COUNTIF('Display Detail'!$K$2:$K$656,3) -> 157 | D35: =COUNTIF('Display Detail'!$K$2:$K$656,2) -> 97 | E35: =COUNTIF('Display Detail'!$K$2:$K$656,1) -> 50 | F35: =COUNTIF('Display Detail'!$K$2:$K$656,">0") -> 494 | G35: =SUMIFS('Display Detail'!$M$2:$M$656,'Display Detail'!$K$2:$K$656,">0") -> 31202 | H35: =SUMIFS('Display Detail'!$P$2:$P$656,'Display Detail'!$K$2:$K$656,">0") -> 302200 | I35: =COUNTIF('Display Detail'!$K$2:$K$656,0) -> 161 | J35: =COUNTA('Display Detail'!$A$2:$A$656) -> 655
A37: A display is counted once, in the single tier its TOTAL case count falls into (85 cases = Gold only, not Gold + Silver + Bronze).
A38: A display carrying more than one supplier is credited to the supplier holding the most cases in that photo — see the Multi-Supplier Audit tab for all 29.
A39: Pabst is on the program slide but has no display submissions in the July/August data, so it reads zero throughout.
A40: Every figure is a live COUNTIFS/SUMIFS over the Display Detail tab — filter that tab to see the records behind any number.
A41: These totals match the published leaderboard and include everything submitted. 65 displays look like the same display logged twice — see the Duplicate Check tab before treating any total as final.
A42: Source: iSellBeer display photo export, 07/01/2026 – 08/31/2026 (Report_59, pulled 08/31/2026).

Sheet Summary by Brand
A1: Summer Display Auction — Qualifying Displays by Lead Brand
A2: Kohler iSell Beer Summer Display Program · 07/01/2026 – 08/31/2026 · one row per photo submission, counted once in its case-size tier
A4: Lead Brand | B4: Gold 70+ cases | C4: Silver 40-69 cases | D4: Bronze 20-39 cases | E4: Other 10-19 cases | F4: Total Qualifying Displays | G4: Total Cases (qualifying) | H4: Total Points | I4: Non-Qualifying (<10 cases) | J4: Total Submissions
A5: CORONA EXTRA | B5: =COUNTIFS('Display Detail'!$R$2:$R$656,$A5,'Display Detail'!$K$2:$K$656,4) -> 23 | C5: =COUNTIFS('Display Detail'!$R$2:$R$656,$A5,'Display Detail'!$K$2:$K$656,3) -> 21 | D5: =COUNTIFS('Display Detail'!$R$2:$R$656,$A5,'Display Detail'!$K$2:$K$656,2) -> 11 | E5: =COUNTIFS('Display Detail'!$R$2:$R$656,$A5,'Display Detail'!$K$2:$K$656,1) -> 3 | F5: =COUNTIFS('Display Detail'!$R$2:$R$656,$A5,'Display Detail'!$K$2:$K$656,">0") -> 58 | G5: =SUMIFS('Display Detail'!$M$2:$M$656,'Display Detail'!$R$2:$R$656,$A5,'Display Detail'!$K$2:$K$656,">0") -> 3712 | H5: =SUMIFS('Display Detail'!$P$2:$P$656,'Display Detail'!$R$2:$R$656,$A5,'Display Detail'!$K$2:$K$656,">0") -> 37400 | I5: =COUNTIFS('Display Detail'!$R$2:$R$656,$A5,'Display Detail'!$K$2:$K$656,0) -> 20 | J5: =COUNTIF('Display Detail'!$R$2:$R$656,$A5) -> 78
A6: MODELO CERVEZA | B6: =COUNTIFS('Display Detail'!$R$2:$R$656,$A6,'Display Detail'!$K$2:$K$656,4) -> 23 | C6: =COUNTIFS('Display Detail'!$R$2:$R$656,$A6,'Display Detail'!$K$2:$K$656,3) -> 19 | D6: =COUNTIFS('Display Detail'!$R$2:$R$656,$A6,'Display Detail'!$K$2:$K$656,2) -> 9 | E6: =COUNTIFS('Display Detail'!$R$2:$R$656,$A6,'Display Detail'!$K$2:$K$656,1) -> 5 | F6: =COUNTIFS('Display Detail'!$R$2:$R$656,$A6,'Display Detail'!$K$2:$K$656,">0") -> 56 | G6: =SUMIFS('Display Detail'!$M$2:$M$656,'Display Detail'!$R$2:$R$656,$A6,'Display Detail'!$K$2:$K$656,">0") -> 3492 | H6: =SUMIFS('Display Detail'!$P$2:$P$656,'Display Detail'!$R$2:$R$656,$A6,'Display Detail'!$K$2:$K$656,">0") -> 36200 | I6: =COUNTIFS('Display Detail'!$R$2:$R$656,$A6,'Display Detail'!$K$2:$K$656,0) -> 20 | J6: =COUNTIF('Display Detail'!$R$2:$R$656,$A6) -> 76
A7: SUN CRUISERS RTD | B7: =COUNTIFS('Display Detail'!$R$2:$R$656,$A7,'Display Detail'!$K$2:$K$656,4) -> 20 | C7: =COUNTIFS('Display Detail'!$R$2:$R$656,$A7,'Display Detail'!$K$2:$K$656,3) -> 12 | D7: =COUNTIFS('Display Detail'!$R$2:$R$656,$A7,'Display Detail'!$K$2:$K$656,2) -> 11 | E7: =COUNTIFS('Display Detail'!$R$2:$R$656,$A7,'Display Detail'!$K$2:$K$656,1) -> 1 | F7: =COUNTIFS('Display Detail'!$R$2:$R$656,$A7,'Display Detail'!$K$2:$K$656,">0") -> 44 | G7: =SUMIFS('Display Detail'!$M$2:$M$656,'Display Detail'!$R$2:$R$656,$A7,'Display Detail'!$K$2:$K$656,">0") -> 3331 | H7: =SUMIFS('Display Detail'!$P$2:$P$656,'Display Detail'!$R$2:$R$656,$A7,'Display Detail'!$K$2:$K$656,">0") -> 29500 | I7: =COUNTIFS('Display Detail'!$R$2:$R$656,$A7,'Display Detail'!$K$2:$K$656,0) -> 0 | J7: =COUNTIF('Display Detail'!$R$2:$R$656,$A7) -> 44
A8: HEINEKEN | B8: =COUNTIFS('Display Detail'!$R$2:$R$656,$A8,'Display Detail'!$K$2:$K$656,4) -> 15 | C8: =COUNTIFS('Display Detail'!$R$2:$R$656,$A8,'Display Detail'!$K$2:$K$656,3) -> 19 | D8: =COUNTIFS('Display Detail'!$R$2:$R$656,$A8,'Display Detail'!$K$2:$K$656,2) -> 4 | E8: =COUNTIFS('Display Detail'!$R$2:$R$656,$A8,'Display Detail'!$K$2:$K$656,1) -> 4 | F8: =COUNTIFS('Display Detail'!$R$2:$R$656,$A8,'Display Detail'!$K$2:$K$656,">0") -> 42 | G8: =SUMIFS('Display Detail'!$M$2:$M$656,'Display Detail'!$R$2:$R$656,$A8,'Display Detail'!$K$2:$K$656,">0") -> 2697 | H8: =SUMIFS('Display Detail'!$P$2:$P$656,'Display Detail'!$R$2:$R$656,$A8,'Display Detail'!$K$2:$K$656,">0") -> 26500 | I8: =COUNTIFS('Display Detail'!$R$2:$R$656,$A8,'Display Detail'!$K$2:$K$656,0) -> 2 | J8: =COUNTIF('Display Detail'!$R$2:$R$656,$A8) -> 44
A9: COORS LIGHT | B9: =COUNTIFS('Display Detail'!$R$2:$R$656,$A9,'Display Detail'!$K$2:$K$656,4) -> 19 | C9: =COUNTIFS('Display Detail'!$R$2:$R$656,$A9,'Display Detail'!$K$2:$K$656,3) -> 10 | D9: =COUNTIFS('Display Detail'!$R$2:$R$656,$A9,'Display Detail'!$K$2:$K$656,2) -> 9 | E9: =COUNTIFS('Display Detail'!$R$2:$R$656,$A9,'Display Detail'!$K$2:$K$656,1) -> 0 | F9: =COUNTIFS('Display Detail'!$R$2:$R$656,$A9,'Display Detail'!$K$2:$K$656,">0") -> 38 | G9: =SUMIFS('Display Detail'!$M$2:$M$656,'Display Detail'!$R$2:$R$656,$A9,'Display Detail'!$K$2:$K$656,">0") -> 2666 | H9: =SUMIFS('Display Detail'!$P$2:$P$656,'Display Detail'!$R$2:$R$656,$A9,'Display Detail'!$K$2:$K$656,">0") -> 26700 | I9: =COUNTIFS('Display Detail'!$R$2:$R$656,$A9,'Display Detail'!$K$2:$K$656,0) -> 12 | J9: =COUNTIF('Display Detail'!$R$2:$R$656,$A9) -> 50
A10: TWISTED TEA | B10: =COUNTIFS('Display Detail'!$R$2:$R$656,$A10,'Display Detail'!$K$2:$K$656,4) -> 10 | C10: =COUNTIFS('Display Detail'!$R$2:$R$656,$A10,'Display Detail'!$K$2:$K$656,3) -> 8 | D10: =COUNTIFS('Display Detail'!$R$2:$R$656,$A10,'Display Detail'!$K$2:$K$656,2) -> 7 | E10: =COUNTIFS('Display Detail'!$R$2:$R$656,$A10,'Display Detail'!$K$2:$K$656,1) -> 3 | F10: =COUNTIFS('Display Detail'!$R$2:$R$656,$A10,'Display Detail'!$K$2:$K$656,">0") -> 28 | G10: =SUMIFS('Display Detail'!$M$2:$M$656,'Display Detail'!$R$2:$R$656,$A10,'Display Detail'!$K$2:$K$656,">0") -> 1681 | H10: =SUMIFS('Display Detail'!$P$2:$P$656,'Display Detail'!$R$2:$R$656,$A10,'Display Detail'!$K$2:$K$656,">0") -> 16700 | I10: =COUNTIFS('Display Detail'!$R$2:$R$656,$A10,'Display Detail'!$K$2:$K$656,0) -> 0 | J10: =COUNTIF('Display Detail'!$R$2:$R$656,$A10) -> 28
A11: MILLER LITE | B11: =COUNTIFS('Display Detail'!$R$2:$R$656,$A11,'Display Detail'!$K$2:$K$656,4) -> 14 | C11: =COUNTIFS('Display Detail'!$R$2:$R$656,$A11,'Display Detail'!$K$2:$K$656,3) -> 11 | D11: =COUNTIFS('Display Detail'!$R$2:$R$656,$A11,'Display Detail'!$K$2:$K$656,2) -> 0 | E11: =COUNTIFS('Display Detail'!$R$2:$R$656,$A11,'Display Detail'!$K$2:$K$656,1) -> 1 | F11: =COUNTIFS('Display Detail'!$R$2:$R$656,$A11,'Display Detail'!$K$2:$K$656,">0") -> 26 | G11: =SUMIFS('Display Detail'!$M$2:$M$656,'Display Detail'!$R$2:$R$656,$A11,'Display Detail'!$K$2:$K$656,">0") -> 2236 | H11: =SUMIFS('Display Detail'!$P$2:$P$656,'Display Detail'!$R$2:$R$656,$A11,'Display Detail'!$K$2:$K$656,">0") -> 19700 | I11: =COUNTIFS('Display Detail'!$R$2:$R$656,$A11,'Display Detail'!$K$2:$K$656,0) -> 3 | J11: =COUNTIF('Display Detail'!$R$2:$R$656,$A11) -> 29
A12: WHITE CLAW ORIGINAL HARD SELTZER | B12: =COUNTIFS('Display Detail'!$R$2:$R$656,$A12,'Display Detail'!$K$2:$K$656,4) -> 11 | C12: =COUNTIFS('Display Detail'!$R$2:$R$656,$A12,'Display Detail'!$K$2:$K$656,3) -> 5 | D12: =COUNTIFS('Display Detail'!$R$2:$R$656,$A12,'Display Detail'!$K$2:$K$656,2) -> 1 | E12: =COUNTIFS('Display Detail'!$R$2:$R$656,$A12,'Display Detail'!$K$2:$K$656,1) -> 0 | F12: =COUNTIFS('Display Detail'!$R$2:$R$656,$A12,'Display Detail'!$K$2:$K$656,">0") -> 17 | G12: =SUMIFS('Display Detail'!$M$2:$M$656,'Display Detail'!$R$2:$R$656,$A12,'Display Detail'!$K$2:$K$656,">0") -> 1813 | H12: =SUMIFS('Display Detail'!$P$2:$P$656,'Display Detail'!$R$2:$R$656,$A12,'Display Detail'!$K$2:$K$656,">0") -> 13800 | I12: =COUNTIFS('Display Detail'!$R$2:$R$656,$A12,'Display Detail'!$K$2:$K$656,0) -> 0 | J12: =COUNTIF('Display Detail'!$R$2:$R$656,$A12) -> 17
A13: WHITE CLAW SURF HARD SELTZER | B13: =COUNTIFS('Display Detail'!$R$2:$R$656,$A13,'Display Detail'!$K$2:$K$656,4) -> 12 | C13: =COUNTIFS('Display Detail'!$R$2:$R$656,$A13,'Display Detail'!$K$2:$K$656,3) -> 3 | D13: =COUNTIFS('Display Detail'!$R$2:$R$656,$A13,'Display Detail'!$K$2:$K$656,2) -> 0 | E13: =COUNTIFS('Display Detail'!$R$2:$R$656,$A13,'Display Detail'!$K$2:$K$656,1) -> 1 | F13: =COUNTIFS('Display Detail'!$R$2:$R$656,$A13,'Display Detail'!$K$2:$K$656,">0") -> 16 | G13: =SUMIFS('Display Detail'!$M$2:$M$656,'Display Detail'!$R$2:$R$656,$A13,'Display Detail'!$K$2:$K$656,">0") -> 1478 | H13: =SUMIFS('Display Detail'!$P$2:$P$656,'Display Detail'!$R$2:$R$656,$A13,'Display Detail'!$K$2:$K$656,">0") -> 13700 | I13: =COUNTIFS('Display Detail'!$R$2:$R$656,$A13,'Display Detail'!$K$2:$K$656,0) -> 0 | J13: =COUNTIF('Display Detail'!$R$2:$R$656,$A13) -> 16
A14: TRULY | B14: =COUNTIFS('Display Detail'!$R$2:$R$656,$A14,'Display Detail'!$K$2:$K$656,4) -> 4 | C14: =COUNTIFS('Display Detail'!$R$2:$R$656,$A14,'Display Detail'!$K$2:$K$656,3) -> 5 | D14: =COUNTIFS('Display Detail'!$R$2:$R$656,$A14,'Display Detail'!$K$2:$K$656,2) -> 4 | E14: =COUNTIFS('Display Detail'!$R$2:$R$656,$A14,'Display Detail'!$K$2:$K$656,1) -> 1 | F14: =COUNTIFS('Display Detail'!$R$2:$R$656,$A14,'Display Detail'!$K$2:$K$656,">0") -> 14 | G14: =SUMIFS('Display Detail'!$M$2:$M$656,'Display Detail'!$R$2:$R$656,$A14,'Display Detail'!$K$2:$K$656,">0") -> 761 | H14: =SUMIFS('Display Detail'!$P$2:$P$656,'Display Detail'!$R$2:$R$656,$A14,'Display Detail'!$K$2:$K$656,">0") -> 7900 | I14: =COUNTIFS('Display Detail'!$R$2:$R$656,$A14,'Display Detail'!$K$2:$K$656,0) -> 0 | J14: =COUNTIF('Display Detail'!$R$2:$R$656,$A14) -> 14
A15: SAM ADAMS SEASONAL | B15: =COUNTIFS('Display Detail'!$R$2:$R$656,$A15,'Display Detail'!$K$2:$K$656,4) -> 3 | C15: =COUNTIFS('Display Detail'!$R$2:$R$656,$A15,'Display Detail'!$K$2:$K$656,3) -> 7 | D15: =COUNTIFS('Display Detail'!$R$2:$R$656,$A15,'Display Detail'!$K$2:$K$656,2) -> 3 | E15: =COUNTIFS('Display Detail'!$R$2:$R$656,$A15,'Display Detail'!$K$2:$K$656,1) -> 0 | F15: =COUNTIFS('Display Detail'!$R$2:$R$656,$A15,'Display Detail'!$K$2:$K$656,">0") -> 13 | G15: =SUMIFS('Display Detail'!$M$2:$M$656,'Display Detail'!$R$2:$R$656,$A15,'Display Detail'!$K$2:$K$656,">0") -> 715 | H15: =SUMIFS('Display Detail'!$P$2:$P$656,'Display Detail'!$R$2:$R$656,$A15,'Display Detail'!$K$2:$K$656,">0") -> 7400 | I15: =COUNTIFS('Display Detail'!$R$2:$R$656,$A15,'Display Detail'!$K$2:$K$656,0) -> 0 | J15: =COUNTIF('Display Detail'!$R$2:$R$656,$A15) -> 13
A16: CORONA | B16: =COUNTIFS('Display Detail'!$R$2:$R$656,$A16,'Display Detail'!$K$2:$K$656,4) -> 5 | C16: =COUNTIFS('Display Detail'!$R$2:$R$656,$A16,'Display Detail'!$K$2:$K$656,3) -> 5 | D16: =COUNTIFS('Display Detail'!$R$2:$R$656,$A16,'Display Detail'!$K$2:$K$656,2) -> 1 | E16: =COUNTIFS('Display Detail'!$R$2:$R$656,$A16,'Display Detail'!$K$2:$K$656,1) -> 1 | F16: =COUNTIFS('Display Detail'!$R$2:$R$656,$A16,'Display Detail'!$K$2:$K$656,">0") -> 12 | G16: =SUMIFS('Display Detail'!$M$2:$M$656,'Display Detail'!$R$2:$R$656,$A16,'Display Detail'!$K$2:$K$656,">0") -> 832 | H16: =SUMIFS('Display Detail'!$P$2:$P$656,'Display Detail'!$R$2:$R$656,$A16,'Display Detail'!$K$2:$K$656,">0") -> 8000 | I16: =COUNTIFS('Display Detail'!$R$2:$R$656,$A16,'Display Detail'!$K$2:$K$656,0) -> 4 | J16: =COUNTIF('Display Detail'!$R$2:$R$656,$A16) -> 16
... A69: VIVA TEQUILA SELTZER | B69: =COUNTIFS('Display Detail'!$R$2:$R$656,$A69,'Display Detail'!$K$2:$K$656,4) -> 0 | C69: =COUNTIFS('Display Detail'!$R$2:$R$656,$A69,'Display Detail'!$K$2:$K$656,3) -> 0 | D69: =COUNTIFS('Display Detail'!$R$2:$R$656,$A69,'Display Detail'!$K$2:$K$656,2) -> 0 | E69: =COUNTIFS('Display Detail'!$R$2:$R$656,$A69,'Display Detail'!$K$2:$K$656,1) -> 0 | F69: =COUNTIFS('Display Detail'!$R$2:$R$656,$A69,'Display Detail'!$K$2:$K$656,">0") -> 0 | G69: =SUMIFS('Display Detail'!$M$2:$M$656,'Display Detail'!$R$2:$R$656,$A69,'Display Detail'!$K$2:$K$656,">0") -> 0 | H69: =SUMIFS('Display Detail'!$P$2:$P$656,'Display Detail'!$R$2:$R$656,$A69,'Display Detail'!$K$2:$K$656,">0") -> 0 | I69: =COUNTIFS('Display Detail'!$R$2:$R$656,$A69,'Display Detail'!$K$2:$K$656,0) -> 1 | J69: =COUNTIF('Display Detail'!$R$2:$R$656,$A69) -> 1
A70: TOTAL — ALL DISPLAYS | B70: =COUNTIF('Display Detail'!$K$2:$K$656,4) -> 190 | C70: =COUNTIF('Display Detail'!$K$2:$K$656,3) -> 157 | D70: =COUNTIF('Display Detail'!$K$2:$K$656,2) -> 97 | E70: =COUNTIF('Display Detail'!$K$2:$K$656,1) -> 50 | F70: =COUNTIF('Display Detail'!$K$2:$K$656,">0") -> 494 | G70: =SUMIFS('Display Detail'!$M$2:$M$656,'Display Detail'!$K$2:$K$656,">0") -> 31202 | H70: =SUMIFS('Display Detail'!$P$2:$P$656,'Display Detail'!$K$2:$K$656,">0") -> 302200 | I70: =COUNTIF('Display Detail'!$K$2:$K$656,0) -> 161 | J70: =COUNTA('Display Detail'!$A$2:$A$656) -> 655
A72: Lead Brand = the brand holding the most cases in that photo submission, so each display appears against exactly one brand.
A73: Multi-brand displays are common (a single photo often carries 3-6 SKUs); the full brand list for every display is on the Display Detail tab.
A74: Source: iSellBeer display photo export, 07/01/2026 – 08/31/2026 (Report_59, pulled 08/31/2026).

Sheet Summary by Person
A1: Summer Display Auction — Qualifying Displays by Person
A2: Kohler iSell Beer Summer Display Program · 07/01/2026 – 08/31/2026 · one row per photo submission, counted once in its case-size tier
A4: Rep / Sales Associate | B4: Gold 70+ cases | C4: Silver 40-69 cases | D4: Bronze 20-39 cases | E4: Other 10-19 cases | F4: Total Qualifying Displays | G4: Total Cases (qualifying) | H4: Total Points | I4: Non-Qualifying (<10 cases) | J4: Total Submissions
A5: SALES REPS — Display Auction
A6: Alex Rodriguez | B6: =COUNTIFS('Display Detail'!$D$2:$D$656,$A6,'Display Detail'!$K$2:$K$656,4) -> 1 | C6: =COUNTIFS('Display Detail'!$D$2:$D$656,$A6,'Display Detail'!$K$2:$K$656,3) -> 1 | D6: =COUNTIFS('Display Detail'!$D$2:$D$656,$A6,'Display Detail'!$K$2:$K$656,2) -> 4 | E6: =COUNTIFS('Display Detail'!$D$2:$D$656,$A6,'Display Detail'!$K$2:$K$656,1) -> 2 | F6: =COUNTIFS('Display Detail'!$D$2:$D$656,$A6,'Display Detail'!$K$2:$K$656,">0") -> 8 | G6: =SUMIFS('Display Detail'!$M$2:$M$656,'Display Detail'!$D$2:$D$656,$A6,'Display Detail'!$K$2:$K$656,">0") -> 364 | H6: =SUMIFS('Display Detail'!$P$2:$P$656,'Display Detail'!$D$2:$D$656,$A6,'Display Detail'!$K$2:$K$656,">0") -> 2900 | I6: =COUNTIFS('Display Detail'!$D$2:$D$656,$A6,'Display Detail'!$K$2:$K$656,0) -> 0 | J6: =COUNTIF('Display Detail'!$D$2:$D$656,$A6) -> 8
A7: Andrew Lundy | B7: =COUNTIFS('Display Detail'!$D$2:$D$656,$A7,'Display Detail'!$K$2:$K$656,4) -> 0 | C7: =COUNTIFS('Display Detail'!$D$2:$D$656,$A7,'Display Detail'!$K$2:$K$656,3) -> 0 | D7: =COUNTIFS('Display Detail'!$D$2:$D$656,$A7,'Display Detail'!$K$2:$K$656,2) -> 1 | E7: =COUNTIFS('Display Detail'!$D$2:$D$656,$A7,'Display Detail'!$K$2:$K$656,1) -> 0 | F7: =COUNTIFS('Display Detail'!$D$2:$D$656,$A7,'Display Detail'!$K$2:$K$656,">0") -> 1 | G7: =SUMIFS('Display Detail'!$M$2:$M$656,'Display Detail'!$D$2:$D$656,$A7,'Display Detail'!$K$2:$K$656,">0") -> 25 | H7: =SUMIFS('Display Detail'!$P$2:$P$656,'Display Detail'!$D$2:$D$656,$A7,'Display Detail'!$K$2:$K$656,">0") -> 300 | I7: =COUNTIFS('Display Detail'!$D$2:$D$656,$A7,'Display Detail'!$K$2:$K$656,0) -> 0 | J7: =COUNTIF('Display Detail'!$D$2:$D$656,$A7) -> 1
A8: Chris Payton | B8: =COUNTIFS('Display Detail'!$D$2:$D$656,$A8,'Display Detail'!$K$2:$K$656,4) -> 1 | C8: =COUNTIFS('Display Detail'!$D$2:$D$656,$A8,'Display Detail'!$K$2:$K$656,3) -> 6 | D8: =COUNTIFS('Display Detail'!$D$2:$D$656,$A8,'Display Detail'!$K$2:$K$656,2) -> 4 | E8: =COUNTIFS('Display Detail'!$D$2:$D$656,$A8,'Display Detail'!$K$2:$K$656,1) -> 0 | F8: =COUNTIFS('Display Detail'!$D$2:$D$656,$A8,'Display Detail'!$K$2:$K$656,">0") -> 11 | G8: =SUMIFS('Display Detail'!$M$2:$M$656,'Display Detail'!$D$2:$D$656,$A8,'Display Detail'!$K$2:$K$656,">0") -> 489 | H8: =SUMIFS('Display Detail'!$P$2:$P$656,'Display Detail'!$D$2:$D$656,$A8,'Display Detail'!$K$2:$K$656,">0") -> 5200 | I8: =COUNTIFS('Display Detail'!$D$2:$D$656,$A8,'Display Detail'!$K$2:$K$656,0) -> 8 | J8: =COUNTIF('Display Detail'!$D$2:$D$656,$A8) -> 19
A9: Daniel La Gala | B9: =COUNTIFS('Display Detail'!$D$2:$D$656,$A9,'Display Detail'!$K$2:$K$656,4) -> 3 | C9: =COUNTIFS('Display Detail'!$D$2:$D$656,$A9,'Display Detail'!$K$2:$K$656,3) -> 0 | D9: =COUNTIFS('Display Detail'!$D$2:$D$656,$A9,'Display Detail'!$K$2:$K$656,2) -> 0 | E9: =COUNTIFS('Display Detail'!$D$2:$D$656,$A9,'Display Detail'!$K$2:$K$656,1) -> 0 | F9: =COUNTIFS('Display Detail'!$D$2:$D$656,$A9,'Display Detail'!$K$2:$K$656,">0") -> 3 | G9: =SUMIFS('Display Detail'!$M$2:$M$656,'Display Detail'!$D$2:$D$656,$A9,'Display Detail'!$K$2:$K$656,">0") -> 300 | H9: =SUMIFS('Display Detail'!$P$2:$P$656,'Display Detail'!$D$2:$D$656,$A9,'Display Detail'!$K$2:$K$656,">0") -> 2600 | I9: =COUNTIFS('Display Detail'!$D$2:$D$656,$A9,'Display Detail'!$K$2:$K$656,0) -> 5 | J9: =COUNTIF('Display Detail'!$D$2:$D$656,$A9) -> 8
A10: Dave Ehlers | B10: =COUNTIFS('Display Detail'!$D$2:$D$656,$A10,'Display Detail'!$K$2:$K$656,4) -> 21 | C10: =COUNTIFS('Display Detail'!$D$2:$D$656,$A10,'Display Detail'!$K$2:$K$656,3) -> 6 | D10: =COUNTIFS('Display Detail'!$D$2:$D$656,$A10,'Display Detail'!$K$2:$K$656,2) -> 4 | E10: =COUNTIFS('Display Detail'!$D$2:$D$656,$A10,'Display Detail'!$K$2:$K$656,1) -> 3 | F10: =COUNTIFS('Display Detail'!$D$2:$D$656,$A10,'Display Detail'!$K$2:$K$656,">0") -> 34 | G10: =SUMIFS('Display Detail'!$M$2:$M$656,'Display Detail'!$D$2:$D$656,$A10,'Display Detail'!$K$2:$K$656,">0") -> 2773 | H10: =SUMIFS('Display Detail'!$P$2:$P$656,'Display Detail'!$D$2:$D$656,$A10,'Display Detail'!$K$2:$K$656,">0") -> 25000 | I10: =COUNTIFS('Display Detail'!$D$2:$D$656,$A10,'Display Detail'!$K$2:$K$656,0) -> 7 | J10: =COUNTIF('Display Detail'!$D$2:$D$656,$A10) -> 41
A11: Derrick laws | B11: =COUNTIFS('Display Detail'!$D$2:$D$656,$A11,'Display Detail'!$K$2:$K$656,4) -> 3 | C11: =COUNTIFS('Display Detail'!$D$2:$D$656,$A11,'Display Detail'!$K$2:$K$656,3) -> 1 | D11: =COUNTIFS('Display Detail'!$D$2:$D$656,$A11,'Display Detail'!$K$2:$K$656,2) -> 4 | E11: =COUNTIFS('Display Detail'!$D$2:$D$656,$A11,'Display Detail'!$K$2:$K$656,1) -> 2 | F11: =COUNTIFS('Display Detail'!$D$2:$D$656,$A11,'Display Detail'!$K$2:$K$656,">0") -> 10 | G11: =SUMIFS('Display Detail'!$M$2:$M$656,'Display Detail'!$D$2:$D$656,$A11,'Display Detail'!$K$2:$K$656,">0") -> 426 | H11: =SUMIFS('Display Detail'!$P$2:$P$656,'Display Detail'!$D$2:$D$656,$A11,'Display Detail'!$K$2:$K$656,">0") -> 5000 | I11: =COUNTIFS('Display Detail'!$D$2:$D$656,$A11,'Display Detail'!$K$2:$K$656,0) -> 2 | J11: =COUNTIF('Display Detail'!$D$2:$D$656,$A11) -> 12
A12: Dylan Rubino | B12: =COUNTIFS('Display Detail'!$D$2:$D$656,$A12,'Display Detail'!$K$2:$K$656,4) -> 0 | C12: =COUNTIFS('Display Detail'!$D$2:$D$656,$A12,'Display Detail'!$K$2:$K$656,3) -> 0 | D12: =COUNTIFS('Display Detail'!$D$2:$D$656,$A12,'Display Detail'!$K$2:$K$656,2) -> 1 | E12: =COUNTIFS('Display Detail'!$D$2:$D$656,$A12,'Display Detail'!$K$2:$K$656,1) -> 0 | F12: =COUNTIFS('Display Detail'!$D$2:$D$656,$A12,'Display Detail'!$K$2:$K$656,">0") -> 1 | G12: =SUMIFS('Display Detail'!$M$2:$M$656,'Display Detail'!$D$2:$D$656,$A12,'Display Detail'!$K$2:$K$656,">0") -> 38 | H12: =SUMIFS('Display Detail'!$P$2:$P$656,'Display Detail'!$D$2:$D$656,$A12,'Display Detail'!$K$2:$K$656,">0") -> 200 | I12: =COUNTIFS('Display Detail'!$D$2:$D$656,$A12,'Display Detail'!$K$2:$K$656,0) -> 5 | J12: =COUNTIF('Display Detail'!$D$2:$D$656,$A12) -> 6
A13: Jaime Colonna | B13: =COUNTIFS('Display Detail'!$D$2:$D$656,$A13,'Display Detail'!$K$2:$K$656,4) -> 0 | C13: =COUNTIFS('Display Detail'!$D$2:$D$656,$A13,'Display Detail'!$K$2:$K$656,3) -> 0 | D13: =COUNTIFS('Display Detail'!$D$2:$D$656,$A13,'Display Detail'!$K$2:$K$656,2) -> 1 | E13: =COUNTIFS('Display Detail'!$D$2:$D$656,$A13,'Display Detail'!$K$2:$K$656,1) -> 0 | F13: =COUNTIFS('Display Detail'!$D$2:$D$656,$A13,'Display Detail'!$K$2:$K$656,">0") -> 1 | G13: =SUMIFS('Display Detail'!$M$2:$M$656,'Display Detail'!$D$2:$D$656,$A13,'Display Detail'!$K$2:$K$656,">0") -> 20 | H13: =SUMIFS('Display Detail'!$P$2:$P$656,'Display Detail'!$D$2:$D$656,$A13,'Display Detail'!$K$2:$K$656,">0") -> 200 | I13: =COUNTIFS('Display Detail'!$D$2:$D$656,$A13,'Display Detail'!$K$2:$K$656,0) -> 0 | J13: =COUNTIF('Display Detail'!$D$2:$D$656,$A13) -> 1
A14: James Heaney | B14: =COUNTIFS('Display Detail'!$D$2:$D$656,$A14,'Display Detail'!$K$2:$K$656,4) -> 3 | C14: =COUNTIFS('Display Detail'!$D$2:$D$656,$A14,'Display Detail'!$K$2:$K$656,3) -> 2 | D14: =COUNTIFS('Display Detail'!$D$2:$D$656,$A14,'Display Detail'!$K$2:$K$656,2) -> 1 | E14: =COUNTIFS('Display Detail'!$D$2:$D$656,$A14,'Display Detail'!$K$2:$K$656,1) -> 1 | F14: =COUNTIFS('Display Detail'!$D$2:$D$656,$A14,'Display Detail'!$K$2:$K$656,">0") -> 7 | G14: =SUMIFS('Display Detail'!$M$2:$M$656,'Display Detail'!$D$2:$D$656,$A14,'Display Detail'!$K$2:$K$656,">0") -> 388 | H14: =SUMIFS('Display Detail'!$P$2:$P$656,'Display Detail'!$D$2:$D$656,$A14,'Display Detail'!$K$2:$K$656,">0") -> 4500 | I14: =COUNTIFS('Display Detail'!$D$2:$D$656,$A14,'Display Detail'!$K$2:$K$656,0) -> 5 | J14: =COUNTIF('Display Detail'!$D$2:$D$656,$A14) -> 12
A15: Javier Melo | B15: =COUNTIFS('Display Detail'!$D$2:$D$656,$A15,'Display Detail'!$K$2:$K$656,4) -> 1 | C15: =COUNTIFS('Display Detail'!$D$2:$D$656,$A15,'Display Detail'!$K$2:$K$656,3) -> 4 | D15: =COUNTIFS('Display Detail'!$D$2:$D$656,$A15,'Display Detail'!$K$2:$K$656,2) -> 5 | E15: =COUNTIFS('Display Detail'!$D$2:$D$656,$A15,'Display Detail'!$K$2:$K$656,1) -> 6 | F15: =COUNTIFS('Display Detail'!$D$2:$D$656,$A15,'Display Detail'!$K$2:$K$656,">0") -> 16 | G15: =SUMIFS('Display Detail'!$M$2:$M$656,'Display Detail'!$D$2:$D$656,$A15,'Display Detail'!$K$2:$K$656,">0") -> 486 | H15: =SUMIFS('Display Detail'!$P$2:$P$656,'Display Detail'!$D$2:$D$656,$A15,'Display Detail'!$K$2:$K$656,">0") -> 5600 | I15: =COUNTIFS('Display Detail'!$D$2:$D$656,$A15,'Display Detail'!$K$2:$K$656,0) -> 3 | J15: =COUNTIF('Display Detail'!$D$2:$D$656,$A15) -> 19
A16: Jayson Romine | B16: =COUNTIFS('Display Detail'!$D$2:$D$656,$A16,'Display Detail'!$K$2:$K$656,4) -> 2 | C16: =COUNTIFS('Display Detail'!$D$2:$D$656,$A16,'Display Detail'!$K$2:$K$656,3) -> 1 | D16: =COUNTIFS('Display Detail'!$D$2:$D$656,$A16,'Display Detail'!$K$2:$K$656,2) -> 2 | E16: =COUNTIFS('Display Detail'!$D$2:$D$656,$A16,'Display Detail'!$K$2:$K$656,1) -> 0 | F16: =COUNTIFS('Display Detail'!$D$2:$D$656,$A16,'Display Detail'!$K$2:$K$656,">0") -> 5 | G16: =SUMIFS('Display Detail'!$M$2:$M$656,'Display Detail'!$D$2:$D$656,$A16,'Display Detail'!$K$2:$K$656,">0") -> 256 | H16: =SUMIFS('Display Detail'!$P$2:$P$656,'Display Detail'!$D$2:$D$656,$A16,'Display Detail'!$K$2:$K$656,">0") -> 3100 | I16: =COUNTIFS('Display Detail'!$D$2:$D$656,$A16,'Display Detail'!$K$2:$K$656,0) -> 5 | J16: =COUNTIF('Display Detail'!$D$2:$D$656,$A16) -> 10
A17: John Neukum | B17: =COUNTIFS('Display Detail'!$D$2:$D$656,$A17,'Display Detail'!$K$2:$K$656,4) -> 13 | C17: =COUNTIFS('Display Detail'!$D$2:$D$656,$A17,'Display Detail'!$K$2:$K$656,3) -> 5 | D17: =COUNTIFS('Display Detail'!$D$2:$D$656,$A17,'Display Detail'!$K$2:$K$656,2) -> 0 | E17: =COUNTIFS('Display Detail'!$D$2:$D$656,$A17,'Display Detail'!$K$2:$K$656,1) -> 1 | F17: =COUNTIFS('Display Detail'!$D$2:$D$656,$A17,'Display Detail'!$K$2:$K$656,">0") -> 19 | G17: =SUMIFS('Display Detail'!$M$2:$M$656,'Display Detail'!$D$2:$D$656,$A17,'Display Detail'!$K$2:$K$656,">0") -> 1584 | H17: =SUMIFS('Display Detail'!$P$2:$P$656,'Display Detail'!$D$2:$D$656,$A17,'Display Detail'!$K$2:$K$656,">0") -> 15700 | I17: =COUNTIFS('Display Detail'!$D$2:$D$656,$A17,'Display Detail'!$K$2:$K$656,0) -> 0 | J17: =COUNTIF('Display Detail'!$D$2:$D$656,$A17) -> 19
... A25: phil Ernst | B25: =COUNTIFS('Display Detail'!$D$2:$D$656,$A25,'Display Detail'!$K$2:$K$656,4) -> 15 | C25: =COUNTIFS('Display Detail'!$D$2:$D$656,$A25,'Display Detail'!$K$2:$K$656,3) -> 26 | D25: =COUNTIFS('Display Detail'!$D$2:$D$656,$A25,'Display Detail'!$K$2:$K$656,2) -> 9 | E25: =COUNTIFS('Display Detail'!$D$2:$D$656,$A25,'Display Detail'!$K$2:$K$656,1) -> 4 | F25: =COUNTIFS('Display Detail'!$D$2:$D$656,$A25,'Display Detail'!$K$2:$K$656,">0") -> 54 | G25: =SUMIFS('Display Detail'!$M$2:$M$656,'Display Detail'!$D$2:$D$656,$A25,'Display Detail'!$K$2:$K$656,">0") -> 3271 | H25: =SUMIFS('Display Detail'!$P$2:$P$656,'Display Detail'!$D$2:$D$656,$A25,'Display Detail'!$K$2:$K$656,">0") -> 31200 | I25: =COUNTIFS('Display Detail'!$D$2:$D$656,$A25,'Display Detail'!$K$2:$K$656,0) -> 18 | J25: =COUNTIF('Display Detail'!$D$2:$D$656,$A25) -> 72
A26: SALES ASSOCIATES — Display Rewards
A27: David Fletcher | B27: =COUNTIFS('Display Detail'!$D$2:$D$656,$A27,'Display Detail'!$K$2:$K$656,4) -> 4 | C27: =COUNTIFS('Display Detail'!$D$2:$D$656,$A27,'Display Detail'!$K$2:$K$656,3) -> 8 | D27: =COUNTIFS('Display Detail'!$D$2:$D$656,$A27,'Display Detail'!$K$2:$K$656,2) -> 3 | E27: =COUNTIFS('Display Detail'!$D$2:$D$656,$A27,'Display Detail'!$K$2:$K$656,1) -> 1 | F27: =COUNTIFS('Display Detail'!$D$2:$D$656,$A27,'Display Detail'!$K$2:$K$656,">0") -> 16 | G27: =SUMIFS('Display Detail'!$M$2:$M$656,'Display Detail'!$D$2:$D$656,$A27,'Display Detail'!$K$2:$K$656,">0") -> 913 | H27: =SUMIFS('Display Detail'!$P$2:$P$656,'Display Detail'!$D$2:$D$656,$A27,'Display Detail'!$K$2:$K$656,">0") -> 9100 | I27: =COUNTIFS('Display Detail'!$D$2:$D$656,$A27,'Display Detail'!$K$2:$K$656,0) -> 17 | J27: =COUNTIF('Display Detail'!$D$2:$D$656,$A27) -> 33
A28: Jay Tabasco | B28: =COUNTIFS('Display Detail'!$D$2:$D$656,$A28,'Display Detail'!$K$2:$K$656,4) -> 11 | C28: =COUNTIFS('Display Detail'!$D$2:$D$656,$A28,'Display Detail'!$K$2:$K$656,3) -> 5 | D28: =COUNTIFS('Display Detail'!$D$2:$D$656,$A28,'Display Detail'!$K$2:$K$656,2) -> 3 | E28: =COUNTIFS('Display Detail'!$D$2:$D$656,$A28,'Display Detail'!$K$2:$K$656,1) -> 3 | F28: =COUNTIFS('Display Detail'!$D$2:$D$656,$A28,'Display Detail'!$K$2:$K$656,">0") -> 22 | G28: =SUMIFS('Display Detail'!$M$2:$M$656,'Display Detail'!$D$2:$D$656,$A28,'Display Detail'!$K$2:$K$656,">0") -> 1389 | H28: =SUMIFS('Display Detail'!$P$2:$P$656,'Display Detail'!$D$2:$D$656,$A28,'Display Detail'!$K$2:$K$656,">0") -> 15000 | I28: =COUNTIFS('Display Detail'!$D$2:$D$656,$A28,'Display Detail'!$K$2:$K$656,0) -> 3 | J28: =COUNTIF('Display Detail'!$D$2:$D$656,$A28) -> 25
A29: Nicholas Micco | B29: =COUNTIFS('Display Detail'!$D$2:$D$656,$A29,'Display Detail'!$K$2:$K$656,4) -> 12 | C29: =COUNTIFS('Display Detail'!$D$2:$D$656,$A29,'Display Detail'!$K$2:$K$656,3) -> 16 | D29: =COUNTIFS('Display Detail'!$D$2:$D$656,$A29,'Display Detail'!$K$2:$K$656,2) -> 6 | E29: =COUNTIFS('Display Detail'!$D$2:$D$656,$A29,'Display Detail'!$K$2:$K$656,1) -> 2 | F29: =COUNTIFS('Display Detail'!$D$2:$D$656,$A29,'Display Detail'!$K$2:$K$656,">0") -> 36 | G29: =SUMIFS('Display Detail'!$M$2:$M$656,'Display Detail'!$D$2:$D$656,$A29,'Display Detail'!$K$2:$K$656,">0") -> 2257 | H29: =SUMIFS('Display Detail'!$P$2:$P$656,'Display Detail'!$D$2:$D$656,$A29,'Display Detail'!$K$2:$K$656,">0") -> 22000 | I29: =COUNTIFS('Display Detail'!$D$2:$D$656,$A29,'Display Detail'!$K$2:$K$656,0) -> 14 | J29: =COUNTIF('Display Detail'!$D$2:$D$656,$A29) -> 50
A30: Todd Ewell | B30: =COUNTIFS('Display Detail'!$D$2:$D$656,$A30,'Display Detail'!$K$2:$K$656,4) -> 10 | C30: =COUNTIFS('Display Detail'!$D$2:$D$656,$A30,'Display Detail'!$K$2:$K$656,3) -> 9 | D30: =COUNTIFS('Display Detail'!$D$2:$D$656,$A30,'Display Detail'!$K$2:$K$656,2) -> 2 | E30: =COUNTIFS('Display Detail'!$D$2:$D$656,$A30,'Display Detail'!$K$2:$K$656,1) -> 1 | F30: =COUNTIFS('Display Detail'!$D$2:$D$656,$A30,'Display Detail'!$K$2:$K$656,">0") -> 22 | G30: =SUMIFS('Display Detail'!$M$2:$M$656,'Display Detail'!$D$2:$D$656,$A30,'Display Detail'!$K$2:$K$656,">0") -> 1348 | H30: =SUMIFS('Display Detail'!$P$2:$P$656,'Display Detail'!$D$2:$D$656,$A30,'Display Detail'!$K$2:$K$656,">0") -> 15300 | I30: =COUNTIFS('Display Detail'!$D$2:$D$656,$A30,'Display Detail'!$K$2:$K$656,0) -> 0 | J30: =COUNTIF('Display Detail'!$D$2:$D$656,$A30) -> 22
A31: Vaughn Gallagher | B31: =COUNTIFS('Display Detail'!$D$2:$D$656,$A31,'Display Detail'!$K$2:$K$656,4) -> 0 | C31: =COUNTIFS('Display Detail'!$D$2:$D$656,$A31,'Display Detail'!$K$2:$K$656,3) -> 2 | D31: =COUNTIFS('Display Detail'!$D$2:$D$656,$A31,'Display Detail'!$K$2:$K$656,2) -> 2 | E31: =COUNTIFS('Display Detail'!$D$2:$D$656,$A31,'Display Detail'!$K$2:$K$656,1) -> 0 | F31: =COUNTIFS('Display Detail'!$D$2:$D$656,$A31,'Display Detail'!$K$2:$K$656,">0") -> 4 | G31: =SUMIFS('Display Detail'!$M$2:$M$656,'Display Detail'!$D$2:$D$656,$A31,'Display Detail'!$K$2:$K$656,">0") -> 161 | H31: =SUMIFS('Display Detail'!$P$2:$P$656,'Display Detail'!$D$2:$D$656,$A31,'Display Detail'!$K$2:$K$656,">0") -> 1600 | I31: =COUNTIFS('Display Detail'!$D$2:$D$656,$A31,'Display Detail'!$K$2:$K$656,0) -> 2 | J31: =COUNTIF('Display Detail'!$D$2:$D$656,$A31) -> 6
A32: mickey obrien | B32: =COUNTIFS('Display Detail'!$D$2:$D$656,$A32,'Display Detail'!$K$2:$K$656,4) -> 24 | C32: =COUNTIFS('Display Detail'!$D$2:$D$656,$A32,'Display Detail'!$K$2:$K$656,3) -> 15 | D32: =COUNTIFS('Display Detail'!$D$2:$D$656,$A32,'Display Detail'!$K$2:$K$656,2) -> 10 | E32: =COUNTIFS('Display Detail'!$D$2:$D$656,$A32,'Display Detail'!$K$2:$K$656,1) -> 4 | F32: =COUNTIFS('Display Detail'!$D$2:$D$656,$A32,'Display Detail'!$K$2:$K$656,">0") -> 53 | G32: =SUMIFS('Display Detail'!$M$2:$M$656,'Display Detail'!$D$2:$D$656,$A32,'Display Detail'!$K$2:$K$656,">0") -> 4044 | H32: =SUMIFS('Display Detail'!$P$2:$P$656,'Display Detail'!$D$2:$D$656,$A32,'Display Detail'!$K$2:$K$656,">0") -> 34300 | I32: =COUNTIFS('Display Detail'!$D$2:$D$656,$A32,'Display Detail'!$K$2:$K$656,0) -> 5 | J32: =COUNTIF('Display Detail'!$D$2:$D$656,$A32) -> 58
A33: patrick infante | B33: =COUNTIFS('Display Detail'!$D$2:$D$656,$A33,'Display Detail'!$K$2:$K$656,4) -> 13 | C33: =COUNTIFS('Display Detail'!$D$2:$D$656,$A33,'Display Detail'!$K$2:$K$656,3) -> 17 | D33: =COUNTIFS('Display Detail'!$D$2:$D$656,$A33,'Display Detail'!$K$2:$K$656,2) -> 13 | E33: =COUNTIFS('Display Detail'!$D$2:$D$656,$A33,'Display Detail'!$K$2:$K$656,1) -> 6 | F33: =COUNTIFS('Display Detail'!$D$2:$D$656,$A33,'Display Detail'!$K$2:$K$656,">0") -> 49 | G33: =SUMIFS('Display Detail'!$M$2:$M$656,'Display Detail'!$D$2:$D$656,$A33,'Display Detail'!$K$2:$K$656,">0") -> 2730 | H33: =SUMIFS('Display Detail'!$P$2:$P$656,'Display Detail'!$D$2:$D$656,$A33,'Display Detail'!$K$2:$K$656,">0") -> 26200 | I33: =COUNTIFS('Display Detail'!$D$2:$D$656,$A33,'Display Detail'!$K$2:$K$656,0) -> 46 | J33: =COUNTIF('Display Detail'!$D$2:$D$656,$A33) -> 95
A34: TOTAL — ALL DISPLAYS | B34: =COUNTIF('Display Detail'!$K$2:$K$656,4) -> 190 | C34: =COUNTIF('Display Detail'!$K$2:$K$656,3) -> 157 | D34: =COUNTIF('Display Detail'!$K$2:$K$656,2) -> 97 | E34: =COUNTIF('Display Detail'!$K$2:$K$656,1) -> 50 | F34: =COUNTIF('Display Detail'!$K$2:$K$656,">0") -> 494 | G34: =SUMIFS('Display Detail'!$M$2:$M$656,'Display Detail'!$K$2:$K$656,">0") -> 31202 | H34: =SUMIFS('Display Detail'!$P$2:$P$656,'Display Detail'!$K$2:$K$656,">0") -> 302200 | I34: =COUNTIF('Display Detail'!$K$2:$K$656,0) -> 161 | J34: =COUNTA('Display Detail'!$A$2:$A$656) -> 655
A36: Sales Reps and Sales Associates run as two separate programs but earn on the same point scale.
A37: Points shown are the tracker's published scale — see the Notes & Method tab on how that compares to the program slide.
A38: Source: iSellBeer display photo export, 07/01/2026 – 08/31/2026 (Report_59, pulled 08/31/2026).

Sheet Duplicate Check
A1: Duplicate Check — displays that may have been logged twice
A2: Qualifying displays only. Clusters are the same account on the same day with the same brands; the earliest submission is kept, the rest are flagged for review.
A4: Clusters found | B4: 59 | C4: Groups of 2+ qualifying displays on one account/day with the same brand list.
A5: Displays flagged as possible duplicates | B5: 65 | C5: Every display in a cluster except the first one submitted.
A6: Points sitting on those displays | B6: 43800 | C6: 14.5% of the 302,200 points on the board.
A7: · Same person — exact repeat | B7: 2 | C7: One person logged the identical display twice, minutes apart. Almost certainly a double submission.
A8: · Cross-person — exact match | B8: 35 | C8: Two+ people logged the same display, same case count. Usually a rep and the associate riding with them.
A9: · Cross-person — same brands, different cases | B9: 28 | C9: Same account/day/brands but the case counts differ — same display, counted differently by each person.
A10: None of these are removed from the summary tabs — those match the published leaderboard exactly. This tab is the review list.
A12: Flag | B12: Cluster | C12: Status | D12: Date / Time | E12: Rep / Associate | F12: Role | G12: Account (DBA) | H12: Account # | I12: Cases | J12: Display Tier | K12: Points | L12: Brands in Display | M12: Photo
A13: Cross-person — exact match | B13: C001 | C13: Kept (first submitted) | D13: 07/02/2026 10:21 AM | E13: Nicholas Micco | F13: Sales Associate | G13: BUY RITE DISCOUNT LIQUOR | H13: 38040 | I13: 30 | J13: Bronze (20-39) | K13: 300 | L13: TWISTED TEA | M13: View Photo
A14: Cross-person — exact match | B14: C001 | C14: Possible duplicate | D14: 07/02/2026 10:23 AM | E14: David Fletcher | F14: Sales Associate | G14: BUY RITE DISCOUNT LIQUOR | H14: 38040 | I14: 30 | J14: Bronze (20-39) | K14: 300 | L14: TWISTED TEA | M14: View Photo
A15: Cross-person — exact match | B15: C002 | C15: Kept (first submitted) | D15: 07/02/2026 12:02 PM | E15: Nicholas Micco | F15: Sales Associate | G15: SUPER WINE WAREHSE(P)PATE | H15: 20106 | I15: 40 | J15: Silver (40-69) | K15: 500 | L15: CAYMAN JACK | M15: View Photo
A16: Cross-person — exact match | B16: C002 | C16: Possible duplicate | D16: 07/02/2026 12:03 PM | E16: David Fletcher | F16: Sales Associate | G16: SUPER WINE WAREHSE(P)PATE | H16: 20106 | I16: 40 | J16: Silver (40-69) | K16: 500 | L16: CAYMAN JACK | M16: View Photo
A17: Cross-person — exact match | B17: C003 | C17: Kept (first submitted) | D17: 07/02/2026 02:25 PM | E17: phil Ernst | F17: Sales Rep | G17: SUPER WINE WAREHSE(P)PATE | H17: 20106 | I17: 50 | J17: Silver (40-69) | K17: 500 | L17: TWISTED TEA | M17: View Photo
A18: Cross-person — exact match | B18: C003 | C18: Possible duplicate | D18: 07/02/2026 12:01 PM | E18: Nicholas Micco | F18: Sales Associate | G18: SUPER WINE WAREHSE(P)PATE | H18: 20106 | I18: 50 | J18: Silver (40-69) | K18: 500 | L18: TWISTED TEA | M18: View Photo
A19: Cross-person — exact match | B19: C004 | C19: Kept (first submitted) | D19: 07/03/2026 01:11 PM | E19: patrick infante | F19: Sales Associate | G19: C TOWN SUPERMARKET(P) | H19: 21026 | I19: 40 | J19: Silver (40-69) | K19: 500 | L19: MODELO CERVEZA | M19: View Photo
A20: Cross-person — exact match | B20: C004 | C20: Possible duplicate | D20: 07/03/2026 01:13 PM | E20: Javier Melo | F20: Sales Rep | G20: C TOWN SUPERMARKET(P) | H20: 21026 | I20: 40 | J20: Silver (40-69) | K20: 500 | L20: MODELO CERVEZA | M20: View Photo
A21: Cross-person — exact match | B21: C005 | C21: Kept (first submitted) | D21: 07/07/2026 11:41 AM | E21: Daniel La Gala | F21: Sales Rep | G21: MITSUWA MARKET (A) | H21: 49066 | I21: 100 | J21: Gold (70+) | K21: 1000 | L21: MODELO CERVEZA | M21: View Photo
A22: Cross-person — exact match | B22: C005 | C22: Possible duplicate | D22: 07/07/2026 11:42 AM | E22: mickey obrien | F22: Sales Associate | G22: MITSUWA MARKET (A) | H22: 49066 | I22: 100 | J22: Gold (70+) | K22: 1000 | L22: MODELO CERVEZA | M22: View Photo
A23: Cross-person — exact match | B23: C006 | C23: Kept (first submitted) | D23: 07/07/2026 11:41 AM | E23: mickey obrien | F23: Sales Associate | G23: MITSUWA MARKET (A) | H23: 49066 | I23: 100 | J23: Gold (70+) | K23: 1000 | L23: HEINEKEN | M23: View Photo
A24: Cross-person — exact match | B24: C006 | C24: Possible duplicate | D24: 07/07/2026 11:42 AM | E24: Daniel La Gala | F24: Sales Rep | G24: MITSUWA MARKET (A) | H24: 49066 | I24: 100 | J24: Gold (70+) | K24: 1000 | L24: HEINEKEN | M24: View Photo
... A136: Same person — exact repeat | B136: C059 | C136: Possible duplicate | D136: 07/30/2026 12:10 PM | E136: Klejdi Lamo | F136: Sales Rep | G136: SHOP RITE WINE & SPIRITS STANHOPE | H136: 191710 | I136: 70 | J136: Gold (70+) | K136: 1000 | L136: SUN CRUISERS RTD | M136: View Photo

Sheet Multi-Supplier Audit
A1: Multi-Supplier Displays — attribution audit
A2: Photo submissions carrying more than one supplier group. Each is credited to the group holding the most cases.
A4: Date | B4: Rep / Associate | C4: Account (DBA) | D4: Total Cases | E4: Display Tier | F4: Credited To | G4: Cases from Credited Supplier | H4: Full Supplier Split (cases) | I4: Qualifying?
A5: 07/07/2026 | B5: patrick infante | C5: MITSUWA MARKET (A) | D5: 200 | E5: Gold (70+) | F5: Constellation | G5: 100 | H5: HUSA (Heineken USA) (100) + Constellation (100) | I5: Yes
A6: 07/24/2026 | B6: John Neukum | C6: BJ'S WAREHOUSE E RUTHERFO | D6: 150 | E6: Gold (70+) | F6: HUSA (Heineken USA) | G6: 90 | H6: HUSA (Heineken USA) (90) + Yuengling (60) | I6: Yes
A7: 07/21/2026 | B7: mickey obrien | C7: BOTTLE KING (A) GLEN ROCK | D7: 135 | E7: Gold (70+) | F7: Boston Beer | G7: 75 | H7: Boston Beer (75) + Molson Coors (60) | I7: Yes
A8: 07/02/2026 | B8: phil Ernst | C8: SUPER WINE WAREHSE(P)PATE | D8: 115 | E8: Gold (70+) | F8: Mark Anthony | G8: 70 | H8: Mark Anthony (70) + Boston Beer (45) | I8: Yes
A9: 08/17/2026 | B9: Mike Ast | C9: BOTTLE KING (A) WAYNE | D9: 91 | E9: Gold (70+) | F9: Yuengling | G9: 33 | H9: Yuengling (33) + All Other: CAPE MAY BREWING COMPANY (19) + All Other: SIERRA NEVADA BREWING COMPANY (17) + All Other: ARTISANAL BREWING VENTURES (EBI) (11) + All Other: THE GAMBRINUS COMPANY (11) | I9: Yes
A10: 08/05/2026 | B10: Shane Barreca | C10: BOTTLE KING (A) DUMONT | D10: 70 | E10: Gold (70+) | F10: All Other: PAULANER | G10: 43 | H10: All Other: PAULANER (43) + All Other: HOFBRAU (20) + Yuengling (7) | I10: Yes
