Workbook

Sheet Summary
A1: Summer of Success 2026 — did it work?
A2: Jun 1 – Aug 31, 2026 vs 2025 · 28 reps · 10 suppliers · 2,016 accounts · built 09/11/2026
A4: THE VERDICT
A5: The incentive did not generate measurable incremental volume or gross profit. It paid for a trend that was already running.
A7: THE TESTS
A8: Test | B8: Result | C8: What it means
A9: 1. Did AMPLIFY growth accelerate when the program started? | B9: ='Acceleration Test'!H7 | C9: No. Already +12% before a dollar was offered.
A10: 1b. Did QUALIFIER volume accelerate? | B10: ='Acceleration Test'!H6 | C10: No — it slowed by nearly three points.
A11: 2. Amplify GP lift vs its own pre-program trajectory | B11: ='Counterfactual'!F12 | C11: Zero, against the amplify payout.
A12: 3. Incented vs the same SUPPLIERS' non-incented brands | B12: ='Control by Supplier'!H13 | C12: The incented book lost to the book with no incentive.
A13: 4. Incented vs non-incented brands in the SAME ACCOUNTS | B13: ='Within-Account Control'!D9 | C13: Same stores, same summer: still no incentive effect.
A14: 5. Did the program build DISTRIBUTION? | B14: ='Distribution'!D7 | C14: Amplify PODs +4.2% — but +5.5% before the program.
A15: 6. Were the qualifier goals set above last year? | B15: ='Goal Design'!$B$147 | C15: No — 9 in 10 sat BELOW the rep's own 2025.
A16: 7. Did payout track performance? | B16: ='Payout vs Performance'!$B$36 | C16: r ≈ 0. Payout did not follow delivery.
A18: THE NUMBERS
A19: Program cases, Jun–Aug | B19: ='Acceleration Test'!F8
A20: vs 2025 | B20: ='Acceleration Test'!G8
A21: Program gross profit, Jun–Aug | B21: ='Acceleration Test'!F13
A22: vs 2025 | B22: ='Acceleration Test'!G13
A23: Gross profit lift vs pre-program trend | B23: ='Counterfactual'!F13
A24: Total payout | B24: =Assumptions!$B$7
A25: Net of payout | B25: ='Counterfactual'!F13-Assumptions!$B$7
A27: WHAT THE PROGRAM CAN HONESTLY CLAIM
A28: Mark Anthony held. Incented White Claw and Cayman Jack fell 5.9% while the same supplier's non-incented brands fell 22.2% — the clearest evidence anywhere here that the incentive changed a rep's behaviour.
A29: No volume was bought with discount. Revenue per case held on every growing amplify brand.
A30: Distribution did not erode. Qualifier PODs fell only 1.2%, matching the control — reps held their accounts. What fell was rate of sale, which is a market result, not an effort one. That is the fair thing to say about the sales team.
A31: Engagement was near-universal: 27 of 28 reps earned something.
A33: AND ONE PLACE IT ACTUALLY WORKED
A34: On-premise — Amplify swing vs its own pre-program rate | B34: ='Channel'!E8
A35: On-premise — Qualifier swing | B35: ='Channel'!E7
A36: On-premise is the only cut in this workbook where the program accelerated — the only positive swings anywhere. It is about 11% of program volume, and even there the incented brands still trailed that channel's non-incented brands.
A37: It is the one version of this incentive the data gives any reason to run again: smaller, and weighted on-premise. See the Channel tab.
A39: THE TWO FINDINGS THAT MATTER FOR 2027
A40: 1. BRAND SELECTION decided the outcome. Boston Beer: the program paid reps to push Twisted Tea (-7,585 cases) and Truly (-3,111), both in structural decline, while Sun Cruiser — no incentive — grew 13,728 cases and $237,182 of GP with the same reps in the same summer.
A41: 2. GOAL DESIGN guaranteed payout regardless. 126 of 137 qualifier goals were set below that rep's own 2025 volume; the aggregate goal asked for 2.5% LESS than last year.
A42: Together they explain the zero correlation between payout and performance: the program paid for goals that were already met, on brands that were already moving — or already falling.
A43: Recommendation: screen candidate brands on their own trailing trajectory before attaching a dollar, and set qualifier goals above prior-year actual. A brand already growing does not need the money; a brand in structural decline will not be saved by it.
A45: AND ONE THING TO WATCH
A46: The amplify gain is concentrated: the top 10 accounts produced 37% of it and the top 100 produced 90%, out of 1,847 accounts buying those brands. Most of it sits in BJ's, Super Wine Warehouse, Beverage Barn, Total Wine and Sam's Club.
A47: Volume in those doors moves on chain decisions and warehouse display buys negotiated above the rep. A per-case incentive paid to 28 reps is not the lever that produced it.
...

Sheet Assumptions
A1: Assumptions, constants and open items
A2: Blue = typed in. Every other tab is formulas off these cells and the Data tabs.
A4: PROGRAM COST
A5: Tier payouts earned | B5: ='Payout vs Performance'!C33 | C5: Summer_of_Success_Recap_vF.xlsx → Rep Totals
A6: Amplify payouts earned | B6: ='Payout vs Performance'!D33 | C6: Summer_of_Success_Recap_vF.xlsx → Rep Totals
A7: Total payout | B7: =SUM(B5:B6)
A8: Reps earning > $0 / reps in the program | B8: =COUNTIF('Payout vs Performance'!$E$5:$E$32,">0")&" of "&28
A10: PERIODS AND DATA
A11: Pre-program baseline | B11: Jan 1 – May 31, 2026 vs 2025
A12: Program period | B12: Jun 1 – Aug 31, 2026 vs 2025
A13: Control | B13: Jun 1 – Aug 31, brands NOT in Summer of Success
A14: Grain of the source exports | B14: rep × supplier × brand × ACCOUNT × county
A15: Accounts / counties in the program | B15: 2,016 / 9
A16: Payout model | B16: Summer_of_Success_Recap_vF.xlsx (final)
A18: PAYOUT MODEL RULES (from the vF recap)
A19: Qualifier — a rep clears a supplier at 100% of their own personal goal; the tier is then read off the route-volume grid. Tier payouts: T1 $750 · T2 $500 · T3 $250.
A20: Amplify — pays only on cases ABOVE each brand's goal, per brand, at $1/case ($2 for Fever Tree, Mike's Harder, MXD). 90%–99.99% of the qualifier goal earns half rate and no tier; below 90% earns nothing.
A21: Excluded to match the dashboard and the recap: Default, Office Tell Sell, Chris Politano.
A23: ⚠ OPEN ITEMS — these move the cost side, not the lift finding
A24: a) FUNDING — no Summer of Success line appears in supplier-budget/expenses.csv. If the suppliers billback the payout, Kohler's cost is near zero and the finding becomes opportunity cost rather than spend. This is the one open item worth resolving before the meeting.
A25: b) TIER BASIS — the deck writes thresholds as "+25,000 CE's". If "+" means GROWTH over 2025 rather than total 2026 CE, almost no one clears Tier 1 and the tier line largely disappears.
A26: c) PER REP vs HOUSE — summer26/README.txt describes the same grid as a company-wide aggregate; the recap applies it per rep, as instructed.
A27: d) The control set is "brands not in SoS," so it contains non-incented brands from the SAME suppliers and the SAME accounts. That is what makes the within-supplier and within-account tests possible.
A28: e) STILL MISSING — a Jan–May pull of the control set (completes a formal difference-in-differences) and September actuals (tests for pull-forward).
A29: f) The account-level exports total about 0.02% more cases than the brand-level exports for the same window — rounding in RDE's aggregation. It moves nothing in this analysis.

Sheet Acceleration Test
A1: Test 1 — did growth accelerate once the program started?
A2: If the incentive worked, Jun–Aug growth should exceed the Jan–May rate the same brands were already running.
B4: Jan–May 2025 | C4: Jan–May 2026 | D4: Jan–May % | E4: Jun–Aug 2025 | F4: Jun–Aug 2026 | G4: Jun–Aug % | H4: Swing
A5: CASE EQUIVALENTS
A6: Qualifier brands | B6: =SUMIFS('Program Brands'!$J$6:$J$37,'Program Brands'!$A$6:$A$37,"Qualifier") | C6: =SUMIFS('Program Brands'!$K$6:$K$37,'Program Brands'!$A$6:$A$37,"Qualifier") | D6: =IFERROR(C6/B6-1,"") | E6: =SUMIFS('Program Brands'!$D$6:$D$37,'Program Brands'!$A$6:$A$37,"Qualifier") | F6: =SUMIFS('Program Brands'!$E$6:$E$37,'Program Brands'!$A$6:$A$37,"Qualifier") | G6: =IFERROR(F6/E6-1,"") | H6: =IFERROR(G6-D6,"")
A7: Amplify brands | B7: =SUMIFS('Program Brands'!$J$6:$J$37,'Program Brands'!$A$6:$A$37,"Amplify") | C7: =SUMIFS('Program Brands'!$K$6:$K$37,'Program Brands'!$A$6:$A$37,"Amplify") | D7: =IFERROR(C7/B7-1,"") | E7: =SUMIFS('Program Brands'!$D$6:$D$37,'Program Brands'!$A$6:$A$37,"Amplify") | F7: =SUMIFS('Program Brands'!$E$6:$E$37,'Program Brands'!$A$6:$A$37,"Amplify") | G7: =IFERROR(F7/E7-1,"") | H7: =IFERROR(G7-D7,"")
A8: All program brands | B8: =SUM(B6:B7) | C8: =SUM(C6:C7) | D8: =IFERROR(C8/B8-1,"") | E8: =SUM(E6:E7) | F8: =SUM(F6:F7) | G8: =IFERROR(F8/E8-1,"") | H8: =IFERROR(G8-D8,"")
A10: GROSS PROFIT
A11: Qualifier brands | B11: =SUMIFS('Program Brands'!$L$6:$L$37,'Program Brands'!$A$6:$A$37,"Qualifier") | C11: =SUMIFS('Program Brands'!$M$6:$M$37,'Program Brands'!$A$6:$A$37,"Qualifier") | D11: =IFERROR(C11/B11-1,"") | E11: =SUMIFS('Program Brands'!$H$6:$H$37,'Program Brands'!$A$6:$A$37,"Qualifier") | F11: =SUMIFS('Program Brands'!$I$6:$I$37,'Program Brands'!$A$6:$A$37,"Qualifier") | G11: =IFERROR(F11/E11-1,"") | H11: =IFERROR(G11-D11,"")
A12: Amplify brands | B12: =SUMIFS('Program Brands'!$L$6:$L$37,'Program Brands'!$A$6:$A$37,"Amplify") | C12: =SUMIFS('Program Brands'!$M$6:$M$37,'Program Brands'!$A$6:$A$37,"Amplify") | D12: =IFERROR(C12/B12-1,"") | E12: =SUMIFS('Program Brands'!$H$6:$H$37,'Program Brands'!$A$6:$A$37,"Amplify") | F12: =SUMIFS('Program Brands'!$I$6:$I$37,'Program Brands'!$A$6:$A$37,"Amplify") | G12: =IFERROR(F12/E12-1,"") | H12: =IFERROR(G12-D12,"")
A13: All program brands | B13: =SUM(B11:B12) | C13: =SUM(C11:C12) | D13: =IFERROR(C13/B13-1,"") | E13: =SUM(E11:E12) | F13: =SUM(F11:F12) | G13: =IFERROR(F13/E13-1,"") | H13: =IFERROR(G13-D13,"")
A15: HOW TO READ THIS
A16: The Swing column is the test: Jun–Aug growth rate minus Jan–May growth rate. A positive swing is the signature of an incentive that changed behaviour.
A17: Amplify entered the summer already growing double digits and did not speed up. Qualifier volume slowed by nearly three points.
A18: Jan–May and Jun–Aug are different seasons, so each period is measured against its OWN prior year — that removes seasonality from the rates being compared. What it cannot remove is a change in the market between the two windows; the control tabs handle that.

Sheet Counterfactual
A1: Test 2 — measured lift against the pre-program trajectory
A2: Applies each segment's Jan–May growth rate to its Jun–Aug 2025 base. The gap to what actually happened is the lift the program can claim.
B4: Jan–May run rate | C4: Jun–Aug 2025 base | D4: Expected Jun–Aug | E4: Actual Jun–Aug | F4: Lift vs trend
A5: CASE EQUIVALENTS
A6: Qualifier brands | B6: ='Acceleration Test'!D6 | C6: ='Acceleration Test'!E6 | D6: =C6*(1+B6) | E6: ='Acceleration Test'!F6 | F6: =E6-D6
A7: Amplify brands | B7: ='Acceleration Test'!D7 | C7: ='Acceleration Test'!E7 | D7: =C7*(1+B7) | E7: ='Acceleration Test'!F7 | F7: =E7-D7
A8: TOTAL | C8: =SUM(C6:C7) | D8: =SUM(D6:D7) | E8: =SUM(E6:E7) | F8: =SUM(F6:F7)
A10: GROSS PROFIT
A11: Qualifier brands | B11: ='Acceleration Test'!D11 | C11: ='Acceleration Test'!E11 | D11: =C11*(1+B11) | E11: ='Acceleration Test'!F11 | F11: =E11-D11
A12: Amplify brands | B12: ='Acceleration Test'!D12 | C12: ='Acceleration Test'!E12 | D12: =C12*(1+B12) | E12: ='Acceleration Test'!F12 | F12: =E12-D12
A13: TOTAL | C13: =SUM(C11:C12) | D13: =SUM(D11:D12) | E13: =SUM(E11:E12) | F13: =SUM(F11:F12)
A15: THE BOTTOM LINE
A16: Gross profit lift vs pre-program trend | B16: =F13
A17: Case lift vs pre-program trend | B17: =F8
A18: Amplify GP lift alone (what the per-case payout targets) | B18: =F12
A19: Total payout | B19: =Assumptions!$B$7
A20: Net of payout | B20: =F13-Assumptions!$B$7
A21: Return per payout dollar | B21: =IFERROR(F13/Assumptions!$B$7,"")
A23: Read the Amplify line first: it is the segment the per-case payout actually targets, and it landed within a rounding error of the trajectory it was already on.
A24: The Qualifier GP line reads positive, but the GP Bridge and control tabs show why that is not program lift — it is a house-wide margin expansion the non-incented book captured far more of, per case.
A25: A trend extrapolation assumes the Jan–May trajectory would have continued. The control tabs test that assumption directly, and agree.

Sheet Control by Supplier
A1: Test 3 — incented brands vs the SAME supplier's non-incented brands
A2: Jun–Aug, same reps, same window, same pricing environment. The only difference between the two halves is whether a payout was attached.
A4: Supplier | B4: Incented CE 2025 | C4: Incented CE 2026 | D4: Incented % | E4: Not incented CE 2025 | F4: Not incented CE 2026 | G4: Not incented % | H4: Gap (pts) | I4: Incented GP Δ | J4: Not incented GP Δ
A5: Bell's | B5: =SUMIFS('Program Brands'!$D$6:$D$37,'Program Brands'!$B$6:$B$37,$A5) | C5: =SUMIFS('Program Brands'!$E$6:$E$37,'Program Brands'!$B$6:$B$37,$A5) | D5: =IFERROR(C5/B5-1,"") | E5: =SUMIFS('Control Brands'!$C$5:$C$296,'Control Brands'!$A$5:$A$296,$A5) | F5: =SUMIFS('Control Brands'!$D$5:$D$296,'Control Brands'!$A$5:$A$296,$A5) | G5: =IFERROR(F5/E5-1,"") | H5: =IFERROR(D5-G5,"") | I5: =SUMIFS('Program Brands'!$I$6:$I$37,'Program Brands'!$B$6:$B$37,$A5)-SUMIFS('Program Brands'!$H$6:$H$37,'Program Brands'!$B$6:$B$37,$A5) | J5: =SUMIFS('Control Brands'!$H$5:$H$296,'Control Brands'!$A$5:$A$296,$A5)-SUMIFS('Control Brands'!$G$5:$G$296,'Control Brands'!$A$5:$A$296,$A5)
A6: Boston Beer Company | B6: =SUMIFS('Program Brands'!$D$6:$D$37,'Program Brands'!$B$6:$B$37,$A6) | C6: =SUMIFS('Program Brands'!$E$6:$E$37,'Program Brands'!$B$6:$B$37,$A6) | D6: =IFERROR(C6/B6-1,"") | E6: =SUMIFS('Control Brands'!$C$5:$C$296,'Control Brands'!$A$5:$A$296,$A6) | F6: =SUMIFS('Control Brands'!$D$5:$D$296,'Control Brands'!$A$5:$A$296,$A6) | G6: =IFERROR(F6/E6-1,"") | H6: =IFERROR(D6-G6,"") | I6: =SUMIFS('Program Brands'!$I$6:$I$37,'Program Brands'!$B$6:$B$37,$A6)-SUMIFS('Program Brands'!$H$6:$H$37,'Program Brands'!$B$6:$B$37,$A6) | J6: =SUMIFS('Control Brands'!$H$5:$H$296,'Control Brands'!$A$5:$A$296,$A6)-SUMIFS('Control Brands'!$G$5:$G$296,'Control Brands'!$A$5:$A$296,$A6)
A7: Constellation Brands | B7: =SUMIFS('Program Brands'!$D$6:$D$37,'Program Brands'!$B$6:$B$37,$A7) | C7: =SUMIFS('Program Brands'!$E$6:$E$37,'Program Brands'!$B$6:$B$37,$A7) | D7: =IFERROR(C7/B7-1,"") | E7: =SUMIFS('Control Brands'!$C$5:$C$296,'Control Brands'!$A$5:$A$296,$A7) | F7: =SUMIFS('Control Brands'!$D$5:$D$296,'Control Brands'!$A$5:$A$296,$A7) | G7: =IFERROR(F7/E7-1,"") | H7: =IFERROR(D7-G7,"") | I7: =SUMIFS('Program Brands'!$I$6:$I$37,'Program Brands'!$B$6:$B$37,$A7)-SUMIFS('Program Brands'!$H$6:$H$37,'Program Brands'!$B$6:$B$37,$A7) | J7: =SUMIFS('Control Brands'!$H$5:$H$296,'Control Brands'!$A$5:$A$296,$A7)-SUMIFS('Control Brands'!$G$5:$G$296,'Control Brands'!$A$5:$A$296,$A7)
A8: DG Yuengling Inc | B8: =SUMIFS('Program Brands'!$D$6:$D$37,'Program Brands'!$B$6:$B$37,$A8) | C8: =SUMIFS('Program Brands'!$E$6:$E$37,'Program Brands'!$B$6:$B$37,$A8) | D8: =IFERROR(C8/B8-1,"") | E8: =SUMIFS('Control Brands'!$C$5:$C$296,'Control Brands'!$A$5:$A$296,$A8) | F8: =SUMIFS('Control Brands'!$D$5:$D$296,'Control Brands'!$A$5:$A$296,$A8) | G8: =IFERROR(F8/E8-1,"") | H8: =IFERROR(D8-G8,"") | I8: =SUMIFS('Program Brands'!$I$6:$I$37,'Program Brands'!$B$6:$B$37,$A8)-SUMIFS('Program Brands'!$H$6:$H$37,'Program Brands'!$B$6:$B$37,$A8) | J8: =SUMIFS('Control Brands'!$H$5:$H$296,'Control Brands'!$A$5:$A$296,$A8)-SUMIFS('Control Brands'!$G$5:$G$296,'Control Brands'!$A$5:$A$296,$A8)
A9: Heineken USA | B9: =SUMIFS('Program Brands'!$D$6:$D$37,'Program Brands'!$B$6:$B$37,$A9) | C9: =SUMIFS('Program Brands'!$E$6:$E$37,'Program Brands'!$B$6:$B$37,$A9) | D9: =IFERROR(C9/B9-1,"") | E9: =SUMIFS('Control Brands'!$C$5:$C$296,'Control Brands'!$A$5:$A$296,$A9) | F9: =SUMIFS('Control Brands'!$D$5:$D$296,'Control Brands'!$A$5:$A$296,$A9) | G9: =IFERROR(F9/E9-1,"") | H9: =IFERROR(D9-G9,"") | I9: =SUMIFS('Program Brands'!$I$6:$I$37,'Program Brands'!$B$6:$B$37,$A9)-SUMIFS('Program Brands'!$H$6:$H$37,'Program Brands'!$B$6:$B$37,$A9) | J9: =SUMIFS('Control Brands'!$H$5:$H$296,'Control Brands'!$A$5:$A$296,$A9)-SUMIFS('Control Brands'!$G$5:$G$296,'Control Brands'!$A$5:$A$296,$A9)
A10: Mark Anthony | B10: =SUMIFS('Program Brands'!$D$6:$D$37,'Program Brands'!$B$6:$B$37,$A10) | C10: =SUMIFS('Program Brands'!$E$6:$E$37,'Program Brands'!$B$6:$B$37,$A10) | D10: =IFERROR(C10/B10-1,"") | E10: =SUMIFS('Control Brands'!$C$5:$C$296,'Control Brands'!$A$5:$A$296,$A10) | F10: =SUMIFS('Control Brands'!$D$5:$D$296,'Control Brands'!$A$5:$A$296,$A10) | G10: =IFERROR(F10/E10-1,"") | H10: =IFERROR(D10-G10,"") | I10: =SUMIFS('Program Brands'!$I$6:$I$37,'Program Brands'!$B$6:$B$37,$A10)-SUMIFS('Program Brands'!$H$6:$H$37,'Program Brands'!$B$6:$B$37,$A10) | J10: =SUMIFS('Control Brands'!$H$5:$H$296,'Control Brands'!$A$5:$A$296,$A10)-SUMIFS('Control Brands'!$G$5:$G$296,'Control Brands'!$A$5:$A$296,$A10)
A11: MolsonCoors Beverage Company | B11: =SUMIFS('Program Brands'!$D$6:$D$37,'Program Brands'!$B$6:$B$37,$A11) | C11: =SUMIFS('Program Brands'!$E$6:$E$37,'Program Brands'!$B$6:$B$37,$A11) | D11: =IFERROR(C11/B11-1,"") | E11: =SUMIFS('Control Brands'!$C$5:$C$296,'Control Brands'!$A$5:$A$296,$A11) | F11: =SUMIFS('Control Brands'!$D$5:$D$296,'Control Brands'!$A$5:$A$296,$A11) | G11: =IFERROR(F11/E11-1,"") | H11: =IFERROR(D11-G11,"") | I11: =SUMIFS('Program Brands'!$I$6:$I$37,'Program Brands'!$B$6:$B$37,$A11)-SUMIFS('Program Brands'!$H$6:$H$37,'Program Brands'!$B$6:$B$37,$A11) | J11: =SUMIFS('Control Brands'!$H$5:$H$296,'Control Brands'!$A$5:$A$296,$A11)-SUMIFS('Control Brands'!$G$5:$G$296,'Control Brands'!$A$5:$A$296,$A11)
A12: New Belgium Brewing Company | B12: =SUMIFS('Program Brands'!$D$6:$D$37,'Program Brands'!$B$6:$B$37,$A12) | C12: =SUMIFS('Program Brands'!$E$6:$E$37,'Program Brands'!$B$6:$B$37,$A12) | D12: =IFERROR(C12/B12-1,"") | E12: =SUMIFS('Control Brands'!$C$5:$C$296,'Control Brands'!$A$5:$A$296,$A12) | F12: =SUMIFS('Control Brands'!$D$5:$D$296,'Control Brands'!$A$5:$A$296,$A12) | G12: =IFERROR(F12/E12-1,"") | H12: =IFERROR(D12-G12,"") | I12: =SUMIFS('Program Brands'!$I$6:$I$37,'Program Brands'!$B$6:$B$37,$A12)-SUMIFS('Program Brands'!$H$6:$H$37,'Program Brands'!$B$6:$B$37,$A12) | J12: =SUMIFS('Control Brands'!$H$5:$H$296,'Control Brands'!$A$5:$A$296,$A12)-SUMIFS('Control Brands'!$G$5:$G$296,'Control Brands'!$A$5:$A$296,$A12)
A13: WEIGHTED TOTAL | B13: =SUM(B5:B12) | C13: =SUM(C5:C12) | D13: =IFERROR(C13/B13-1,"") | E13: =SUM(E5:E12) | F13: =SUM(F5:F12) | G13: =IFERROR(F13/E13-1,"") | H13: =IFERROR(D13-G13,"") | I13: =SUM(I5:I12) | J13: =SUM(J5:J12)
A15: Only suppliers appearing on both sides are shown — those are the ones where a true within-supplier comparison exists.
A16: A negative gap means that supplier's incented brands did worse than its own non-incented brands over the same three months.
A17: Boston Beer is the finding worth presenting — see the Brand Selection tab.

Sheet Within-Account Control
A1: The tightest control available — same account, same summer, same buyer
A2: Restricted to accounts that bought BOTH incented and non-incented brands. Account mix, rep, channel and geography are all held constant; the only difference is the incentive.
B4: CE 2025 | C4: CE 2026 | D4: Change
A5: Accounts buying on both sides | B5: =COUNTIFS('Data - Accounts'!$E$5:$E$2358,">0",'Data - Accounts'!$I$5:$I$2358,">0")
A7: INCENTED brands in those accounts | B7: =SUMIFS('Data - Accounts'!$E$5:$E$2358,'Data - Accounts'!$E$5:$E$2358,">0",'Data - Accounts'!$I$5:$I$2358,">0") | C7: =SUMIFS('Data - Accounts'!$F$5:$F$2358,'Data - Accounts'!$E$5:$E$2358,">0",'Data - Accounts'!$I$5:$I$2358,">0") | D7: =IFERROR(C7/B7-1,"")
A8: NON-incented brands in the SAME accounts | B8: =SUMIFS('Data - Accounts'!$I$5:$I$2358,'Data - Accounts'!$E$5:$E$2358,">0",'Data - Accounts'!$I$5:$I$2358,">0") | C8: =SUMIFS('Data - Accounts'!$J$5:$J$2358,'Data - Accounts'!$E$5:$E$2358,">0",'Data - Accounts'!$I$5:$I$2358,">0") | D8: =IFERROR(C8/B8-1,"")
A9: Gap | D9: =D7-D8
A11: WHY THIS MATTERS MOST
A12: Every other control in this workbook can be answered with "but those were different accounts." This one cannot. Inside the same 1,704 stores, over the same three months, the brands carrying an incentive performed no better than the brands carrying none.
A13: It is also the fairest test to the sales team: it holds constant everything a rep does not control — which accounts they have, what channel, what geography — and still finds no incentive effect.

Sheet Distribution
A1: Did the program build distribution, or just move cases?
A2: A POD is one account × brand that bought. ΔCE splits into a distribution effect (more or fewer PODs) and a rate-of-sale effect (each POD buying more or less).
B4: PODs 2025 | C4: PODs 2026 | D4: POD % | E4: New PODs | F4: CE from new | G4: Lost PODs | H4: CE from lost | I4: Cases/POD 25 | J4: Cases/POD 26 | K4: Rate % | L4: Distribution effect | M4: Rate-of-sale effect | O4: CE 2025 | P4: CE 2026
A5: JUN–AUG — the program period
A6: Qualifier brands | B6: =SUMIFS('Data - Season'!$K$5:$K$743,'Data - Season'!$B$5:$B$743,"Qualifier") | C6: =SUMIFS('Data - Season'!$L$5:$L$743,'Data - Season'!$B$5:$B$743,"Qualifier") | D6: =IFERROR(C6/B6-1,"") | E6: =SUMIFS('Data - Season'!$M$5:$M$743,'Data - Season'!$B$5:$B$743,"Qualifier") | F6: =SUMIFS('Data - Season'!$N$5:$N$743,'Data - Season'!$B$5:$B$743,"Qualifier") | G6: =SUMIFS('Data - Season'!$O$5:$O$743,'Data - Season'!$B$5:$B$743,"Qualifier") | H6: =SUMIFS('Data - Season'!$P$5:$P$743,'Data - Season'!$B$5:$B$743,"Qualifier") | I6: =IFERROR(O6/B6,"") | J6: =IFERROR(P6/C6,"") | K6: =IFERROR(J6/I6-1,"") | L6: =(C6-B6)*I6 | M6: =C6*(J6-I6) | O6: =SUMIFS('Data - Season'!$E$5:$E$743,'Data - Season'!$B$5:$B$743,"Qualifier") | P6: =SUMIFS('Data - Season'!$F$5:$F$743,'Data - Season'!$B$5:$B$743,"Qualifier")
A7: Amplify brands | B7: =SUMIFS('Data - Season'!$K$5:$K$743,'Data - Season'!$B$5:$B$743,"Amplify") | C7: =SUMIFS('Data - Season'!$L$5:$L$743,'Data - Season'!$B$5:$B$743,"Amplify") | D7: =IFERROR(C7/B7-1,"") | E7: =SUMIFS('Data - Season'!$M$5:$M$743,'Data - Season'!$B$5:$B$743,"Amplify") | F7: =SUMIFS('Data - Season'!$N$5:$N$743,'Data - Season'!$B$5:$B$743,"Amplify") | G7: =SUMIFS('Data - Season'!$O$5:$O$743,'Data - Season'!$B$5:$B$743,"Amplify") | H7: =SUMIFS('Data - Season'!$P$5:$P$743,'Data - Season'!$B$5:$B$743,"Amplify") | I7: =IFERROR(O7/B7,"") | J7: =IFERROR(P7/C7,"") | K7: =IFERROR(J7/I7-1,"") | L7: =(C7-B7)*I7 | M7: =C7*(J7-I7) | O7: =SUMIFS('Data - Season'!$E$5:$E$743,'Data - Season'!$B$5:$B$743,"Amplify") | P7: =SUMIFS('Data - Season'!$F$5:$F$743,'Data - Season'!$B$5:$B$743,"Amplify")
A8: Non-program brands (control) | B8: =SUM('Data - Control'!$I$5:$I$296) | C8: =SUM('Data - Control'!$J$5:$J$296) | D8: =IFERROR(C8/B8-1,"") | E8: =SUM('Data - Control'!$K$5:$K$296) | F8: =SUM('Data - Control'!$L$5:$L$296) | G8: =SUM('Data - Control'!$M$5:$M$296) | H8: =SUM('Data - Control'!$N$5:$N$296) | I8: =IFERROR(O8/B8,"") | J8: =IFERROR(P8/C8,"") | K8: =IFERROR(J8/I8-1,"") | L8: =(C8-B8)*I8 | M8: =C8*(J8-I8) | O8: =SUM('Data - Control'!$C$5:$C$296) | P8: =SUM('Data - Control'!$D$5:$D$296)
A10: JAN–MAY — the same brands, before the program
A11: Qualifier brands | B11: =SUMIFS('Data - Pre'!$J$5:$J$36,'Data - Pre'!$A$5:$A$36,"Qualifier") | C11: =SUMIFS('Data - Pre'!$K$5:$K$36,'Data - Pre'!$A$5:$A$36,"Qualifier") | D11: =IFERROR(C11/B11-1,"") | E11: =SUMIFS('Data - Pre'!$L$5:$L$36,'Data - Pre'!$A$5:$A$36,"Qualifier") | F11: =SUMIFS('Data - Pre'!$M$5:$M$36,'Data - Pre'!$A$5:$A$36,"Qualifier") | G11: =SUMIFS('Data - Pre'!$N$5:$N$36,'Data - Pre'!$A$5:$A$36,"Qualifier") | H11: =SUMIFS('Data - Pre'!$O$5:$O$36,'Data - Pre'!$A$5:$A$36,"Qualifier") | I11: =IFERROR(O11/B11,"") | J11: =IFERROR(P11/C11,"") | K11: =IFERROR(J11/I11-1,"") | L11: =(C11-B11)*I11 | M11: =C11*(J11-I11) | O11: =SUMIFS('Data - Pre'!$D$5:$D$36,'Data - Pre'!$A$5:$A$36,"Qualifier") | P11: =SUMIFS('Data - Pre'!$E$5:$E$36,'Data - Pre'!$A$5:$A$36,"Qualifier")
A12: Amplify brands | B12: =SUMIFS('Data - Pre'!$J$5:$J$36,'Data - Pre'!$A$5:$A$36,"Amplify") | C12: =SUMIFS('Data - Pre'!$K$5:$K$36,'Data - Pre'!$A$5:$A$36,"Amplify") | D12: =IFERROR(C12/B12-1,"") | E12: =SUMIFS('Data - Pre'!$L$5:$L$36,'Data - Pre'!$A$5:$A$36,"Amplify") | F12: =SUMIFS('Data - Pre'!$M$5:$M$36,'Data - Pre'!$A$5:$A$36,"Amplify") | G12: =SUMIFS('Data - Pre'!$N$5:$N$36,'Data - Pre'!$A$5:$A$36,"Amplify") | H12: =SUMIFS('Data - Pre'!$O$5:$O$36,'Data - Pre'!$A$5:$A$36,"Amplify") | I12: =IFERROR(O12/B12,"") | J12: =IFERROR(P12/C12,"") | K12: =IFERROR(J12/I12-1,"") | L12: =(C12-B12)*I12 | M12: =C12*(J12-I12) | O12: =SUMIFS('Data - Pre'!$D$5:$D$36,'Data - Pre'!$A$5:$A$36,"Amplify") | P12: =SUMIFS('Data - Pre'!$E$5:$E$36,'Data - Pre'!$A$5:$A$36,"Amplify")
A14: WHAT THIS SETTLES
A15: Amplify PODs grew 4.2% during the program — but 5.5% in the five months BEFORE it. Distribution growth decelerated, exactly like volume did.
A16: The qualifier decline was NOT lost distribution. PODs fell only 1.2%, the same as the control; what collapsed was rate of sale, from -0.9% pre-program to -4.1% during. Reps held their accounts; the accounts bought less. That is a market result, not an effort one.
A17: Distribution effect = (PODs 2026 − PODs 2025) × cases per POD in 2025. Rate-of-sale effect = PODs 2026 × the change in cases per POD. The two sum to ΔCE.

Sheet Account Concentration
A1: How many accounts actually produced the gain?
A2: AMPLIFY volume only — that is the segment with a positive net change, and the only one where "share of the gain" means anything. Accounts ranked by amplify case gain.
A4: Rank | B4: Account | C4: County | D4: Channel | E4: Rep | F4: Amplify CE 2025 | G4: Amplify CE 2026 | H4: Δ cases | I4: Cumulative Δ | J4: Share of net amplify gain
A5: 1 | B5: ='Data - Accounts'!A5 | C5: ='Data - Accounts'!B5 | D5: ='Data - Accounts'!D5 | E5: ='Data - Accounts'!C5 | F5: ='Data - Accounts'!K5 | G5: ='Data - Accounts'!L5 | H5: =G5-F5 | I5: =SUM($H$5:$H5) | J5: =IFERROR($I5/$B$67,"")
A6: 2 | B6: ='Data - Accounts'!A6 | C6: ='Data - Accounts'!B6 | D6: ='Data - Accounts'!D6 | E6: ='Data - Accounts'!C6 | F6: ='Data - Accounts'!K6 | G6: ='Data - Accounts'!L6 | H6: =G6-F6 | I6: =SUM($H$5:$H6) | J6: =IFERROR($I6/$B$67,"")
A7: 3 | B7: ='Data - Accounts'!A7 | C7: ='Data - Accounts'!B7 | D7: ='Data - Accounts'!D7 | E7: ='Data - Accounts'!C7 | F7: ='Data - Accounts'!K7 | G7: ='Data - Accounts'!L7 | H7: =G7-F7 | I7: =SUM($H$5:$H7) | J7: =IFERROR($I7/$B$67,"")
A8: 4 | B8: ='Data - Accounts'!A8 | C8: ='Data - Accounts'!B8 | D8: ='Data - Accounts'!D8 | E8: ='Data - Accounts'!C8 | F8: ='Data - Accounts'!K8 | G8: ='Data - Accounts'!L8 | H8: =G8-F8 | I8: =SUM($H$5:$H8) | J8: =IFERROR($I8/$B$67,"")
A9: 5 | B9: ='Data - Accounts'!A9 | C9: ='Data - Accounts'!B9 | D9: ='Data - Accounts'!D9 | E9: ='Data - Accounts'!C9 | F9: ='Data - Accounts'!K9 | G9: ='Data - Accounts'!L9 | H9: =G9-F9 | I9: =SUM($H$5:$H9) | J9: =IFERROR($I9/$B$67,"")
A10: 6 | B10: ='Data - Accounts'!A10 | C10: ='Data - Accounts'!B10 | D10: ='Data - Accounts'!D10 | E10: ='Data - Accounts'!C10 | F10: ='Data - Accounts'!K10 | G10: ='Data - Accounts'!L10 | H10: =G10-F10 | I10: =SUM($H$5:$H10) | J10: =IFERROR($I10/$B$67,"")
A11: 7 | B11: ='Data - Accounts'!A11 | C11: ='Data - Accounts'!B11 | D11: ='Data - Accounts'!D11 | E11: ='Data - Accounts'!C11 | F11: ='Data - Accounts'!K11 | G11: ='Data - Accounts'!L11 | H11: =G11-F11 | I11: =SUM($H$5:$H11) | J11: =IFERROR($I11/$B$67,"")
A12: 8 | B12: ='Data - Accounts'!A12 | C12: ='Data - Accounts'!B12 | D12: ='Data - Accounts'!D12 | E12: ='Data - Accounts'!C12 | F12: ='Data - Accounts'!K12 | G12: ='Data - Accounts'!L12 | H12: =G12-F12 | I12: =SUM($H$5:$H12) | J12: =IFERROR($I12/$B$67,"")
A13: 9 | B13: ='Data - Accounts'!A13 | C13: ='Data - Accounts'!B13 | D13: ='Data - Accounts'!D13 | E13: ='Data - Accounts'!C13 | F13: ='Data - Accounts'!K13 | G13: ='Data - Accounts'!L13 | H13: =G13-F13 | I13: =SUM($H$5:$H13) | J13: =IFERROR($I13/$B$67,"")
A14: 10 | B14: ='Data - Accounts'!A14 | C14: ='Data - Accounts'!B14 | D14: ='Data - Accounts'!D14 | E14: ='Data - Accounts'!C14 | F14: ='Data - Accounts'!K14 | G14: ='Data - Accounts'!L14 | H14: =G14-F14 | I14: =SUM($H$5:$H14) | J14: =IFERROR($I14/$B$67,"")
A15: 11 | B15: ='Data - Accounts'!A15 | C15: ='Data - Accounts'!B15 | D15: ='Data - Accounts'!D15 | E15: ='Data - Accounts'!C15 | F15: ='Data - Accounts'!K15 | G15: ='Data - Accounts'!L15 | H15: =G15-F15 | I15: =SUM($H$5:$H15) | J15: =IFERROR($I15/$B$67,"")
A16: 12 | B16: ='Data - Accounts'!A16 | C16: ='Data - Accounts'!B16 | D16: ='Data - Accounts'!D16 | E16: ='Data - Accounts'!C16 | F16: ='Data - Accounts'!K16 | G16: ='Data - Accounts'!L16 | H16: =G16-F16 | I16: =SUM($H$5:$H16) | J16: =IFERROR($I16/$B$67,"")
... A64: 60 | B64: ='Data - Accounts'!A64 | C64: ='Data - Accounts'!B64 | D64: ='Data - Accounts'!D64 | E64: ='Data - Accounts'!C64 | F64: ='Data - Accounts'!K64 | G64: ='Data - Accounts'!L64 | H64: =G64-F64 | I64: =SUM($H$5:$H64) | J64: =IFERROR($I64/$B$67,"")
A66: Net AMPLIFY case gain, all accounts
A67: Net amplify case gain, all accounts | B67: =SUM('Data - Accounts'!$L$5:$L$2358)-SUM('Data - Accounts'!$K$5:$K$2358)
A68: Accounts buying amplify brands | B68: =COUNTIF('Data - Accounts'!$L$5:$L$2358,">0")+COUNTIFS('Data - Accounts'!$L$5:$L$2358,0,'Data - Accounts'!$K$5:$K$2358,">0")
A69: of those, accounts that grew | B69: =COUNTIF('Data - Accounts'!$N$5:$N$2358,">0")
A70: accounts that declined | B70: =COUNTIF('Data - Accounts'!$N$5:$N$2358,"<0")
A71: Top 10 accounts — share of the net amplify gain | B71: =IFERROR(SUM($H$5:$H$14)/$B$67,"")
A72: Top 25 accounts — share of the net amplify gain | B72: =IFERROR(SUM($H$5:$H$29)/$B$67,"")
A73: Top 50 accounts — share of the net amplify gain | B73: =IFERROR(SUM($H$5:$H$54)/$B$67,"")
A74: For contrast — net PROGRAM case change, all accounts | B74: =SUM('Data - Accounts'!$F$5:$F$2358)-SUM('Data - Accounts'!$E$5:$E$2358)
A76: WHAT THIS MEANS
A77: The gain is not broad execution across a route. A handful of large-format accounts — BJ's, Super Wine Warehouse, Beverage Barn, Total Wine, Sam's Club — carry most of it.
A78: Volume in those doors moves on chain decisions and warehouse display buys negotiated above the rep. A per-case incentive paid to 28 reps is not the lever that produced it, and would not reliably reproduce it.
A79: This is also why the program looked better at brand level than it does here: brand totals hide the fact that the growth came from very few doors.
A80: The last line is the reminder that the program as a whole LOST cases. Concentration is measured on amplify because that is the only segment with a gain to concentrate.

Sheet Channel
A1: On-premise vs off-premise — the one place the program shows a pulse
A2: Same acceleration test as Test 1, cut by channel, with each channel's own non-incented brands as the control.
A4: Channel | B4: Segment | C4: Jan–May % | D4: Jun–Aug % | E4: Swing | F4: Jun–Aug CE 2026 | G4: Share of program volume | H4: Control % (same channel) | I4: Gap vs control
A5: Off-premise | B5: Qualifier | C5: =IFERROR(SUMIFS('Data - Channel'!$E$5:$E$19,'Data - Channel'!$A$5:$A$19,"Off-premise",'Data - Channel'!$B$5:$B$19,"Jan–May",'Data - Channel'!$C$5:$C$19,"Qualifier")/SUMIFS('Data - Channel'!$D$5:$D$19,'Data - Channel'!$A$5:$A$19,"Off-premise",'Data - Channel'!$B$5:$B$19,"Jan–May",'Data - Channel'!$C$5:$C$19,"Qualifier")-1,"") | D5: =IFERROR(SUMIFS('Data - Channel'!$E$5:$E$19,'Data - Channel'!$A$5:$A$19,"Off-premise",'Data - Channel'!$B$5:$B$19,"Jun–Aug",'Data - Channel'!$C$5:$C$19,"Qualifier")/SUMIFS('Data - Channel'!$D$5:$D$19,'Data - Channel'!$A$5:$A$19,"Off-premise",'Data - Channel'!$B$5:$B$19,"Jun–Aug",'Data - Channel'!$C$5:$C$19,"Qualifier")-1,"") | E5: =IFERROR(D5-C5,"") | F5: =SUMIFS('Data - Channel'!$E$5:$E$19,'Data - Channel'!$A$5:$A$19,"Off-premise",'Data - Channel'!$B$5:$B$19,"Jun–Aug",'Data - Channel'!$C$5:$C$19,"Qualifier") | G5: =IFERROR(F5/SUM('Data - Accounts'!$F$5:$F$2358),"") | H5: =IFERROR(SUMIFS('Data - Channel'!$E$5:$E$19,'Data - Channel'!$A$5:$A$19,"Off-premise",'Data - Channel'!$B$5:$B$19,"Jun–Aug",'Data - Channel'!$C$5:$C$19,"Control")/SUMIFS('Data - Channel'!$D$5:$D$19,'Data - Channel'!$A$5:$A$19,"Off-premise",'Data - Channel'!$B$5:$B$19,"Jun–Aug",'Data - Channel'!$C$5:$C$19,"Control")-1,"") | I5: =IFERROR(D5-H5,"")
A6: Off-premise | B6: Amplify | C6: =IFERROR(SUMIFS('Data - Channel'!$E$5:$E$19,'Data - Channel'!$A$5:$A$19,"Off-premise",'Data - Channel'!$B$5:$B$19,"Jan–May",'Data - Channel'!$C$5:$C$19,"Amplify")/SUMIFS('Data - Channel'!$D$5:$D$19,'Data - Channel'!$A$5:$A$19,"Off-premise",'Data - Channel'!$B$5:$B$19,"Jan–May",'Data - Channel'!$C$5:$C$19,"Amplify")-1,"") | D6: =IFERROR(SUMIFS('Data - Channel'!$E$5:$E$19,'Data - Channel'!$A$5:$A$19,"Off-premise",'Data - Channel'!$B$5:$B$19,"Jun–Aug",'Data - Channel'!$C$5:$C$19,"Amplify")/SUMIFS('Data - Channel'!$D$5:$D$19,'Data - Channel'!$A$5:$A$19,"Off-premise",'Data - Channel'!$B$5:$B$19,"Jun–Aug",'Data - Channel'!$C$5:$C$19,"Amplify")-1,"") | E6: =IFERROR(D6-C6,"") | F6: =SUMIFS('Data - Channel'!$E$5:$E$19,'Data - Channel'!$A$5:$A$19,"Off-premise",'Data - Channel'!$B$5:$B$19,"Jun–Aug",'Data - Channel'!$C$5:$C$19,"Amplify") | G6: =IFERROR(F6/SUM('Data - Accounts'!$F$5:$F$2358),"") | H6: =IFERROR(SUMIFS('Data - Channel'!$E$5:$E$19,'Data - Channel'!$A$5:$A$19,"Off-premise",'Data - Channel'!$B$5:$B$19,"Jun–Aug",'Data - Channel'!$C$5:$C$19,"Control")/SUMIFS('Data - Channel'!$D$5:$D$19,'Data - Channel'!$A$5:$A$19,"Off-premise",'Data - Channel'!$B$5:$B$19,"Jun–Aug",'Data - Channel'!$C$5:$C$19,"Control")-1,"") | I6: =IFERROR(D6-H6,"")
A7: On-premise | B7: Qualifier | C7: =IFERROR(SUMIFS('Data - Channel'!$E$5:$E$19,'Data - Channel'!$A$5:$A$19,"On-premise",'Data - Channel'!$B$5:$B$19,"Jan–May",'Data - Channel'!$C$5:$C$19,"Qualifier")/SUMIFS('Data - Channel'!$D$5:$D$19,'Data - Channel'!$A$5:$A$19,"On-premise",'Data - Channel'!$B$5:$B$19,"Jan–May",'Data - Channel'!$C$5:$C$19,"Qualifier")-1,"") | D7: =IFERROR(SUMIFS('Data - Channel'!$E$5:$E$19,'Data - Channel'!$A$5:$A$19,"On-premise",'Data - Channel'!$B$5:$B$19,"Jun–Aug",'Data - Channel'!$C$5:$C$19,"Qualifier")/SUMIFS('Data - Channel'!$D$5:$D$19,'Data - Channel'!$A$5:$A$19,"On-premise",'Data - Channel'!$B$5:$B$19,"Jun–Aug",'Data - Channel'!$C$5:$C$19,"Qualifier")-1,"") | E7: =IFERROR(D7-C7,"") | F7: =SUMIFS('Data - Channel'!$E$5:$E$19,'Data - Channel'!$A$5:$A$19,"On-premise",'Data - Channel'!$B$5:$B$19,"Jun–Aug",'Data - Channel'!$C$5:$C$19,"Qualifier") | G7: =IFERROR(F7/SUM('Data - Accounts'!$F$5:$F$2358),"") | H7: =IFERROR(SUMIFS('Data - Channel'!$E$5:$E$19,'Data - Channel'!$A$5:$A$19,"On-premise",'Data - Channel'!$B$5:$B$19,"Jun–Aug",'Data - Channel'!$C$5:$C$19,"Control")/SUMIFS('Data - Channel'!$D$5:$D$19,'Data - Channel'!$A$5:$A$19,"On-premise",'Data - Channel'!$B$5:$B$19,"Jun–Aug",'Data - Channel'!$C$5:$C$19,"Control")-1,"") | I7: =IFERROR(D7-H7,"")
A8: On-premise | B8: Amplify | C8: =IFERROR(SUMIFS('Data - Channel'!$E$5:$E$19,'Data - Channel'!$A$5:$A$19,"On-premise",'Data - Channel'!$B$5:$B$19,"Jan–May",'Data - Channel'!$C$5:$C$19,"Amplify")/SUMIFS('Data - Channel'!$D$5:$D$19,'Data - Channel'!$A$5:$A$19,"On-premise",'Data - Channel'!$B$5:$B$19,"Jan–May",'Data - Channel'!$C$5:$C$19,"Amplify")-1,"") | D8: =IFERROR(SUMIFS('Data - Channel'!$E$5:$E$19,'Data - Channel'!$A$5:$A$19,"On-premise",'Data - Channel'!$B$5:$B$19,"Jun–Aug",'Data - Channel'!$C$5:$C$19,"Amplify")/SUMIFS('Data - Channel'!$D$5:$D$19,'Data - Channel'!$A$5:$A$19,"On-premise",'Data - Channel'!$B$5:$B$19,"Jun–Aug",'Data - Channel'!$C$5:$C$19,"Amplify")-1,"") | E8: =IFERROR(D8-C8,"") | F8: =SUMIFS('Data - Channel'!$E$5:$E$19,'Data - Channel'!$A$5:$A$19,"On-premise",'Data - Channel'!$B$5:$B$19,"Jun–Aug",'Data - Channel'!$C$5:$C$19,"Amplify") | G8: =IFERROR(F8/SUM('Data - Accounts'!$F$5:$F$2358),"") | H8: =IFERROR(SUMIFS('Data - Channel'!$E$5:$E$19,'Data - Channel'!$A$5:$A$19,"On-premise",'Data - Channel'!$B$5:$B$19,"Jun–Aug",'Data - Channel'!$C$5:$C$19,"Control")/SUMIFS('Data - Channel'!$D$5:$D$19,'Data - Channel'!$A$5:$A$19,"On-premise",'Data - Channel'!$B$5:$B$19,"Jun–Aug",'Data - Channel'!$C$5:$C$19,"Control")-1,"") | I8: =IFERROR(D8-H8,"")
A9: Unmatched | B9: Qualifier | C9: =IFERROR(SUMIFS('Data - Channel'!$E$5:$E$19,'Data - Channel'!$A$5:$A$19,"Unmatched",'Data - Channel'!$B$5:$B$19,"Jan–May",'Data - Channel'!$C$5:$C$19,"Qualifier")/SUMIFS('Data - Channel'!$D$5:$D$19,'Data - Channel'!$A$5:$A$19,"Unmatched",'Data - Channel'!$B$5:$B$19,"Jan–May",'Data - Channel'!$C$5:$C$19,"Qualifier")-1,"") | D9: =IFERROR(SUMIFS('Data - Channel'!$E$5:$E$19,'Data - Channel'!$A$5:$A$19,"Unmatched",'Data - Channel'!$B$5:$B$19,"Jun–Aug",'Data - Channel'!$C$5:$C$19,"Qualifier")/SUMIFS('Data - Channel'!$D$5:$D$19,'Data - Channel'!$A$5:$A$19,"Unmatched",'Data - Channel'!$B$5:$B$19,"Jun–Aug",'Data - Channel'!$C$5:$C$19,"Qualifier")-1,"") | E9: =IFERROR(D9-C9,"") | F9: =SUMIFS('Data - Channel'!$E$5:$E$19,'Data - Channel'!$A$5:$A$19,"Unmatched",'Data - Channel'!$B$5:$B$19,"Jun–Aug",'Data - Channel'!$C$5:$C$19,"Qualifier") | G9: =IFERROR(F9/SUM('Data - Accounts'!$F$5:$F$2358),"") | H9: =IFERROR(SUMIFS('Data - Channel'!$E$5:$E$19,'Data - Channel'!$A$5:$A$19,"Unmatched",'Data - Channel'!$B$5:$B$19,"Jun–Aug",'Data - Channel'!$C$5:$C$19,"Control")/SUMIFS('Data - Channel'!$D$5:$D$19,'Data - Channel'!$A$5:$A$19,"Unmatched",'Data - Channel'!$B$5:$B$19,"Jun–Aug",'Data - Channel'!$C$5:$C$19,"Control")-1,"") | I9: =IFERROR(D9-H9,"")
A10: Unmatched | B10: Amplify | C10: =IFERROR(SUMIFS('Data - Channel'!$E$5:$E$19,'Data - Channel'!$A$5:$A$19,"Unmatched",'Data - Channel'!$B$5:$B$19,"Jan–May",'Data - Channel'!$C$5:$C$19,"Amplify")/SUMIFS('Data - Channel'!$D$5:$D$19,'Data - Channel'!$A$5:$A$19,"Unmatched",'Data - Channel'!$B$5:$B$19,"Jan–May",'Data - Channel'!$C$5:$C$19,"Amplify")-1,"") | D10: =IFERROR(SUMIFS('Data - Channel'!$E$5:$E$19,'Data - Channel'!$A$5:$A$19,"Unmatched",'Data - Channel'!$B$5:$B$19,"Jun–Aug",'Data - Channel'!$C$5:$C$19,"Amplify")/SUMIFS('Data - Channel'!$D$5:$D$19,'Data - Channel'!$A$5:$A$19,"Unmatched",'Data - Channel'!$B$5:$B$19,"Jun–Aug",'Data - Channel'!$C$5:$C$19,"Amplify")-1,"") | E10: =IFERROR(D10-C10,"") | F10: =SUMIFS('Data - Channel'!$E$5:$E$19,'Data - Channel'!$A$5:$A$19,"Unmatched",'Data - Channel'!$B$5:$B$19,"Jun–Aug",'Data - Channel'!$C$5:$C$19,"Amplify") | G10: =IFERROR(F10/SUM('Data - Accounts'!$F$5:$F$2358),"") | H10: =IFERROR(SUMIFS('Data - Channel'!$E$5:$E$19,'Data - Channel'!$A$5:$A$19,"Unmatched",'Data - Channel'!$B$5:$B$19,"Jun–Aug",'Data - Channel'!$C$5:$C$19,"Control")/SUMIFS('Data - Channel'!$D$5:$D$19,'Data - Channel'!$A$5:$A$19,"Unmatched",'Data - Channel'!$B$5:$B$19,"Jun–Aug",'Data - Channel'!$C$5:$C$19,"Control")-1,"") | I10: =IFERROR(D10-H10,"")
A12: THE ONE CONSTRUCTIVE FINDING IN THIS WORKBOOK
A13: On-premise is the only cut where the program accelerated. Amplify went from +13.7% pre-program to +18.4% during it, and Qualifier from -3.6% to -0.1% — the only positive swings anywhere in this analysis.
A14: Read it with two caveats. On-premise is about 11% of program volume, so it cannot rescue the total. And even there the incented brands still trailed that channel's non-incented brands, so the acceleration is real but the lead is not.
A15: Off-premise, which is 87% of the volume and where the concentrated large-format gains sit, decelerated in both segments.
A16: This is the part worth testing deliberately in 2027: a smaller, on-premise-weighted program is the one version of this incentive the data gives any reason to believe in.

Sheet County
A1: Did the program work anywhere in particular?
A2: Program vs non-program brands by county, Jun–Aug. The control column is the same county's non-incented volume.
A4: County | B4: Program CE 2025 | C4: Program CE 2026 | D4: Program % | E4: Non-program CE 2025 | F4: Non-program CE 2026 | G4: Non-program % | H4: Gap | I4: Share of program volume
A5: Bergen | B5: =SUMIFS('Data - Accounts'!$E$5:$E$2358,'Data - Accounts'!$B$5:$B$2358,$A5) | C5: =SUMIFS('Data - Accounts'!$F$5:$F$2358,'Data - Accounts'!$B$5:$B$2358,$A5) | D5: =IFERROR(C5/B5-1,"") | E5: =SUMIFS('Data - Accounts'!$I$5:$I$2358,'Data - Accounts'!$B$5:$B$2358,$A5) | F5: =SUMIFS('Data - Accounts'!$J$5:$J$2358,'Data - Accounts'!$B$5:$B$2358,$A5) | G5: =IFERROR(F5/E5-1,"") | H5: =IFERROR(D5-G5,"") | I5: =IFERROR(C5/SUM('Data - Accounts'!$F$5:$F$2358),"")
A6: Essex | B6: =SUMIFS('Data - Accounts'!$E$5:$E$2358,'Data - Accounts'!$B$5:$B$2358,$A6) | C6: =SUMIFS('Data - Accounts'!$F$5:$F$2358,'Data - Accounts'!$B$5:$B$2358,$A6) | D6: =IFERROR(C6/B6-1,"") | E6: =SUMIFS('Data - Accounts'!$I$5:$I$2358,'Data - Accounts'!$B$5:$B$2358,$A6) | F6: =SUMIFS('Data - Accounts'!$J$5:$J$2358,'Data - Accounts'!$B$5:$B$2358,$A6) | G6: =IFERROR(F6/E6-1,"") | H6: =IFERROR(D6-G6,"") | I6: =IFERROR(C6/SUM('Data - Accounts'!$F$5:$F$2358),"")
A7: Hudson | B7: =SUMIFS('Data - Accounts'!$E$5:$E$2358,'Data - Accounts'!$B$5:$B$2358,$A7) | C7: =SUMIFS('Data - Accounts'!$F$5:$F$2358,'Data - Accounts'!$B$5:$B$2358,$A7) | D7: =IFERROR(C7/B7-1,"") | E7: =SUMIFS('Data - Accounts'!$I$5:$I$2358,'Data - Accounts'!$B$5:$B$2358,$A7) | F7: =SUMIFS('Data - Accounts'!$J$5:$J$2358,'Data - Accounts'!$B$5:$B$2358,$A7) | G7: =IFERROR(F7/E7-1,"") | H7: =IFERROR(D7-G7,"") | I7: =IFERROR(C7/SUM('Data - Accounts'!$F$5:$F$2358),"")
A8: Middlesex | B8: =SUMIFS('Data - Accounts'!$E$5:$E$2358,'Data - Accounts'!$B$5:$B$2358,$A8) | C8: =SUMIFS('Data - Accounts'!$F$5:$F$2358,'Data - Accounts'!$B$5:$B$2358,$A8) | D8: =IFERROR(C8/B8-1,"") | E8: =SUMIFS('Data - Accounts'!$I$5:$I$2358,'Data - Accounts'!$B$5:$B$2358,$A8) | F8: =SUMIFS('Data - Accounts'!$J$5:$J$2358,'Data - Accounts'!$B$5:$B$2358,$A8) | G8: =IFERROR(F8/E8-1,"") | H8: =IFERROR(D8-G8,"") | I8: =IFERROR(C8/SUM('Data - Accounts'!$F$5:$F$2358),"")
A9: Morris | B9: =SUMIFS('Data - Accounts'!$E$5:$E$2358,'Data - Accounts'!$B$5:$B$2358,$A9) | C9: =SUMIFS('Data - Accounts'!$F$5:$F$2358,'Data - Accounts'!$B$5:$B$2358,$A9) | D9: =IFERROR(C9/B9-1,"") | E9: =SUMIFS('Data - Accounts'!$I$5:$I$2358,'Data - Accounts'!$B$5:$B$2358,$A9) | F9: =SUMIFS('Data - Accounts'!$J$5:$J$2358,'Data - Accounts'!$B$5:$B$2358,$A9) | G9: =IFERROR(F9/E9-1,"") | H9: =IFERROR(D9-G9,"") | I9: =IFERROR(C9/SUM('Data - Accounts'!$F$5:$F$2358),"")
A10: Passaic | B10: =SUMIFS('Data - Accounts'!$E$5:$E$2358,'Data - Accounts'!$B$5:$B$2358,$A10) | C10: =SUMIFS('Data - Accounts'!$F$5:$F$2358,'Data - Accounts'!$B$5:$B$2358,$A10) | D10: =IFERROR(C10/B10-1,"") | E10: =SUMIFS('Data - Accounts'!$I$5:$I$2358,'Data - Accounts'!$B$5:$B$2358,$A10) | F10: =SUMIFS('Data - Accounts'!$J$5:$J$2358,'Data - Accounts'!$B$5:$B$2358,$A10) | G10: =IFERROR(F10/E10-1,"") | H10: =IFERROR(D10-G10,"") | I10: =IFERROR(C10/SUM('Data - Accounts'!$F$5:$F$2358),"")
A11: Sussex | B11: =SUMIFS('Data - Accounts'!$E$5:$E$2358,'Data - Accounts'!$B$5:$B$2358,$A11) | C11: =SUMIFS('Data - Accounts'!$F$5:$F$2358,'Data - Accounts'!$B$5:$B$2358,$A11) | D11: =IFERROR(C11/B11-1,"") | E11: =SUMIFS('Data - Accounts'!$I$5:$I$2358,'Data - Accounts'!$B$5:$B$2358,$A11) | F11: =SUMIFS('Data - Accounts'!$J$5:$J$2358,'Data - Accounts'!$B$5:$B$2358,$A11) | G11: =IFERROR(F11/E11-1,"") | H11: =IFERROR(D11-G11,"") | I11: =IFERROR(C11/SUM('Data - Accounts'!$F$5:$F$2358),"")
A12: Union | B12: =SUMIFS('Data - Accounts'!$E$5:$E$2358,'Data - Accounts'!$B$5:$B$2358,$A12) | C12: =SUMIFS('Data - Accounts'!$F$5:$F$2358,'Data - Accounts'!$B$5:$B$2358,$A12) | D12: =IFERROR(C12/B12-1,"") | E12: =SUMIFS('Data - Accounts'!$I$5:$I$2358,'Data - Accounts'!$B$5:$B$2358,$A12) | F12: =SUMIFS('Data - Accounts'!$J$5:$J$2358,'Data - Accounts'!$B$5:$B$2358,$A12) | G12: =IFERROR(F12/E12-1,"") | H12: =IFERROR(D12-G12,"") | I12: =IFERROR(C12/SUM('Data - Accounts'!$F$5:$F$2358),"")
A13: Warren | B13: =SUMIFS('Data - Accounts'!$E$5:$E$2358,'Data - Accounts'!$B$5:$B$2358,$A13) | C13: =SUMIFS('Data - Accounts'!$F$5:$F$2358,'Data - Accounts'!$B$5:$B$2358,$A13) | D13: =IFERROR(C13/B13-1,"") | E13: =SUMIFS('Data - Accounts'!$I$5:$I$2358,'Data - Accounts'!$B$5:$B$2358,$A13) | F13: =SUMIFS('Data - Accounts'!$J$5:$J$2358,'Data - Accounts'!$B$5:$B$2358,$A13) | G13: =IFERROR(F13/E13-1,"") | H13: =IFERROR(D13-G13,"") | I13: =IFERROR(C13/SUM('Data - Accounts'!$F$5:$F$2358),"")
A14: TOTAL | B14: =SUM(B5:B13) | C14: =SUM(C5:C13) | D14: =IFERROR(C14/B14-1,"") | E14: =SUM(E5:E13) | F14: =SUM(F5:F13) | G14: =IFERROR(F14/E14-1,"") | H14: =IFERROR(D14-G14,"")
A16: The four counties carrying essentially all the volume — Bergen, Passaic, Morris, Sussex — each trailed their own county's non-incented brands.
A17: Hudson, Union and Essex show big positive percentages on a base of roughly 12,000 cases between them, under 1% of the program. Read the Share column before the Gap column.

Sheet GP Bridge
A1: Where the gross profit change actually came from
A2: ΔGP split three ways: cases sold (Volume), which brands sold (Mix), and gross profit per case within a brand (Rate). Volume is the only one an incentive plausibly drives.
B4: Program brands | C4: Non-program brands (control)
A5: Cases 2025 | B5: =SUM('Program Brands'!$D$6:$D$37) | C5: =SUM('Control Brands'!$C$5:$C$296)
A6: Cases 2026 | B6: =SUM('Program Brands'!$E$6:$E$37) | C6: =SUM('Control Brands'!$D$5:$D$296)
A7: Gross profit 2025 | B7: =SUM('Program Brands'!$H$6:$H$37) | C7: =SUM('Control Brands'!$G$5:$G$296)
A8: Gross profit 2026 | B8: =SUM('Program Brands'!$I$6:$I$37) | C8: =SUM('Control Brands'!$H$5:$H$296)
A9: Actual ΔGP | B9: =B8-B7 | C9: =C8-C7
A11: DECOMPOSED
A12: Volume — cases, at last year's GP/CE | B12: =(B6-B5)*(B7/B5) | C12: =(C6-C5)*(C7/C5)
A13: Mix — which brands sold | B13: =SUM('Program Brands'!$R$6:$R$37)-B6*(B7/B5) | C13: =SUM('Control Brands'!$K$5:$K$296)-C6*(C7/C5)
A14: Rate — GP per case within a brand | B14: =SUM('Program Brands'!$S$6:$S$37) | C14: =SUM('Control Brands'!$L$5:$L$296)
A15: Sum (ties to Actual ΔGP) | B15: =SUM(B12:B14) | C15: =SUM(C12:C14)
A17: RATE EFFECT PER 2026 CASE
A18: Rate effect per case | B18: =IFERROR(B14/B6,"") | C18: =IFERROR(C14/C6,"")
A19: Control advantage per case | B19: =C18-B18
A21: The margin gain was real but house-wide. Per case, the non-incented book captured several times the rate improvement the incented book did, so the program cannot claim it.
A22: Volume is the line an incentive is supposed to move, and on the program brands it is the negative one.
A23: Control mix is large because the non-program book shifted toward higher-margin brands (Sun Cruiser, Sierra Nevada) while low-margin Pabst declined.

Sheet Brand Selection
A1: The variable that decided the outcome — which brands got incented
A2: Every brand of every supplier appearing on both sides, Jun–Aug. INCENTED rows carried a payout; NOT INCENTED rows did not.
A4: Supplier | B4: Incented? | C4: Brand Family | D4: CE 2025 | E4: CE 2026 | F4: Δ cases | G4: Cases % | H4: GP 2025 | I4: GP 2026 | J4: Δ GP | K4: PODs 2026
A5: Bell's | B5: INCENTED | C5: Bell's | D5: =SUMIFS('Program Brands'!$D$6:$D$37,'Program Brands'!$B$6:$B$37,$A5,'Program Brands'!$C$6:$C$37,$C5) | E5: =SUMIFS('Program Brands'!$E$6:$E$37,'Program Brands'!$B$6:$B$37,$A5,'Program Brands'!$C$6:$C$37,$C5) | F5: =E5-D5 | G5: =IFERROR(E5/D5-1,"") | H5: =SUMIFS('Program Brands'!$H$6:$H$37,'Program Brands'!$B$6:$B$37,$A5,'Program Brands'!$C$6:$C$37,$C5) | I5: =SUMIFS('Program Brands'!$I$6:$I$37,'Program Brands'!$B$6:$B$37,$A5,'Program Brands'!$C$6:$C$37,$C5) | J5: =I5-H5 | K5: =SUMIFS('Data - Season'!$L$5:$L$743,'Data - Season'!$C$5:$C$743,$A5,'Data - Season'!$D$5:$D$743,$C5)
A6: Bell's | B6: not incented | C6: Bell's Hearted Family | D6: =SUMIFS('Control Brands'!$C$5:$C$296,'Control Brands'!$A$5:$A$296,$A6,'Control Brands'!$B$5:$B$296,$C6) | E6: =SUMIFS('Control Brands'!$D$5:$D$296,'Control Brands'!$A$5:$A$296,$A6,'Control Brands'!$B$5:$B$296,$C6) | F6: =E6-D6 | G6: =IFERROR(E6/D6-1,"") | H6: =SUMIFS('Control Brands'!$G$5:$G$296,'Control Brands'!$A$5:$A$296,$A6,'Control Brands'!$B$5:$B$296,$C6) | I6: =SUMIFS('Control Brands'!$H$5:$H$296,'Control Brands'!$A$5:$A$296,$A6,'Control Brands'!$B$5:$B$296,$C6) | J6: =I6-H6 | K6: =SUMIFS('Data - Control'!$J$5:$J$296,'Data - Control'!$A$5:$A$296,$A6,'Data - Control'!$B$5:$B$296,$C6)
C7: Bell's — total | D7: =SUM(D5:D6) | E7: =SUM(E5:E6) | F7: =SUM(F5:F6) | H7: =SUM(H5:H6) | I7: =SUM(I5:I6) | J7: =SUM(J5:J6) | K7: =SUM(K5:K6)
A9: Boston Beer Company | B9: INCENTED | C9: Dogfish Head Beer | D9: =SUMIFS('Program Brands'!$D$6:$D$37,'Program Brands'!$B$6:$B$37,$A9,'Program Brands'!$C$6:$C$37,$C9) | E9: =SUMIFS('Program Brands'!$E$6:$E$37,'Program Brands'!$B$6:$B$37,$A9,'Program Brands'!$C$6:$C$37,$C9) | F9: =E9-D9 | G9: =IFERROR(E9/D9-1,"") | H9: =SUMIFS('Program Brands'!$H$6:$H$37,'Program Brands'!$B$6:$B$37,$A9,'Program Brands'!$C$6:$C$37,$C9) | I9: =SUMIFS('Program Brands'!$I$6:$I$37,'Program Brands'!$B$6:$B$37,$A9,'Program Brands'!$C$6:$C$37,$C9) | J9: =I9-H9 | K9: =SUMIFS('Data - Season'!$L$5:$L$743,'Data - Season'!$C$5:$C$743,$A9,'Data - Season'!$D$5:$D$743,$C9)
A10: Boston Beer Company | B10: INCENTED | C10: Dogfish Head Spirits | D10: =SUMIFS('Program Brands'!$D$6:$D$37,'Program Brands'!$B$6:$B$37,$A10,'Program Brands'!$C$6:$C$37,$C10) | E10: =SUMIFS('Program Brands'!$E$6:$E$37,'Program Brands'!$B$6:$B$37,$A10,'Program Brands'!$C$6:$C$37,$C10) | F10: =E10-D10 | G10: =IFERROR(E10/D10-1,"") | H10: =SUMIFS('Program Brands'!$H$6:$H$37,'Program Brands'!$B$6:$B$37,$A10,'Program Brands'!$C$6:$C$37,$C10) | I10: =SUMIFS('Program Brands'!$I$6:$I$37,'Program Brands'!$B$6:$B$37,$A10,'Program Brands'!$C$6:$C$37,$C10) | J10: =I10-H10 | K10: =SUMIFS('Data - Season'!$L$5:$L$743,'Data - Season'!$C$5:$C$743,$A10,'Data - Season'!$D$5:$D$743,$C10)
A11: Boston Beer Company | B11: INCENTED | C11: Truly | D11: =SUMIFS('Program Brands'!$D$6:$D$37,'Program Brands'!$B$6:$B$37,$A11,'Program Brands'!$C$6:$C$37,$C11) | E11: =SUMIFS('Program Brands'!$E$6:$E$37,'Program Brands'!$B$6:$B$37,$A11,'Program Brands'!$C$6:$C$37,$C11) | F11: =E11-D11 | G11: =IFERROR(E11/D11-1,"") | H11: =SUMIFS('Program Brands'!$H$6:$H$37,'Program Brands'!$B$6:$B$37,$A11,'Program Brands'!$C$6:$C$37,$C11) | I11: =SUMIFS('Program Brands'!$I$6:$I$37,'Program Brands'!$B$6:$B$37,$A11,'Program Brands'!$C$6:$C$37,$C11) | J11: =I11-H11 | K11: =SUMIFS('Data - Season'!$L$5:$L$743,'Data - Season'!$C$5:$C$743,$A11,'Data - Season'!$D$5:$D$743,$C11)
A12: Boston Beer Company | B12: INCENTED | C12: Twisted Tea | D12: =SUMIFS('Program Brands'!$D$6:$D$37,'Program Brands'!$B$6:$B$37,$A12,'Program Brands'!$C$6:$C$37,$C12) | E12: =SUMIFS('Program Brands'!$E$6:$E$37,'Program Brands'!$B$6:$B$37,$A12,'Program Brands'!$C$6:$C$37,$C12) | F12: =E12-D12 | G12: =IFERROR(E12/D12-1,"") | H12: =SUMIFS('Program Brands'!$H$6:$H$37,'Program Brands'!$B$6:$B$37,$A12,'Program Brands'!$C$6:$C$37,$C12) | I12: =SUMIFS('Program Brands'!$I$6:$I$37,'Program Brands'!$B$6:$B$37,$A12,'Program Brands'!$C$6:$C$37,$C12) | J12: =I12-H12 | K12: =SUMIFS('Data - Season'!$L$5:$L$743,'Data - Season'!$C$5:$C$743,$A12,'Data - Season'!$D$5:$D$743,$C12)
A13: Boston Beer Company | B13: not incented | C13: Angry Orchard | D13: =SUMIFS('Control Brands'!$C$5:$C$296,'Control Brands'!$A$5:$A$296,$A13,'Control Brands'!$B$5:$B$296,$C13) | E13: =SUMIFS('Control Brands'!$D$5:$D$296,'Control Brands'!$A$5:$A$296,$A13,'Control Brands'!$B$5:$B$296,$C13) | F13: =E13-D13 | G13: =IFERROR(E13/D13-1,"") | H13: =SUMIFS('Control Brands'!$G$5:$G$296,'Control Brands'!$A$5:$A$296,$A13,'Control Brands'!$B$5:$B$296,$C13) | I13: =SUMIFS('Control Brands'!$H$5:$H$296,'Control Brands'!$A$5:$A$296,$A13,'Control Brands'!$B$5:$B$296,$C13) | J13: =I13-H13 | K13: =SUMIFS('Data - Control'!$J$5:$J$296,'Data - Control'!$A$5:$A$296,$A13,'Data - Control'!$B$5:$B$296,$C13)
A14: Boston Beer Company | B14: not incented | C14: Coney Island | D14: =SUMIFS('Control Brands'!$C$5:$C$296,'Control Brands'!$A$5:$A$296,$A14,'Control Brands'!$B$5:$B$296,$C14) | E14: =SUMIFS('Control Brands'!$D$5:$D$296,'Control Brands'!$A$5:$A$296,$A14,'Control Brands'!$B$5:$B$296,$C14) | F14: =E14-D14 | G14: =IFERROR(E14/D14-1,"") | H14: =SUMIFS('Control Brands'!$G$5:$G$296,'Control Brands'!$A$5:$A$296,$A14,'Control Brands'!$B$5:$B$296,$C14) | I14: =SUMIFS('Control Brands'!$H$5:$H$296,'Control Brands'!$A$5:$A$296,$A14,'Control Brands'!$B$5:$B$296,$C14) | J14: =I14-H14 | K14: =SUMIFS('Data - Control'!$J$5:$J$296,'Data - Control'!$A$5:$A$296,$A14,'Data - Control'!$B$5:$B$296,$C14)
A15: Boston Beer Company | B15: not incented | C15: Hard Mountain Dew | D15: =SUMIFS('Control Brands'!$C$5:$C$296,'Control Brands'!$A$5:$A$296,$A15,'Control Brands'!$B$5:$B$296,$C15) | E15: =SUMIFS('Control Brands'!$D$5:$D$296,'Control Brands'!$A$5:$A$296,$A15,'Control Brands'!$B$5:$B$296,$C15) | F15: =E15-D15 | G15: =IFERROR(E15/D15-1,"") | H15: =SUMIFS('Control Brands'!$G$5:$G$296,'Control Brands'!$A$5:$A$296,$A15,'Control Brands'!$B$5:$B$296,$C15) | I15: =SUMIFS('Control Brands'!$H$5:$H$296,'Control Brands'!$A$5:$A$296,$A15,'Control Brands'!$B$5:$B$296,$C15) | J15: =I15-H15 | K15: =SUMIFS('Data - Control'!$J$5:$J$296,'Data - Control'!$A$5:$A$296,$A15,'Data - Control'!$B$5:$B$296,$C15)
A16: Boston Beer Company | B16: not incented | C16: Lytt | D16: =SUMIFS('Control Brands'!$C$5:$C$296,'Control Brands'!$A$5:$A$296,$A16,'Control Brands'!$B$5:$B$296,$C16) | E16: =SUMIFS('Control Brands'!$D$5:$D$296,'Control Brands'!$A$5:$A$296,$A16,'Control Brands'!$B$5:$B$296,$C16) | F16: =E16-D16 | G16: =IFERROR(E16/D16-1,"") | H16: =SUMIFS('Control Brands'!$G$5:$G$296,'Control Brands'!$A$5:$A$296,$A16,'Control Brands'!$B$5:$B$296,$C16) | I16: =SUMIFS('Control Brands'!$H$5:$H$296,'Control Brands'!$A$5:$A$296,$A16,'Control Brands'!$B$5:$B$296,$C16) | J16: =I16-H16 | K16: =SUMIFS('Data - Control'!$J$5:$J$296,'Data - Control'!$A$5:$A$296,$A16,'Data - Control'!$B$5:$B$296,$C16)
A17: Boston Beer Company | B17: not incented | C17: Samuel Adams | D17: =SUMIFS('Control Brands'!$C$5:$C$296,'Control Brands'!$A$5:$A$296,$A17,'Control Brands'!$B$5:$B$296,$C17) | E17: =SUMIFS('Control Brands'!$D$5:$D$296,'Control Brands'!$A$5:$A$296,$A17,'Control Brands'!$B$5:$B$296,$C17) | F17: =E17-D17 | G17: =IFERROR(E17/D17-1,"") | H17: =SUMIFS('Control Brands'!$G$5:$G$296,'Control Brands'!$A$5:$A$296,$A17,'Control Brands'!$B$5:$B$296,$C17) | I17: =SUMIFS('Control Brands'!$H$5:$H$296,'Control Brands'!$A$5:$A$296,$A17,'Control Brands'!$B$5:$B$296,$C17) | J17: =I17-H17 | K17: =SUMIFS('Data - Control'!$J$5:$J$296,'Data - Control'!$A$5:$A$296,$A17,'Data - Control'!$B$5:$B$296,$C17)
A18: Boston Beer Company | B18: not incented | C18: Sinless Vodka Cocktail | D18: =SUMIFS('Control Brands'!$C$5:$C$296,'Control Brands'!$A$5:$A$296,$A18,'Control Brands'!$B$5:$B$296,$C18) | E18: =SUMIFS('Control Brands'!$D$5:$D$296,'Control Brands'!$A$5:$A$296,$A18,'Control Brands'!$B$5:$B$296,$C18) | F18: =E18-D18 | G18: =IFERROR(E18/D18-1,"") | H18: =SUMIFS('Control Brands'!$G$5:$G$296,'Control Brands'!$A$5:$A$296,$A18,'Control Brands'!$B$5:$B$296,$C18) | I18: =SUMIFS('Control Brands'!$H$5:$H$296,'Control Brands'!$A$5:$A$296,$A18,'Control Brands'!$B$5:$B$296,$C18) | J18: =I18-H18 | K18: =SUMIFS('Data - Control'!$J$5:$J$296,'Data - Control'!$A$5:$A$296,$A18,'Data - Control'!$B$5:$B$296,$C18)
A19: Boston Beer Company | B19: not incented | C19: Sun Cruiser | D19: =SUMIFS('Control Brands'!$C$5:$C$296,'Control Brands'!$A$5:$A$296,$A19,'Control Brands'!$B$5:$B$296,$C19) | E19: =SUMIFS('Control Brands'!$D$5:$D$296,'Control Brands'!$A$5:$A$296,$A19,'Control Brands'!$B$5:$B$296,$C19) | F19: =E19-D19 | G19: =IFERROR(E19/D19-1,"") | H19: =SUMIFS('Control Brands'!$G$5:$G$296,'Control Brands'!$A$5:$A$296,$A19,'Control Brands'!$B$5:$B$296,$C19) | I19: =SUMIFS('Control Brands'!$H$5:$H$296,'Control Brands'!$A$5:$A$296,$A19,'Control Brands'!$B$5:$B$296,$C19) | J19: =I19-H19 | K19: =SUMIFS('Data - Control'!$J$5:$J$296,'Data - Control'!$A$5:$A$296,$A19,'Data - Control'!$B$5:$B$296,$C19)
C20: Boston Beer Company — total | D20: =SUM(D9:D19) | E20: =SUM(E9:E19) | F20: =SUM(F9:F19) | H20: =SUM(H9:H19) | I20: =SUM(I9:I19) | J20: =SUM(J9:J19) | K20: =SUM(K9:K19)
A22: New Belgium Brewing Company | B22: INCENTED | C22: Fat Tire Family | D22: =SUMIFS('Program Brands'!$D$6:$D$37,'Program Brands'!$B$6:$B$37,$A22,'Program Brands'!$C$6:$C$37,$C22) | E22: =SUMIFS('Program Brands'!$E$6:$E$37,'Program Brands'!$B$6:$B$37,$A22,'Program Brands'!$C$6:$C$37,$C22) | F22: =E22-D22 | G22: =IFERROR(E22/D22-1,"") | H22: =SUMIFS('Program Brands'!$H$6:$H$37,'Program Brands'!$B$6:$B$37,$A22,'Program Brands'!$C$6:$C$37,$C22) | I22: =SUMIFS('Program Brands'!$I$6:$I$37,'Program Brands'!$B$6:$B$37,$A22,'Program Brands'!$C$6:$C$37,$C22) | J22: =I22-H22 | K22: =SUMIFS('Data - Season'!$L$5:$L$743,'Data - Season'!$C$5:$C$743,$A22,'Data - Season'!$D$5:$D$743,$C22)
A23: New Belgium Brewing Company | B23: INCENTED | C23: Kirin Ichiban | D23: =SUMIFS('Program Brands'!$D$6:$D$37,'Program Brands'!$B$6:$B$37,$A23,'Program Brands'!$C$6:$C$37,$C23) | E23: =SUMIFS('Program Brands'!$E$6:$E$37,'Program Brands'!$B$6:$B$37,$A23,'Program Brands'!$C$6:$C$37,$C23) | F23: =E23-D23 | G23: =IFERROR(E23/D23-1,"") | H23: =SUMIFS('Program Brands'!$H$6:$H$37,'Program Brands'!$B$6:$B$37,$A23,'Program Brands'!$C$6:$C$37,$C23) | I23: =SUMIFS('Program Brands'!$I$6:$I$37,'Program Brands'!$B$6:$B$37,$A23,'Program Brands'!$C$6:$C$37,$C23) | J23: =I23-H23 | K23: =SUMIFS('Data - Season'!$L$5:$L$743,'Data - Season'!$C$5:$C$743,$A23,'Data - Season'!$D$5:$D$743,$C23)
A24: New Belgium Brewing Company | B24: INCENTED | C24: Voodoo Family | D24: =SUMIFS('Program Brands'!$D$6:$D$37,'Program Brands'!$B$6:$B$37,$A24,'Program Brands'!$C$6:$C$37,$C24) | E24: =SUMIFS('Program Brands'!$E$6:$E$37,'Program Brands'!$B$6:$B$37,$A24,'Program Brands'!$C$6:$C$37,$C24) | F24: =E24-D24 | G24: =IFERROR(E24/D24-1,"") | H24: =SUMIFS('Program Brands'!$H$6:$H$37,'Program Brands'!$B$6:$B$37,$A24,'Program Brands'!$C$6:$C$37,$C24) | I24: =SUMIFS('Program Brands'!$I$6:$I$37,'Program Brands'!$B$6:$B$37,$A24,'Program Brands'!$C$6:$C$37,$C24) | J24: =I24-H24 | K24: =SUMIFS('Data - Season'!$L$5:$L$743,'Data - Season'!$C$5:$C$743,$A24,'Data - Season'!$D$5:$D$743,$C24)
A25: New Belgium Brewing Company | B25: not incented | C25: Kirin Light | D25: =SUMIFS('Control Brands'!$C$5:$C$296,'Control Brands'!$A$5:$A$296,$A25,'Control Brands'!$B$5:$B$296,$C25) | E25: =SUMIFS('Control Brands'!$D$5:$D$296,'Control Brands'!$A$5:$A$296,$A25,'Control Brands'!$B$5:$B$296,$C25) | F25: =E25-D25 | G25: =IFERROR(E25/D25-1,"") | H25: =SUMIFS('Control Brands'!$G$5:$G$296,'Control Brands'!$A$5:$A$296,$A25,'Control Brands'!$B$5:$B$296,$C25) | I25: =SUMIFS('Control Brands'!$H$5:$H$296,'Control Brands'!$A$5:$A$296,$A25,'Control Brands'!$B$5:$B$296,$C25) | J25: =I25-H25 | K25: =SUMIFS('Data - Control'!$J$5:$J$296,'Data - Control'!$A$5:$A$296,$A25,'Data - Control'!$B$5:$B$296,$C25)
A26: New Belgium Brewing Company | B26: not incented | C26: Lightstrike | D26: =SUMIFS('Control Brands'!$C$5:$C$296,'Control Brands'!$A$5:$A$296,$A26,'Control Brands'!$B$5:$B$296,$C26) | E26: =SUMIFS('Control Brands'!$D$5:$D$296,'Control Brands'!$A$5:$A$296,$A26,'Control Brands'!$B$5:$B$296,$C26) | F26: =E26-D26 | G26: =IFERROR(E26/D26-1,"") | H26: =SUMIFS('Control Brands'!$G$5:$G$296,'Control Brands'!$A$5:$A$296,$A26,'Control Brands'!$B$5:$B$296,$C26) | I26: =SUMIFS('Control Brands'!$H$5:$H$296,'Control Brands'!$A$5:$A$296,$A26,'Control Brands'!$B$5:$B$296,$C26) | J26: =I26-H26 | K26: =SUMIFS('Data - Control'!$J$5:$J$296,'Data - Control'!$A$5:$A$296,$A26,'Data - Control'!$B$5:$B$296,$C26)
