Workbook

Sheet 2026 Planning by Brand
A1: Supplier / Brand Family | B1: Supplier | C1: Brand Manager | D1: Segment | E1: Sub-Segment | F1: Unique ID | G1: Unique ID 2 | H1: Estimated 2025 Finish | I1: Estimated % +/- | J1: 2025 Finish | K1: 2026 Brewery Goal +/-% | L1: 2026 Brewery CE Change | M1: 2026 Brewery Goal CE | N1: 2026 Kohler Goal +/-% | O1: 2026 Kohler CE Change | P1: 2026 Kohler Goal CE | R1: Notes
A2: Total | F2: =A2&"|"&B2 -> Total| | H2: =_xlfn.XLOOKUP(F2,'DATA - 2025 Review'!C:C,'DATA - 2025 Review'!I:I,"") -> 7085209.6 | I2: =_xlfn.XLOOKUP(F2,'DATA - 2025 Review'!C:C,'DATA - 2025 Review'!J:J,"") -> -0.05884793 | J2: =_xlfn.XLOOKUP(F2,'2025 Finish (ACTUAL)'!C:C,'2025 Finish (ACTUAL)'!D:D) -> 7067012.3 | K2: =L2/H2 -> -0.0062418651 | L2: =SUMIFS(L3:L472,A3:A472,"<>",B3:B472,"") -> -44224.923 | M2: =SUMIFS(M3:M472,A3:A472,"<>",B3:B472,"") -> 7055675.3 | N2: =O2/H2 -> -0.024569207 | O2: =SUMIFS(O3:O472,A3:A472,"<>",B3:B472,"") -> -174077.98 | P2: =SUMIFS(P3:P472,A3:A472,"<>",B3:B472,"") -> 6908383
A3: Constellation Brands | C3: =_xlfn.XLOOKUP(A3,'Brand Managers'!A:A,'Brand Managers'!B:B) -> Steve Halloran | F3: =A3&"|"&B3 -> Constellation Brands| | G3: =A3&"|"&B3&"|"&D3&"|"&E3 -> Constellation Brands||| | H3: =_xlfn.XLOOKUP(F3,'DATA - 2025 Review'!C:C,'DATA - 2025 Review'!I:I,"") -> 2620051.9 | I3: =_xlfn.XLOOKUP(F3,'DATA - 2025 Review'!C:C,'DATA - 2025 Review'!J:J) -> -0.057688778 | J3: =_xlfn.XLOOKUP(F3,'2025 Finish (ACTUAL)'!C:C,'2025 Finish (ACTUAL)'!D:D) -> 2631932.7 | K3: =L3/J3 -> 0.00061581932 | L3: =SUMIF(B:B,A3,L:L) -> 1620.795 | M3: =SUMIF(B:B,A3,M:M) -> 2633553.5 | N3: =O3/J3 -> -0.019964201 | O3: =SUMIF(B:B,A3,O:O) -> -52544.434 | P3: =SUMIF(B:B,A3,P:P) -> 2579388.3
A4: Corona Extra | B4: Constellation Brands | C4: Steve Halloran | D4: =_xlfn.XLOOKUP(F4,'DATA - Segments'!C:C,'DATA - Segments'!D:D) -> Beer | E4: =_xlfn.XLOOKUP(F4,'DATA - Segments'!C:C,'DATA - Segments'!E:E) -> Beer - Import | F4: =A4&"|"&B4 -> Corona Extra|Constellation Brands | G4: =A4&"|"&B4&"|"&D4&"|"&E4 -> Corona Extra|Constellation Brands|Beer|Beer - Import | H4: =_xlfn.XLOOKUP(F4,'DATA - 2025 Review'!C:C,'DATA - 2025 Review'!I:I,"") -> 1218179.5 | I4: =_xlfn.XLOOKUP(F4,'DATA - 2025 Review'!C:C,'DATA - 2025 Review'!J:J) -> -0.073932646 | J4: =_xlfn.XLOOKUP(F4,'2025 Finish (ACTUAL)'!$C:$C,'2025 Finish (ACTUAL)'!$D:$D) -> 1217068.1 | K4: -0.042 | L4: =K4*J4 -> -51116.86 | M4: =L4+J4 -> 1165951.2 | N4: -0.042 | O4: =N4*J4 -> -51116.86 | P4: =O4+J4 -> 1165951.2
A5: Modelo Especial | B5: Constellation Brands | C5: Steve Halloran | D5: =_xlfn.XLOOKUP(F5,'DATA - Segments'!C:C,'DATA - Segments'!D:D) -> Beer | E5: =_xlfn.XLOOKUP(F5,'DATA - Segments'!C:C,'DATA - Segments'!E:E) -> Beer - Import | F5: =A5&"|"&B5 -> Modelo Especial|Constellation Brands | G5: =A5&"|"&B5&"|"&D5&"|"&E5 -> Modelo Especial|Constellation Brands|Beer|Beer - Import | H5: =_xlfn.XLOOKUP(F5,'DATA - 2025 Review'!C:C,'DATA - 2025 Review'!I:I,"") -> 1053905.8 | I5: =_xlfn.XLOOKUP(F5,'DATA - 2025 Review'!C:C,'DATA - 2025 Review'!J:J) -> -0.057997953 | J5: =_xlfn.XLOOKUP(F5,'2025 Finish (ACTUAL)'!$C:$C,'2025 Finish (ACTUAL)'!$D:$D) -> 1061492.6 | K5: 0.04 | L5: =K5*J5 -> 42459.703 | M5: =L5+J5 -> 1103952.3 | N5: -0.01 | O5: =N5*J5 -> -10614.926 | P5: =O5+J5 -> 1050877.6
A6: Modelo Chelada | B6: Constellation Brands | C6: Steve Halloran | D6: =_xlfn.XLOOKUP(F6,'DATA - Segments'!C:C,'DATA - Segments'!D:D) -> Beer | E6: =_xlfn.XLOOKUP(F6,'DATA - Segments'!C:C,'DATA - Segments'!E:E) -> Beer - Import | F6: =A6&"|"&B6 -> Modelo Chelada|Constellation Brands | G6: =A6&"|"&B6&"|"&D6&"|"&E6 -> Modelo Chelada|Constellation Brands|Beer|Beer - Import | H6: =_xlfn.XLOOKUP(F6,'DATA - 2025 Review'!C:C,'DATA - 2025 Review'!I:I,"") -> 84035.676 | I6: =_xlfn.XLOOKUP(F6,'DATA - 2025 Review'!C:C,'DATA - 2025 Review'!J:J) -> 0.075794355 | J6: =_xlfn.XLOOKUP(F6,'2025 Finish (ACTUAL)'!$C:$C,'2025 Finish (ACTUAL)'!$D:$D) -> 86203.667 | K6: 0.06 | L6: =K6*J6 -> 5172.22 | M6: =L6+J6 -> 91375.887 | N6: 0.06 | O6: =N6*J6 -> 5172.22 | P6: =O6+J6 -> 91375.887
A7: Victoria | B7: Constellation Brands | C7: Steve Halloran | D7: =_xlfn.XLOOKUP(F7,'DATA - Segments'!C:C,'DATA - Segments'!D:D) -> Beer | E7: =_xlfn.XLOOKUP(F7,'DATA - Segments'!C:C,'DATA - Segments'!E:E) -> Beer - Import | F7: =A7&"|"&B7 -> Victoria|Constellation Brands | G7: =A7&"|"&B7&"|"&D7&"|"&E7 -> Victoria|Constellation Brands|Beer|Beer - Import | H7: =_xlfn.XLOOKUP(F7,'DATA - 2025 Review'!C:C,'DATA - 2025 Review'!I:I,"") -> 61653.515 | I7: =_xlfn.XLOOKUP(F7,'DATA - 2025 Review'!C:C,'DATA - 2025 Review'!J:J) -> 0.096523882 | J7: =_xlfn.XLOOKUP(F7,'2025 Finish (ACTUAL)'!$C:$C,'2025 Finish (ACTUAL)'!$D:$D) -> 62550.664 | K7: 0.1 | L7: =K7*J7 -> 6255.0664 | M7: =L7+J7 -> 68805.73 | N7: 0.1 | O7: =N7*J7 -> 6255.0664 | P7: =O7+J7 -> 68805.73
A8: Corona Light | B8: Constellation Brands | C8: Steve Halloran | D8: =_xlfn.XLOOKUP(F8,'DATA - Segments'!C:C,'DATA - Segments'!D:D) -> Beer | E8: =_xlfn.XLOOKUP(F8,'DATA - Segments'!C:C,'DATA - Segments'!E:E) -> Beer - Import | F8: =A8&"|"&B8 -> Corona Light|Constellation Brands | G8: =A8&"|"&B8&"|"&D8&"|"&E8 -> Corona Light|Constellation Brands|Beer|Beer - Import | H8: =_xlfn.XLOOKUP(F8,'DATA - 2025 Review'!C:C,'DATA - 2025 Review'!I:I,"") -> 48789.669 | I8: =_xlfn.XLOOKUP(F8,'DATA - 2025 Review'!C:C,'DATA - 2025 Review'!J:J) -> -0.15743326 | J8: =_xlfn.XLOOKUP(F8,'2025 Finish (ACTUAL)'!$C:$C,'2025 Finish (ACTUAL)'!$D:$D) -> 49496 | K8: -0.08 | L8: =K8*J8 -> -3959.68 | M8: =L8+J8 -> 45536.32 | N8: -0.08 | O8: =N8*J8 -> -3959.68 | P8: =O8+J8 -> 45536.32
A9: Corona Familiar | B9: Constellation Brands | C9: Steve Halloran | D9: =_xlfn.XLOOKUP(F9,'DATA - Segments'!C:C,'DATA - Segments'!D:D) -> Beer | E9: =_xlfn.XLOOKUP(F9,'DATA - Segments'!C:C,'DATA - Segments'!E:E) -> Beer - Import | F9: =A9&"|"&B9 -> Corona Familiar|Constellation Brands | G9: =A9&"|"&B9&"|"&D9&"|"&E9 -> Corona Familiar|Constellation Brands|Beer|Beer - Import | H9: =_xlfn.XLOOKUP(F9,'DATA - 2025 Review'!C:C,'DATA - 2025 Review'!I:I,"") -> 35524.507 | I9: =_xlfn.XLOOKUP(F9,'DATA - 2025 Review'!C:C,'DATA - 2025 Review'!J:J) -> 0.096086016 | J9: =_xlfn.XLOOKUP(F9,'2025 Finish (ACTUAL)'!$C:$C,'2025 Finish (ACTUAL)'!$D:$D) -> 35513.661 | K9: 0.08 | L9: =K9*J9 -> 2841.0929 | M9: =L9+J9 -> 38354.754 | N9: 0.08 | O9: =N9*J9 -> 2841.0929 | P9: =O9+J9 -> 38354.754
A10: Corona Premier | B10: Constellation Brands | C10: Steve Halloran | D10: =_xlfn.XLOOKUP(F10,'DATA - Segments'!C:C,'DATA - Segments'!D:D) -> Beer | E10: =_xlfn.XLOOKUP(F10,'DATA - Segments'!C:C,'DATA - Segments'!E:E) -> Beer - Import | F10: =A10&"|"&B10 -> Corona Premier|Constellation Brands | G10: =A10&"|"&B10&"|"&D10&"|"&E10 -> Corona Premier|Constellation Brands|Beer|Beer - Import | H10: =_xlfn.XLOOKUP(F10,'DATA - 2025 Review'!C:C,'DATA - 2025 Review'!I:I,"") -> 32988.861 | I10: =_xlfn.XLOOKUP(F10,'DATA - 2025 Review'!C:C,'DATA - 2025 Review'!J:J) -> -0.13464841 | J10: =_xlfn.XLOOKUP(F10,'2025 Finish (ACTUAL)'!$C:$C,'2025 Finish (ACTUAL)'!$D:$D) -> 33624.306 | K10: -0.09 | L10: =K10*J10 -> -3026.1875 | M10: =L10+J10 -> 30598.118 | N10: -0.09 | O10: =N10*J10 -> -3026.1875 | P10: =O10+J10 -> 30598.118
A11: Pacifico | B11: Constellation Brands | C11: Steve Halloran | D11: =_xlfn.XLOOKUP(F11,'DATA - Segments'!C:C,'DATA - Segments'!D:D) -> Beer | E11: =_xlfn.XLOOKUP(F11,'DATA - Segments'!C:C,'DATA - Segments'!E:E) -> Beer - Import | F11: =A11&"|"&B11 -> Pacifico|Constellation Brands | G11: =A11&"|"&B11&"|"&D11&"|"&E11 -> Pacifico|Constellation Brands|Beer|Beer - Import | H11: =_xlfn.XLOOKUP(F11,'DATA - 2025 Review'!C:C,'DATA - 2025 Review'!I:I,"") -> 33073.875 | I11: =_xlfn.XLOOKUP(F11,'DATA - 2025 Review'!C:C,'DATA - 2025 Review'!J:J) -> 0.18824026 | J11: =_xlfn.XLOOKUP(F11,'2025 Finish (ACTUAL)'!$C:$C,'2025 Finish (ACTUAL)'!$D:$D) -> 33530.222 | K11: 0.1 | L11: =K11*J11 -> 3353.0222 | M11: =L11+J11 -> 36883.244 | N11: 0.1 | O11: =N11*J11 -> 3353.0222 | P11: =O11+J11 -> 36883.244
A12: Modelo Negra | B12: Constellation Brands | C12: Steve Halloran | D12: =_xlfn.XLOOKUP(F12,'DATA - Segments'!C:C,'DATA - Segments'!D:D) -> Beer | E12: =_xlfn.XLOOKUP(F12,'DATA - Segments'!C:C,'DATA - Segments'!E:E) -> Beer - Import | F12: =A12&"|"&B12 -> Modelo Negra|Constellation Brands | G12: =A12&"|"&B12&"|"&D12&"|"&E12 -> Modelo Negra|Constellation Brands|Beer|Beer - Import | H12: =_xlfn.XLOOKUP(F12,'DATA - 2025 Review'!C:C,'DATA - 2025 Review'!I:I,"") -> 24998.023 | I12: =_xlfn.XLOOKUP(F12,'DATA - 2025 Review'!C:C,'DATA - 2025 Review'!J:J) -> -0.060766114 | J12: =_xlfn.XLOOKUP(F12,'2025 Finish (ACTUAL)'!$C:$C,'2025 Finish (ACTUAL)'!$D:$D) -> 25034.555 | K12: -0.04 | L12: =K12*J12 -> -1001.3822 | M12: =L12+J12 -> 24033.173 | N12: -0.04 | O12: =N12*J12 -> -1001.3822 | P12: =O12+J12 -> 24033.173
A13: Corona NA | B13: Constellation Brands | C13: Steve Halloran | D13: =_xlfn.XLOOKUP(F13,'DATA - Segments'!C:C,'DATA - Segments'!D:D) -> Beer | E13: =_xlfn.XLOOKUP(F13,'DATA - Segments'!C:C,'DATA - Segments'!E:E) -> Beer - Non-Alc | F13: =A13&"|"&B13 -> Corona NA|Constellation Brands | G13: =A13&"|"&B13&"|"&D13&"|"&E13 -> Corona NA|Constellation Brands|Beer|Beer - Non-Alc | H13: =_xlfn.XLOOKUP(F13,'DATA - 2025 Review'!C:C,'DATA - 2025 Review'!I:I,"") -> 8547.5698 | I13: =_xlfn.XLOOKUP(F13,'DATA - 2025 Review'!C:C,'DATA - 2025 Review'!J:J) -> 0.43656636 | J13: =_xlfn.XLOOKUP(F13,'2025 Finish (ACTUAL)'!$C:$C,'2025 Finish (ACTUAL)'!$D:$D) -> 8481 | K13: 0.25 | L13: =K13*J13 -> 2120.25 | M13: =L13+J13 -> 10601.25 | N13: 0.25 | O13: =N13*J13 -> 2120.25 | P13: =O13+J13 -> 10601.25
A14: Modelo Oro | B14: Constellation Brands | C14: Steve Halloran | D14: =_xlfn.XLOOKUP(F14,'DATA - Segments'!C:C,'DATA - Segments'!D:D) -> Beer | E14: =_xlfn.XLOOKUP(F14,'DATA - Segments'!C:C,'DATA - Segments'!E:E) -> Beer - Import | F14: =A14&"|"&B14 -> Modelo Oro|Constellation Brands | G14: =A14&"|"&B14&"|"&D14&"|"&E14 -> Modelo Oro|Constellation Brands|Beer|Beer - Import | H14: =_xlfn.XLOOKUP(F14,'DATA - 2025 Review'!C:C,'DATA - 2025 Review'!I:I,"") -> 5403.01 | I14: =_xlfn.XLOOKUP(F14,'DATA - 2025 Review'!C:C,'DATA - 2025 Review'!J:J) -> -0.14913228 | J14: =_xlfn.XLOOKUP(F14,'2025 Finish (ACTUAL)'!$C:$C,'2025 Finish (ACTUAL)'!$D:$D) -> 5453 | K14: -0.05 | L14: =K14*J14 -> -272.65 | M14: =L14+J14 -> 5180.35 | N14: -0.25 | O14: =N14*J14 -> -1363.25 | P14: =O14+J14 -> 4089.75
A15: Corona Sunbrew | B15: Constellation Brands | C15: Steve Halloran | D15: =_xlfn.XLOOKUP(F15,'DATA - Segments'!C:C,'DATA - Segments'!D:D) -> Beer | E15: =_xlfn.XLOOKUP(F15,'DATA - Segments'!C:C,'DATA - Segments'!E:E) -> Beer - Import | F15: =A15&"|"&B15 -> Corona Sunbrew|Constellation Brands | G15: =A15&"|"&B15&"|"&D15&"|"&E15 -> Corona Sunbrew|Constellation Brands|Beer|Beer - Import | H15: =_xlfn.XLOOKUP(F15,'DATA - 2025 Review'!C:C,'DATA - 2025 Review'!I:I,"") -> 9752.12 | I15: =_xlfn.XLOOKUP(F15,'DATA - 2025 Review'!C:C,'DATA - 2025 Review'!J:J) -> 0.8660773 | J15: =_xlfn.XLOOKUP(F15,'2025 Finish (ACTUAL)'!$C:$C,'2025 Finish (ACTUAL)'!$D:$D) -> 9386 | K15: 0.2 | L15: =K15*J15 -> 1877.2 | M15: =L15+J15 -> 11263.2 | N15: 0.2 | O15: =N15*J15 -> 1877.2 | P15: =O15+J15 -> 11263.2
A16: Corona Refresca | B16: Constellation Brands | D16: =_xlfn.XLOOKUP(F16,'DATA - Segments'!C:C,'DATA - Segments'!D:D) -> FMB | E16: =_xlfn.XLOOKUP(F16,'DATA - Segments'!C:C,'DATA - Segments'!E:E) -> FMB | F16: =A16&"|"&B16 -> Corona Refresca|Constellation Brands | G16: =A16&"|"&B16&"|"&D16&"|"&E16 -> Corona Refresca|Constellation Brands|FMB|FMB | H16: =_xlfn.XLOOKUP(F16,'DATA - 2025 Review'!C:C,'DATA - 2025 Review'!I:I,"") -> 1195.0132 | I16: =_xlfn.XLOOKUP(F16,'DATA - 2025 Review'!C:C,'DATA - 2025 Review'!J:J) -> -0.7722917 | J16: =_xlfn.XLOOKUP(F16,'2025 Finish (ACTUAL)'!$C:$C,'2025 Finish (ACTUAL)'!$D:$D) -> 1093 | K16: -1 | L16: =K16*J16 -> -1093 | M16: =L16+J16 -> 0 | N16: -1 | O16: =N16*J16 -> -1093 | P16: =O16+J16 -> 0
A17: Modelo Aquas Frescas | B17: Constellation Brands | C17: Steve Halloran | D17: =_xlfn.XLOOKUP(F17,'DATA - Segments'!C:C,'DATA - Segments'!D:D) -> FMB | E17: =_xlfn.XLOOKUP(F17,'DATA - Segments'!C:C,'DATA - Segments'!E:E) -> FMB | F17: =A17&"|"&B17 -> Modelo Aquas Frescas|Constellation Brands | G17: =A17&"|"&B17&"|"&D17&"|"&E17 -> Modelo Aquas Frescas|Constellation Brands|FMB|FMB | H17: =_xlfn.XLOOKUP(F17,'DATA - 2025 Review'!C:C,'DATA - 2025 Review'!I:I,"") -> 1856.6564 | I17: =_xlfn.XLOOKUP(F17,'DATA - 2025 Review'!C:C,'DATA - 2025 Review'!J:J) -> -0.51649572 | J17: =_xlfn.XLOOKUP(F17,'2025 Finish (ACTUAL)'!$C:$C,'2025 Finish (ACTUAL)'!$D:$D) -> 2036 | K17: -0.5 | L17: =K17*J17 -> -1018 | M17: =L17+J17 -> 1018 | N17: -0.5 | O17: =N17*J17 -> -1018 | P17: =O17+J17 -> 1018
A18: Fresca Mixed | B18: Constellation Brands | D18: =_xlfn.XLOOKUP(F18,'DATA - Segments'!C:C,'DATA - Segments'!D:D) -> RTD | E18: =_xlfn.XLOOKUP(F18,'DATA - Segments'!C:C,'DATA - Segments'!E:E) -> RTD | F18: =A18&"|"&B18 -> Fresca Mixed|Constellation Brands | G18: =A18&"|"&B18&"|"&D18&"|"&E18 -> Fresca Mixed|Constellation Brands|RTD|RTD | H18: =_xlfn.XLOOKUP(F18,'DATA - 2025 Review'!C:C,'DATA - 2025 Review'!I:I,"") -> 546.8311 | I18: =_xlfn.XLOOKUP(F18,'DATA - 2025 Review'!C:C,'DATA - 2025 Review'!J:J) -> -0.50868724 | J18: =_xlfn.XLOOKUP(F18,'2025 Finish (ACTUAL)'!$C:$C,'2025 Finish (ACTUAL)'!$D:$D) -> 605 | K18: -1 | L18: =K18*J18 -> -605 | M18: =L18+J18 -> 0 | N18: -1 | O18: =N18*J18 -> -605 | P18: =O18+J18 -> 0
A19: The Drop | B19: Constellation Brands | D19: =_xlfn.XLOOKUP(F19,'DATA - Segments'!C:C,'DATA - Segments'!D:D) -> FMB | E19: =_xlfn.XLOOKUP(F19,'DATA - Segments'!C:C,'DATA - Segments'!E:E) -> FMB | F19: =A19&"|"&B19 -> The Drop|Constellation Brands | G19: =A19&"|"&B19&"|"&D19&"|"&E19 -> The Drop|Constellation Brands|FMB|FMB | H19: =_xlfn.XLOOKUP(F19,'DATA - 2025 Review'!C:C,'DATA - 2025 Review'!I:I,"") -> 351 | I19: =_xlfn.XLOOKUP(F19,'DATA - 2025 Review'!C:C,'DATA - 2025 Review'!J:J) -> 0 | J19: =_xlfn.XLOOKUP(F19,'2025 Finish (ACTUAL)'!$C:$C,'2025 Finish (ACTUAL)'!$D:$D) -> 365 | K19: -1 | L19: =K19*J19 -> -365 | M19: =L19+J19 -> 0 | N19: -1 | O19: =N19*J19 -> -365 | P19: =O19+J19 -> 0
A20: Corona Seltzer | B20: Constellation Brands | F20: =A20&"|"&B20 -> Corona Seltzer|Constellation Brands | G20: =A20&"|"&B20&"|"&D20&"|"&E20 -> Corona Seltzer|Constellation Brands|| | H20: =_xlfn.XLOOKUP(F20,'DATA - 2025 Review'!C:C,'DATA - 2025 Review'!I:I,"") -> 0 | I20: =_xlfn.XLOOKUP(F20,'DATA - 2025 Review'!C:C,'DATA - 2025 Review'!J:J) -> -1 | K20: -1 | M20: =L20+J20 -> 0 | N20: -1 | O20: =N20*J20 -> 0 | P20: =O20+J20 -> 0
A21: MolsonCoors Beverage Company | C21: =_xlfn.XLOOKUP(A21,'Brand Managers'!A:A,'Brand Managers'!B:B) -> Dan Downing | F21: =A21&"|"&B21 -> MolsonCoors Beverage Company| | G21: =A21&"|"&B21&"|"&D21&"|"&E21 -> MolsonCoors Beverage Company||| | H21: =_xlfn.XLOOKUP(F21,'DATA - 2025 Review'!C:C,'DATA - 2025 Review'!I:I,"") -> 1873956.7 | I21: =_xlfn.XLOOKUP(F21,'DATA - 2025 Review'!C:C,'DATA - 2025 Review'!J:J) -> -0.078339709 | J21: =_xlfn.XLOOKUP(F21,'2025 Finish (ACTUAL)'!$C:$C,'2025 Finish (ACTUAL)'!$D:$D) -> 1864356.1 | K21: =L21/J21 -> -0.027720047 | L21: =SUMIF(B:B,A21,L:L) -> -51680.037 | M21: =SUMIF(B:B,A21,M:M) -> 1812676 | N21: =O21/J21 -> -0.040256919 | O21: =SUMIF(B:B,A21,O:O) -> -75053.231 | P21: =SUMIF(B:B,A21,P:P) -> 1789302.8
A22: Coors Light | B22: MolsonCoors Beverage Company | C22: Dan Downing | D22: =_xlfn.XLOOKUP(F22,'DATA - Segments'!C:C,'DATA - Segments'!D:D) -> Beer | E22: =_xlfn.XLOOKUP(F22,'DATA - Segments'!C:C,'DATA - Segments'!E:E) -> Beer - Premium | F22: =A22&"|"&B22 -> Coors Light|MolsonCoors Beverage Company | G22: =A22&"|"&B22&"|"&D22&"|"&E22 -> Coors Light|MolsonCoors Beverage Company|Beer|Beer - Premium | H22: =_xlfn.XLOOKUP(F22,'DATA - 2025 Review'!C:C,'DATA - 2025 Review'!I:I,"") -> 798103.69 | I22: =_xlfn.XLOOKUP(F22,'DATA - 2025 Review'!C:C,'DATA - 2025 Review'!J:J) -> -0.098448146 | J22: =_xlfn.XLOOKUP(F22,'2025 Finish (ACTUAL)'!$C:$C,'2025 Finish (ACTUAL)'!$D:$D) -> 792237.3 | K22: -0.06 | L22: =K22*J22 -> -47534.238 | M22: =L22+J22 -> 744703.07 | N22: -0.06 | O22: =N22*J22 -> -47534.238 | P22: =O22+J22 -> 744703.07
A23: Lite | B23: MolsonCoors Beverage Company | C23: Dan Downing | D23: =_xlfn.XLOOKUP(F23,'DATA - Segments'!C:C,'DATA - Segments'!D:D) -> Beer | E23: =_xlfn.XLOOKUP(F23,'DATA - Segments'!C:C,'DATA - Segments'!E:E) -> Beer - Premium | F23: =A23&"|"&B23 -> Lite|MolsonCoors Beverage Company | G23: =A23&"|"&B23&"|"&D23&"|"&E23 -> Lite|MolsonCoors Beverage Company|Beer|Beer - Premium | H23: =_xlfn.XLOOKUP(F23,'DATA - 2025 Review'!C:C,'DATA - 2025 Review'!I:I,"") -> 517515.29 | I23: =_xlfn.XLOOKUP(F23,'DATA - 2025 Review'!C:C,'DATA - 2025 Review'!J:J) -> -0.068860275 | J23: =_xlfn.XLOOKUP(F23,'2025 Finish (ACTUAL)'!$C:$C,'2025 Finish (ACTUAL)'!$D:$D) -> 514391.6 | K23: -0.04 | L23: =K23*J23 -> -20575.664 | M23: =L23+J23 -> 493815.93 | N23: -0.04 | O23: =N23*J23 -> -20575.664 | P23: =O23+J23 -> 493815.93
A24: Blue Moon | B24: MolsonCoors Beverage Company | C24: Dan Downing | D24: =_xlfn.XLOOKUP(F24,'DATA - Segments'!C:C,'DATA - Segments'!D:D) -> Beer | E24: =_xlfn.XLOOKUP(F24,'DATA - Segments'!C:C,'DATA - Segments'!E:E) -> Beer - Craft | F24: =A24&"|"&B24 -> Blue Moon|MolsonCoors Beverage Company | G24: =A24&"|"&B24&"|"&D24&"|"&E24 -> Blue Moon|MolsonCoors Beverage Company|Beer|Beer - Craft | H24: =_xlfn.XLOOKUP(F24,'DATA - 2025 Review'!C:C,'DATA - 2025 Review'!I:I,"") -> 123830.6 | I24: =_xlfn.XLOOKUP(F24,'DATA - 2025 Review'!C:C,'DATA - 2025 Review'!J:J) -> -0.072981964 | J24: =_xlfn.XLOOKUP(F24,'2025 Finish (ACTUAL)'!$C:$C,'2025 Finish (ACTUAL)'!$D:$D) -> 123103.9 | K24: -0.045 | L24: =K24*J24 -> -5539.6754 | M24: =L24+J24 -> 117564.22 | N24: -0.045 | O24: =N24*J24 -> -5539.6754 | P24: =O24+J24 -> 117564.22
A25: Coors | B25: MolsonCoors Beverage Company | C25: Dan Downing | D25: =_xlfn.XLOOKUP(F25,'DATA - Segments'!C:C,'DATA - Segments'!D:D) -> Beer | E25: =_xlfn.XLOOKUP(F25,'DATA - Segments'!C:C,'DATA - Segments'!E:E) -> Beer - Premium | F25: =A25&"|"&B25 -> Coors|MolsonCoors Beverage Company | G25: =A25&"|"&B25&"|"&D25&"|"&E25 -> Coors|MolsonCoors Beverage Company|Beer|Beer - Premium | H25: =_xlfn.XLOOKUP(F25,'DATA - 2025 Review'!C:C,'DATA - 2025 Review'!I:I,"") -> 114505.24 | I25: =_xlfn.XLOOKUP(F25,'DATA - 2025 Review'!C:C,'DATA - 2025 Review'!J:J) -> 0.06073403 | J25: =_xlfn.XLOOKUP(F25,'2025 Finish (ACTUAL)'!$C:$C,'2025 Finish (ACTUAL)'!$D:$D) -> 112534.69 | K25: 0.085 | L25: =K25*J25 -> 9565.449 | M25: =L25+J25 -> 122100.14 | N25: 0.085 | O25: =N25*J25 -> 9565.449 | P25: =O25+J25 -> 122100.14
A26: Miller High Life | B26: MolsonCoors Beverage Company | C26: Dan Downing | D26: =_xlfn.XLOOKUP(F26,'DATA - Segments'!C:C,'DATA - Segments'!D:D) -> Beer | E26: =_xlfn.XLOOKUP(F26,'DATA - Segments'!C:C,'DATA - Segments'!E:E) -> Beer - Economy | F26: =A26&"|"&B26 -> Miller High Life|MolsonCoors Beverage Company | G26: =A26&"|"&B26&"|"&D26&"|"&E26 -> Miller High Life|MolsonCoors Beverage Company|Beer|Beer - Economy | H26: =_xlfn.XLOOKUP(F26,'DATA - 2025 Review'!C:C,'DATA - 2025 Review'!I:I,"") -> 66853.721 | I26: =_xlfn.XLOOKUP(F26,'DATA - 2025 Review'!C:C,'DATA - 2025 Review'!J:J) -> -0.041370959 | J26: =_xlfn.XLOOKUP(F26,'2025 Finish (ACTUAL)'!$C:$C,'2025 Finish (ACTUAL)'!$D:$D) -> 66734.691 | K26: -0.01 | L26: =K26*J26 -> -667.34691 | M26: =L26+J26 -> 66067.344 | N26: -0.03 | O26: =N26*J26 -> -2002.0407 | P26: =O26+J26 -> 64732.65
A27: Peroni | B27: MolsonCoors Beverage Company | C27: Dan Downing | D27: =_xlfn.XLOOKUP(F27,'DATA - Segments'!C:C,'DATA - Segments'!D:D) -> Beer | E27: =_xlfn.XLOOKUP(F27,'DATA - Segments'!C:C,'DATA - Segments'!E:E) -> Beer - Import | F27: =A27&"|"&B27 -> Peroni|MolsonCoors Beverage Company | G27: =A27&"|"&B27&"|"&D27&"|"&E27 -> Peroni|MolsonCoors Beverage Company|Beer|Beer - Import | H27: =_xlfn.XLOOKUP(F27,'DATA - 2025 Review'!C:C,'DATA - 2025 Review'!I:I,"") -> 57815.761 | I27: =_xlfn.XLOOKUP(F27,'DATA - 2025 Review'!C:C,'DATA - 2025 Review'!J:J) -> 0.12607869 | J27: =_xlfn.XLOOKUP(F27,'2025 Finish (ACTUAL)'!$C:$C,'2025 Finish (ACTUAL)'!$D:$D) -> 57382.712 | K27: 0.126 | L27: =K27*J27 -> 7230.2218 | M27: =L27+J27 -> 64612.934 | N27: 0.126 | O27: =N27*J27 -> 7230.2218 | P27: =O27+J27 -> 64612.934
A28: Fosters | B28: MolsonCoors Beverage Company | C28: Dan Downing | D28: =_xlfn.XLOOKUP(F28,'DATA - Segments'!C:C,'DATA - Segments'!D:D) -> Beer | E28: =_xlfn.XLOOKUP(F28,'DATA - Segments'!C:C,'DATA - Segments'!E:E) -> Beer - Import | F28: =A28&"|"&B28 -> Fosters|MolsonCoors Beverage Company | G28: =A28&"|"&B28&"|"&D28&"|"&E28 -> Fosters|MolsonCoors Beverage Company|Beer|Beer - Import | H28: =_xlfn.XLOOKUP(F28,'DATA - 2025 Review'!C:C,'DATA - 2025 Review'!I:I,"") -> 22754.153 | I28: =_xlfn.XLOOKUP(F28,'DATA - 2025 Review'!C:C,'DATA - 2025 Review'!J:J) -> -0.096091369 | J28: =_xlfn.XLOOKUP(F28,'2025 Finish (ACTUAL)'!$C:$C,'2025 Finish (ACTUAL)'!$D:$D) -> 22845.126 | K28: -0.114 | L28: =K28*J28 -> -2604.3444 | M28: =L28+J28 -> 20240.782 | N28: -0.114 | O28: =N28*J28 -> -2604.3444 | P28: =O28+J28 -> 20240.782
A29: Tyskie Gronie | B29: MolsonCoors Beverage Company | C29: Dan Downing | D29: =_xlfn.XLOOKUP(F29,'DATA - Segments'!C:C,'DATA - Segments'!D:D) -> Beer | E29: =_xlfn.XLOOKUP(F29,'DATA - Segments'!C:C,'DATA - Segments'!E:E) -> Beer - Import | F29: =A29&"|"&B29 -> Tyskie Gronie|MolsonCoors Beverage Company | G29: =A29&"|"&B29&"|"&D29&"|"&E29 -> Tyskie Gronie|MolsonCoors Beverage Company|Beer|Beer - Import | H29: =_xlfn.XLOOKUP(F29,'DATA - 2025 Review'!C:C,'DATA - 2025 Review'!I:I,"") -> 20010.671 | I29: =_xlfn.XLOOKUP(F29,'DATA - 2025 Review'!C:C,'DATA - 2025 Review'!J:J) -> 0.01029807 | J29: =_xlfn.XLOOKUP(F29,'2025 Finish (ACTUAL)'!$C:$C,'2025 Finish (ACTUAL)'!$D:$D) -> 19094.721 | K29: -0.114 | L29: =K29*J29 -> -2176.7982 | M29: =L29+J29 -> 16917.923 | N29: -0.114 | O29: =N29*J29 -> -2176.7982 | P29: =O29+J29 -> 16917.923
A30: Arnold Palmer | B30: MolsonCoors Beverage Company | C30: Dan Downing | D30: =_xlfn.XLOOKUP(F30,'DATA - Segments'!C:C,'DATA - Segments'!D:D) -> FMB | E30: =_xlfn.XLOOKUP(F30,'DATA - Segments'!C:C,'DATA - Segments'!E:E) -> FMB | F30: =A30&"|"&B30 -> Arnold Palmer|MolsonCoors Beverage Company | G30: =A30&"|"&B30&"|"&D30&"|"&E30 -> Arnold Palmer|MolsonCoors Beverage Company|FMB|FMB | H30: =_xlfn.XLOOKUP(F30,'DATA - 2025 Review'!C:C,'DATA - 2025 Review'!I:I,"") -> 18022.648 | I30: =_xlfn.XLOOKUP(F30,'DATA - 2025 Review'!C:C,'DATA - 2025 Review'!J:J) -> -0.16769892 | J30: =_xlfn.XLOOKUP(F30,'2025 Finish (ACTUAL)'!$C:$C,'2025 Finish (ACTUAL)'!$D:$D) -> 17932 | K30: -0.05 | L30: =K30*J30 -> -896.6 | M30: =L30+J30 -> 17035.4 | N30: -0.2 | O30: =N30*J30 -> -3586.4 | P30: =O30+J30 -> 14345.6
A31: Keystone | B31: MolsonCoors Beverage Company | C31: Dan Downing | D31: =_xlfn.XLOOKUP(F31,'DATA - Segments'!C:C,'DATA - Segments'!D:D) -> Beer | E31: =_xlfn.XLOOKUP(F31,'DATA - Segments'!C:C,'DATA - Segments'!E:E) -> Beer - Economy | F31: =A31&"|"&B31 -> Keystone|MolsonCoors Beverage Company | G31: =A31&"|"&B31&"|"&D31&"|"&E31 -> Keystone|MolsonCoors Beverage Company|Beer|Beer - Economy | H31: =_xlfn.XLOOKUP(F31,'DATA - 2025 Review'!C:C,'DATA - 2025 Review'!I:I,"") -> 14500.068 | I31: =_xlfn.XLOOKUP(F31,'DATA - 2025 Review'!C:C,'DATA - 2025 Review'!J:J) -> -0.17723108 | J31: =_xlfn.XLOOKUP(F31,'2025 Finish (ACTUAL)'!$C:$C,'2025 Finish (ACTUAL)'!$D:$D) -> 14746.5 | K31: -0.157 | L31: =K31*J31 -> -2315.2005 | M31: =L31+J31 -> 12431.3 | N31: -0.157 | O31: =N31*J31 -> -2315.2005 | P31: =O31+J31 -> 12431.3
A32: Steel Reserve | B32: MolsonCoors Beverage Company | C32: Dan Downing | D32: =_xlfn.XLOOKUP(F32,'DATA - Segments'!C:C,'DATA - Segments'!D:D) -> Beer | E32: =_xlfn.XLOOKUP(F32,'DATA - Segments'!C:C,'DATA - Segments'!E:E) -> Beer - Economy | F32: =A32&"|"&B32 -> Steel Reserve|MolsonCoors Beverage Company | G32: =A32&"|"&B32&"|"&D32&"|"&E32 -> Steel Reserve|MolsonCoors Beverage Company|Beer|Beer - Economy | H32: =_xlfn.XLOOKUP(F32,'DATA - 2025 Review'!C:C,'DATA - 2025 Review'!I:I,"") -> 13279.784 | I32: =_xlfn.XLOOKUP(F32,'DATA - 2025 Review'!C:C,'DATA - 2025 Review'!J:J) -> -0.069288139 | J32: =_xlfn.XLOOKUP(F32,'2025 Finish (ACTUAL)'!$C:$C,'2025 Finish (ACTUAL)'!$D:$D) -> 13417.249 | K32: -0.034 | L32: =K32*J32 -> -456.18648 | M32: =L32+J32 -> 12961.063 | N32: -0.034 | O32: =N32*J32 -> -456.18648 | P32: =O32+J32 -> 12961.063
A33: Molson | B33: MolsonCoors Beverage Company | C33: Dan Downing | D33: =_xlfn.XLOOKUP(F33,'DATA - Segments'!C:C,'DATA - Segments'!D:D) -> Beer | E33: =_xlfn.XLOOKUP(F33,'DATA - Segments'!C:C,'DATA - Segments'!E:E) -> Beer - Import | F33: =A33&"|"&B33 -> Molson|MolsonCoors Beverage Company | G33: =A33&"|"&B33&"|"&D33&"|"&E33 -> Molson|MolsonCoors Beverage Company|Beer|Beer - Import | H33: =_xlfn.XLOOKUP(F33,'DATA - 2025 Review'!C:C,'DATA - 2025 Review'!I:I,"") -> 10160.468 | I33: =_xlfn.XLOOKUP(F33,'DATA - 2025 Review'!C:C,'DATA - 2025 Review'!J:J) -> -0.20024385 | J33: =_xlfn.XLOOKUP(F33,'2025 Finish (ACTUAL)'!$C:$C,'2025 Finish (ACTUAL)'!$D:$D) -> 10193.958 | K33: 0.03 | L33: =K33*J33 -> 305.81873 | M33: =L33+J33 -> 10499.776 | N33: -0.2 | O33: =N33*J33 -> -2038.7915 | P33: =O33+J33 -> 8155.1662
... A53: Steel Reserve Alloy Series | B53: MolsonCoors Beverage Company | C53: Dan Downing | D53: =_xlfn.XLOOKUP(F53,'DATA - Segments'!C:C,'DATA - Segments'!D:D) -> Beer | E53: =_xlfn.XLOOKUP(F53,'DATA - Segments'!C:C,'DATA - Segments'!E:E) -> Beer - Economy | F53: =A53&"|"&B53 -> Steel Reserve Alloy Series|MolsonCoors Beverage Company | G53: =A53&"|"&B53&"|"&D53&"|"&E53 -> Steel Reserve Alloy Series|MolsonCoors Beverage Company|Beer|Beer - Economy | H53: =_xlfn.XLOOKUP(F53,'DATA - 2025 Review'!C:C,'DATA - 2025 Review'!I:I,"") -> 10 | I53: =_xlfn.XLOOKUP(F53,'DATA - 2025 Review'!C:C,'DATA - 2025 Review'!J:J) -> -0.85074627 | J53: =_xlfn.XLOOKUP(F53,'2025 Finish (ACTUAL)'!$C:$C,'2025 Finish (ACTUAL)'!$D:$D) -> 10 | K53: -0.06 | L53: =K53*J53 -> -0.6 | M53: =L53+J53 -> 9.4 | N53: 0 | O53: =N53*J53 -> 0 | P53: =O53+J53 -> 10
A54: Lech | B54: MolsonCoors Beverage Company | F54: =A54&"|"&B54 -> Lech|MolsonCoors Beverage Company | G54: =A54&"|"&B54&"|"&D54&"|"&E54 -> Lech|MolsonCoors Beverage Company|| | H54: =_xlfn.XLOOKUP(F54,'DATA - 2025 Review'!C:C,'DATA - 2025 Review'!I:I,"") -> 0 | I54: =_xlfn.XLOOKUP(F54,'DATA - 2025 Review'!C:C,'DATA - 2025 Review'!J:J) -> -1 | K54: 0 | M54: =L54+J54 -> 0 | N54: 0 | O54: =N54*J54 -> 0 | P54: =O54+J54 -> 0
A55: Fever Tree | B55: MolsonCoors Beverage Company | C55: Dan Downing | D55: =_xlfn.XLOOKUP(F55,'DATA - Segments'!C:C,'DATA - Segments'!D:D) -> Non-Alc | E55: =_xlfn.XLOOKUP(F55,'DATA - Segments'!C:C,'DATA - Segments'!E:E) -> Non-Alc - Soda | F55: =A55&"|"&B55 -> Fever Tree|MolsonCoors Beverage Company | G55: =A55&"|"&B55&"|"&D55&"|"&E55 -> Fever Tree|MolsonCoors Beverage Company|Non-Alc|Non-Alc - Soda | H55: =_xlfn.XLOOKUP(F55,'DATA - 2025 Review'!C:C,'DATA - 2025 Review'!I:I,"") -> 2400.8189 | I55: =_xlfn.XLOOKUP(F55,'DATA - 2025 Review'!C:C,'DATA - 2025 Review'!J:J) -> 0 | J55: =_xlfn.XLOOKUP(F55,'2025 Finish (ACTUAL)'!$C:$C,'2025 Finish (ACTUAL)'!$D:$D) -> 3470.7233 | K55: 6.27 | L55: =K55*J55 -> 21761.435 | M55: =L55+J55 -> 25232.159 | N55: 2.5 | O55: =N55*J55 -> 8676.8083 | P55: =O55+J55 -> 12147.532
A56: Milwaukee's Best | B56: MolsonCoors Beverage Company | F56: =A56&"|"&B56 -> Milwaukee's Best|MolsonCoors Beverage Company | G56: =A56&"|"&B56&"|"&D56&"|"&E56 -> Milwaukee's Best|MolsonCoors Beverage Company|| | H56: =_xlfn.XLOOKUP(F56,'DATA - 2025 Review'!C:C,'DATA - 2025 Review'!I:I,"") -> -5 | I56: =_xlfn.XLOOKUP(F56,'DATA - 2025 Review'!C:C,'DATA - 2025 Review'!J:J) -> 1 | K56: -0.1 | M56: =L56+J56 -> 0 | N56: -0.1 | O56: =N56*J56 -> 0 | P56: =O56+J56 -> 0
A57: Leinenkugel | B57: MolsonCoors Beverage Company | C57: Dan Downing | D57: =_xlfn.XLOOKUP(F57,'DATA - Segments'!C:C,'DATA - Segments'!D:D) -> Beer | E57: =_xlfn.XLOOKUP(F57,'DATA - Segments'!C:C,'DATA - Segments'!E:E) -> Beer - Craft | F57: =A57&"|"&B57 -> Leinenkugel|MolsonCoors Beverage Company | G57: =A57&"|"&B57&"|"&D57&"|"&E57 -> Leinenkugel|MolsonCoors Beverage Company|Beer|Beer - Craft | H57: =_xlfn.XLOOKUP(F57,'DATA - 2025 Review'!C:C,'DATA - 2025 Review'!I:I,"") -> 17424.431 | I57: =_xlfn.XLOOKUP(F57,'DATA - 2025 Review'!C:C,'DATA - 2025 Review'!J:J) -> -0.19509171 | J57: =_xlfn.XLOOKUP(F57,'2025 Finish (ACTUAL)'!$C:$C,'2025 Finish (ACTUAL)'!$D:$D) -> 17664.34 | K57: -0.1348 | L57: =K57*J57 -> -2381.1531 | M57: =L57+J57 -> 15283.187 | N57: -0.15 | O57: =N57*J57 -> -2649.651 | P57: =O57+J57 -> 15014.689
A58: Happy Thursday Spiked Refresher | B58: MolsonCoors Beverage Company | C58: Dan Downing | D58: =_xlfn.XLOOKUP(F58,'DATA - Segments'!C:C,'DATA - Segments'!D:D) -> FMB | E58: =_xlfn.XLOOKUP(F58,'DATA - Segments'!C:C,'DATA - Segments'!E:E) -> FMB | F58: =A58&"|"&B58 -> Happy Thursday Spiked Refresher|MolsonCoors Beverage Company | G58: =A58&"|"&B58&"|"&D58&"|"&E58 -> Happy Thursday Spiked Refresher|MolsonCoors Beverage Company|FMB|FMB | H58: =_xlfn.XLOOKUP(F58,'DATA - 2025 Review'!C:C,'DATA - 2025 Review'!I:I,"") -> 279.1091 | I58: =_xlfn.XLOOKUP(F58,'DATA - 2025 Review'!C:C,'DATA - 2025 Review'!J:J) -> -0.6090909 | J58: =_xlfn.XLOOKUP(F58,'2025 Finish (ACTUAL)'!$C:$C,'2025 Finish (ACTUAL)'!$D:$D) -> 299 | K58: -0.43 | L58: =K58*J58 -> -128.57 | M58: =L58+J58 -> 170.43 | N58: -0.6 | O58: =N58*J58 -> -179.4 | P58: =O58+J58 -> 119.6
A59: Heineken USA | C59: =_xlfn.XLOOKUP(A59,'Brand Managers'!A:A,'Brand Managers'!B:B) -> Perry Calderone | F59: =A59&"|"&B59 -> Heineken USA| | G59: =A59&"|"&B59&"|"&D59&"|"&E59 -> Heineken USA||| | H59: =_xlfn.XLOOKUP(F59,'DATA - 2025 Review'!C:C,'DATA - 2025 Review'!I:I,"") -> 541821.3 | I59: =_xlfn.XLOOKUP(F59,'DATA - 2025 Review'!C:C,'DATA - 2025 Review'!J:J) -> -0.10487382 | J59: =_xlfn.XLOOKUP(F59,'2025 Finish (ACTUAL)'!$C:$C,'2025 Finish (ACTUAL)'!$D:$D) -> 538278.18 | K59: =L59/J59 -> -0.040452484 | L59: =SUMIF(B:B,A59,L:L) -> -21774.689 | M59: =SUMIF(B:B,A59,M:M) -> 516503.49 | N59: =O59/J59 -> -0.053569377 | O59: =SUMIF(B:B,A59,O:O) -> -28835.227 | P59: =SUMIF(B:B,A59,P:P) -> 509442.95
...

Sheet 2026 Planning by Sub-Segment
G1: Key | J1: Key
G2: Brewery has a more aggressive goal | J2: Brewery has a more aggressive goal
G3: Kohler has a more aggressive goal | J3: Kohler has a more aggressive goal
B6: Segment | C6: Sub-Segment | D6: 2025 Est Finish | E6: 2026 Brewery % Goal +/- | F6: 2026 Kohler % Goal +/- | G6: Brewery - Kohler % Diff | H6: 2026 Brewery CE Change | I6: 2026 Kohler CE Change | J6: Brewery - Kohler CE Diff
B7: Totals | D7: =SUM(D8:D32) -> 7068821.1 | E7: =H7/D7 -> -0.0065708511 | F7: =I7/D7 -> -0.024658437 | G7: =AVERAGE(G8:G16,G18:G21) -> 0.28918265 | H7: =SUM(H8:H32) -> -46448.171 | I7: =SUM(I8:I32) -> -174306.08 | J7: =SUM(J8:J32) -> 127857.91
B8: Beer | C8: Beer - Import | D8: =SUMIF('2026 Planning by Brand'!$E:$E,'2026 Planning by Brand'!$E$4,'2026 Planning by Brand'!H:H) -> 3525505.5 | E8: =AVERAGEIF('2026 Planning by Brand'!$E:$E,'2026 Planning by Brand'!$E$4,'2026 Planning by Brand'!K:K) -> -0.034654167 | F8: =AVERAGEIF('2026 Planning by Brand'!$E:$E,'2026 Planning by Brand'!$E$4,'2026 Planning by Brand'!N:N) -> -0.034403659 | G8: =E8-F8 -> -0.00025050813 | H8: =SUMIF('2026 Planning by Brand'!$E:$E,'2026 Planning by Brand'!$E$4,'2026 Planning by Brand'!L:L) -> -8467.0827 | I8: =SUMIF('2026 Planning by Brand'!$E:$E,'2026 Planning by Brand'!$E$4,'2026 Planning by Brand'!O:O) -> -75121.087 | J8: =H8-I8 -> 66654.005
B9: Beer | C9: Beer - Premium | D9: =SUMIF('2026 Planning by Brand'!$E:$E,'2026 Planning by Brand'!$E$25,'2026 Planning by Brand'!H:H) -> 1433167 | E9: =AVERAGEIF('2026 Planning by Brand'!$E:$E,'2026 Planning by Brand'!$E$25,'2026 Planning by Brand'!K:K) -> -0.03225 | F9: =AVERAGEIF('2026 Planning by Brand'!$E:$E,'2026 Planning by Brand'!$E$25,'2026 Planning by Brand'!N:N) -> -0.02875 | G9: =E9-F9 -> -0.0035 | H9: =SUMIF('2026 Planning by Brand'!$E:$E,'2026 Planning by Brand'!$E$25,'2026 Planning by Brand'!L:L) -> -58887.91 | I9: =SUMIF('2026 Planning by Brand'!$E:$E,'2026 Planning by Brand'!$E$25,'2026 Planning by Brand'!O:O) -> -58845.731 | J9: =H9-I9 -> -42.178889
B10: Beer | C10: Beer - Economy | D10: =SUMIF('2026 Planning by Brand'!$E:$E,'2026 Planning by Brand'!$E$26,'2026 Planning by Brand'!H:H) -> 438231.58 | E10: =AVERAGEIF('2026 Planning by Brand'!$E:$E,'2026 Planning by Brand'!$E$26,'2026 Planning by Brand'!K:K) -> -0.087103448 | F10: =AVERAGEIF('2026 Planning by Brand'!$E:$E,'2026 Planning by Brand'!$E$26,'2026 Planning by Brand'!N:N) -> -0.090068966 | G10: =E10-F10 -> 0.0029655172 | H10: =SUMIF('2026 Planning by Brand'!$E:$E,'2026 Planning by Brand'!$E$26,'2026 Planning by Brand'!L:L) -> -15390.41 | I10: =SUMIF('2026 Planning by Brand'!$E:$E,'2026 Planning by Brand'!$E$26,'2026 Planning by Brand'!O:O) -> -24641.278 | J10: =H10-I10 -> 9250.8681
B11: Beer | C11: Beer - Craft | D11: =SUMIF('2026 Planning by Brand'!$E:$E,'2026 Planning by Brand'!$E$24,'2026 Planning by Brand'!H:H) -> 795816.78 | E11: =AVERAGEIF('2026 Planning by Brand'!$E:$E,'2026 Planning by Brand'!$E$24,'2026 Planning by Brand'!K:K) -> -0.061688462 | F11: =AVERAGEIF('2026 Planning by Brand'!$E:$E,'2026 Planning by Brand'!$E$24,'2026 Planning by Brand'!N:N) -> -0.11057407 | G11: =E11-F11 -> 0.048885613 | H11: =SUMIF('2026 Planning by Brand'!$E:$E,'2026 Planning by Brand'!$E$24,'2026 Planning by Brand'!L:L) -> -8634.2607 | I11: =SUMIF('2026 Planning by Brand'!$E:$E,'2026 Planning by Brand'!$E$24,'2026 Planning by Brand'!O:O) -> -19776.763 | J11: =H11-I11 -> 11142.502
B12: Beer | C12: Beer - Non-Alc | D12: =SUMIF('2026 Planning by Brand'!$E:$E,'2026 Planning by Brand'!$E$47,'2026 Planning by Brand'!H:H) -> 64650.281 | E12: =AVERAGEIF('2026 Planning by Brand'!$E:$E,'2026 Planning by Brand'!$E$47,'2026 Planning by Brand'!K:K) -> 0.069 | F12: =AVERAGEIF('2026 Planning by Brand'!$E:$E,'2026 Planning by Brand'!$E$47,'2026 Planning by Brand'!N:N) -> 0.053428571 | G12: =E12-F12 -> 0.015571429 | H12: =SUMIF('2026 Planning by Brand'!$E:$E,'2026 Planning by Brand'!$E$47,'2026 Planning by Brand'!L:L) -> 6801.871 | I12: =SUMIF('2026 Planning by Brand'!$E:$E,'2026 Planning by Brand'!$E$47,'2026 Planning by Brand'!O:O) -> 6510.9665 | J12: =H12-I12 -> 290.90441
B13: Beer | C13: Beer - Super Premium | D13: =SUMIF('2026 Planning by Brand'!$E:$E,'2026 Planning by Brand'!$E$36,'2026 Planning by Brand'!H:H) -> 10440.15 | E13: =AVERAGEIF('2026 Planning by Brand'!$E:$E,'2026 Planning by Brand'!$E$36,'2026 Planning by Brand'!K:K) -> -0.026 | F13: =AVERAGEIF('2026 Planning by Brand'!$E:$E,'2026 Planning by Brand'!$E$36,'2026 Planning by Brand'!N:N) -> -0.026 | G13: =E13-F13 -> 0 | H13: =SUMIF('2026 Planning by Brand'!$E:$E,'2026 Planning by Brand'!$E$36,'2026 Planning by Brand'!L:L) -> -274.703 | I13: =SUMIF('2026 Planning by Brand'!$E:$E,'2026 Planning by Brand'!$E$36,'2026 Planning by Brand'!O:O) -> -274.703 | J13: =H13-I13 -> 0
B14: Cider | C14: Cider | D14: =SUMIF('2026 Planning by Brand'!$E:$E,'2026 Planning by Brand'!$E$70,'2026 Planning by Brand'!H:H) -> 80279.239 | E14: =AVERAGEIF('2026 Planning by Brand'!$E:$E,'2026 Planning by Brand'!$E$70,'2026 Planning by Brand'!K:K) -> 0.0155 | F14: =AVERAGEIF('2026 Planning by Brand'!$E:$E,'2026 Planning by Brand'!$E$70,'2026 Planning by Brand'!N:N) -> -0.051 | G14: =E14-F14 -> 0.0665 | H14: =SUMIF('2026 Planning by Brand'!$E:$E,'2026 Planning by Brand'!$E$70,'2026 Planning by Brand'!L:L) -> -1160.466 | I14: =SUMIF('2026 Planning by Brand'!$E:$E,'2026 Planning by Brand'!$E$70,'2026 Planning by Brand'!O:O) -> 1102.1027 | J14: =H14-I14 -> -2262.5687 | K14: We have big % discrepancy for: Doc's
B15: FMB | C15: FMB | D15: =SUMIF('2026 Planning by Brand'!$E:$E,'2026 Planning by Brand'!$E$44,'2026 Planning by Brand'!H:H) -> 237577.33 | E15: =AVERAGEIF('2026 Planning by Brand'!$E:$E,'2026 Planning by Brand'!$E$44,'2026 Planning by Brand'!K:K) -> 0.35592857 | F15: =AVERAGEIF('2026 Planning by Brand'!$E:$E,'2026 Planning by Brand'!$E$44,'2026 Planning by Brand'!N:N) -> 0.22432143 | G15: =E15-F15 -> 0.13160714 | H15: =SUMIF('2026 Planning by Brand'!$E:$E,'2026 Planning by Brand'!$E$44,'2026 Planning by Brand'!L:L) -> -19154.884 | I15: =SUMIF('2026 Planning by Brand'!$E:$E,'2026 Planning by Brand'!$E$44,'2026 Planning by Brand'!O:O) -> -25970.269 | J15: =H15-I15 -> 6815.3854
B16: Non-Alc | C16: Non-Alc - Energy | D16: =SUMIF('2026 Planning by Brand'!$E:$E,'2026 Planning by Brand'!$E$221,'2026 Planning by Brand'!H:H) -> 7223.3167 | E16: =AVERAGEIF('2026 Planning by Brand'!$E:$E,'2026 Planning by Brand'!$E$221,'2026 Planning by Brand'!K:K) -> 0.06 | F16: =AVERAGEIF('2026 Planning by Brand'!$E:$E,'2026 Planning by Brand'!$E$221,'2026 Planning by Brand'!N:N) -> 0.06 | G16: =E16-F16 -> 0 | H16: =SUMIF('2026 Planning by Brand'!$E:$E,'2026 Planning by Brand'!$E$221,'2026 Planning by Brand'!L:L) -> 426.3884 | I16: =SUMIF('2026 Planning by Brand'!$E:$E,'2026 Planning by Brand'!$E$221,'2026 Planning by Brand'!O:O) -> 426.3884 | J16: =H16-I16 -> 0
B17: Non-Alc | C17: Non-Alc - Water | D17: =SUMIF('2026 Planning by Brand'!$E:$E,'2026 Planning by Brand'!$E$233,'2026 Planning by Brand'!H:H) -> 6689.2372 | E17: =AVERAGEIF('2026 Planning by Brand'!$E:$E,'2026 Planning by Brand'!$E$233,'2026 Planning by Brand'!K:K) -> #DIV/0! | F17: =AVERAGEIF('2026 Planning by Brand'!$E:$E,'2026 Planning by Brand'!$E$233,'2026 Planning by Brand'!N:N) -> 0 | G17: =E17-F17 -> #DIV/0! | H17: =SUMIF('2026 Planning by Brand'!$E:$E,'2026 Planning by Brand'!$E$233,'2026 Planning by Brand'!L:L) -> 0 | I17: =SUMIF('2026 Planning by Brand'!$E:$E,'2026 Planning by Brand'!$E$233,'2026 Planning by Brand'!O:O) -> 0 | J17: =H17-I17 -> 0
B18: Non-Alc | C18: Non-Alc - Soda | D18: =SUMIF('2026 Planning by Brand'!$E:$E,'2026 Planning by Brand'!$E$55,'2026 Planning by Brand'!H:H) -> 3464.1849 | E18: =AVERAGEIF('2026 Planning by Brand'!$E:$E,'2026 Planning by Brand'!$E$55,'2026 Planning by Brand'!K:K) -> 1.4233333 | F18: =AVERAGEIF('2026 Planning by Brand'!$E:$E,'2026 Planning by Brand'!$E$55,'2026 Planning by Brand'!N:N) -> 0.16666667 | G18: =E18-F18 -> 1.2566667 | H18: =SUMIF('2026 Planning by Brand'!$E:$E,'2026 Planning by Brand'!$E$55,'2026 Planning by Brand'!L:L) -> 21734.891 | I18: =SUMIF('2026 Planning by Brand'!$E:$E,'2026 Planning by Brand'!$E$55,'2026 Planning by Brand'!O:O) -> 8650.2639 | J18: =H18-I18 -> 13084.627
B19: Non-Alc | C19: Non-Alc – Mixer | D19: =SUMIF('2026 Planning by Brand'!$E:$E,'2026 Planning by Brand'!$E$331,'2026 Planning by Brand'!H:H) -> 306.63963 | E19: =AVERAGEIF('2026 Planning by Brand'!$E:$E,'2026 Planning by Brand'!$E$331,'2026 Planning by Brand'!K:K) -> 1.625 | F19: =AVERAGEIF('2026 Planning by Brand'!$E:$E,'2026 Planning by Brand'!$E$331,'2026 Planning by Brand'!N:N) -> -0.375 | G19: =E19-F19 -> 2 | H19: =SUMIF('2026 Planning by Brand'!$E:$E,'2026 Planning by Brand'!$E$331,'2026 Planning by Brand'!L:L) -> 158.76018 | I19: =SUMIF('2026 Planning by Brand'!$E:$E,'2026 Planning by Brand'!$E$331,'2026 Planning by Brand'!O:O) -> -81.239945 | J19: =H19-I19 -> 240.00012
B20: RTD | C20: RTD | D20: =SUMIF('2026 Planning by Brand'!$E:$E,'2026 Planning by Brand'!$E$18,'2026 Planning by Brand'!H:H) -> 102278.72 | E20: =AVERAGEIF('2026 Planning by Brand'!$E:$E,'2026 Planning by Brand'!$E$18,'2026 Planning by Brand'!K:K) -> 1.9070714 | F20: =AVERAGEIF('2026 Planning by Brand'!$E:$E,'2026 Planning by Brand'!$E$18,'2026 Planning by Brand'!N:N) -> 1.6746429 | G20: =E20-F20 -> 0.23242857 | H20: =SUMIF('2026 Planning by Brand'!$E:$E,'2026 Planning by Brand'!$E$18,'2026 Planning by Brand'!L:L) -> 72048.615 | I20: =SUMIF('2026 Planning by Brand'!$E:$E,'2026 Planning by Brand'!$E$18,'2026 Planning by Brand'!O:O) -> 48080.369 | J20: =H20-I20 -> 23968.246
B21: Seltzer | C21: Seltzer | D21: =SUMIF('2026 Planning by Brand'!$E:$E,'2026 Planning by Brand'!$E$80,'2026 Planning by Brand'!H:H) -> 336213.79 | E21: =AVERAGEIF('2026 Planning by Brand'!$E:$E,'2026 Planning by Brand'!$E$80,'2026 Planning by Brand'!K:K) -> -0.3085 | F21: =AVERAGEIF('2026 Planning by Brand'!$E:$E,'2026 Planning by Brand'!$E$80,'2026 Planning by Brand'!N:N) -> -0.317 | G21: =E21-F21 -> 0.0085 | H21: =SUMIF('2026 Planning by Brand'!$E:$E,'2026 Planning by Brand'!$E$80,'2026 Planning by Brand'!L:L) -> -35648.98 | I21: =SUMIF('2026 Planning by Brand'!$E:$E,'2026 Planning by Brand'!$E$80,'2026 Planning by Brand'!O:O) -> -42943.262 | J21: =H21-I21 -> 7294.2815
B22: Spirits | C22: Spirits - Vodka | D22: =SUMIF('2026 Planning by Brand'!$E:$E,'2026 Planning by Brand'!$E$215,'2026 Planning by Brand'!H:H) -> 16986.597 | E22: =AVERAGEIF('2026 Planning by Brand'!$E:$E,'2026 Planning by Brand'!$E$215,'2026 Planning by Brand'!K:K) -> #DIV/0! | F22: =AVERAGEIF('2026 Planning by Brand'!$E:$E,'2026 Planning by Brand'!$E$215,'2026 Planning by Brand'!N:N) -> 0.67 | G22: =E22-F22 -> #DIV/0! | H22: =SUMIF('2026 Planning by Brand'!$E:$E,'2026 Planning by Brand'!$E$215,'2026 Planning by Brand'!L:L) -> 0 | I22: =SUMIF('2026 Planning by Brand'!$E:$E,'2026 Planning by Brand'!$E$215,'2026 Planning by Brand'!O:O) -> 772.29624 | J22: =H22-I22 -> -772.29624
B23: Spirits | C23: Spirits - Whiskey | D23: =SUMIF('2026 Planning by Brand'!$E:$E,'2026 Planning by Brand'!$E$343,'2026 Planning by Brand'!H:H) -> 866.00649 | E23: =AVERAGEIF('2026 Planning by Brand'!$E:$E,'2026 Planning by Brand'!$E$343,'2026 Planning by Brand'!K:K) -> #DIV/0! | F23: =AVERAGEIF('2026 Planning by Brand'!$E:$E,'2026 Planning by Brand'!$E$343,'2026 Planning by Brand'!N:N) -> 0.83333333 | G23: =E23-F23 -> #DIV/0! | H23: =SUMIF('2026 Planning by Brand'!$E:$E,'2026 Planning by Brand'!$E$343,'2026 Planning by Brand'!L:L) -> 0 | I23: =SUMIF('2026 Planning by Brand'!$E:$E,'2026 Planning by Brand'!$E$343,'2026 Planning by Brand'!O:O) -> 274.00487 | J23: =H23-I23 -> -274.00487
B24: Spirits | C24: Spirits - Other | D24: =SUMIF('2026 Planning by Brand'!$E:$E,'2026 Planning by Brand'!$E$297,'2026 Planning by Brand'!H:H) -> 460.74997 | E24: =AVERAGEIF('2026 Planning by Brand'!$E:$E,'2026 Planning by Brand'!$E$297,'2026 Planning by Brand'!K:K) -> #DIV/0! | F24: =AVERAGEIF('2026 Planning by Brand'!$E:$E,'2026 Planning by Brand'!$E$297,'2026 Planning by Brand'!N:N) -> 1.26 | G24: =E24-F24 -> #DIV/0! | H24: =SUMIF('2026 Planning by Brand'!$E:$E,'2026 Planning by Brand'!$E$297,'2026 Planning by Brand'!L:L) -> 0 | I24: =SUMIF('2026 Planning by Brand'!$E:$E,'2026 Planning by Brand'!$E$297,'2026 Planning by Brand'!O:O) -> 101.6964 | J24: =H24-I24 -> -101.6964
B25: Spirits | C25: Spirits - Gin | D25: =SUMIF('2026 Planning by Brand'!$E:$E,'2026 Planning by Brand'!$E$191,'2026 Planning by Brand'!H:H) -> 27.625 | E25: =AVERAGEIF('2026 Planning by Brand'!$E:$E,'2026 Planning by Brand'!$E$191,'2026 Planning by Brand'!K:K) -> #DIV/0! | F25: =AVERAGEIF('2026 Planning by Brand'!$E:$E,'2026 Planning by Brand'!$E$191,'2026 Planning by Brand'!N:N) -> 1.6666667 | G25: =E25-F25 -> #DIV/0! | H25: =SUMIF('2026 Planning by Brand'!$E:$E,'2026 Planning by Brand'!$E$191,'2026 Planning by Brand'!L:L) -> 0 | I25: =SUMIF('2026 Planning by Brand'!$E:$E,'2026 Planning by Brand'!$E$191,'2026 Planning by Brand'!O:O) -> 80.499952 | J25: =H25-I25 -> -80.499952
B26: Spirits | C26: Spirits - Brandy | D26: =SUMIF('2026 Planning by Brand'!$E:$E,'2026 Planning by Brand'!$E$466,'2026 Planning by Brand'!H:H) -> 8 | E26: =AVERAGEIF('2026 Planning by Brand'!$E:$E,'2026 Planning by Brand'!$E$466,'2026 Planning by Brand'!K:K) -> #DIV/0! | F26: =AVERAGEIF('2026 Planning by Brand'!$E:$E,'2026 Planning by Brand'!$E$466,'2026 Planning by Brand'!N:N) -> #DIV/0! | G26: =E26-F26 -> #DIV/0! | H26: =SUMIF('2026 Planning by Brand'!$E:$E,'2026 Planning by Brand'!$E$466,'2026 Planning by Brand'!L:L) -> 0 | I26: =SUMIF('2026 Planning by Brand'!$E:$E,'2026 Planning by Brand'!$E$466,'2026 Planning by Brand'!O:O) -> 0 | J26: =H26-I26 -> 0
B27: Spirits | C27: Spirits - Tequila | D27: =SUMIF('2026 Planning by Brand'!$E:$E,'2026 Planning by Brand'!$E$368,'2026 Planning by Brand'!H:H) -> 13.736465 | E27: =AVERAGEIF('2026 Planning by Brand'!$E:$E,'2026 Planning by Brand'!$E$368,'2026 Planning by Brand'!K:K) -> #DIV/0! | F27: =AVERAGEIF('2026 Planning by Brand'!$E:$E,'2026 Planning by Brand'!$E$368,'2026 Planning by Brand'!N:N) -> 2.6666667 | G27: =E27-F27 -> #DIV/0! | H27: =SUMIF('2026 Planning by Brand'!$E:$E,'2026 Planning by Brand'!$E$368,'2026 Planning by Brand'!L:L) -> 0 | I27: =SUMIF('2026 Planning by Brand'!$E:$E,'2026 Planning by Brand'!$E$368,'2026 Planning by Brand'!O:O) -> 35.50389 | J27: =H27-I27 -> -35.50389
B28: THC | C28: THC | D28: =SUMIF('2026 Planning by Brand'!$E:$E,'2026 Planning by Brand'!$E$354,'2026 Planning by Brand'!H:H) -> 7634.667 | E28: =AVERAGEIF('2026 Planning by Brand'!$E:$E,'2026 Planning by Brand'!$E$354,'2026 Planning by Brand'!K:K) -> #DIV/0! | F28: =AVERAGEIF('2026 Planning by Brand'!$E:$E,'2026 Planning by Brand'!$E$354,'2026 Planning by Brand'!N:N) -> 4.3690476 | G28: =E28-F28 -> #DIV/0! | H28: =SUMIF('2026 Planning by Brand'!$E:$E,'2026 Planning by Brand'!$E$354,'2026 Planning by Brand'!L:L) -> 0 | I28: =SUMIF('2026 Planning by Brand'!$E:$E,'2026 Planning by Brand'!$E$354,'2026 Planning by Brand'!O:O) -> 6158.5041 | J28: =H28-I28 -> -6158.5041
B29: Wine | C29: Wine - Other | D29: =SUMIF('2026 Planning by Brand'!$E:$E,'2026 Planning by Brand'!$E$337,'2026 Planning by Brand'!H:H) -> 781.99498 | E29: =AVERAGEIF('2026 Planning by Brand'!$E:$E,'2026 Planning by Brand'!$E$337,'2026 Planning by Brand'!K:K) -> #DIV/0! | F29: =AVERAGEIF('2026 Planning by Brand'!$E:$E,'2026 Planning by Brand'!$E$337,'2026 Planning by Brand'!N:N) -> 0.083333333 | G29: =E29-F29 -> #DIV/0! | H29: =SUMIF('2026 Planning by Brand'!$E:$E,'2026 Planning by Brand'!$E$337,'2026 Planning by Brand'!L:L) -> 0 | I29: =SUMIF('2026 Planning by Brand'!$E:$E,'2026 Planning by Brand'!$E$337,'2026 Planning by Brand'!O:O) -> 27.843729 | J29: =H29-I29 -> -27.843729
B30: Wine | C30: Wine - White | D30: =SUMIF('2026 Planning by Brand'!$E:$E,'2026 Planning by Brand'!$E$296,'2026 Planning by Brand'!H:H) -> 174.78572 | E30: =AVERAGEIF('2026 Planning by Brand'!$E:$E,'2026 Planning by Brand'!$E$296,'2026 Planning by Brand'!K:K) -> #DIV/0! | F30: =AVERAGEIF('2026 Planning by Brand'!$E:$E,'2026 Planning by Brand'!$E$296,'2026 Planning by Brand'!N:N) -> 9.82 | G30: =E30-F30 -> #DIV/0! | H30: =SUMIF('2026 Planning by Brand'!$E:$E,'2026 Planning by Brand'!$E$296,'2026 Planning by Brand'!L:L) -> 0 | I30: =SUMIF('2026 Planning by Brand'!$E:$E,'2026 Planning by Brand'!$E$296,'2026 Planning by Brand'!O:O) -> 563.42604 | J30: =H30-I30 -> -563.42604
B31: Wine | C31: Wine - Red | D31: =SUMIF('2026 Planning by Brand'!$E:$E,'2026 Planning by Brand'!$E$367,'2026 Planning by Brand'!H:H) -> 19.972198 | E31: =AVERAGEIF('2026 Planning by Brand'!$E:$E,'2026 Planning by Brand'!$E$367,'2026 Planning by Brand'!K:K) -> #DIV/0! | F31: =AVERAGEIF('2026 Planning by Brand'!$E:$E,'2026 Planning by Brand'!$E$367,'2026 Planning by Brand'!N:N) -> 8 | G31: =E31-F31 -> #DIV/0! | H31: =SUMIF('2026 Planning by Brand'!$E:$E,'2026 Planning by Brand'!$E$367,'2026 Planning by Brand'!L:L) -> 0 | I31: =SUMIF('2026 Planning by Brand'!$E:$E,'2026 Planning by Brand'!$E$367,'2026 Planning by Brand'!O:O) -> 516.83529 | J31: =H31-I31 -> -516.83529
B32: Wine | C32: Wine - Rose | D32: =SUMIF('2026 Planning by Brand'!$E:$E,'2026 Planning by Brand'!$E$398,'2026 Planning by Brand'!H:H) -> 3.170064 | E32: =AVERAGEIF('2026 Planning by Brand'!$E:$E,'2026 Planning by Brand'!$E$398,'2026 Planning by Brand'!K:K) -> #DIV/0! | F32: =AVERAGEIF('2026 Planning by Brand'!$E:$E,'2026 Planning by Brand'!$E$398,'2026 Planning by Brand'!N:N) -> 15 | G32: =E32-F32 -> #DIV/0! | H32: =SUMIF('2026 Planning by Brand'!$E:$E,'2026 Planning by Brand'!$E$398,'2026 Planning by Brand'!L:L) -> 0 | I32: =SUMIF('2026 Planning by Brand'!$E:$E,'2026 Planning by Brand'!$E$398,'2026 Planning by Brand'!O:O) -> 47.55096 | J32: =H32-I32 -> -47.55096

Sheet 2025 Finish (ACTUAL)
A1: Supplier / Brand Family | B1: Supplier | D1: Case Equiv 1/1/2025 - 12/31/2025
A2: Total | C2: =A2&"|"&B2 -> Total| | D2: 7067012.3
A3: Constellation Brands | C3: =A3&"|"&B3 -> Constellation Brands| | D3: 2631932.7
A4: Corona Extra | B4: Constellation Brands | C4: =A4&"|"&B4 -> Corona Extra|Constellation Brands | D4: 1217068.1
A5: Modelo Especial | B5: Constellation Brands | C5: =A5&"|"&B5 -> Modelo Especial|Constellation Brands | D5: 1061492.6
A6: Modelo Chelada | B6: Constellation Brands | C6: =A6&"|"&B6 -> Modelo Chelada|Constellation Brands | D6: 86203.667
A7: Victoria | B7: Constellation Brands | C7: =A7&"|"&B7 -> Victoria|Constellation Brands | D7: 62550.664
A8: Corona Light | B8: Constellation Brands | C8: =A8&"|"&B8 -> Corona Light|Constellation Brands | D8: 49496
A9: Corona Familiar | B9: Constellation Brands | C9: =A9&"|"&B9 -> Corona Familiar|Constellation Brands | D9: 35513.661
A10: Corona Premier | B10: Constellation Brands | C10: =A10&"|"&B10 -> Corona Premier|Constellation Brands | D10: 33624.306
A11: Pacifico | B11: Constellation Brands | C11: =A11&"|"&B11 -> Pacifico|Constellation Brands | D11: 33530.222
A12: Modelo Negra | B12: Constellation Brands | C12: =A12&"|"&B12 -> Modelo Negra|Constellation Brands | D12: 25034.555
A13: Corona Sunbrew | B13: Constellation Brands | C13: =A13&"|"&B13 -> Corona Sunbrew|Constellation Brands | D13: 9386
A14: Corona NA | B14: Constellation Brands | C14: =A14&"|"&B14 -> Corona NA|Constellation Brands | D14: 8481
A15: Modelo Oro | B15: Constellation Brands | C15: =A15&"|"&B15 -> Modelo Oro|Constellation Brands | D15: 5453
... A19: The Drop | B19: Constellation Brands | C19: =A19&"|"&B19 -> The Drop|Constellation Brands | D19: 365
A20: MolsonCoors Beverage Company | C20: =A20&"|"&B20 -> MolsonCoors Beverage Company| | D20: 1864356.1
A21: Coors Light | B21: MolsonCoors Beverage Company | C21: =A21&"|"&B21 -> Coors Light|MolsonCoors Beverage Company | D21: 792237.3
A22: Lite | B22: MolsonCoors Beverage Company | C22: =A22&"|"&B22 -> Lite|MolsonCoors Beverage Company | D22: 514391.6
A23: Blue Moon | B23: MolsonCoors Beverage Company | C23: =A23&"|"&B23 -> Blue Moon|MolsonCoors Beverage Company | D23: 123103.9
A24: Coors | B24: MolsonCoors Beverage Company | C24: =A24&"|"&B24 -> Coors|MolsonCoors Beverage Company | D24: 112534.69
A25: Miller High Life | B25: MolsonCoors Beverage Company | C25: =A25&"|"&B25 -> Miller High Life|MolsonCoors Beverage Company | D25: 66734.691
A26: Peroni | B26: MolsonCoors Beverage Company | C26: =A26&"|"&B26 -> Peroni|MolsonCoors Beverage Company | D26: 57382.712
A27: Fosters | B27: MolsonCoors Beverage Company | C27: =A27&"|"&B27 -> Fosters|MolsonCoors Beverage Company | D27: 22845.126
A28: Tyskie Gronie | B28: MolsonCoors Beverage Company | C28: =A28&"|"&B28 -> Tyskie Gronie|MolsonCoors Beverage Company | D28: 19094.721
A29: Arnold Palmer | B29: MolsonCoors Beverage Company | C29: =A29&"|"&B29 -> Arnold Palmer|MolsonCoors Beverage Company | D29: 17932
A30: Leinenkugel | B30: MolsonCoors Beverage Company | C30: =A30&"|"&B30 -> Leinenkugel|MolsonCoors Beverage Company | D30: 17664.34
A31: Keystone | B31: MolsonCoors Beverage Company | C31: =A31&"|"&B31 -> Keystone|MolsonCoors Beverage Company | D31: 14746.5
A32: Steel Reserve | B32: MolsonCoors Beverage Company | C32: =A32&"|"&B32 -> Steel Reserve|MolsonCoors Beverage Company | D32: 13417.249
... A55: Steel Reserve Alloy Series | B55: MolsonCoors Beverage Company | C55: =A55&"|"&B55 -> Steel Reserve Alloy Series|MolsonCoors Beverage Company | D55: 10
A56: Heineken USA | C56: =A56&"|"&B56 -> Heineken USA| | D56: 538278.18
A57: Heineken USA | B57: Heineken USA | C57: =A57&"|"&B57 -> Heineken USA|Heineken USA | D57: 427765.62
A58: Heineken Light | B58: Heineken USA | C58: =A58&"|"&B58 -> Heineken Light|Heineken USA | D58: 35718
A59: Heineken 0.0 | B59: Heineken USA | C59: =A59&"|"&B59 -> Heineken 0.0|Heineken USA | D59: 26535.735
A60: Amstel | B60: Heineken USA | C60: =A60&"|"&B60 -> Amstel|Heineken USA | D60: 13528
A61: Tecate | B61: Heineken USA | C61: =A61&"|"&B61 -> Tecate|Heineken USA | D61: 11132
A62: Dos Equis | B62: Heineken USA | C62: =A62&"|"&B62 -> Dos Equis|Heineken USA | D62: 8335.8889
A63: Red Stripe | B63: Heineken USA | C63: =A63&"|"&B63 -> Red Stripe|Heineken USA | D63: 7300.5711
A64: Heineken Silver | B64: Heineken USA | C64: =A64&"|"&B64 -> Heineken Silver|Heineken USA | D64: 3651
A65: Murphy's | B65: Heineken USA | C65: =A65&"|"&B65 -> Murphy's|Heineken USA | D65: 1656.9936
...

Sheet Brand Managers
A1: Supplier | B1: Brand Manager
A2: 2 Towns Ciderhouse | B2: Chris Politano
A3: Alias Brew Works | B3: Sean Donahue
A4: Alte Beverage | B4: Jason Koo
A5: American Fruits | B5: Tom Gibbons
A6: Artisanal Imports | B6: Steve Halloran
A7: Athletic Brewing Company | B7: Dan Downing
A8: Bardstown Bourbon Co | B8: Jason Koo
A9: Barn Brew Co | B9: Sean Donahue
A10: Beak & Skiff | B10: Steve Halloran
A11: Bell's | B11: Chris Politano
A12: Bella Ray Beverage | B12: Jason Koo
A13: Berczy LLC
A14: BJ'S Private Label Brew | B14: Sean Donahue
A15: Blaze Life LLC | B15: Jason Koo
A16: Bold Rock Hard Cider | B16: Sean Donahue
A17: Boston Beer Company | B17: Chris Politano
A18: Brewt's LLC | B18: Chris Politano
A19: Buzbee's Beverages USA LLC | B19: Chris Politano
A20: Cape May | B20: Sean Donahue
A21: Caravella Inc | B21: Jason Koo
A22: Cavalier Ventures, LLC | B22: Chris Politano
A23: Cerveceria La Tropical | B23: Steve Halloran
A24: Chateau Diana Winery | B24: Jason Koo
A25: Citizen Cider | B25: Tom Gibbons
... A38: Emergent Beverage Partners | B38: Jason Koo
A39: Ever Grand Group LLC
A40: Evil Genius | B40: Sean Donahue
A41: Famosa | B41: Tom Gibbons
A42: FIFCO | B42: Dan Downing
A43: Florida Caribbean Distillers LLC
A44: Flying Fish | B44: Sean Donahue
A45: Food & Bev Enterprise LLC | B45: Denise Montes
A46: Forged Irish Stout | B46: Chris Politano
A47: FX Matt | B47: Tom Gibbons
A48: Gambrinus Imports | B48: Perry Calderone
A49: Garage Beer | B49: Sean Donahue
A50: Gigli
A51: Global Beer | B51: Perry Calderone
A52: Global Village Imp. | B52: Dan Downing
...

Sheet DATA - 2025 Review
A1: Supplier / Brand Family | B1: Supplier | C1: Unique ID | D1: CE 1/1/2024 - 10/31/2024 | E1: CE 1/1/2025 - 10/31/2025 | F1: CE % ± | G1: CE 11/1/2024 - 12/31/2024 | H1: 2024 Finish | I1: Estimated 2025 Finish | J1: Estimated % +/- | K1: 2025 Brewery Goal % Change | L1: 2025 Brewery CE Change | M1: Actual vs. Brewery | N1: 2025 Kohler Goal +/- % | O1: 2025 Kohler Goal CE Change | P1: Actual vs. Kohler | Q1: Kohler v. Brewery | U1: 2025 Brewery Goal
A2: Total | C2: =A2&"|"&B2 -> Total| | D2: 6303001.8 | E2: 5917790.3 | F2: -0.061116 | G2: 1225228.6 | H2: 7528230.4 | I2: =SUMIF(B3:B462,"<>",I3:I462) -> 7085209.6 | J2: =IFERROR((I2/H2)-1,0) -> -0.05884793 | K2: =L2/I2 -> 0.033584264 | L2: =SUMIF(B3:B462,"<>",L3:L462) -> 237951.55 | M2: =J2-K2 -> -0.092432193 | N2: =O2/H2 -> 0.020818312 | O2: =SUMIF(B3:B462,"<>",O3:O462) -> 156725.05 | P2: =J2-N2 -> -0.079666242 | Q2: =P2-M2 -> 0.012765952 | U2: =SUMIF(B3:B462,"<>",U3:U462) -> #VALUE!
A3: Constellation Brands | C3: =A3&"|"&B3 -> Constellation Brands| | D3: 2337400.8 | E3: 2202559.1 | F3: -0.057689 | G3: 443052 | H3: 2780452.8 | I3: =((G3*F3)+G3)+E3 -> 2620051.9 | J3: =IFERROR((I3/H3)-1,0) -> -0.057688778 | K3: =_xlfn.XLOOKUP(C3,'2025 Goal Data'!C:C,'2025 Goal Data'!F:F,"") -> 0.045978764 | L3: =IFERROR(K3*H3,0) -> 127841.78 | M3: =IFERROR(J3-K3,0) -> -0.10366754 | N3: =_xlfn.XLOOKUP(C3,'2025 Goal Data'!C:C,'2025 Goal Data'!I:I,"") -> 0.045978764 | O3: =IFERROR(N3*H3,0) -> 127841.78 | P3: =IFERROR(J3-N3,0) -> -0.10366754 | Q3: =P3-M3 -> 0 | U3: =SUMIF(B:B,A3,K:K) -> 1.209
A4: Corona Extra | B4: Constellation Brands | C4: =A4&"|"&B4 -> Corona Extra|Constellation Brands | D4: 1103390.1 | E4: 1021813.6 | F4: -0.073933 | G4: 212042.89 | H4: 1315433 | I4: =((G4*F4)+G4)+E4 -> 1218179.5 | J4: =IFERROR((I4/H4)-1,0) -> -0.073932646 | K4: =_xlfn.XLOOKUP(C4,'2025 Goal Data'!C:C,'2025 Goal Data'!F:F,"") -> 0.01 | L4: =IFERROR(K4*H4,0) -> 13154.33 | M4: =IFERROR(J4-K4,0) -> -0.083932646 | N4: =_xlfn.XLOOKUP(C4,'2025 Goal Data'!C:C,'2025 Goal Data'!I:I,"") -> 0.01 | O4: =IFERROR(N4*H4,0) -> 13154.33 | P4: =IFERROR(J4-N4,0) -> -0.083932646 | Q4: =P4-M4 -> 0 | U4: =(H4*K4)+H4 -> 1328587.3
A5: Modelo Especial | B5: Constellation Brands | C5: =A5&"|"&B5 -> Modelo Especial|Constellation Brands | D5: 938653.53 | E5: 884213.55 | F5: -0.057998 | G5: 180140.05 | H5: 1118793.6 | I5: =((G5*F5)+G5)+E5 -> 1053905.8 | J5: =IFERROR((I5/H5)-1,0) -> -0.057997953 | K5: =_xlfn.XLOOKUP(C5,'2025 Goal Data'!C:C,'2025 Goal Data'!F:F,"") -> 0.075 | L5: =IFERROR(K5*H5,0) -> 83909.518 | M5: =IFERROR(J5-K5,0) -> -0.13299795 | N5: =_xlfn.XLOOKUP(C5,'2025 Goal Data'!C:C,'2025 Goal Data'!I:I,"") -> 0.075 | O5: =IFERROR(N5*H5,0) -> 83909.518 | P5: =IFERROR(J5-N5,0) -> -0.13299795 | Q5: =P5-M5 -> 0 | U5: =(H5*K5)+H5 -> 1202703.1
A6: Modelo Chelada | B6: Constellation Brands | C6: =A6&"|"&B6 -> Modelo Chelada|Constellation Brands | D6: 67041 | E6: 72122.333 | F6: 0.075794 | G6: 11074 | H6: 78115 | I6: =((G6*F6)+G6)+E6 -> 84035.676 | J6: =IFERROR((I6/H6)-1,0) -> 0.075794355 | K6: =_xlfn.XLOOKUP(C6,'2025 Goal Data'!C:C,'2025 Goal Data'!F:F,"") -> 0.1 | L6: =IFERROR(K6*H6,0) -> 7811.5 | M6: =IFERROR(J6-K6,0) -> -0.024205645 | N6: =_xlfn.XLOOKUP(C6,'2025 Goal Data'!C:C,'2025 Goal Data'!I:I,"") -> 0.1 | O6: =IFERROR(N6*H6,0) -> 7811.5 | P6: =IFERROR(J6-N6,0) -> -0.024205645 | Q6: =P6-M6 -> 0 | U6: =(H6*K6)+H6 -> 85926.5
A7: Victoria | B7: Constellation Brands | C7: =A7&"|"&B7 -> Victoria|Constellation Brands | D7: 46862.331 | E7: 51385.664 | F7: 0.096524 | G7: 9363.9997 | H7: 56226.331 | I7: =((G7*F7)+G7)+E7 -> 61653.515 | J7: =IFERROR((I7/H7)-1,0) -> 0.096523882 | K7: =_xlfn.XLOOKUP(C7,'2025 Goal Data'!C:C,'2025 Goal Data'!F:F,"") -> 0.24 | L7: =IFERROR(K7*H7,0) -> 13494.319 | M7: =IFERROR(J7-K7,0) -> -0.14347612 | N7: =_xlfn.XLOOKUP(C7,'2025 Goal Data'!C:C,'2025 Goal Data'!I:I,"") -> 0.24 | O7: =IFERROR(N7*H7,0) -> 13494.319 | P7: =IFERROR(J7-N7,0) -> -0.14347612 | Q7: =P7-M7 -> 0 | U7: =(H7*K7)+H7 -> 69720.65
A8: Corona Light | B8: Constellation Brands | C8: =A8&"|"&B8 -> Corona Light|Constellation Brands | D8: 50415 | E8: 42478 | F8: -0.157433 | G8: 7491 | H8: 57906 | I8: =((G8*F8)+G8)+E8 -> 48789.669 | J8: =IFERROR((I8/H8)-1,0) -> -0.15743326 | K8: =_xlfn.XLOOKUP(C8,'2025 Goal Data'!C:C,'2025 Goal Data'!F:F,"") -> -0.09 | L8: =IFERROR(K8*H8,0) -> -5211.54 | M8: =IFERROR(J8-K8,0) -> -0.067433264 | N8: =_xlfn.XLOOKUP(C8,'2025 Goal Data'!C:C,'2025 Goal Data'!I:I,"") -> -0.09 | O8: =IFERROR(N8*H8,0) -> -5211.54 | P8: =IFERROR(J8-N8,0) -> -0.067433264 | Q8: =P8-M8 -> 0 | U8: =(H8*K8)+H8 -> 52694.46
A9: Corona Familiar | B9: Constellation Brands | C9: =A9&"|"&B9 -> Corona Familiar|Constellation Brands | D9: 26843.996 | E9: 29423.328 | F9: 0.096086 | G9: 5566.3324 | H9: 32410.328 | I9: =((G9*F9)+G9)+E9 -> 35524.507 | J9: =IFERROR((I9/H9)-1,0) -> 0.096086016 | K9: =_xlfn.XLOOKUP(C9,'2025 Goal Data'!C:C,'2025 Goal Data'!F:F,"") -> 0.04 | L9: =IFERROR(K9*H9,0) -> 1296.4131 | M9: =IFERROR(J9-K9,0) -> 0.056086016 | N9: =_xlfn.XLOOKUP(C9,'2025 Goal Data'!C:C,'2025 Goal Data'!I:I,"") -> 0.04 | O9: =IFERROR(N9*H9,0) -> 1296.4131 | P9: =IFERROR(J9-N9,0) -> 0.056086016 | Q9: =P9-M9 -> 0 | U9: =(H9*K9)+H9 -> 33706.741
A10: Corona Premier | B10: Constellation Brands | C10: =A10&"|"&B10 -> Corona Premier|Constellation Brands | D10: 32719.972 | E10: 28314.278 | F10: -0.134648 | G10: 5401.9444 | H10: 38121.917 | I10: =((G10*F10)+G10)+E10 -> 32988.861 | J10: =IFERROR((I10/H10)-1,0) -> -0.13464841 | K10: =_xlfn.XLOOKUP(C10,'2025 Goal Data'!C:C,'2025 Goal Data'!F:F,"") -> -0.09 | L10: =IFERROR(K10*H10,0) -> -3430.9725 | M10: =IFERROR(J10-K10,0) -> -0.04464841 | N10: =_xlfn.XLOOKUP(C10,'2025 Goal Data'!C:C,'2025 Goal Data'!I:I,"") -> -0.09 | O10: =IFERROR(N10*H10,0) -> -3430.9725 | P10: =IFERROR(J10-N10,0) -> -0.04464841 | Q10: =P10-M10 -> 0 | U10: =(H10*K10)+H10 -> 34690.944
