Workbook

Sheet Recap
A1: Summer of Success 2026 — Recap by rep and supplier
A2: Filter any column from row 4. Status drives everything: Qualified = tier payout + full Amplify rate · 90% Partial = half Amplify rate, no tier · Not Qualified = nothing.
A4: Rep | B4: Manager | C4: Supplier | D4: Qualifier goal | E4: Actual CE | F4: % to goal | G4: Status | H4: Tier earned | I4: Tier payout | J4: Amplify actual CE | K4: Amplify goal CE | L4: Eligible amplify CE | M4: Amplify payout | N4: Total payout | O4: Rate multiplier | P4: Key
A5: Alex Rodriguez | B5: Mike Kennedy | C5: Sapporo | F5: =IF($D5>0,$E5/$D5,"") | G5: =IF($D5>0,IF($F5>=1,"Qualified",IF($F5>=0.9,"90% Partial Amplify","Not Qualified")),"No qualifier - Amplify open") | H5: =IF($G5<>"Qualified","-",IFERROR(IF($E5>=INDEX('Program Setup'!$C$18:$C$23,MATCH($C5,'Program Setup'!$B$18:$B$23,0)),1,IF($E5>=INDEX('Program Setup'!$D$18:$D$23,MATCH($C5,'Program Setup'!$B$18:$B$23,0)),2,IF($E5>=INDEX('Program Setup'!$E$18:$E$23,MATCH($C5,'Program Setup'!$B$18:$B$23,0)),3,"-"))),"-")) | I5: =IF(ISNUMBER($H5),INDEX('Program Setup'!$B$6:$B$8,MATCH($H5,'Program Setup'!$A$6:$A$8,0)),0) | J5: =SUMIFS('Amplify Detail'!$E$5:$E$496,'Amplify Detail'!$A$5:$A$496,$A5,'Amplify Detail'!$C$5:$C$496,$C5) | K5: =SUMIFS('Amplify Detail'!$F$5:$F$496,'Amplify Detail'!$A$5:$A$496,$A5,'Amplify Detail'!$C$5:$C$496,$C5) | L5: =SUMIFS('Amplify Detail'!$G$5:$G$496,'Amplify Detail'!$A$5:$A$496,$A5,'Amplify Detail'!$C$5:$C$496,$C5) | M5: =SUMIFS('Amplify Detail'!$J$5:$J$496,'Amplify Detail'!$A$5:$A$496,$A5,'Amplify Detail'!$C$5:$C$496,$C5) | N5: =$I5+$M5 | O5: =IF($G5="No qualifier - Amplify open",1,IFERROR(INDEX('Program Setup'!$B$12:$B$14,MATCH($G5,'Program Setup'!$A$12:$A$14,0)),0)) | P5: =$A5&"|"&$C5
A6: Alisa Acciardi | B6: Mike Kennedy | C6: Boston Beer Company | E6: 24 | F6: =IF($D6>0,$E6/$D6,"") | G6: =IF($D6>0,IF($F6>=1,"Qualified",IF($F6>=0.9,"90% Partial Amplify","Not Qualified")),"No qualifier - Amplify open") | H6: =IF($G6<>"Qualified","-",IFERROR(IF($E6>=INDEX('Program Setup'!$C$18:$C$23,MATCH($C6,'Program Setup'!$B$18:$B$23,0)),1,IF($E6>=INDEX('Program Setup'!$D$18:$D$23,MATCH($C6,'Program Setup'!$B$18:$B$23,0)),2,IF($E6>=INDEX('Program Setup'!$E$18:$E$23,MATCH($C6,'Program Setup'!$B$18:$B$23,0)),3,"-"))),"-")) | I6: =IF(ISNUMBER($H6),INDEX('Program Setup'!$B$6:$B$8,MATCH($H6,'Program Setup'!$A$6:$A$8,0)),0) | J6: =SUMIFS('Amplify Detail'!$E$5:$E$496,'Amplify Detail'!$A$5:$A$496,$A6,'Amplify Detail'!$C$5:$C$496,$C6) | K6: =SUMIFS('Amplify Detail'!$F$5:$F$496,'Amplify Detail'!$A$5:$A$496,$A6,'Amplify Detail'!$C$5:$C$496,$C6) | L6: =SUMIFS('Amplify Detail'!$G$5:$G$496,'Amplify Detail'!$A$5:$A$496,$A6,'Amplify Detail'!$C$5:$C$496,$C6) | M6: =SUMIFS('Amplify Detail'!$J$5:$J$496,'Amplify Detail'!$A$5:$A$496,$A6,'Amplify Detail'!$C$5:$C$496,$C6) | N6: =$I6+$M6 | O6: =IF($G6="No qualifier - Amplify open",1,IFERROR(INDEX('Program Setup'!$B$12:$B$14,MATCH($G6,'Program Setup'!$A$12:$A$14,0)),0)) | P6: =$A6&"|"&$C6
A7: Alisa Acciardi | B7: Mike Kennedy | C7: Cape May | F7: =IF($D7>0,$E7/$D7,"") | G7: =IF($D7>0,IF($F7>=1,"Qualified",IF($F7>=0.9,"90% Partial Amplify","Not Qualified")),"No qualifier - Amplify open") | H7: =IF($G7<>"Qualified","-",IFERROR(IF($E7>=INDEX('Program Setup'!$C$18:$C$23,MATCH($C7,'Program Setup'!$B$18:$B$23,0)),1,IF($E7>=INDEX('Program Setup'!$D$18:$D$23,MATCH($C7,'Program Setup'!$B$18:$B$23,0)),2,IF($E7>=INDEX('Program Setup'!$E$18:$E$23,MATCH($C7,'Program Setup'!$B$18:$B$23,0)),3,"-"))),"-")) | I7: =IF(ISNUMBER($H7),INDEX('Program Setup'!$B$6:$B$8,MATCH($H7,'Program Setup'!$A$6:$A$8,0)),0) | J7: =SUMIFS('Amplify Detail'!$E$5:$E$496,'Amplify Detail'!$A$5:$A$496,$A7,'Amplify Detail'!$C$5:$C$496,$C7) | K7: =SUMIFS('Amplify Detail'!$F$5:$F$496,'Amplify Detail'!$A$5:$A$496,$A7,'Amplify Detail'!$C$5:$C$496,$C7) | L7: =SUMIFS('Amplify Detail'!$G$5:$G$496,'Amplify Detail'!$A$5:$A$496,$A7,'Amplify Detail'!$C$5:$C$496,$C7) | M7: =SUMIFS('Amplify Detail'!$J$5:$J$496,'Amplify Detail'!$A$5:$A$496,$A7,'Amplify Detail'!$C$5:$C$496,$C7) | N7: =$I7+$M7 | O7: =IF($G7="No qualifier - Amplify open",1,IFERROR(INDEX('Program Setup'!$B$12:$B$14,MATCH($G7,'Program Setup'!$A$12:$A$14,0)),0)) | P7: =$A7&"|"&$C7
A8: Alisa Acciardi | B8: Mike Kennedy | C8: Constellation Brands | D8: 453 | E8: 430 | F8: =IF($D8>0,$E8/$D8,"") | G8: =IF($D8>0,IF($F8>=1,"Qualified",IF($F8>=0.9,"90% Partial Amplify","Not Qualified")),"No qualifier - Amplify open") | H8: =IF($G8<>"Qualified","-",IFERROR(IF($E8>=INDEX('Program Setup'!$C$18:$C$23,MATCH($C8,'Program Setup'!$B$18:$B$23,0)),1,IF($E8>=INDEX('Program Setup'!$D$18:$D$23,MATCH($C8,'Program Setup'!$B$18:$B$23,0)),2,IF($E8>=INDEX('Program Setup'!$E$18:$E$23,MATCH($C8,'Program Setup'!$B$18:$B$23,0)),3,"-"))),"-")) | I8: =IF(ISNUMBER($H8),INDEX('Program Setup'!$B$6:$B$8,MATCH($H8,'Program Setup'!$A$6:$A$8,0)),0) | J8: =SUMIFS('Amplify Detail'!$E$5:$E$496,'Amplify Detail'!$A$5:$A$496,$A8,'Amplify Detail'!$C$5:$C$496,$C8) | K8: =SUMIFS('Amplify Detail'!$F$5:$F$496,'Amplify Detail'!$A$5:$A$496,$A8,'Amplify Detail'!$C$5:$C$496,$C8) | L8: =SUMIFS('Amplify Detail'!$G$5:$G$496,'Amplify Detail'!$A$5:$A$496,$A8,'Amplify Detail'!$C$5:$C$496,$C8) | M8: =SUMIFS('Amplify Detail'!$J$5:$J$496,'Amplify Detail'!$A$5:$A$496,$A8,'Amplify Detail'!$C$5:$C$496,$C8) | N8: =$I8+$M8 | O8: =IF($G8="No qualifier - Amplify open",1,IFERROR(INDEX('Program Setup'!$B$12:$B$14,MATCH($G8,'Program Setup'!$A$12:$A$14,0)),0)) | P8: =$A8&"|"&$C8
A9: Alisa Acciardi | B9: Mike Kennedy | C9: DG Yuengling Inc | D9: 19 | E9: 22 | F9: =IF($D9>0,$E9/$D9,"") | G9: =IF($D9>0,IF($F9>=1,"Qualified",IF($F9>=0.9,"90% Partial Amplify","Not Qualified")),"No qualifier - Amplify open") | H9: =IF($G9<>"Qualified","-",IFERROR(IF($E9>=INDEX('Program Setup'!$C$18:$C$23,MATCH($C9,'Program Setup'!$B$18:$B$23,0)),1,IF($E9>=INDEX('Program Setup'!$D$18:$D$23,MATCH($C9,'Program Setup'!$B$18:$B$23,0)),2,IF($E9>=INDEX('Program Setup'!$E$18:$E$23,MATCH($C9,'Program Setup'!$B$18:$B$23,0)),3,"-"))),"-")) | I9: =IF(ISNUMBER($H9),INDEX('Program Setup'!$B$6:$B$8,MATCH($H9,'Program Setup'!$A$6:$A$8,0)),0) | J9: =SUMIFS('Amplify Detail'!$E$5:$E$496,'Amplify Detail'!$A$5:$A$496,$A9,'Amplify Detail'!$C$5:$C$496,$C9) | K9: =SUMIFS('Amplify Detail'!$F$5:$F$496,'Amplify Detail'!$A$5:$A$496,$A9,'Amplify Detail'!$C$5:$C$496,$C9) | L9: =SUMIFS('Amplify Detail'!$G$5:$G$496,'Amplify Detail'!$A$5:$A$496,$A9,'Amplify Detail'!$C$5:$C$496,$C9) | M9: =SUMIFS('Amplify Detail'!$J$5:$J$496,'Amplify Detail'!$A$5:$A$496,$A9,'Amplify Detail'!$C$5:$C$496,$C9) | N9: =$I9+$M9 | O9: =IF($G9="No qualifier - Amplify open",1,IFERROR(INDEX('Program Setup'!$B$12:$B$14,MATCH($G9,'Program Setup'!$A$12:$A$14,0)),0)) | P9: =$A9&"|"&$C9
A10: Alisa Acciardi | B10: Mike Kennedy | C10: Heineken USA | D10: 149 | E10: 76 | F10: =IF($D10>0,$E10/$D10,"") | G10: =IF($D10>0,IF($F10>=1,"Qualified",IF($F10>=0.9,"90% Partial Amplify","Not Qualified")),"No qualifier - Amplify open") | H10: =IF($G10<>"Qualified","-",IFERROR(IF($E10>=INDEX('Program Setup'!$C$18:$C$23,MATCH($C10,'Program Setup'!$B$18:$B$23,0)),1,IF($E10>=INDEX('Program Setup'!$D$18:$D$23,MATCH($C10,'Program Setup'!$B$18:$B$23,0)),2,IF($E10>=INDEX('Program Setup'!$E$18:$E$23,MATCH($C10,'Program Setup'!$B$18:$B$23,0)),3,"-"))),"-")) | I10: =IF(ISNUMBER($H10),INDEX('Program Setup'!$B$6:$B$8,MATCH($H10,'Program Setup'!$A$6:$A$8,0)),0) | J10: =SUMIFS('Amplify Detail'!$E$5:$E$496,'Amplify Detail'!$A$5:$A$496,$A10,'Amplify Detail'!$C$5:$C$496,$C10) | K10: =SUMIFS('Amplify Detail'!$F$5:$F$496,'Amplify Detail'!$A$5:$A$496,$A10,'Amplify Detail'!$C$5:$C$496,$C10) | L10: =SUMIFS('Amplify Detail'!$G$5:$G$496,'Amplify Detail'!$A$5:$A$496,$A10,'Amplify Detail'!$C$5:$C$496,$C10) | M10: =SUMIFS('Amplify Detail'!$J$5:$J$496,'Amplify Detail'!$A$5:$A$496,$A10,'Amplify Detail'!$C$5:$C$496,$C10) | N10: =$I10+$M10 | O10: =IF($G10="No qualifier - Amplify open",1,IFERROR(INDEX('Program Setup'!$B$12:$B$14,MATCH($G10,'Program Setup'!$A$12:$A$14,0)),0)) | P10: =$A10&"|"&$C10
A11: Alisa Acciardi | B11: Mike Kennedy | C11: Mark Anthony | D11: 80 | E11: 83 | F11: =IF($D11>0,$E11/$D11,"") | G11: =IF($D11>0,IF($F11>=1,"Qualified",IF($F11>=0.9,"90% Partial Amplify","Not Qualified")),"No qualifier - Amplify open") | H11: =IF($G11<>"Qualified","-",IFERROR(IF($E11>=INDEX('Program Setup'!$C$18:$C$23,MATCH($C11,'Program Setup'!$B$18:$B$23,0)),1,IF($E11>=INDEX('Program Setup'!$D$18:$D$23,MATCH($C11,'Program Setup'!$B$18:$B$23,0)),2,IF($E11>=INDEX('Program Setup'!$E$18:$E$23,MATCH($C11,'Program Setup'!$B$18:$B$23,0)),3,"-"))),"-")) | I11: =IF(ISNUMBER($H11),INDEX('Program Setup'!$B$6:$B$8,MATCH($H11,'Program Setup'!$A$6:$A$8,0)),0) | J11: =SUMIFS('Amplify Detail'!$E$5:$E$496,'Amplify Detail'!$A$5:$A$496,$A11,'Amplify Detail'!$C$5:$C$496,$C11) | K11: =SUMIFS('Amplify Detail'!$F$5:$F$496,'Amplify Detail'!$A$5:$A$496,$A11,'Amplify Detail'!$C$5:$C$496,$C11) | L11: =SUMIFS('Amplify Detail'!$G$5:$G$496,'Amplify Detail'!$A$5:$A$496,$A11,'Amplify Detail'!$C$5:$C$496,$C11) | M11: =SUMIFS('Amplify Detail'!$J$5:$J$496,'Amplify Detail'!$A$5:$A$496,$A11,'Amplify Detail'!$C$5:$C$496,$C11) | N11: =$I11+$M11 | O11: =IF($G11="No qualifier - Amplify open",1,IFERROR(INDEX('Program Setup'!$B$12:$B$14,MATCH($G11,'Program Setup'!$A$12:$A$14,0)),0)) | P11: =$A11&"|"&$C11
A12: Alisa Acciardi | B12: Mike Kennedy | C12: MolsonCoors Beverage Company | D12: 491 | E12: 348 | F12: =IF($D12>0,$E12/$D12,"") | G12: =IF($D12>0,IF($F12>=1,"Qualified",IF($F12>=0.9,"90% Partial Amplify","Not Qualified")),"No qualifier - Amplify open") | H12: =IF($G12<>"Qualified","-",IFERROR(IF($E12>=INDEX('Program Setup'!$C$18:$C$23,MATCH($C12,'Program Setup'!$B$18:$B$23,0)),1,IF($E12>=INDEX('Program Setup'!$D$18:$D$23,MATCH($C12,'Program Setup'!$B$18:$B$23,0)),2,IF($E12>=INDEX('Program Setup'!$E$18:$E$23,MATCH($C12,'Program Setup'!$B$18:$B$23,0)),3,"-"))),"-")) | I12: =IF(ISNUMBER($H12),INDEX('Program Setup'!$B$6:$B$8,MATCH($H12,'Program Setup'!$A$6:$A$8,0)),0) | J12: =SUMIFS('Amplify Detail'!$E$5:$E$496,'Amplify Detail'!$A$5:$A$496,$A12,'Amplify Detail'!$C$5:$C$496,$C12) | K12: =SUMIFS('Amplify Detail'!$F$5:$F$496,'Amplify Detail'!$A$5:$A$496,$A12,'Amplify Detail'!$C$5:$C$496,$C12) | L12: =SUMIFS('Amplify Detail'!$G$5:$G$496,'Amplify Detail'!$A$5:$A$496,$A12,'Amplify Detail'!$C$5:$C$496,$C12) | M12: =SUMIFS('Amplify Detail'!$J$5:$J$496,'Amplify Detail'!$A$5:$A$496,$A12,'Amplify Detail'!$C$5:$C$496,$C12) | N12: =$I12+$M12 | O12: =IF($G12="No qualifier - Amplify open",1,IFERROR(INDEX('Program Setup'!$B$12:$B$14,MATCH($G12,'Program Setup'!$A$12:$A$14,0)),0)) | P12: =$A12&"|"&$C12
A13: Alisa Acciardi | B13: Mike Kennedy | C13: New Belgium Brewing Company | F13: =IF($D13>0,$E13/$D13,"") | G13: =IF($D13>0,IF($F13>=1,"Qualified",IF($F13>=0.9,"90% Partial Amplify","Not Qualified")),"No qualifier - Amplify open") | H13: =IF($G13<>"Qualified","-",IFERROR(IF($E13>=INDEX('Program Setup'!$C$18:$C$23,MATCH($C13,'Program Setup'!$B$18:$B$23,0)),1,IF($E13>=INDEX('Program Setup'!$D$18:$D$23,MATCH($C13,'Program Setup'!$B$18:$B$23,0)),2,IF($E13>=INDEX('Program Setup'!$E$18:$E$23,MATCH($C13,'Program Setup'!$B$18:$B$23,0)),3,"-"))),"-")) | I13: =IF(ISNUMBER($H13),INDEX('Program Setup'!$B$6:$B$8,MATCH($H13,'Program Setup'!$A$6:$A$8,0)),0) | J13: =SUMIFS('Amplify Detail'!$E$5:$E$496,'Amplify Detail'!$A$5:$A$496,$A13,'Amplify Detail'!$C$5:$C$496,$C13) | K13: =SUMIFS('Amplify Detail'!$F$5:$F$496,'Amplify Detail'!$A$5:$A$496,$A13,'Amplify Detail'!$C$5:$C$496,$C13) | L13: =SUMIFS('Amplify Detail'!$G$5:$G$496,'Amplify Detail'!$A$5:$A$496,$A13,'Amplify Detail'!$C$5:$C$496,$C13) | M13: =SUMIFS('Amplify Detail'!$J$5:$J$496,'Amplify Detail'!$A$5:$A$496,$A13,'Amplify Detail'!$C$5:$C$496,$C13) | N13: =$I13+$M13 | O13: =IF($G13="No qualifier - Amplify open",1,IFERROR(INDEX('Program Setup'!$B$12:$B$14,MATCH($G13,'Program Setup'!$A$12:$A$14,0)),0)) | P13: =$A13&"|"&$C13
A14: Alisa Acciardi | B14: Mike Kennedy | C14: Sapporo | F14: =IF($D14>0,$E14/$D14,"") | G14: =IF($D14>0,IF($F14>=1,"Qualified",IF($F14>=0.9,"90% Partial Amplify","Not Qualified")),"No qualifier - Amplify open") | H14: =IF($G14<>"Qualified","-",IFERROR(IF($E14>=INDEX('Program Setup'!$C$18:$C$23,MATCH($C14,'Program Setup'!$B$18:$B$23,0)),1,IF($E14>=INDEX('Program Setup'!$D$18:$D$23,MATCH($C14,'Program Setup'!$B$18:$B$23,0)),2,IF($E14>=INDEX('Program Setup'!$E$18:$E$23,MATCH($C14,'Program Setup'!$B$18:$B$23,0)),3,"-"))),"-")) | I14: =IF(ISNUMBER($H14),INDEX('Program Setup'!$B$6:$B$8,MATCH($H14,'Program Setup'!$A$6:$A$8,0)),0) | J14: =SUMIFS('Amplify Detail'!$E$5:$E$496,'Amplify Detail'!$A$5:$A$496,$A14,'Amplify Detail'!$C$5:$C$496,$C14) | K14: =SUMIFS('Amplify Detail'!$F$5:$F$496,'Amplify Detail'!$A$5:$A$496,$A14,'Amplify Detail'!$C$5:$C$496,$C14) | L14: =SUMIFS('Amplify Detail'!$G$5:$G$496,'Amplify Detail'!$A$5:$A$496,$A14,'Amplify Detail'!$C$5:$C$496,$C14) | M14: =SUMIFS('Amplify Detail'!$J$5:$J$496,'Amplify Detail'!$A$5:$A$496,$A14,'Amplify Detail'!$C$5:$C$496,$C14) | N14: =$I14+$M14 | O14: =IF($G14="No qualifier - Amplify open",1,IFERROR(INDEX('Program Setup'!$B$12:$B$14,MATCH($G14,'Program Setup'!$A$12:$A$14,0)),0)) | P14: =$A14&"|"&$C14
A15: Allison Scott | B15: Chris McCrohan | C15: Boston Beer Company | D15: 265 | E15: 279 | F15: =IF($D15>0,$E15/$D15,"") | G15: =IF($D15>0,IF($F15>=1,"Qualified",IF($F15>=0.9,"90% Partial Amplify","Not Qualified")),"No qualifier - Amplify open") | H15: =IF($G15<>"Qualified","-",IFERROR(IF($E15>=INDEX('Program Setup'!$C$18:$C$23,MATCH($C15,'Program Setup'!$B$18:$B$23,0)),1,IF($E15>=INDEX('Program Setup'!$D$18:$D$23,MATCH($C15,'Program Setup'!$B$18:$B$23,0)),2,IF($E15>=INDEX('Program Setup'!$E$18:$E$23,MATCH($C15,'Program Setup'!$B$18:$B$23,0)),3,"-"))),"-")) | I15: =IF(ISNUMBER($H15),INDEX('Program Setup'!$B$6:$B$8,MATCH($H15,'Program Setup'!$A$6:$A$8,0)),0) | J15: =SUMIFS('Amplify Detail'!$E$5:$E$496,'Amplify Detail'!$A$5:$A$496,$A15,'Amplify Detail'!$C$5:$C$496,$C15) | K15: =SUMIFS('Amplify Detail'!$F$5:$F$496,'Amplify Detail'!$A$5:$A$496,$A15,'Amplify Detail'!$C$5:$C$496,$C15) | L15: =SUMIFS('Amplify Detail'!$G$5:$G$496,'Amplify Detail'!$A$5:$A$496,$A15,'Amplify Detail'!$C$5:$C$496,$C15) | M15: =SUMIFS('Amplify Detail'!$J$5:$J$496,'Amplify Detail'!$A$5:$A$496,$A15,'Amplify Detail'!$C$5:$C$496,$C15) | N15: =$I15+$M15 | O15: =IF($G15="No qualifier - Amplify open",1,IFERROR(INDEX('Program Setup'!$B$12:$B$14,MATCH($G15,'Program Setup'!$A$12:$A$14,0)),0)) | P15: =$A15&"|"&$C15
A16: Allison Scott | B16: Chris McCrohan | C16: Cape May | F16: =IF($D16>0,$E16/$D16,"") | G16: =IF($D16>0,IF($F16>=1,"Qualified",IF($F16>=0.9,"90% Partial Amplify","Not Qualified")),"No qualifier - Amplify open") | H16: =IF($G16<>"Qualified","-",IFERROR(IF($E16>=INDEX('Program Setup'!$C$18:$C$23,MATCH($C16,'Program Setup'!$B$18:$B$23,0)),1,IF($E16>=INDEX('Program Setup'!$D$18:$D$23,MATCH($C16,'Program Setup'!$B$18:$B$23,0)),2,IF($E16>=INDEX('Program Setup'!$E$18:$E$23,MATCH($C16,'Program Setup'!$B$18:$B$23,0)),3,"-"))),"-")) | I16: =IF(ISNUMBER($H16),INDEX('Program Setup'!$B$6:$B$8,MATCH($H16,'Program Setup'!$A$6:$A$8,0)),0) | J16: =SUMIFS('Amplify Detail'!$E$5:$E$496,'Amplify Detail'!$A$5:$A$496,$A16,'Amplify Detail'!$C$5:$C$496,$C16) | K16: =SUMIFS('Amplify Detail'!$F$5:$F$496,'Amplify Detail'!$A$5:$A$496,$A16,'Amplify Detail'!$C$5:$C$496,$C16) | L16: =SUMIFS('Amplify Detail'!$G$5:$G$496,'Amplify Detail'!$A$5:$A$496,$A16,'Amplify Detail'!$C$5:$C$496,$C16) | M16: =SUMIFS('Amplify Detail'!$J$5:$J$496,'Amplify Detail'!$A$5:$A$496,$A16,'Amplify Detail'!$C$5:$C$496,$C16) | N16: =$I16+$M16 | O16: =IF($G16="No qualifier - Amplify open",1,IFERROR(INDEX('Program Setup'!$B$12:$B$14,MATCH($G16,'Program Setup'!$A$12:$A$14,0)),0)) | P16: =$A16&"|"&$C16
A17: Allison Scott | B17: Chris McCrohan | C17: Constellation Brands | D17: 7193 | E17: 7676 | F17: =IF($D17>0,$E17/$D17,"") | G17: =IF($D17>0,IF($F17>=1,"Qualified",IF($F17>=0.9,"90% Partial Amplify","Not Qualified")),"No qualifier - Amplify open") | H17: =IF($G17<>"Qualified","-",IFERROR(IF($E17>=INDEX('Program Setup'!$C$18:$C$23,MATCH($C17,'Program Setup'!$B$18:$B$23,0)),1,IF($E17>=INDEX('Program Setup'!$D$18:$D$23,MATCH($C17,'Program Setup'!$B$18:$B$23,0)),2,IF($E17>=INDEX('Program Setup'!$E$18:$E$23,MATCH($C17,'Program Setup'!$B$18:$B$23,0)),3,"-"))),"-")) | I17: =IF(ISNUMBER($H17),INDEX('Program Setup'!$B$6:$B$8,MATCH($H17,'Program Setup'!$A$6:$A$8,0)),0) | J17: =SUMIFS('Amplify Detail'!$E$5:$E$496,'Amplify Detail'!$A$5:$A$496,$A17,'Amplify Detail'!$C$5:$C$496,$C17) | K17: =SUMIFS('Amplify Detail'!$F$5:$F$496,'Amplify Detail'!$A$5:$A$496,$A17,'Amplify Detail'!$C$5:$C$496,$C17) | L17: =SUMIFS('Amplify Detail'!$G$5:$G$496,'Amplify Detail'!$A$5:$A$496,$A17,'Amplify Detail'!$C$5:$C$496,$C17) | M17: =SUMIFS('Amplify Detail'!$J$5:$J$496,'Amplify Detail'!$A$5:$A$496,$A17,'Amplify Detail'!$C$5:$C$496,$C17) | N17: =$I17+$M17 | O17: =IF($G17="No qualifier - Amplify open",1,IFERROR(INDEX('Program Setup'!$B$12:$B$14,MATCH($G17,'Program Setup'!$A$12:$A$14,0)),0)) | P17: =$A17&"|"&$C17
A18: Allison Scott | B18: Chris McCrohan | C18: DG Yuengling Inc | D18: 2762 | E18: 2943 | F18: =IF($D18>0,$E18/$D18,"") | G18: =IF($D18>0,IF($F18>=1,"Qualified",IF($F18>=0.9,"90% Partial Amplify","Not Qualified")),"No qualifier - Amplify open") | H18: =IF($G18<>"Qualified","-",IFERROR(IF($E18>=INDEX('Program Setup'!$C$18:$C$23,MATCH($C18,'Program Setup'!$B$18:$B$23,0)),1,IF($E18>=INDEX('Program Setup'!$D$18:$D$23,MATCH($C18,'Program Setup'!$B$18:$B$23,0)),2,IF($E18>=INDEX('Program Setup'!$E$18:$E$23,MATCH($C18,'Program Setup'!$B$18:$B$23,0)),3,"-"))),"-")) | I18: =IF(ISNUMBER($H18),INDEX('Program Setup'!$B$6:$B$8,MATCH($H18,'Program Setup'!$A$6:$A$8,0)),0) | J18: =SUMIFS('Amplify Detail'!$E$5:$E$496,'Amplify Detail'!$A$5:$A$496,$A18,'Amplify Detail'!$C$5:$C$496,$C18) | K18: =SUMIFS('Amplify Detail'!$F$5:$F$496,'Amplify Detail'!$A$5:$A$496,$A18,'Amplify Detail'!$C$5:$C$496,$C18) | L18: =SUMIFS('Amplify Detail'!$G$5:$G$496,'Amplify Detail'!$A$5:$A$496,$A18,'Amplify Detail'!$C$5:$C$496,$C18) | M18: =SUMIFS('Amplify Detail'!$J$5:$J$496,'Amplify Detail'!$A$5:$A$496,$A18,'Amplify Detail'!$C$5:$C$496,$C18) | N18: =$I18+$M18 | O18: =IF($G18="No qualifier - Amplify open",1,IFERROR(INDEX('Program Setup'!$B$12:$B$14,MATCH($G18,'Program Setup'!$A$12:$A$14,0)),0)) | P18: =$A18&"|"&$C18
A19: Allison Scott | B19: Chris McCrohan | C19: Heineken USA | D19: 1846 | E19: 1813 | F19: =IF($D19>0,$E19/$D19,"") | G19: =IF($D19>0,IF($F19>=1,"Qualified",IF($F19>=0.9,"90% Partial Amplify","Not Qualified")),"No qualifier - Amplify open") | H19: =IF($G19<>"Qualified","-",IFERROR(IF($E19>=INDEX('Program Setup'!$C$18:$C$23,MATCH($C19,'Program Setup'!$B$18:$B$23,0)),1,IF($E19>=INDEX('Program Setup'!$D$18:$D$23,MATCH($C19,'Program Setup'!$B$18:$B$23,0)),2,IF($E19>=INDEX('Program Setup'!$E$18:$E$23,MATCH($C19,'Program Setup'!$B$18:$B$23,0)),3,"-"))),"-")) | I19: =IF(ISNUMBER($H19),INDEX('Program Setup'!$B$6:$B$8,MATCH($H19,'Program Setup'!$A$6:$A$8,0)),0) | J19: =SUMIFS('Amplify Detail'!$E$5:$E$496,'Amplify Detail'!$A$5:$A$496,$A19,'Amplify Detail'!$C$5:$C$496,$C19) | K19: =SUMIFS('Amplify Detail'!$F$5:$F$496,'Amplify Detail'!$A$5:$A$496,$A19,'Amplify Detail'!$C$5:$C$496,$C19) | L19: =SUMIFS('Amplify Detail'!$G$5:$G$496,'Amplify Detail'!$A$5:$A$496,$A19,'Amplify Detail'!$C$5:$C$496,$C19) | M19: =SUMIFS('Amplify Detail'!$J$5:$J$496,'Amplify Detail'!$A$5:$A$496,$A19,'Amplify Detail'!$C$5:$C$496,$C19) | N19: =$I19+$M19 | O19: =IF($G19="No qualifier - Amplify open",1,IFERROR(INDEX('Program Setup'!$B$12:$B$14,MATCH($G19,'Program Setup'!$A$12:$A$14,0)),0)) | P19: =$A19&"|"&$C19
A20: Allison Scott | B20: Chris McCrohan | C20: Mark Anthony | D20: 940 | E20: 879 | F20: =IF($D20>0,$E20/$D20,"") | G20: =IF($D20>0,IF($F20>=1,"Qualified",IF($F20>=0.9,"90% Partial Amplify","Not Qualified")),"No qualifier - Amplify open") | H20: =IF($G20<>"Qualified","-",IFERROR(IF($E20>=INDEX('Program Setup'!$C$18:$C$23,MATCH($C20,'Program Setup'!$B$18:$B$23,0)),1,IF($E20>=INDEX('Program Setup'!$D$18:$D$23,MATCH($C20,'Program Setup'!$B$18:$B$23,0)),2,IF($E20>=INDEX('Program Setup'!$E$18:$E$23,MATCH($C20,'Program Setup'!$B$18:$B$23,0)),3,"-"))),"-")) | I20: =IF(ISNUMBER($H20),INDEX('Program Setup'!$B$6:$B$8,MATCH($H20,'Program Setup'!$A$6:$A$8,0)),0) | J20: =SUMIFS('Amplify Detail'!$E$5:$E$496,'Amplify Detail'!$A$5:$A$496,$A20,'Amplify Detail'!$C$5:$C$496,$C20) | K20: =SUMIFS('Amplify Detail'!$F$5:$F$496,'Amplify Detail'!$A$5:$A$496,$A20,'Amplify Detail'!$C$5:$C$496,$C20) | L20: =SUMIFS('Amplify Detail'!$G$5:$G$496,'Amplify Detail'!$A$5:$A$496,$A20,'Amplify Detail'!$C$5:$C$496,$C20) | M20: =SUMIFS('Amplify Detail'!$J$5:$J$496,'Amplify Detail'!$A$5:$A$496,$A20,'Amplify Detail'!$C$5:$C$496,$C20) | N20: =$I20+$M20 | O20: =IF($G20="No qualifier - Amplify open",1,IFERROR(INDEX('Program Setup'!$B$12:$B$14,MATCH($G20,'Program Setup'!$A$12:$A$14,0)),0)) | P20: =$A20&"|"&$C20
A21: Allison Scott | B21: Chris McCrohan | C21: MolsonCoors Beverage Company | D21: 12865 | E21: 13278 | F21: =IF($D21>0,$E21/$D21,"") | G21: =IF($D21>0,IF($F21>=1,"Qualified",IF($F21>=0.9,"90% Partial Amplify","Not Qualified")),"No qualifier - Amplify open") | H21: =IF($G21<>"Qualified","-",IFERROR(IF($E21>=INDEX('Program Setup'!$C$18:$C$23,MATCH($C21,'Program Setup'!$B$18:$B$23,0)),1,IF($E21>=INDEX('Program Setup'!$D$18:$D$23,MATCH($C21,'Program Setup'!$B$18:$B$23,0)),2,IF($E21>=INDEX('Program Setup'!$E$18:$E$23,MATCH($C21,'Program Setup'!$B$18:$B$23,0)),3,"-"))),"-")) | I21: =IF(ISNUMBER($H21),INDEX('Program Setup'!$B$6:$B$8,MATCH($H21,'Program Setup'!$A$6:$A$8,0)),0) | J21: =SUMIFS('Amplify Detail'!$E$5:$E$496,'Amplify Detail'!$A$5:$A$496,$A21,'Amplify Detail'!$C$5:$C$496,$C21) | K21: =SUMIFS('Amplify Detail'!$F$5:$F$496,'Amplify Detail'!$A$5:$A$496,$A21,'Amplify Detail'!$C$5:$C$496,$C21) | L21: =SUMIFS('Amplify Detail'!$G$5:$G$496,'Amplify Detail'!$A$5:$A$496,$A21,'Amplify Detail'!$C$5:$C$496,$C21) | M21: =SUMIFS('Amplify Detail'!$J$5:$J$496,'Amplify Detail'!$A$5:$A$496,$A21,'Amplify Detail'!$C$5:$C$496,$C21) | N21: =$I21+$M21 | O21: =IF($G21="No qualifier - Amplify open",1,IFERROR(INDEX('Program Setup'!$B$12:$B$14,MATCH($G21,'Program Setup'!$A$12:$A$14,0)),0)) | P21: =$A21&"|"&$C21
A22: Allison Scott | B22: Chris McCrohan | C22: New Belgium Brewing Company | F22: =IF($D22>0,$E22/$D22,"") | G22: =IF($D22>0,IF($F22>=1,"Qualified",IF($F22>=0.9,"90% Partial Amplify","Not Qualified")),"No qualifier - Amplify open") | H22: =IF($G22<>"Qualified","-",IFERROR(IF($E22>=INDEX('Program Setup'!$C$18:$C$23,MATCH($C22,'Program Setup'!$B$18:$B$23,0)),1,IF($E22>=INDEX('Program Setup'!$D$18:$D$23,MATCH($C22,'Program Setup'!$B$18:$B$23,0)),2,IF($E22>=INDEX('Program Setup'!$E$18:$E$23,MATCH($C22,'Program Setup'!$B$18:$B$23,0)),3,"-"))),"-")) | I22: =IF(ISNUMBER($H22),INDEX('Program Setup'!$B$6:$B$8,MATCH($H22,'Program Setup'!$A$6:$A$8,0)),0) | J22: =SUMIFS('Amplify Detail'!$E$5:$E$496,'Amplify Detail'!$A$5:$A$496,$A22,'Amplify Detail'!$C$5:$C$496,$C22) | K22: =SUMIFS('Amplify Detail'!$F$5:$F$496,'Amplify Detail'!$A$5:$A$496,$A22,'Amplify Detail'!$C$5:$C$496,$C22) | L22: =SUMIFS('Amplify Detail'!$G$5:$G$496,'Amplify Detail'!$A$5:$A$496,$A22,'Amplify Detail'!$C$5:$C$496,$C22) | M22: =SUMIFS('Amplify Detail'!$J$5:$J$496,'Amplify Detail'!$A$5:$A$496,$A22,'Amplify Detail'!$C$5:$C$496,$C22) | N22: =$I22+$M22 | O22: =IF($G22="No qualifier - Amplify open",1,IFERROR(INDEX('Program Setup'!$B$12:$B$14,MATCH($G22,'Program Setup'!$A$12:$A$14,0)),0)) | P22: =$A22&"|"&$C22
A23: Allison Scott | B23: Chris McCrohan | C23: Sapporo | F23: =IF($D23>0,$E23/$D23,"") | G23: =IF($D23>0,IF($F23>=1,"Qualified",IF($F23>=0.9,"90% Partial Amplify","Not Qualified")),"No qualifier - Amplify open") | H23: =IF($G23<>"Qualified","-",IFERROR(IF($E23>=INDEX('Program Setup'!$C$18:$C$23,MATCH($C23,'Program Setup'!$B$18:$B$23,0)),1,IF($E23>=INDEX('Program Setup'!$D$18:$D$23,MATCH($C23,'Program Setup'!$B$18:$B$23,0)),2,IF($E23>=INDEX('Program Setup'!$E$18:$E$23,MATCH($C23,'Program Setup'!$B$18:$B$23,0)),3,"-"))),"-")) | I23: =IF(ISNUMBER($H23),INDEX('Program Setup'!$B$6:$B$8,MATCH($H23,'Program Setup'!$A$6:$A$8,0)),0) | J23: =SUMIFS('Amplify Detail'!$E$5:$E$496,'Amplify Detail'!$A$5:$A$496,$A23,'Amplify Detail'!$C$5:$C$496,$C23) | K23: =SUMIFS('Amplify Detail'!$F$5:$F$496,'Amplify Detail'!$A$5:$A$496,$A23,'Amplify Detail'!$C$5:$C$496,$C23) | L23: =SUMIFS('Amplify Detail'!$G$5:$G$496,'Amplify Detail'!$A$5:$A$496,$A23,'Amplify Detail'!$C$5:$C$496,$C23) | M23: =SUMIFS('Amplify Detail'!$J$5:$J$496,'Amplify Detail'!$A$5:$A$496,$A23,'Amplify Detail'!$C$5:$C$496,$C23) | N23: =$I23+$M23 | O23: =IF($G23="No qualifier - Amplify open",1,IFERROR(INDEX('Program Setup'!$B$12:$B$14,MATCH($G23,'Program Setup'!$A$12:$A$14,0)),0)) | P23: =$A23&"|"&$C23
A24: Andrew Lundy | B24: Mike Kennedy | C24: MolsonCoors Beverage Company | F24: =IF($D24>0,$E24/$D24,"") | G24: =IF($D24>0,IF($F24>=1,"Qualified",IF($F24>=0.9,"90% Partial Amplify","Not Qualified")),"No qualifier - Amplify open") | H24: =IF($G24<>"Qualified","-",IFERROR(IF($E24>=INDEX('Program Setup'!$C$18:$C$23,MATCH($C24,'Program Setup'!$B$18:$B$23,0)),1,IF($E24>=INDEX('Program Setup'!$D$18:$D$23,MATCH($C24,'Program Setup'!$B$18:$B$23,0)),2,IF($E24>=INDEX('Program Setup'!$E$18:$E$23,MATCH($C24,'Program Setup'!$B$18:$B$23,0)),3,"-"))),"-")) | I24: =IF(ISNUMBER($H24),INDEX('Program Setup'!$B$6:$B$8,MATCH($H24,'Program Setup'!$A$6:$A$8,0)),0) | J24: =SUMIFS('Amplify Detail'!$E$5:$E$496,'Amplify Detail'!$A$5:$A$496,$A24,'Amplify Detail'!$C$5:$C$496,$C24) | K24: =SUMIFS('Amplify Detail'!$F$5:$F$496,'Amplify Detail'!$A$5:$A$496,$A24,'Amplify Detail'!$C$5:$C$496,$C24) | L24: =SUMIFS('Amplify Detail'!$G$5:$G$496,'Amplify Detail'!$A$5:$A$496,$A24,'Amplify Detail'!$C$5:$C$496,$C24) | M24: =SUMIFS('Amplify Detail'!$J$5:$J$496,'Amplify Detail'!$A$5:$A$496,$A24,'Amplify Detail'!$C$5:$C$496,$C24) | N24: =$I24+$M24 | O24: =IF($G24="No qualifier - Amplify open",1,IFERROR(INDEX('Program Setup'!$B$12:$B$14,MATCH($G24,'Program Setup'!$A$12:$A$14,0)),0)) | P24: =$A24&"|"&$C24
A25: Andrew Lundy | B25: Mike Kennedy | C25: Sapporo | F25: =IF($D25>0,$E25/$D25,"") | G25: =IF($D25>0,IF($F25>=1,"Qualified",IF($F25>=0.9,"90% Partial Amplify","Not Qualified")),"No qualifier - Amplify open") | H25: =IF($G25<>"Qualified","-",IFERROR(IF($E25>=INDEX('Program Setup'!$C$18:$C$23,MATCH($C25,'Program Setup'!$B$18:$B$23,0)),1,IF($E25>=INDEX('Program Setup'!$D$18:$D$23,MATCH($C25,'Program Setup'!$B$18:$B$23,0)),2,IF($E25>=INDEX('Program Setup'!$E$18:$E$23,MATCH($C25,'Program Setup'!$B$18:$B$23,0)),3,"-"))),"-")) | I25: =IF(ISNUMBER($H25),INDEX('Program Setup'!$B$6:$B$8,MATCH($H25,'Program Setup'!$A$6:$A$8,0)),0) | J25: =SUMIFS('Amplify Detail'!$E$5:$E$496,'Amplify Detail'!$A$5:$A$496,$A25,'Amplify Detail'!$C$5:$C$496,$C25) | K25: =SUMIFS('Amplify Detail'!$F$5:$F$496,'Amplify Detail'!$A$5:$A$496,$A25,'Amplify Detail'!$C$5:$C$496,$C25) | L25: =SUMIFS('Amplify Detail'!$G$5:$G$496,'Amplify Detail'!$A$5:$A$496,$A25,'Amplify Detail'!$C$5:$C$496,$C25) | M25: =SUMIFS('Amplify Detail'!$J$5:$J$496,'Amplify Detail'!$A$5:$A$496,$A25,'Amplify Detail'!$C$5:$C$496,$C25) | N25: =$I25+$M25 | O25: =IF($G25="No qualifier - Amplify open",1,IFERROR(INDEX('Program Setup'!$B$12:$B$14,MATCH($G25,'Program Setup'!$A$12:$A$14,0)),0)) | P25: =$A25&"|"&$C25
A26: Anthony Palmisano | B26: Chris McCrohan | C26: Boston Beer Company | D26: 4450 | E26: 3671 | F26: =IF($D26>0,$E26/$D26,"") | G26: =IF($D26>0,IF($F26>=1,"Qualified",IF($F26>=0.9,"90% Partial Amplify","Not Qualified")),"No qualifier - Amplify open") | H26: =IF($G26<>"Qualified","-",IFERROR(IF($E26>=INDEX('Program Setup'!$C$18:$C$23,MATCH($C26,'Program Setup'!$B$18:$B$23,0)),1,IF($E26>=INDEX('Program Setup'!$D$18:$D$23,MATCH($C26,'Program Setup'!$B$18:$B$23,0)),2,IF($E26>=INDEX('Program Setup'!$E$18:$E$23,MATCH($C26,'Program Setup'!$B$18:$B$23,0)),3,"-"))),"-")) | I26: =IF(ISNUMBER($H26),INDEX('Program Setup'!$B$6:$B$8,MATCH($H26,'Program Setup'!$A$6:$A$8,0)),0) | J26: =SUMIFS('Amplify Detail'!$E$5:$E$496,'Amplify Detail'!$A$5:$A$496,$A26,'Amplify Detail'!$C$5:$C$496,$C26) | K26: =SUMIFS('Amplify Detail'!$F$5:$F$496,'Amplify Detail'!$A$5:$A$496,$A26,'Amplify Detail'!$C$5:$C$496,$C26) | L26: =SUMIFS('Amplify Detail'!$G$5:$G$496,'Amplify Detail'!$A$5:$A$496,$A26,'Amplify Detail'!$C$5:$C$496,$C26) | M26: =SUMIFS('Amplify Detail'!$J$5:$J$496,'Amplify Detail'!$A$5:$A$496,$A26,'Amplify Detail'!$C$5:$C$496,$C26) | N26: =$I26+$M26 | O26: =IF($G26="No qualifier - Amplify open",1,IFERROR(INDEX('Program Setup'!$B$12:$B$14,MATCH($G26,'Program Setup'!$A$12:$A$14,0)),0)) | P26: =$A26&"|"&$C26
A27: Anthony Palmisano | B27: Chris McCrohan | C27: Cape May | F27: =IF($D27>0,$E27/$D27,"") | G27: =IF($D27>0,IF($F27>=1,"Qualified",IF($F27>=0.9,"90% Partial Amplify","Not Qualified")),"No qualifier - Amplify open") | H27: =IF($G27<>"Qualified","-",IFERROR(IF($E27>=INDEX('Program Setup'!$C$18:$C$23,MATCH($C27,'Program Setup'!$B$18:$B$23,0)),1,IF($E27>=INDEX('Program Setup'!$D$18:$D$23,MATCH($C27,'Program Setup'!$B$18:$B$23,0)),2,IF($E27>=INDEX('Program Setup'!$E$18:$E$23,MATCH($C27,'Program Setup'!$B$18:$B$23,0)),3,"-"))),"-")) | I27: =IF(ISNUMBER($H27),INDEX('Program Setup'!$B$6:$B$8,MATCH($H27,'Program Setup'!$A$6:$A$8,0)),0) | J27: =SUMIFS('Amplify Detail'!$E$5:$E$496,'Amplify Detail'!$A$5:$A$496,$A27,'Amplify Detail'!$C$5:$C$496,$C27) | K27: =SUMIFS('Amplify Detail'!$F$5:$F$496,'Amplify Detail'!$A$5:$A$496,$A27,'Amplify Detail'!$C$5:$C$496,$C27) | L27: =SUMIFS('Amplify Detail'!$G$5:$G$496,'Amplify Detail'!$A$5:$A$496,$A27,'Amplify Detail'!$C$5:$C$496,$C27) | M27: =SUMIFS('Amplify Detail'!$J$5:$J$496,'Amplify Detail'!$A$5:$A$496,$A27,'Amplify Detail'!$C$5:$C$496,$C27) | N27: =$I27+$M27 | O27: =IF($G27="No qualifier - Amplify open",1,IFERROR(INDEX('Program Setup'!$B$12:$B$14,MATCH($G27,'Program Setup'!$A$12:$A$14,0)),0)) | P27: =$A27&"|"&$C27
A28: Anthony Palmisano | B28: Chris McCrohan | C28: Constellation Brands | D28: 18078 | E28: 18611 | F28: =IF($D28>0,$E28/$D28,"") | G28: =IF($D28>0,IF($F28>=1,"Qualified",IF($F28>=0.9,"90% Partial Amplify","Not Qualified")),"No qualifier - Amplify open") | H28: =IF($G28<>"Qualified","-",IFERROR(IF($E28>=INDEX('Program Setup'!$C$18:$C$23,MATCH($C28,'Program Setup'!$B$18:$B$23,0)),1,IF($E28>=INDEX('Program Setup'!$D$18:$D$23,MATCH($C28,'Program Setup'!$B$18:$B$23,0)),2,IF($E28>=INDEX('Program Setup'!$E$18:$E$23,MATCH($C28,'Program Setup'!$B$18:$B$23,0)),3,"-"))),"-")) | I28: =IF(ISNUMBER($H28),INDEX('Program Setup'!$B$6:$B$8,MATCH($H28,'Program Setup'!$A$6:$A$8,0)),0) | J28: =SUMIFS('Amplify Detail'!$E$5:$E$496,'Amplify Detail'!$A$5:$A$496,$A28,'Amplify Detail'!$C$5:$C$496,$C28) | K28: =SUMIFS('Amplify Detail'!$F$5:$F$496,'Amplify Detail'!$A$5:$A$496,$A28,'Amplify Detail'!$C$5:$C$496,$C28) | L28: =SUMIFS('Amplify Detail'!$G$5:$G$496,'Amplify Detail'!$A$5:$A$496,$A28,'Amplify Detail'!$C$5:$C$496,$C28) | M28: =SUMIFS('Amplify Detail'!$J$5:$J$496,'Amplify Detail'!$A$5:$A$496,$A28,'Amplify Detail'!$C$5:$C$496,$C28) | N28: =$I28+$M28 | O28: =IF($G28="No qualifier - Amplify open",1,IFERROR(INDEX('Program Setup'!$B$12:$B$14,MATCH($G28,'Program Setup'!$A$12:$A$14,0)),0)) | P28: =$A28&"|"&$C28
A29: Anthony Palmisano | B29: Chris McCrohan | C29: DG Yuengling Inc | D29: 4331 | E29: 4275 | F29: =IF($D29>0,$E29/$D29,"") | G29: =IF($D29>0,IF($F29>=1,"Qualified",IF($F29>=0.9,"90% Partial Amplify","Not Qualified")),"No qualifier - Amplify open") | H29: =IF($G29<>"Qualified","-",IFERROR(IF($E29>=INDEX('Program Setup'!$C$18:$C$23,MATCH($C29,'Program Setup'!$B$18:$B$23,0)),1,IF($E29>=INDEX('Program Setup'!$D$18:$D$23,MATCH($C29,'Program Setup'!$B$18:$B$23,0)),2,IF($E29>=INDEX('Program Setup'!$E$18:$E$23,MATCH($C29,'Program Setup'!$B$18:$B$23,0)),3,"-"))),"-")) | I29: =IF(ISNUMBER($H29),INDEX('Program Setup'!$B$6:$B$8,MATCH($H29,'Program Setup'!$A$6:$A$8,0)),0) | J29: =SUMIFS('Amplify Detail'!$E$5:$E$496,'Amplify Detail'!$A$5:$A$496,$A29,'Amplify Detail'!$C$5:$C$496,$C29) | K29: =SUMIFS('Amplify Detail'!$F$5:$F$496,'Amplify Detail'!$A$5:$A$496,$A29,'Amplify Detail'!$C$5:$C$496,$C29) | L29: =SUMIFS('Amplify Detail'!$G$5:$G$496,'Amplify Detail'!$A$5:$A$496,$A29,'Amplify Detail'!$C$5:$C$496,$C29) | M29: =SUMIFS('Amplify Detail'!$J$5:$J$496,'Amplify Detail'!$A$5:$A$496,$A29,'Amplify Detail'!$C$5:$C$496,$C29) | N29: =$I29+$M29 | O29: =IF($G29="No qualifier - Amplify open",1,IFERROR(INDEX('Program Setup'!$B$12:$B$14,MATCH($G29,'Program Setup'!$A$12:$A$14,0)),0)) | P29: =$A29&"|"&$C29
A30: Anthony Palmisano | B30: Chris McCrohan | C30: Heineken USA | D30: 2985 | E30: 2640 | F30: =IF($D30>0,$E30/$D30,"") | G30: =IF($D30>0,IF($F30>=1,"Qualified",IF($F30>=0.9,"90% Partial Amplify","Not Qualified")),"No qualifier - Amplify open") | H30: =IF($G30<>"Qualified","-",IFERROR(IF($E30>=INDEX('Program Setup'!$C$18:$C$23,MATCH($C30,'Program Setup'!$B$18:$B$23,0)),1,IF($E30>=INDEX('Program Setup'!$D$18:$D$23,MATCH($C30,'Program Setup'!$B$18:$B$23,0)),2,IF($E30>=INDEX('Program Setup'!$E$18:$E$23,MATCH($C30,'Program Setup'!$B$18:$B$23,0)),3,"-"))),"-")) | I30: =IF(ISNUMBER($H30),INDEX('Program Setup'!$B$6:$B$8,MATCH($H30,'Program Setup'!$A$6:$A$8,0)),0) | J30: =SUMIFS('Amplify Detail'!$E$5:$E$496,'Amplify Detail'!$A$5:$A$496,$A30,'Amplify Detail'!$C$5:$C$496,$C30) | K30: =SUMIFS('Amplify Detail'!$F$5:$F$496,'Amplify Detail'!$A$5:$A$496,$A30,'Amplify Detail'!$C$5:$C$496,$C30) | L30: =SUMIFS('Amplify Detail'!$G$5:$G$496,'Amplify Detail'!$A$5:$A$496,$A30,'Amplify Detail'!$C$5:$C$496,$C30) | M30: =SUMIFS('Amplify Detail'!$J$5:$J$496,'Amplify Detail'!$A$5:$A$496,$A30,'Amplify Detail'!$C$5:$C$496,$C30) | N30: =$I30+$M30 | O30: =IF($G30="No qualifier - Amplify open",1,IFERROR(INDEX('Program Setup'!$B$12:$B$14,MATCH($G30,'Program Setup'!$A$12:$A$14,0)),0)) | P30: =$A30&"|"&$C30
A31: Anthony Palmisano | B31: Chris McCrohan | C31: Mark Anthony | D31: 6666 | E31: 7386 | F31: =IF($D31>0,$E31/$D31,"") | G31: =IF($D31>0,IF($F31>=1,"Qualified",IF($F31>=0.9,"90% Partial Amplify","Not Qualified")),"No qualifier - Amplify open") | H31: =IF($G31<>"Qualified","-",IFERROR(IF($E31>=INDEX('Program Setup'!$C$18:$C$23,MATCH($C31,'Program Setup'!$B$18:$B$23,0)),1,IF($E31>=INDEX('Program Setup'!$D$18:$D$23,MATCH($C31,'Program Setup'!$B$18:$B$23,0)),2,IF($E31>=INDEX('Program Setup'!$E$18:$E$23,MATCH($C31,'Program Setup'!$B$18:$B$23,0)),3,"-"))),"-")) | I31: =IF(ISNUMBER($H31),INDEX('Program Setup'!$B$6:$B$8,MATCH($H31,'Program Setup'!$A$6:$A$8,0)),0) | J31: =SUMIFS('Amplify Detail'!$E$5:$E$496,'Amplify Detail'!$A$5:$A$496,$A31,'Amplify Detail'!$C$5:$C$496,$C31) | K31: =SUMIFS('Amplify Detail'!$F$5:$F$496,'Amplify Detail'!$A$5:$A$496,$A31,'Amplify Detail'!$C$5:$C$496,$C31) | L31: =SUMIFS('Amplify Detail'!$G$5:$G$496,'Amplify Detail'!$A$5:$A$496,$A31,'Amplify Detail'!$C$5:$C$496,$C31) | M31: =SUMIFS('Amplify Detail'!$J$5:$J$496,'Amplify Detail'!$A$5:$A$496,$A31,'Amplify Detail'!$C$5:$C$496,$C31) | N31: =$I31+$M31 | O31: =IF($G31="No qualifier - Amplify open",1,IFERROR(INDEX('Program Setup'!$B$12:$B$14,MATCH($G31,'Program Setup'!$A$12:$A$14,0)),0)) | P31: =$A31&"|"&$C31
A32: Anthony Palmisano | B32: Chris McCrohan | C32: MolsonCoors Beverage Company | D32: 29338 | E32: 27917 | F32: =IF($D32>0,$E32/$D32,"") | G32: =IF($D32>0,IF($F32>=1,"Qualified",IF($F32>=0.9,"90% Partial Amplify","Not Qualified")),"No qualifier - Amplify open") | H32: =IF($G32<>"Qualified","-",IFERROR(IF($E32>=INDEX('Program Setup'!$C$18:$C$23,MATCH($C32,'Program Setup'!$B$18:$B$23,0)),1,IF($E32>=INDEX('Program Setup'!$D$18:$D$23,MATCH($C32,'Program Setup'!$B$18:$B$23,0)),2,IF($E32>=INDEX('Program Setup'!$E$18:$E$23,MATCH($C32,'Program Setup'!$B$18:$B$23,0)),3,"-"))),"-")) | I32: =IF(ISNUMBER($H32),INDEX('Program Setup'!$B$6:$B$8,MATCH($H32,'Program Setup'!$A$6:$A$8,0)),0) | J32: =SUMIFS('Amplify Detail'!$E$5:$E$496,'Amplify Detail'!$A$5:$A$496,$A32,'Amplify Detail'!$C$5:$C$496,$C32) | K32: =SUMIFS('Amplify Detail'!$F$5:$F$496,'Amplify Detail'!$A$5:$A$496,$A32,'Amplify Detail'!$C$5:$C$496,$C32) | L32: =SUMIFS('Amplify Detail'!$G$5:$G$496,'Amplify Detail'!$A$5:$A$496,$A32,'Amplify Detail'!$C$5:$C$496,$C32) | M32: =SUMIFS('Amplify Detail'!$J$5:$J$496,'Amplify Detail'!$A$5:$A$496,$A32,'Amplify Detail'!$C$5:$C$496,$C32) | N32: =$I32+$M32 | O32: =IF($G32="No qualifier - Amplify open",1,IFERROR(INDEX('Program Setup'!$B$12:$B$14,MATCH($G32,'Program Setup'!$A$12:$A$14,0)),0)) | P32: =$A32&"|"&$C32
A33: Anthony Palmisano | B33: Chris McCrohan | C33: New Belgium Brewing Company | F33: =IF($D33>0,$E33/$D33,"") | G33: =IF($D33>0,IF($F33>=1,"Qualified",IF($F33>=0.9,"90% Partial Amplify","Not Qualified")),"No qualifier - Amplify open") | H33: =IF($G33<>"Qualified","-",IFERROR(IF($E33>=INDEX('Program Setup'!$C$18:$C$23,MATCH($C33,'Program Setup'!$B$18:$B$23,0)),1,IF($E33>=INDEX('Program Setup'!$D$18:$D$23,MATCH($C33,'Program Setup'!$B$18:$B$23,0)),2,IF($E33>=INDEX('Program Setup'!$E$18:$E$23,MATCH($C33,'Program Setup'!$B$18:$B$23,0)),3,"-"))),"-")) | I33: =IF(ISNUMBER($H33),INDEX('Program Setup'!$B$6:$B$8,MATCH($H33,'Program Setup'!$A$6:$A$8,0)),0) | J33: =SUMIFS('Amplify Detail'!$E$5:$E$496,'Amplify Detail'!$A$5:$A$496,$A33,'Amplify Detail'!$C$5:$C$496,$C33) | K33: =SUMIFS('Amplify Detail'!$F$5:$F$496,'Amplify Detail'!$A$5:$A$496,$A33,'Amplify Detail'!$C$5:$C$496,$C33) | L33: =SUMIFS('Amplify Detail'!$G$5:$G$496,'Amplify Detail'!$A$5:$A$496,$A33,'Amplify Detail'!$C$5:$C$496,$C33) | M33: =SUMIFS('Amplify Detail'!$J$5:$J$496,'Amplify Detail'!$A$5:$A$496,$A33,'Amplify Detail'!$C$5:$C$496,$C33) | N33: =$I33+$M33 | O33: =IF($G33="No qualifier - Amplify open",1,IFERROR(INDEX('Program Setup'!$B$12:$B$14,MATCH($G33,'Program Setup'!$A$12:$A$14,0)),0)) | P33: =$A33&"|"&$C33
A34: Anthony Palmisano | B34: Chris McCrohan | C34: Sapporo | F34: =IF($D34>0,$E34/$D34,"") | G34: =IF($D34>0,IF($F34>=1,"Qualified",IF($F34>=0.9,"90% Partial Amplify","Not Qualified")),"No qualifier - Amplify open") | H34: =IF($G34<>"Qualified","-",IFERROR(IF($E34>=INDEX('Program Setup'!$C$18:$C$23,MATCH($C34,'Program Setup'!$B$18:$B$23,0)),1,IF($E34>=INDEX('Program Setup'!$D$18:$D$23,MATCH($C34,'Program Setup'!$B$18:$B$23,0)),2,IF($E34>=INDEX('Program Setup'!$E$18:$E$23,MATCH($C34,'Program Setup'!$B$18:$B$23,0)),3,"-"))),"-")) | I34: =IF(ISNUMBER($H34),INDEX('Program Setup'!$B$6:$B$8,MATCH($H34,'Program Setup'!$A$6:$A$8,0)),0) | J34: =SUMIFS('Amplify Detail'!$E$5:$E$496,'Amplify Detail'!$A$5:$A$496,$A34,'Amplify Detail'!$C$5:$C$496,$C34) | K34: =SUMIFS('Amplify Detail'!$F$5:$F$496,'Amplify Detail'!$A$5:$A$496,$A34,'Amplify Detail'!$C$5:$C$496,$C34) | L34: =SUMIFS('Amplify Detail'!$G$5:$G$496,'Amplify Detail'!$A$5:$A$496,$A34,'Amplify Detail'!$C$5:$C$496,$C34) | M34: =SUMIFS('Amplify Detail'!$J$5:$J$496,'Amplify Detail'!$A$5:$A$496,$A34,'Amplify Detail'!$C$5:$C$496,$C34) | N34: =$I34+$M34 | O34: =IF($G34="No qualifier - Amplify open",1,IFERROR(INDEX('Program Setup'!$B$12:$B$14,MATCH($G34,'Program Setup'!$A$12:$A$14,0)),0)) | P34: =$A34&"|"&$C34
A35: Brian Sengebush | B35: Chris McCrohan | C35: Boston Beer Company | D35: 1575 | E35: 1075 | F35: =IF($D35>0,$E35/$D35,"") | G35: =IF($D35>0,IF($F35>=1,"Qualified",IF($F35>=0.9,"90% Partial Amplify","Not Qualified")),"No qualifier - Amplify open") | H35: =IF($G35<>"Qualified","-",IFERROR(IF($E35>=INDEX('Program Setup'!$C$18:$C$23,MATCH($C35,'Program Setup'!$B$18:$B$23,0)),1,IF($E35>=INDEX('Program Setup'!$D$18:$D$23,MATCH($C35,'Program Setup'!$B$18:$B$23,0)),2,IF($E35>=INDEX('Program Setup'!$E$18:$E$23,MATCH($C35,'Program Setup'!$B$18:$B$23,0)),3,"-"))),"-")) | I35: =IF(ISNUMBER($H35),INDEX('Program Setup'!$B$6:$B$8,MATCH($H35,'Program Setup'!$A$6:$A$8,0)),0) | J35: =SUMIFS('Amplify Detail'!$E$5:$E$496,'Amplify Detail'!$A$5:$A$496,$A35,'Amplify Detail'!$C$5:$C$496,$C35) | K35: =SUMIFS('Amplify Detail'!$F$5:$F$496,'Amplify Detail'!$A$5:$A$496,$A35,'Amplify Detail'!$C$5:$C$496,$C35) | L35: =SUMIFS('Amplify Detail'!$G$5:$G$496,'Amplify Detail'!$A$5:$A$496,$A35,'Amplify Detail'!$C$5:$C$496,$C35) | M35: =SUMIFS('Amplify Detail'!$J$5:$J$496,'Amplify Detail'!$A$5:$A$496,$A35,'Amplify Detail'!$C$5:$C$496,$C35) | N35: =$I35+$M35 | O35: =IF($G35="No qualifier - Amplify open",1,IFERROR(INDEX('Program Setup'!$B$12:$B$14,MATCH($G35,'Program Setup'!$A$12:$A$14,0)),0)) | P35: =$A35&"|"&$C35
A36: Brian Sengebush | B36: Chris McCrohan | C36: Cape May | F36: =IF($D36>0,$E36/$D36,"") | G36: =IF($D36>0,IF($F36>=1,"Qualified",IF($F36>=0.9,"90% Partial Amplify","Not Qualified")),"No qualifier - Amplify open") | H36: =IF($G36<>"Qualified","-",IFERROR(IF($E36>=INDEX('Program Setup'!$C$18:$C$23,MATCH($C36,'Program Setup'!$B$18:$B$23,0)),1,IF($E36>=INDEX('Program Setup'!$D$18:$D$23,MATCH($C36,'Program Setup'!$B$18:$B$23,0)),2,IF($E36>=INDEX('Program Setup'!$E$18:$E$23,MATCH($C36,'Program Setup'!$B$18:$B$23,0)),3,"-"))),"-")) | I36: =IF(ISNUMBER($H36),INDEX('Program Setup'!$B$6:$B$8,MATCH($H36,'Program Setup'!$A$6:$A$8,0)),0) | J36: =SUMIFS('Amplify Detail'!$E$5:$E$496,'Amplify Detail'!$A$5:$A$496,$A36,'Amplify Detail'!$C$5:$C$496,$C36) | K36: =SUMIFS('Amplify Detail'!$F$5:$F$496,'Amplify Detail'!$A$5:$A$496,$A36,'Amplify Detail'!$C$5:$C$496,$C36) | L36: =SUMIFS('Amplify Detail'!$G$5:$G$496,'Amplify Detail'!$A$5:$A$496,$A36,'Amplify Detail'!$C$5:$C$496,$C36) | M36: =SUMIFS('Amplify Detail'!$J$5:$J$496,'Amplify Detail'!$A$5:$A$496,$A36,'Amplify Detail'!$C$5:$C$496,$C36) | N36: =$I36+$M36 | O36: =IF($G36="No qualifier - Amplify open",1,IFERROR(INDEX('Program Setup'!$B$12:$B$14,MATCH($G36,'Program Setup'!$A$12:$A$14,0)),0)) | P36: =$A36&"|"&$C36
A37: Brian Sengebush | B37: Chris McCrohan | C37: Constellation Brands | D37: 5395 | E37: 5033 | F37: =IF($D37>0,$E37/$D37,"") | G37: =IF($D37>0,IF($F37>=1,"Qualified",IF($F37>=0.9,"90% Partial Amplify","Not Qualified")),"No qualifier - Amplify open") | H37: =IF($G37<>"Qualified","-",IFERROR(IF($E37>=INDEX('Program Setup'!$C$18:$C$23,MATCH($C37,'Program Setup'!$B$18:$B$23,0)),1,IF($E37>=INDEX('Program Setup'!$D$18:$D$23,MATCH($C37,'Program Setup'!$B$18:$B$23,0)),2,IF($E37>=INDEX('Program Setup'!$E$18:$E$23,MATCH($C37,'Program Setup'!$B$18:$B$23,0)),3,"-"))),"-")) | I37: =IF(ISNUMBER($H37),INDEX('Program Setup'!$B$6:$B$8,MATCH($H37,'Program Setup'!$A$6:$A$8,0)),0) | J37: =SUMIFS('Amplify Detail'!$E$5:$E$496,'Amplify Detail'!$A$5:$A$496,$A37,'Amplify Detail'!$C$5:$C$496,$C37) | K37: =SUMIFS('Amplify Detail'!$F$5:$F$496,'Amplify Detail'!$A$5:$A$496,$A37,'Amplify Detail'!$C$5:$C$496,$C37) | L37: =SUMIFS('Amplify Detail'!$G$5:$G$496,'Amplify Detail'!$A$5:$A$496,$A37,'Amplify Detail'!$C$5:$C$496,$C37) | M37: =SUMIFS('Amplify Detail'!$J$5:$J$496,'Amplify Detail'!$A$5:$A$496,$A37,'Amplify Detail'!$C$5:$C$496,$C37) | N37: =$I37+$M37 | O37: =IF($G37="No qualifier - Amplify open",1,IFERROR(INDEX('Program Setup'!$B$12:$B$14,MATCH($G37,'Program Setup'!$A$12:$A$14,0)),0)) | P37: =$A37&"|"&$C37
A38: Brian Sengebush | B38: Chris McCrohan | C38: DG Yuengling Inc | D38: 4861 | E38: 4375 | F38: =IF($D38>0,$E38/$D38,"") | G38: =IF($D38>0,IF($F38>=1,"Qualified",IF($F38>=0.9,"90% Partial Amplify","Not Qualified")),"No qualifier - Amplify open") | H38: =IF($G38<>"Qualified","-",IFERROR(IF($E38>=INDEX('Program Setup'!$C$18:$C$23,MATCH($C38,'Program Setup'!$B$18:$B$23,0)),1,IF($E38>=INDEX('Program Setup'!$D$18:$D$23,MATCH($C38,'Program Setup'!$B$18:$B$23,0)),2,IF($E38>=INDEX('Program Setup'!$E$18:$E$23,MATCH($C38,'Program Setup'!$B$18:$B$23,0)),3,"-"))),"-")) | I38: =IF(ISNUMBER($H38),INDEX('Program Setup'!$B$6:$B$8,MATCH($H38,'Program Setup'!$A$6:$A$8,0)),0) | J38: =SUMIFS('Amplify Detail'!$E$5:$E$496,'Amplify Detail'!$A$5:$A$496,$A38,'Amplify Detail'!$C$5:$C$496,$C38) | K38: =SUMIFS('Amplify Detail'!$F$5:$F$496,'Amplify Detail'!$A$5:$A$496,$A38,'Amplify Detail'!$C$5:$C$496,$C38) | L38: =SUMIFS('Amplify Detail'!$G$5:$G$496,'Amplify Detail'!$A$5:$A$496,$A38,'Amplify Detail'!$C$5:$C$496,$C38) | M38: =SUMIFS('Amplify Detail'!$J$5:$J$496,'Amplify Detail'!$A$5:$A$496,$A38,'Amplify Detail'!$C$5:$C$496,$C38) | N38: =$I38+$M38 | O38: =IF($G38="No qualifier - Amplify open",1,IFERROR(INDEX('Program Setup'!$B$12:$B$14,MATCH($G38,'Program Setup'!$A$12:$A$14,0)),0)) | P38: =$A38&"|"&$C38
A39: Brian Sengebush | B39: Chris McCrohan | C39: Mark Anthony | D39: 1470 | E39: 1156 | F39: =IF($D39>0,$E39/$D39,"") | G39: =IF($D39>0,IF($F39>=1,"Qualified",IF($F39>=0.9,"90% Partial Amplify","Not Qualified")),"No qualifier - Amplify open") | H39: =IF($G39<>"Qualified","-",IFERROR(IF($E39>=INDEX('Program Setup'!$C$18:$C$23,MATCH($C39,'Program Setup'!$B$18:$B$23,0)),1,IF($E39>=INDEX('Program Setup'!$D$18:$D$23,MATCH($C39,'Program Setup'!$B$18:$B$23,0)),2,IF($E39>=INDEX('Program Setup'!$E$18:$E$23,MATCH($C39,'Program Setup'!$B$18:$B$23,0)),3,"-"))),"-")) | I39: =IF(ISNUMBER($H39),INDEX('Program Setup'!$B$6:$B$8,MATCH($H39,'Program Setup'!$A$6:$A$8,0)),0) | J39: =SUMIFS('Amplify Detail'!$E$5:$E$496,'Amplify Detail'!$A$5:$A$496,$A39,'Amplify Detail'!$C$5:$C$496,$C39) | K39: =SUMIFS('Amplify Detail'!$F$5:$F$496,'Amplify Detail'!$A$5:$A$496,$A39,'Amplify Detail'!$C$5:$C$496,$C39) | L39: =SUMIFS('Amplify Detail'!$G$5:$G$496,'Amplify Detail'!$A$5:$A$496,$A39,'Amplify Detail'!$C$5:$C$496,$C39) | M39: =SUMIFS('Amplify Detail'!$J$5:$J$496,'Amplify Detail'!$A$5:$A$496,$A39,'Amplify Detail'!$C$5:$C$496,$C39) | N39: =$I39+$M39 | O39: =IF($G39="No qualifier - Amplify open",1,IFERROR(INDEX('Program Setup'!$B$12:$B$14,MATCH($G39,'Program Setup'!$A$12:$A$14,0)),0)) | P39: =$A39&"|"&$C39
A40: Brian Sengebush | B40: Chris McCrohan | C40: MolsonCoors Beverage Company | D40: 16115 | E40: 14813 | F40: =IF($D40>0,$E40/$D40,"") | G40: =IF($D40>0,IF($F40>=1,"Qualified",IF($F40>=0.9,"90% Partial Amplify","Not Qualified")),"No qualifier - Amplify open") | H40: =IF($G40<>"Qualified","-",IFERROR(IF($E40>=INDEX('Program Setup'!$C$18:$C$23,MATCH($C40,'Program Setup'!$B$18:$B$23,0)),1,IF($E40>=INDEX('Program Setup'!$D$18:$D$23,MATCH($C40,'Program Setup'!$B$18:$B$23,0)),2,IF($E40>=INDEX('Program Setup'!$E$18:$E$23,MATCH($C40,'Program Setup'!$B$18:$B$23,0)),3,"-"))),"-")) | I40: =IF(ISNUMBER($H40),INDEX('Program Setup'!$B$6:$B$8,MATCH($H40,'Program Setup'!$A$6:$A$8,0)),0) | J40: =SUMIFS('Amplify Detail'!$E$5:$E$496,'Amplify Detail'!$A$5:$A$496,$A40,'Amplify Detail'!$C$5:$C$496,$C40) | K40: =SUMIFS('Amplify Detail'!$F$5:$F$496,'Amplify Detail'!$A$5:$A$496,$A40,'Amplify Detail'!$C$5:$C$496,$C40) | L40: =SUMIFS('Amplify Detail'!$G$5:$G$496,'Amplify Detail'!$A$5:$A$496,$A40,'Amplify Detail'!$C$5:$C$496,$C40) | M40: =SUMIFS('Amplify Detail'!$J$5:$J$496,'Amplify Detail'!$A$5:$A$496,$A40,'Amplify Detail'!$C$5:$C$496,$C40) | N40: =$I40+$M40 | O40: =IF($G40="No qualifier - Amplify open",1,IFERROR(INDEX('Program Setup'!$B$12:$B$14,MATCH($G40,'Program Setup'!$A$12:$A$14,0)),0)) | P40: =$A40&"|"&$C40
A41: Brian Sengebush | B41: Chris McCrohan | C41: New Belgium Brewing Company | F41: =IF($D41>0,$E41/$D41,"") | G41: =IF($D41>0,IF($F41>=1,"Qualified",IF($F41>=0.9,"90% Partial Amplify","Not Qualified")),"No qualifier - Amplify open") | H41: =IF($G41<>"Qualified","-",IFERROR(IF($E41>=INDEX('Program Setup'!$C$18:$C$23,MATCH($C41,'Program Setup'!$B$18:$B$23,0)),1,IF($E41>=INDEX('Program Setup'!$D$18:$D$23,MATCH($C41,'Program Setup'!$B$18:$B$23,0)),2,IF($E41>=INDEX('Program Setup'!$E$18:$E$23,MATCH($C41,'Program Setup'!$B$18:$B$23,0)),3,"-"))),"-")) | I41: =IF(ISNUMBER($H41),INDEX('Program Setup'!$B$6:$B$8,MATCH($H41,'Program Setup'!$A$6:$A$8,0)),0) | J41: =SUMIFS('Amplify Detail'!$E$5:$E$496,'Amplify Detail'!$A$5:$A$496,$A41,'Amplify Detail'!$C$5:$C$496,$C41) | K41: =SUMIFS('Amplify Detail'!$F$5:$F$496,'Amplify Detail'!$A$5:$A$496,$A41,'Amplify Detail'!$C$5:$C$496,$C41) | L41: =SUMIFS('Amplify Detail'!$G$5:$G$496,'Amplify Detail'!$A$5:$A$496,$A41,'Amplify Detail'!$C$5:$C$496,$C41) | M41: =SUMIFS('Amplify Detail'!$J$5:$J$496,'Amplify Detail'!$A$5:$A$496,$A41,'Amplify Detail'!$C$5:$C$496,$C41) | N41: =$I41+$M41 | O41: =IF($G41="No qualifier - Amplify open",1,IFERROR(INDEX('Program Setup'!$B$12:$B$14,MATCH($G41,'Program Setup'!$A$12:$A$14,0)),0)) | P41: =$A41&"|"&$C41
...

Sheet Program Setup
A1: Summer of Success 2026 — program rules used in this recap
A2: Season 6/1/2026–8/31/2026. Blue = typed in from the deck / source data. Everything on the other tabs is a formula off these cells.
A4: Tier payout amounts
A5: Tier | B5: Payout
A6: 1 | B6: 750
A7: 2 | B7: 500
A8: 3 | B8: 250
A10: Amplify rate multiplier by qualifier result
A11: Qualifier result | B11: Amplify rate multiplier
A12: Qualified | B12: 1
A13: 90% Partial Amplify | B13: 0.5
A14: Not Qualified | B14: 0
A16: Tier CE thresholds by supplier — the deck's “Rewards Payouts — by Route Volume” grid
A17: Supplier (deck) | B17: Supplier (as named in the data) | C17: Tier 1 CE | D17: Tier 2 CE | E17: Tier 3 CE
A18: Constellation Brands | B18: Constellation Brands | C18: 25000 | D18: 6000 | E18: 1000
A19: Molson Coors | B19: MolsonCoors Beverage Company | C19: 16000 | D19: 8000 | E19: 1000
A20: Heineken (HUSA) | B20: Heineken USA | C20: 8200 | D20: 2300 | E20: 100
A21: Yuengling | B21: DG Yuengling Inc | C21: 2600 | D21: 1000 | E21: 100
A22: Mike's (MABI) | B22: Mark Anthony | C22: 4000 | D22: 1000 | E22: 500
A23: Boston Beer co. | B23: Boston Beer Company | C23: 4000 | D23: 2000 | E23: 500
A26: Rules applied
A27: 1. QUALIFIER — a rep clears a supplier when their 2026 qualifier CE reaches their own personal goal (goals are per rep, not flat).
A28: 2. TIER PAYOUT — only at 100%+ of goal. The tier is then read off the grid above using that same actual 2026 qualifier CE.
A29: Example: Javier Melo, Constellation Brands, goal 71,156, actual 71,979 = 101% → Qualified; 71,979 clears the 25,000 Tier 1 line → $750.
A30: 3. AMPLIFY — pays ONLY on cases ABOVE the brand's Amplify goal: Eligible CE = MAX(Actual CE − Amplify goal CE, 0), calculated PER BRAND.
A31: A brand below its goal pays $0 and does NOT offset a brand that is above goal.
A32: Example: Javier Melo, Constellation Brands — Pacifico 1,538 − 975 = 563 × $1 = $563; Modelo Chelada 3,272 − 3,102 = 170 × $1 = $170; Victoria 3,355 − 3,216 = 139 × $1 = $139. Total $872.
A33: 4. AMPLIFY RATE — $1/case, except Fever Tree, Mike's Harder and MXD at $2/case.
A34: 5. 90% PARTIAL — 90.00%–99.99% of the qualifier goal earns NO tier payout but HALF the Amplify rate ($0.50 / $1.00). Below 90% earns no Amplify at all.
A35: 6. Suppliers with no qualifier in the data (Sapporo, Cape May, New Belgium) have no tier payout; their Amplify is open at full rate.
A36: 7. Excluded, matching the dashboard: Default, Office Tell Sell, Chris Politano. Bell's is rolled into New Belgium Brewing Company.
A38: ⚠ FOUR THINGS TO CONFIRM BEFORE THIS PAYS ANYONE
... A47: The largest is Michael Harboy, MolsonCoors Beverage Company, 3,941 CE. Filter Status for that label to see them. If those reps were meant to have goals, their tier payout is being missed.

Sheet Amplify Detail
A1: Amplify detail — brand level
A2: Amplify pays ONLY on cases above the brand's goal: Eligible = MAX(Actual − Goal, 0), per brand. A brand below goal pays $0 and does not offset others.
A4: Rep | B4: Manager | C4: Supplier | D4: Amplify brand | E4: Actual CE (2026) | F4: Amplify goal CE (2025) | G4: Eligible CE (above goal) | H4: Normal rate | I4: Applied rate | J4: Payout | K4: Key
A5: Alex Rodriguez | B5: Mike Kennedy | C5: Sapporo | D5: Sapporo | E5: 875 | F5: 578 | G5: =MAX(0,$E5-$F5) | H5: =IF(OR(ISNUMBER(SEARCH("fever",$D5)),ISNUMBER(SEARCH("mike",$D5)),ISNUMBER(SEARCH("mxd",$D5))),2,1) | I5: =$H5*IFERROR(INDEX('Recap'!$O$5:$O$233,MATCH($K5,'Recap'!$P$5:$P$233,0)),0) | J5: =$G5*$I5 | K5: =$A5&"|"&$C5
A6: Alisa Acciardi | B6: Mike Kennedy | C6: Boston Beer Company | D6: Dogfish Head Beer | E6: 2 | F6: 6 | G6: =MAX(0,$E6-$F6) | H6: =IF(OR(ISNUMBER(SEARCH("fever",$D6)),ISNUMBER(SEARCH("mike",$D6)),ISNUMBER(SEARCH("mxd",$D6))),2,1) | I6: =$H6*IFERROR(INDEX('Recap'!$O$5:$O$233,MATCH($K6,'Recap'!$P$5:$P$233,0)),0) | J6: =$G6*$I6 | K6: =$A6&"|"&$C6
A7: Alisa Acciardi | B7: Mike Kennedy | C7: Cape May | D7: Cape May | E7: 0 | F7: 8 | G7: =MAX(0,$E7-$F7) | H7: =IF(OR(ISNUMBER(SEARCH("fever",$D7)),ISNUMBER(SEARCH("mike",$D7)),ISNUMBER(SEARCH("mxd",$D7))),2,1) | I7: =$H7*IFERROR(INDEX('Recap'!$O$5:$O$233,MATCH($K7,'Recap'!$P$5:$P$233,0)),0) | J7: =$G7*$I7 | K7: =$A7&"|"&$C7
A8: Alisa Acciardi | B8: Mike Kennedy | C8: Constellation Brands | D8: Corona Premier | E8: 6 | F8: 7 | G8: =MAX(0,$E8-$F8) | H8: =IF(OR(ISNUMBER(SEARCH("fever",$D8)),ISNUMBER(SEARCH("mike",$D8)),ISNUMBER(SEARCH("mxd",$D8))),2,1) | I8: =$H8*IFERROR(INDEX('Recap'!$O$5:$O$233,MATCH($K8,'Recap'!$P$5:$P$233,0)),0) | J8: =$G8*$I8 | K8: =$A8&"|"&$C8
A9: Alisa Acciardi | B9: Mike Kennedy | C9: Constellation Brands | D9: Modelo Chelada | E9: 31 | F9: 51 | G9: =MAX(0,$E9-$F9) | H9: =IF(OR(ISNUMBER(SEARCH("fever",$D9)),ISNUMBER(SEARCH("mike",$D9)),ISNUMBER(SEARCH("mxd",$D9))),2,1) | I9: =$H9*IFERROR(INDEX('Recap'!$O$5:$O$233,MATCH($K9,'Recap'!$P$5:$P$233,0)),0) | J9: =$G9*$I9 | K9: =$A9&"|"&$C9
A10: Alisa Acciardi | B10: Mike Kennedy | C10: Constellation Brands | D10: Pacifico | E10: 8 | F10: 34 | G10: =MAX(0,$E10-$F10) | H10: =IF(OR(ISNUMBER(SEARCH("fever",$D10)),ISNUMBER(SEARCH("mike",$D10)),ISNUMBER(SEARCH("mxd",$D10))),2,1) | I10: =$H10*IFERROR(INDEX('Recap'!$O$5:$O$233,MATCH($K10,'Recap'!$P$5:$P$233,0)),0) | J10: =$G10*$I10 | K10: =$A10&"|"&$C10
A11: Alisa Acciardi | B11: Mike Kennedy | C11: Constellation Brands | D11: Victoria | E11: 9 | F11: 5 | G11: =MAX(0,$E11-$F11) | H11: =IF(OR(ISNUMBER(SEARCH("fever",$D11)),ISNUMBER(SEARCH("mike",$D11)),ISNUMBER(SEARCH("mxd",$D11))),2,1) | I11: =$H11*IFERROR(INDEX('Recap'!$O$5:$O$233,MATCH($K11,'Recap'!$P$5:$P$233,0)),0) | J11: =$G11*$I11 | K11: =$A11&"|"&$C11
A12: Alisa Acciardi | B12: Mike Kennedy | C12: DG Yuengling Inc | D12: Yuengling Flight | E12: 2 | F12: 2 | G12: =MAX(0,$E12-$F12) | H12: =IF(OR(ISNUMBER(SEARCH("fever",$D12)),ISNUMBER(SEARCH("mike",$D12)),ISNUMBER(SEARCH("mxd",$D12))),2,1) | I12: =$H12*IFERROR(INDEX('Recap'!$O$5:$O$233,MATCH($K12,'Recap'!$P$5:$P$233,0)),0) | J12: =$G12*$I12 | K12: =$A12&"|"&$C12
A13: Alisa Acciardi | B13: Mike Kennedy | C13: DG Yuengling Inc | D13: Yuengling Light Lager | E13: 2 | F13: 1 | G13: =MAX(0,$E13-$F13) | H13: =IF(OR(ISNUMBER(SEARCH("fever",$D13)),ISNUMBER(SEARCH("mike",$D13)),ISNUMBER(SEARCH("mxd",$D13))),2,1) | I13: =$H13*IFERROR(INDEX('Recap'!$O$5:$O$233,MATCH($K13,'Recap'!$P$5:$P$233,0)),0) | J13: =$G13*$I13 | K13: =$A13&"|"&$C13
A14: Alisa Acciardi | B14: Mike Kennedy | C14: Heineken USA | D14: Heineken 0.0 | E14: 3 | F14: 8 | G14: =MAX(0,$E14-$F14) | H14: =IF(OR(ISNUMBER(SEARCH("fever",$D14)),ISNUMBER(SEARCH("mike",$D14)),ISNUMBER(SEARCH("mxd",$D14))),2,1) | I14: =$H14*IFERROR(INDEX('Recap'!$O$5:$O$233,MATCH($K14,'Recap'!$P$5:$P$233,0)),0) | J14: =$G14*$I14 | K14: =$A14&"|"&$C14
A15: Alisa Acciardi | B15: Mike Kennedy | C15: Heineken USA | D15: Heineken Light | E15: 12 | F15: 19 | G15: =MAX(0,$E15-$F15) | H15: =IF(OR(ISNUMBER(SEARCH("fever",$D15)),ISNUMBER(SEARCH("mike",$D15)),ISNUMBER(SEARCH("mxd",$D15))),2,1) | I15: =$H15*IFERROR(INDEX('Recap'!$O$5:$O$233,MATCH($K15,'Recap'!$P$5:$P$233,0)),0) | J15: =$G15*$I15 | K15: =$A15&"|"&$C15
A16: Alisa Acciardi | B16: Mike Kennedy | C16: Mark Anthony | D16: Cayman Jack | E16: 3 | F16: 5 | G16: =MAX(0,$E16-$F16) | H16: =IF(OR(ISNUMBER(SEARCH("fever",$D16)),ISNUMBER(SEARCH("mike",$D16)),ISNUMBER(SEARCH("mxd",$D16))),2,1) | I16: =$H16*IFERROR(INDEX('Recap'!$O$5:$O$233,MATCH($K16,'Recap'!$P$5:$P$233,0)),0) | J16: =$G16*$I16 | K16: =$A16&"|"&$C16
... A259: Jim Heaney | B259: Denise Montes | C259: Sapporo | D259: Sapporo | E259: 532 | F259: 409 | G259: =MAX(0,$E259-$F259) | H259: =IF(OR(ISNUMBER(SEARCH("fever",$D259)),ISNUMBER(SEARCH("mike",$D259)),ISNUMBER(SEARCH("mxd",$D259))),2,1) | I259: =$H259*IFERROR(INDEX('Recap'!$O$5:$O$233,MATCH($K259,'Recap'!$P$5:$P$233,0)),0) | J259: =$G259*$I259 | K259: =$A259&"|"&$C259
A260: John Neukum | C260: Constellation Brands | D260: Corona Premier | E260: 336 | F260: 168 | G260: =MAX(0,$E260-$F260) | H260: =IF(OR(ISNUMBER(SEARCH("fever",$D260)),ISNUMBER(SEARCH("mike",$D260)),ISNUMBER(SEARCH("mxd",$D260))),2,1) | I260: =$H260*IFERROR(INDEX('Recap'!$O$5:$O$233,MATCH($K260,'Recap'!$P$5:$P$233,0)),0) | J260: =$G260*$I260 | K260: =$A260&"|"&$C260
A261: John Neukum | C261: Constellation Brands | D261: Modelo Chelada | E261: 2129 | F261: 987 | G261: =MAX(0,$E261-$F261) | H261: =IF(OR(ISNUMBER(SEARCH("fever",$D261)),ISNUMBER(SEARCH("mike",$D261)),ISNUMBER(SEARCH("mxd",$D261))),2,1) | I261: =$H261*IFERROR(INDEX('Recap'!$O$5:$O$233,MATCH($K261,'Recap'!$P$5:$P$233,0)),0) | J261: =$G261*$I261 | K261: =$A261&"|"&$C261
A262: John Neukum | C262: Constellation Brands | D262: Pacifico | E262: 794 | F262: 567 | G262: =MAX(0,$E262-$F262) | H262: =IF(OR(ISNUMBER(SEARCH("fever",$D262)),ISNUMBER(SEARCH("mike",$D262)),ISNUMBER(SEARCH("mxd",$D262))),2,1) | I262: =$H262*IFERROR(INDEX('Recap'!$O$5:$O$233,MATCH($K262,'Recap'!$P$5:$P$233,0)),0) | J262: =$G262*$I262 | K262: =$A262&"|"&$C262
A263: John Neukum | C263: Constellation Brands | D263: Victoria | E263: 3527 | F263: 2261 | G263: =MAX(0,$E263-$F263) | H263: =IF(OR(ISNUMBER(SEARCH("fever",$D263)),ISNUMBER(SEARCH("mike",$D263)),ISNUMBER(SEARCH("mxd",$D263))),2,1) | I263: =$H263*IFERROR(INDEX('Recap'!$O$5:$O$233,MATCH($K263,'Recap'!$P$5:$P$233,0)),0) | J263: =$G263*$I263 | K263: =$A263&"|"&$C263
A264: John Neukum | C264: Heineken USA | D264: Heineken 0.0 | E264: 174 | F264: 375 | G264: =MAX(0,$E264-$F264) | H264: =IF(OR(ISNUMBER(SEARCH("fever",$D264)),ISNUMBER(SEARCH("mike",$D264)),ISNUMBER(SEARCH("mxd",$D264))),2,1) | I264: =$H264*IFERROR(INDEX('Recap'!$O$5:$O$233,MATCH($K264,'Recap'!$P$5:$P$233,0)),0) | J264: =$G264*$I264 | K264: =$A264&"|"&$C264
A265: John Neukum | C265: Heineken USA | D265: Heineken Light | E265: 756 | F265: 588 | G265: =MAX(0,$E265-$F265) | H265: =IF(OR(ISNUMBER(SEARCH("fever",$D265)),ISNUMBER(SEARCH("mike",$D265)),ISNUMBER(SEARCH("mxd",$D265))),2,1) | I265: =$H265*IFERROR(INDEX('Recap'!$O$5:$O$233,MATCH($K265,'Recap'!$P$5:$P$233,0)),0) | J265: =$G265*$I265 | K265: =$A265&"|"&$C265
A266: John Neukum | C266: Mark Anthony | D266: Cayman Jack | E266: 949 | F266: 943 | G266: =MAX(0,$E266-$F266) | H266: =IF(OR(ISNUMBER(SEARCH("fever",$D266)),ISNUMBER(SEARCH("mike",$D266)),ISNUMBER(SEARCH("mxd",$D266))),2,1) | I266: =$H266*IFERROR(INDEX('Recap'!$O$5:$O$233,MATCH($K266,'Recap'!$P$5:$P$233,0)),0) | J266: =$G266*$I266 | K266: =$A266&"|"&$C266
A267: John Neukum | C267: MolsonCoors Beverage Company | D267: Coors | E267: 1175 | F267: 1078 | G267: =MAX(0,$E267-$F267) | H267: =IF(OR(ISNUMBER(SEARCH("fever",$D267)),ISNUMBER(SEARCH("mike",$D267)),ISNUMBER(SEARCH("mxd",$D267))),2,1) | I267: =$H267*IFERROR(INDEX('Recap'!$O$5:$O$233,MATCH($K267,'Recap'!$P$5:$P$233,0)),0) | J267: =$G267*$I267 | K267: =$A267&"|"&$C267
A268: John Neukum | C268: MolsonCoors Beverage Company | D268: Fever Tree | E268: 39 | F268: 0 | G268: =MAX(0,$E268-$F268) | H268: =IF(OR(ISNUMBER(SEARCH("fever",$D268)),ISNUMBER(SEARCH("mike",$D268)),ISNUMBER(SEARCH("mxd",$D268))),2,1) | I268: =$H268*IFERROR(INDEX('Recap'!$O$5:$O$233,MATCH($K268,'Recap'!$P$5:$P$233,0)),0) | J268: =$G268*$I268 | K268: =$A268&"|"&$C268
A269: John Neukum | C269: MolsonCoors Beverage Company | D269: Peroni | E269: 1457 | F269: 1604 | G269: =MAX(0,$E269-$F269) | H269: =IF(OR(ISNUMBER(SEARCH("fever",$D269)),ISNUMBER(SEARCH("mike",$D269)),ISNUMBER(SEARCH("mxd",$D269))),2,1) | I269: =$H269*IFERROR(INDEX('Recap'!$O$5:$O$233,MATCH($K269,'Recap'!$P$5:$P$233,0)),0) | J269: =$G269*$I269 | K269: =$A269&"|"&$C269
A270: John Neukum | C270: New Belgium Brewing Company | D270: Voodoo Family | E270: 40 | F270: 60 | G270: =MAX(0,$E270-$F270) | H270: =IF(OR(ISNUMBER(SEARCH("fever",$D270)),ISNUMBER(SEARCH("mike",$D270)),ISNUMBER(SEARCH("mxd",$D270))),2,1) | I270: =$H270*IFERROR(INDEX('Recap'!$O$5:$O$233,MATCH($K270,'Recap'!$P$5:$P$233,0)),0) | J270: =$G270*$I270 | K270: =$A270&"|"&$C270
